Workbook

Sheet Settings
A1: WTI crude (CL): every individual futures contract since 2016 (oil-futures)
A3: Start date | B3: 42370 | C3: First date of history
A4: End date | C4: Leave blank for today
A5: As-of date | B5: 46308 | C5: Set to today's date; decides expired vs live tickers
A7: Legend
A8: Yellow cells with blue text | B8: inputs you may change; everything else is a formula
A10: How to use
A11: 1. Open this file in Excel on the Bloomberg PC with the Terminal logged in. Click Enable Editing / Enable Content.
A12: 2. Wait until no cell says 'Requesting Data...'. If nothing loads: Bloomberg tab > Refresh > Refresh Workbook.
A13: 3. A cell reading '#N/A Invalid Security' or '#N/A Field Not Applicable' just means that item is unavailable.
A14: 4. File > Save As, keep .xlsx, and add the date to the name. Upload the saved file to Claude.
A15: 5. Row 1 ticker: expired contracts use a 2-digit year (CLZ25), live ones 1-digit (CLZ6). It switches on the As-of date.
A16: 6. If one contract shows '#N/A Invalid Security', change As-of date to today and reopen.

Sheet CL 2016
A1: ="CLF"&IF(A2<Settings!$B$5,"16","6")&" Comdty" | J1: ="CLG"&IF(J2<Settings!$B$5,"16","6")&" Comdty" | S1: ="CLH"&IF(S2<Settings!$B$5,"16","6")&" Comdty" | AB1: ="CLJ"&IF(AB2<Settings!$B$5,"16","6")&" Comdty" | AK1: ="CLK"&IF(AK2<Settings!$B$5,"16","6")&" Comdty" | AT1: ="CLM"&IF(AT2<Settings!$B$5,"16","6")&" Comdty" | BC1: ="CLN"&IF(BC2<Settings!$B$5,"16","6")&" Comdty" | BL1: ="CLQ"&IF(BL2<Settings!$B$5,"16","6")&" Comdty" | BU1: ="CLU"&IF(BU2<Settings!$B$5,"16","6")&" Comdty" | CD1: ="CLV"&IF(CD2<Settings!$B$5,"16","6")&" Comdty" | CM1: ="CLX"&IF(CM2<Settings!$B$5,"16","6")&" Comdty" | CV1: ="CLZ"&IF(CV2<Settings!$B$5,"16","6")&" Comdty"
A2: =WORKDAY(DATE(2016,0,25),-3) | B2: =BDP(A$1,"LAST_TRADEABLE_DT") | J2: =WORKDAY(DATE(2016,1,25),-3) | K2: =BDP(J$1,"LAST_TRADEABLE_DT") | S2: =WORKDAY(DATE(2016,2,25),-3) | T2: =BDP(S$1,"LAST_TRADEABLE_DT") | AB2: =WORKDAY(DATE(2016,3,25),-3) | AC2: =BDP(AB$1,"LAST_TRADEABLE_DT") | AK2: =WORKDAY(DATE(2016,4,25),-3) | AL2: =BDP(AK$1,"LAST_TRADEABLE_DT") | AT2: =WORKDAY(DATE(2016,5,25),-3) | AU2: =BDP(AT$1,"LAST_TRADEABLE_DT") | BC2: =WORKDAY(DATE(2016,6,25),-3) | BD2: =BDP(BC$1,"LAST_TRADEABLE_DT") | BL2: =WORKDAY(DATE(2016,7,25),-3) | BM2: =BDP(BL$1,"LAST_TRADEABLE_DT") | BU2: =WORKDAY(DATE(2016,8,25),-3) | BV2: =BDP(BU$1,"LAST_TRADEABLE_DT") | CD2: =WORKDAY(DATE(2016,9,25),-3) | CE2: =BDP(CD$1,"LAST_TRADEABLE_DT") | CM2: =WORKDAY(DATE(2016,10,25),-3) | CN2: =BDP(CM$1,"LAST_TRADEABLE_DT") | CV2: =WORKDAY(DATE(2016,11,25),-3) | CW2: =BDP(CV$1,"LAST_TRADEABLE_DT")
A3: Date | B3: PX_OPEN | C3: PX_HIGH | D3: PX_LOW | E3: PX_LAST | F3: PX_SETTLE | G3: PX_VOLUME | H3: OPEN_INT | J3: Date | K3: PX_OPEN | L3: PX_HIGH | M3: PX_LOW | N3: PX_LAST | O3: PX_SETTLE | P3: PX_VOLUME | Q3: OPEN_INT | S3: Date | T3: PX_OPEN | U3: PX_HIGH | V3: PX_LOW | W3: PX_LAST | X3: PX_SETTLE | Y3: PX_VOLUME | Z3: OPEN_INT | AB3: Date | AC3: PX_OPEN | AD3: PX_HIGH | AE3: PX_LOW | AF3: PX_LAST | AG3: PX_SETTLE | AH3: PX_VOLUME | AI3: OPEN_INT | AK3: Date | AL3: PX_OPEN | AM3: PX_HIGH | AN3: PX_LOW | AO3: PX_LAST | AP3: PX_SETTLE | AQ3: PX_VOLUME | AR3: OPEN_INT | AT3: Date | AU3: PX_OPEN | AV3: PX_HIGH | AW3: PX_LOW | AX3: PX_LAST | AY3: PX_SETTLE | AZ3: PX_VOLUME | BA3: OPEN_INT | BC3: Date | BD3: PX_OPEN | BE3: PX_HIGH | BF3: PX_LOW | BG3: PX_LAST | BH3: PX_SETTLE | BI3: PX_VOLUME | BJ3: OPEN_INT | BL3: Date | BM3: PX_OPEN | BN3: PX_HIGH | BO3: PX_LOW | BP3: PX_LAST | BQ3: PX_SETTLE | BR3: PX_VOLUME | BS3: OPEN_INT | BU3: Date | BV3: PX_OPEN | BW3: PX_HIGH | BX3: PX_LOW | BY3: PX_LAST | BZ3: PX_SETTLE | CA3: PX_VOLUME | CB3: OPEN_INT | CD3: Date | CE3: PX_OPEN | CF3: PX_HIGH | CG3: PX_LOW | CH3: PX_LAST | CI3: PX_SETTLE | CJ3: PX_VOLUME | CK3: OPEN_INT | CM3: Date | CN3: PX_OPEN | CO3: PX_HIGH | CP3: PX_LOW | CQ3: PX_LAST | CR3: PX_SETTLE | CS3: PX_VOLUME | CT3: OPEN_INT | CV3: Date | CW3: PX_OPEN | CX3: PX_HIGH | CY3: PX_LOW | CZ3: PX_LAST | DA3: PX_SETTLE | DB3: PX_VOLUME | DC3: OPEN_INT
A4: =BDH(A$1,B$3:H$3,Settings!$B$3,IF(Settings!$B$4="","",Settings!$B$4),"Dir=V","Dts=S","Sort=A","Days=T","Fill=B") | J4: =BDH(J$1,K$3:Q$3,Settings!$B$3,IF(Settings!$B$4="","",Settings!$B$4),"Dir=V","Dts=S","Sort=A","Days=T","Fill=B") | S4: =BDH(S$1,T$3:Z$3,Settings!$B$3,IF(Settings!$B$4="","",Settings!$B$4),"Dir=V","Dts=S","Sort=A","Days=T","Fill=B") | AB4: =BDH(AB$1,AC$3:AI$3,Settings!$B$3,IF(Settings!$B$4="","",Settings!$B$4),"Dir=V","Dts=S","Sort=A","Days=T","Fill=B") | AK4: =BDH(AK$1,AL$3:AR$3,Settings!$B$3,IF(Settings!$B$4="","",Settings!$B$4),"Dir=V","Dts=S","Sort=A","Days=T","Fill=B") | AT4: =BDH(AT$1,AU$3:BA$3,Settings!$B$3,IF(Settings!$B$4="","",Settings!$B$4),"Dir=V","Dts=S","Sort=A","Days=T","Fill=B") | BC4: =BDH(BC$1,BD$3:BJ$3,Settings!$B$3,IF(Settings!$B$4="","",Settings!$B$4),"Dir=V","Dts=S","Sort=A","Days=T","Fill=B") | BL4: =BDH(BL$1,BM$3:BS$3,Settings!$B$3,IF(Settings!$B$4="","",Settings!$B$4),"Dir=V","Dts=S","Sort=A","Days=T","Fill=B") | BU4: =BDH(BU$1,BV$3:CB$3,Settings!$B$3,IF(Settings!$B$4="","",Settings!$B$4),"Dir=V","Dts=S","Sort=A","Days=T","Fill=B") | CD4: =BDH(CD$1,CE$3:CK$3,Settings!$B$3,IF(Settings!$B$4="","",Settings!$B$4),"Dir=V","Dts=S","Sort=A","Days=T","Fill=B") | CM4: =BDH(CM$1,CN$3:CT$3,Settings!$B$3,IF(Settings!$B$4="","",Settings!$B$4),"Dir=V","Dts=S","Sort=A","Days=T","Fill=B") | CV4: =BDH(CV$1,CW$3:DC$3,Settings!$B$3,IF(Settings!$B$4="","",Settings!$B$4),"Dir=V","Dts=S","Sort=A","Days=T","Fill=B")

Sheet CL 2017
A1: ="CLF"&IF(A2<Settings!$B$5,"17","7")&" Comdty" | J1: ="CLG"&IF(J2<Settings!$B$5,"17","7")&" Comdty" | S1: ="CLH"&IF(S2<Settings!$B$5,"17","7")&" Comdty" | AB1: ="CLJ"&IF(AB2<Settings!$B$5,"17","7")&" Comdty" | AK1: ="CLK"&IF(AK2<Settings!$B$5,"17","7")&" Comdty" | AT1: ="CLM"&IF(AT2<Settings!$B$5,"17","7")&" Comdty" | BC1: ="CLN"&IF(BC2<Settings!$B$5,"17","7")&" Comdty" | BL1: ="CLQ"&IF(BL2<Settings!$B$5,"17","7")&" Comdty" | BU1: ="CLU"&IF(BU2<Settings!$B$5,"17","7")&" Comdty" | CD1: ="CLV"&IF(CD2<Settings!$B$5,"17","7")&" Comdty" | CM1: ="CLX"&IF(CM2<Settings!$B$5,"17","7")&" Comdty" | CV1: ="CLZ"&IF(CV2<Settings!$B$5,"17","7")&" Comdty"
A2: =WORKDAY(DATE(2017,0,25),-3) | B2: =BDP(A$1,"LAST_TRADEABLE_DT") | J2: =WORKDAY(DATE(2017,1,25),-3) | K2: =BDP(J$1,"LAST_TRADEABLE_DT") | S2: =WORKDAY(DATE(2017,2,25),-3) | T2: =BDP(S$1,"LAST_TRADEABLE_DT") | AB2: =WORKDAY(DATE(2017,3,25),-3) | AC2: =BDP(AB$1,"LAST_TRADEABLE_DT") | AK2: =WORKDAY(DATE(2017,4,25),-3) | AL2: =BDP(AK$1,"LAST_TRADEABLE_DT") | AT2: =WORKDAY(DATE(2017,5,25),-3) | AU2: =BDP(AT$1,"LAST_TRADEABLE_DT") | BC2: =WORKDAY(DATE(2017,6,25),-3) | BD2: =BDP(BC$1,"LAST_TRADEABLE_DT") | BL2: =WORKDAY(DATE(2017,7,25),-3) | BM2: =BDP(BL$1,"LAST_TRADEABLE_DT") | BU2: =WORKDAY(DATE(2017,8,25),-3) | BV2: =BDP(BU$1,"LAST_TRADEABLE_DT") | CD2: =WORKDAY(DATE(2017,9,25),-3) | CE2: =BDP(CD$1,"LAST_TRADEABLE_DT") | CM2: =WORKDAY(DATE(2017,10,25),-3) | CN2: =BDP(CM$1,"LAST_TRADEABLE_DT") | CV2: =WORKDAY(DATE(2017,11,25),-3) | CW2: =BDP(CV$1,"LAST_TRADEABLE_DT")
A3: Date | B3: PX_OPEN | C3: PX_HIGH | D3: PX_LOW | E3: PX_LAST | F3: PX_SETTLE | G3: PX_VOLUME | H3: OPEN_INT | J3: Date | K3: PX_OPEN | L3: PX_HIGH | M3: PX_LOW | N3: PX_LAST | O3: PX_SETTLE | P3: PX_VOLUME | Q3: OPEN_INT | S3: Date | T3: PX_OPEN | U3: PX_HIGH | V3: PX_LOW | W3: PX_LAST | X3: PX_SETTLE | Y3: PX_VOLUME | Z3: OPEN_INT | AB3: Date | AC3: PX_OPEN | AD3: PX_HIGH | AE3: PX_LOW | AF3: PX_LAST | AG3: PX_SETTLE | AH3: PX_VOLUME | AI3: OPEN_INT | AK3: Date | AL3: PX_OPEN | AM3: PX_HIGH | AN3: PX_LOW | AO3: PX_LAST | AP3: PX_SETTLE | AQ3: PX_VOLUME | AR3: OPEN_INT | AT3: Date | AU3: PX_OPEN | AV3: PX_HIGH | AW3: PX_LOW | AX3: PX_LAST | AY3: PX_SETTLE | AZ3: PX_VOLUME | BA3: OPEN_INT | BC3: Date | BD3: PX_OPEN | BE3: PX_HIGH | BF3: PX_LOW | BG3: PX_LAST | BH3: PX_SETTLE | BI3: PX_VOLUME | BJ3: OPEN_INT | BL3: Date | BM3: PX_OPEN | BN3: PX_HIGH | BO3: PX_LOW | BP3: PX_LAST | BQ3: PX_SETTLE | BR3: PX_VOLUME | BS3: OPEN_INT | BU3: Date | BV3: PX_OPEN | BW3: PX_HIGH | BX3: PX_LOW | BY3: PX_LAST | BZ3: PX_SETTLE | CA3: PX_VOLUME | CB3: OPEN_INT | CD3: Date | CE3: PX_OPEN | CF3: PX_HIGH | CG3: PX_LOW | CH3: PX_LAST | CI3: PX_SETTLE | CJ3: PX_VOLUME | CK3: OPEN_INT | CM3: Date | CN3: PX_OPEN | CO3: PX_HIGH | CP3: PX_LOW | CQ3: PX_LAST | CR3: PX_SETTLE | CS3: PX_VOLUME | CT3: OPEN_INT | CV3: Date | CW3: PX_OPEN | CX3: PX_HIGH | CY3: PX_LOW | CZ3: PX_LAST | DA3: PX_SETTLE | DB3: PX_VOLUME | DC3: OPEN_INT
A4: =BDH(A$1,B$3:H$3,Settings!$B$3,IF(Settings!$B$4="","",Settings!$B$4),"Dir=V","Dts=S","Sort=A","Days=T","Fill=B") | J4: =BDH(J$1,K$3:Q$3,Settings!$B$3,IF(Settings!$B$4="","",Settings!$B$4),"Dir=V","Dts=S","Sort=A","Days=T","Fill=B") | S4: =BDH(S$1,T$3:Z$3,Settings!$B$3,IF(Settings!$B$4="","",Settings!$B$4),"Dir=V","Dts=S","Sort=A","Days=T","Fill=B") | AB4: =BDH(AB$1,AC$3:AI$3,Settings!$B$3,IF(Settings!$B$4="","",Settings!$B$4),"Dir=V","Dts=S","Sort=A","Days=T","Fill=B") | AK4: =BDH(AK$1,AL$3:AR$3,Settings!$B$3,IF(Settings!$B$4="","",Settings!$B$4),"Dir=V","Dts=S","Sort=A","Days=T","Fill=B") | AT4: =BDH(AT$1,AU$3:BA$3,Settings!$B$3,IF(Settings!$B$4="","",Settings!$B$4),"Dir=V","Dts=S","Sort=A","Days=T","Fill=B") | BC4: =BDH(BC$1,BD$3:BJ$3,Settings!$B$3,IF(Settings!$B$4="","",Settings!$B$4),"Dir=V","Dts=S","Sort=A","Days=T","Fill=B") | BL4: =BDH(BL$1,BM$3:BS$3,Settings!$B$3,IF(Settings!$B$4="","",Settings!$B$4),"Dir=V","Dts=S","Sort=A","Days=T","Fill=B") | BU4: =BDH(BU$1,BV$3:CB$3,Settings!$B$3,IF(Settings!$B$4="","",Settings!$B$4),"Dir=V","Dts=S","Sort=A","Days=T","Fill=B") | CD4: =BDH(CD$1,CE$3:CK$3,Settings!$B$3,IF(Settings!$B$4="","",Settings!$B$4),"Dir=V","Dts=S","Sort=A","Days=T","Fill=B") | CM4: =BDH(CM$1,CN$3:CT$3,Settings!$B$3,IF(Settings!$B$4="","",Settings!$B$4),"Dir=V","Dts=S","Sort=A","Days=T","Fill=B") | CV4: =BDH(CV$1,CW$3:DC$3,Settings!$B$3,IF(Settings!$B$4="","",Settings!$B$4),"Dir=V","Dts=S","Sort=A","Days=T","Fill=B")

Sheet CL 2018
A1: ="CLF"&IF(A2<Settings!$B$5,"18","8")&" Comdty" | J1: ="CLG"&IF(J2<Settings!$B$5,"18","8")&" Comdty" | S1: ="CLH"&IF(S2<Settings!$B$5,"18","8")&" Comdty" | AB1: ="CLJ"&IF(AB2<Settings!$B$5,"18","8")&" Comdty" | AK1: ="CLK"&IF(AK2<Settings!$B$5,"18","8")&" Comdty" | AT1: ="CLM"&IF(AT2<Settings!$B$5,"18","8")&" Comdty" | BC1: ="CLN"&IF(BC2<Settings!$B$5,"18","8")&" Comdty" | BL1: ="CLQ"&IF(BL2<Settings!$B$5,"18","8")&" Comdty" | BU1: ="CLU"&IF(BU2<Settings!$B$5,"18","8")&" Comdty" | CD1: ="CLV"&IF(CD2<Settings!$B$5,"18","8")&" Comdty" | CM1: ="CLX"&IF(CM2<Settings!$B$5,"18","8")&" Comdty" | CV1: ="CLZ"&IF(CV2<Settings!$B$5,"18","8")&" Comdty"
A2: =WORKDAY(DATE(2018,0,25),-3) | B2: =BDP(A$1,"LAST_TRADEABLE_DT") | J2: =WORKDAY(DATE(2018,1,25),-3) | K2: =BDP(J$1,"LAST_TRADEABLE_DT") | S2: =WORKDAY(DATE(2018,2,25),-3) | T2: =BDP(S$1,"LAST_TRADEABLE_DT") | AB2: =WORKDAY(DATE(2018,3,25),-3) | AC2: =BDP(AB$1,"LAST_TRADEABLE_DT") | AK2: =WORKDAY(DATE(2018,4,25),-3) | AL2: =BDP(AK$1,"LAST_TRADEABLE_DT") | AT2: =WORKDAY(DATE(2018,5,25),-3) | AU2: =BDP(AT$1,"LAST_TRADEABLE_DT") | BC2: =WORKDAY(DATE(2018,6,25),-3) | BD2: =BDP(BC$1,"LAST_TRADEABLE_DT") | BL2: =WORKDAY(DATE(2018,7,25),-3) | BM2: =BDP(BL$1,"LAST_TRADEABLE_DT") | BU2: =WORKDAY(DATE(2018,8,25),-3) | BV2: =BDP(BU$1,"LAST_TRADEABLE_DT") | CD2: =WORKDAY(DATE(2018,9,25),-3) | CE2: =BDP(CD$1,"LAST_TRADEABLE_DT") | CM2: =WORKDAY(DATE(2018,10,25),-3) | CN2: =BDP(CM$1,"LAST_TRADEABLE_DT") | CV2: =WORKDAY(DATE(2018,11,25),-3) | CW2: =BDP(CV$1,"LAST_TRADEABLE_DT")
A3: Date | B3: PX_OPEN | C3: PX_HIGH | D3: PX_LOW | E3: PX_LAST | F3: PX_SETTLE | G3: PX_VOLUME | H3: OPEN_INT | J3: Date | K3: PX_OPEN | L3: PX_HIGH | M3: PX_LOW | N3: PX_LAST | O3: PX_SETTLE | P3: PX_VOLUME | Q3: OPEN_INT | S3: Date | T3: PX_OPEN | U3: PX_HIGH | V3: PX_LOW | W3: PX_LAST | X3: PX_SETTLE | Y3: PX_VOLUME | Z3: OPEN_INT | AB3: Date | AC3: PX_OPEN | AD3: PX_HIGH | AE3: PX_LOW | AF3: PX_LAST | AG3: PX_SETTLE | AH3: PX_VOLUME | AI3: OPEN_INT | AK3: Date | AL3: PX_OPEN | AM3: PX_HIGH | AN3: PX_LOW | AO3: PX_LAST | AP3: PX_SETTLE | AQ3: PX_VOLUME | AR3: OPEN_INT | AT3: Date | AU3: PX_OPEN | AV3: PX_HIGH | AW3: PX_LOW | AX3: PX_LAST | AY3: PX_SETTLE | AZ3: PX_VOLUME | BA3: OPEN_INT | BC3: Date | BD3: PX_OPEN | BE3: PX_HIGH | BF3: PX_LOW | BG3: PX_LAST | BH3: PX_SETTLE | BI3: PX_VOLUME | BJ3: OPEN_INT | BL3: Date | BM3: PX_OPEN | BN3: PX_HIGH | BO3: PX_LOW | BP3: PX_LAST | BQ3: PX_SETTLE | BR3: PX_VOLUME | BS3: OPEN_INT | BU3: Date | BV3: PX_OPEN | BW3: PX_HIGH | BX3: PX_LOW | BY3: PX_LAST | BZ3: PX_SETTLE | CA3: PX_VOLUME | CB3: OPEN_INT | CD3: Date | CE3: PX_OPEN | CF3: PX_HIGH | CG3: PX_LOW | CH3: PX_LAST | CI3: PX_SETTLE | CJ3: PX_VOLUME | CK3: OPEN_INT | CM3: Date | CN3: PX_OPEN | CO3: PX_HIGH | CP3: PX_LOW | CQ3: PX_LAST | CR3: PX_SETTLE | CS3: PX_VOLUME | CT3: OPEN_INT | CV3: Date | CW3: PX_OPEN | CX3: PX_HIGH | CY3: PX_LOW | CZ3: PX_LAST | DA3: PX_SETTLE | DB3: PX_VOLUME | DC3: OPEN_INT
A4: =BDH(A$1,B$3:H$3,Settings!$B$3,IF(Settings!$B$4="","",Settings!$B$4),"Dir=V","Dts=S","Sort=A","Days=T","Fill=B") | J4: =BDH(J$1,K$3:Q$3,Settings!$B$3,IF(Settings!$B$4="","",Settings!$B$4),"Dir=V","Dts=S","Sort=A","Days=T","Fill=B") | S4: =BDH(S$1,T$3:Z$3,Settings!$B$3,IF(Settings!$B$4="","",Settings!$B$4),"Dir=V","Dts=S","Sort=A","Days=T","Fill=B") | AB4: =BDH(AB$1,AC$3:AI$3,Settings!$B$3,IF(Settings!$B$4="","",Settings!$B$4),"Dir=V","Dts=S","Sort=A","Days=T","Fill=B") | AK4: =BDH(AK$1,AL$3:AR$3,Settings!$B$3,IF(Settings!$B$4="","",Settings!$B$4),"Dir=V","Dts=S","Sort=A","Days=T","Fill=B") | AT4: =BDH(AT$1,AU$3:BA$3,Settings!$B$3,IF(Settings!$B$4="","",Settings!$B$4),"Dir=V","Dts=S","Sort=A","Days=T","Fill=B") | BC4: =BDH(BC$1,BD$3:BJ$3,Settings!$B$3,IF(Settings!$B$4="","",Settings!$B$4),"Dir=V","Dts=S","Sort=A","Days=T","Fill=B") | BL4: =BDH(BL$1,BM$3:BS$3,Settings!$B$3,IF(Settings!$B$4="","",Settings!$B$4),"Dir=V","Dts=S","Sort=A","Days=T","Fill=B") | BU4: =BDH(BU$1,BV$3:CB$3,Settings!$B$3,IF(Settings!$B$4="","",Settings!$B$4),"Dir=V","Dts=S","Sort=A","Days=T","Fill=B") | CD4: =BDH(CD$1,CE$3:CK$3,Settings!$B$3,IF(Settings!$B$4="","",Settings!$B$4),"Dir=V","Dts=S","Sort=A","Days=T","Fill=B") | CM4: =BDH(CM$1,CN$3:CT$3,Settings!$B$3,IF(Settings!$B$4="","",Settings!$B$4),"Dir=V","Dts=S","Sort=A","Days=T","Fill=B") | CV4: =BDH(CV$1,CW$3:DC$3,Settings!$B$3,IF(Settings!$B$4="","",Settings!$B$4),"Dir=V","Dts=S","Sort=A","Days=T","Fill=B")

Sheet CL 2019
A1: ="CLF"&IF(A2<Settings!$B$5,"19","9")&" Comdty" | J1: ="CLG"&IF(J2<Settings!$B$5,"19","9")&" Comdty" | S1: ="CLH"&IF(S2<Settings!$B$5,"19","9")&" Comdty" | AB1: ="CLJ"&IF(AB2<Settings!$B$5,"19","9")&" Comdty" | AK1: ="CLK"&IF(AK2<Settings!$B$5,"19","9")&" Comdty" | AT1: ="CLM"&IF(AT2<Settings!$B$5,"19","9")&" Comdty" | BC1: ="CLN"&IF(BC2<Settings!$B$5,"19","9")&" Comdty" | BL1: ="CLQ"&IF(BL2<Settings!$B$5,"19","9")&" Comdty" | BU1: ="CLU"&IF(BU2<Settings!$B$5,"19","9")&" Comdty" | CD1: ="CLV"&IF(CD2<Settings!$B$5,"19","9")&" Comdty" | CM1: ="CLX"&IF(CM2<Settings!$B$5,"19","9")&" Comdty" | CV1: ="CLZ"&IF(CV2<Settings!$B$5,"19","9")&" Comdty"
A2: =WORKDAY(DATE(2019,0,25),-3) | B2: =BDP(A$1,"LAST_TRADEABLE_DT") | J2: =WORKDAY(DATE(2019,1,25),-3) | K2: =BDP(J$1,"LAST_TRADEABLE_DT") | S2: =WORKDAY(DATE(2019,2,25),-3) | T2: =BDP(S$1,"LAST_TRADEABLE_DT") | AB2: =WORKDAY(DATE(2019,3,25),-3) | AC2: =BDP(AB$1,"LAST_TRADEABLE_DT") | AK2: =WORKDAY(DATE(2019,4,25),-3) | AL2: =BDP(AK$1,"LAST_TRADEABLE_DT") | AT2: =WORKDAY(DATE(2019,5,25),-3) | AU2: =BDP(AT$1,"LAST_TRADEABLE_DT") | BC2: =WORKDAY(DATE(2019,6,25),-3) | BD2: =BDP(BC$1,"LAST_TRADEABLE_DT") | BL2: =WORKDAY(DATE(2019,7,25),-3) | BM2: =BDP(BL$1,"LAST_TRADEABLE_DT") | BU2: =WORKDAY(DATE(2019,8,25),-3) | BV2: =BDP(BU$1,"LAST_TRADEABLE_DT") | CD2: =WORKDAY(DATE(2019,9,25),-3) | CE2: =BDP(CD$1,"LAST_TRADEABLE_DT") | CM2: =WORKDAY(DATE(2019,10,25),-3) | CN2: =BDP(CM$1,"LAST_TRADEABLE_DT") | CV2: =WORKDAY(DATE(2019,11,25),-3) | CW2: =BDP(CV$1,"LAST_TRADEABLE_DT")
A3: Date | B3: PX_OPEN | C3: PX_HIGH | D3: PX_LOW | E3: PX_LAST | F3: PX_SETTLE | G3: PX_VOLUME | H3: OPEN_INT | J3: Date | K3: PX_OPEN | L3: PX_HIGH | M3: PX_LOW | N3: PX_LAST | O3: PX_SETTLE | P3: PX_VOLUME | Q3: OPEN_INT | S3: Date | T3: PX_OPEN | U3: PX_HIGH | V3: PX_LOW | W3: PX_LAST | X3: PX_SETTLE | Y3: PX_VOLUME | Z3: OPEN_INT | AB3: Date | AC3: PX_OPEN | AD3: PX_HIGH | AE3: PX_LOW | AF3: PX_LAST | AG3: PX_SETTLE | AH3: PX_VOLUME | AI3: OPEN_INT | AK3: Date | AL3: PX_OPEN | AM3: PX_HIGH | AN3: PX_LOW | AO3: PX_LAST | AP3: PX_SETTLE | AQ3: PX_VOLUME | AR3: OPEN_INT | AT3: Date | AU3: PX_OPEN | AV3: PX_HIGH | AW3: PX_LOW | AX3: PX_LAST | AY3: PX_SETTLE | AZ3: PX_VOLUME | BA3: OPEN_INT | BC3: Date | BD3: PX_OPEN | BE3: PX_HIGH | BF3: PX_LOW | BG3: PX_LAST | BH3: PX_SETTLE | BI3: PX_VOLUME | BJ3: OPEN_INT | BL3: Date | BM3: PX_OPEN | BN3: PX_HIGH | BO3: PX_LOW | BP3: PX_LAST | BQ3: PX_SETTLE | BR3: PX_VOLUME | BS3: OPEN_INT | BU3: Date | BV3: PX_OPEN | BW3: PX_HIGH | BX3: PX_LOW | BY3: PX_LAST | BZ3: PX_SETTLE | CA3: PX_VOLUME | CB3: OPEN_INT | CD3: Date | CE3: PX_OPEN | CF3: PX_HIGH | CG3: PX_LOW | CH3: PX_LAST | CI3: PX_SETTLE | CJ3: PX_VOLUME | CK3: OPEN_INT | CM3: Date | CN3: PX_OPEN | CO3: PX_HIGH | CP3: PX_LOW | CQ3: PX_LAST | CR3: PX_SETTLE | CS3: PX_VOLUME | CT3: OPEN_INT | CV3: Date | CW3: PX_OPEN | CX3: PX_HIGH | CY3: PX_LOW | CZ3: PX_LAST | DA3: PX_SETTLE | DB3: PX_VOLUME | DC3: OPEN_INT
A4: =BDH(A$1,B$3:H$3,Settings!$B$3,IF(Settings!$B$4="","",Settings!$B$4),"Dir=V","Dts=S","Sort=A","Days=T","Fill=B") | J4: =BDH(J$1,K$3:Q$3,Settings!$B$3,IF(Settings!$B$4="","",Settings!$B$4),"Dir=V","Dts=S","Sort=A","Days=T","Fill=B") | S4: =BDH(S$1,T$3:Z$3,Settings!$B$3,IF(Settings!$B$4="","",Settings!$B$4),"Dir=V","Dts=S","Sort=A","Days=T","Fill=B") | AB4: =BDH(AB$1,AC$3:AI$3,Settings!$B$3,IF(Settings!$B$4="","",Settings!$B$4),"Dir=V","Dts=S","Sort=A","Days=T","Fill=B") | AK4: =BDH(AK$1,AL$3:AR$3,Settings!$B$3,IF(Settings!$B$4="","",Settings!$B$4),"Dir=V","Dts=S","Sort=A","Days=T","Fill=B") | AT4: =BDH(AT$1,AU$3:BA$3,Settings!$B$3,IF(Settings!$B$4="","",Settings!$B$4),"Dir=V","Dts=S","Sort=A","Days=T","Fill=B") | BC4: =BDH(BC$1,BD$3:BJ$3,Settings!$B$3,IF(Settings!$B$4="","",Settings!$B$4),"Dir=V","Dts=S","Sort=A","Days=T","Fill=B") | BL4: =BDH(BL$1,BM$3:BS$3,Settings!$B$3,IF(Settings!$B$4="","",Settings!$B$4),"Dir=V","Dts=S","Sort=A","Days=T","Fill=B") | BU4: =BDH(BU$1,BV$3:CB$3,Settings!$B$3,IF(Settings!$B$4="","",Settings!$B$4),"Dir=V","Dts=S","Sort=A","Days=T","Fill=B") | CD4: =BDH(CD$1,CE$3:CK$3,Settings!$B$3,IF(Settings!$B$4="","",Settings!$B$4),"Dir=V","Dts=S","Sort=A","Days=T","Fill=B") | CM4: =BDH(CM$1,CN$3:CT$3,Settings!$B$3,IF(Settings!$B$4="","",Settings!$B$4),"Dir=V","Dts=S","Sort=A","Days=T","Fill=B") | CV4: =BDH(CV$1,CW$3:DC$3,Settings!$B$3,IF(Settings!$B$4="","",Settings!$B$4),"Dir=V","Dts=S","Sort=A","Days=T","Fill=B")

Sheet CL 2020
A1: ="CLF"&IF(A2<Settings!$B$5,"20","0")&" Comdty" | J1: ="CLG"&IF(J2<Settings!$B$5,"20","0")&" Comdty" | S1: ="CLH"&IF(S2<Settings!$B$5,"20","0")&" Comdty" | AB1: ="CLJ"&IF(AB2<Settings!$B$5,"20","0")&" Comdty" | AK1: ="CLK"&IF(AK2<Settings!$B$5,"20","0")&" Comdty" | AT1: ="CLM"&IF(AT2<Settings!$B$5,"20","0")&" Comdty" | BC1: ="CLN"&IF(BC2<Settings!$B$5,"20","0")&" Comdty" | BL1: ="CLQ"&IF(BL2<Settings!$B$5,"20","0")&" Comdty" | BU1: ="CLU"&IF(BU2<Settings!$B$5,"20","0")&" Comdty" | CD1: ="CLV"&IF(CD2<Settings!$B$5,"20","0")&" Comdty" | CM1: ="CLX"&IF(CM2<Settings!$B$5,"20","0")&" Comdty" | CV1: ="CLZ"&IF(CV2<Settings!$B$5,"20","0")&" Comdty"
A2: =WORKDAY(DATE(2020,0,25),-3) | B2: =BDP(A$1,"LAST_TRADEABLE_DT") | J2: =WORKDAY(DATE(2020,1,25),-3) | K2: =BDP(J$1,"LAST_TRADEABLE_DT") | S2: =WORKDAY(DATE(2020,2,25),-3) | T2: =BDP(S$1,"LAST_TRADEABLE_DT") | AB2: =WORKDAY(DATE(2020,3,25),-3) | AC2: =BDP(AB$1,"LAST_TRADEABLE_DT") | AK2: =WORKDAY(DATE(2020,4,25),-3) | AL2: =BDP(AK$1,"LAST_TRADEABLE_DT") | AT2: =WORKDAY(DATE(2020,5,25),-3) | AU2: =BDP(AT$1,"LAST_TRADEABLE_DT") | BC2: =WORKDAY(DATE(2020,6,25),-3) | BD2: =BDP(BC$1,"LAST_TRADEABLE_DT") | BL2: =WORKDAY(DATE(2020,7,25),-3) | BM2: =BDP(BL$1,"LAST_TRADEABLE_DT") | BU2: =WORKDAY(DATE(2020,8,25),-3) | BV2: =BDP(BU$1,"LAST_TRADEABLE_DT") | CD2: =WORKDAY(DATE(2020,9,25),-3) | CE2: =BDP(CD$1,"LAST_TRADEABLE_DT") | CM2: =WORKDAY(DATE(2020,10,25),-3) | CN2: =BDP(CM$1,"LAST_TRADEABLE_DT") | CV2: =WORKDAY(DATE(2020,11,25),-3) | CW2: =BDP(CV$1,"LAST_TRADEABLE_DT")
A3: Date | B3: PX_OPEN | C3: PX_HIGH | D3: PX_LOW | E3: PX_LAST | F3: PX_SETTLE | G3: PX_VOLUME | H3: OPEN_INT | J3: Date | K3: PX_OPEN | L3: PX_HIGH | M3: PX_LOW | N3: PX_LAST | O3: PX_SETTLE | P3: PX_VOLUME | Q3: OPEN_INT | S3: Date | T3: PX_OPEN | U3: PX_HIGH | V3: PX_LOW | W3: PX_LAST | X3: PX_SETTLE | Y3: PX_VOLUME | Z3: OPEN_INT | AB3: Date | AC3: PX_OPEN | AD3: PX_HIGH | AE3: PX_LOW | AF3: PX_LAST | AG3: PX_SETTLE | AH3: PX_VOLUME | AI3: OPEN_INT | AK3: Date | AL3: PX_OPEN | AM3: PX_HIGH | AN3: PX_LOW | AO3: PX_LAST | AP3: PX_SETTLE | AQ3: PX_VOLUME | AR3: OPEN_INT | AT3: Date | AU3: PX_OPEN | AV3: PX_HIGH | AW3: PX_LOW | AX3: PX_LAST | AY3: PX_SETTLE | AZ3: PX_VOLUME | BA3: OPEN_INT | BC3: Date | BD3: PX_OPEN | BE3: PX_HIGH | BF3: PX_LOW | BG3: PX_LAST | BH3: PX_SETTLE | BI3: PX_VOLUME | BJ3: OPEN_INT | BL3: Date | BM3: PX_OPEN | BN3: PX_HIGH | BO3: PX_LOW | BP3: PX_LAST | BQ3: PX_SETTLE | BR3: PX_VOLUME | BS3: OPEN_INT | BU3: Date | BV3: PX_OPEN | BW3: PX_HIGH | BX3: PX_LOW | BY3: PX_LAST | BZ3: PX_SETTLE | CA3: PX_VOLUME | CB3: OPEN_INT | CD3: Date | CE3: PX_OPEN | CF3: PX_HIGH | CG3: PX_LOW | CH3: PX_LAST | CI3: PX_SETTLE | CJ3: PX_VOLUME | CK3: OPEN_INT | CM3: Date | CN3: PX_OPEN | CO3: PX_HIGH | CP3: PX_LOW | CQ3: PX_LAST | CR3: PX_SETTLE | CS3: PX_VOLUME | CT3: OPEN_INT | CV3: Date | CW3: PX_OPEN | CX3: PX_HIGH | CY3: PX_LOW | CZ3: PX_LAST | DA3: PX_SETTLE | DB3: PX_VOLUME | DC3: OPEN_INT
A4: =BDH(A$1,B$3:H$3,Settings!$B$3,IF(Settings!$B$4="","",Settings!$B$4),"Dir=V","Dts=S","Sort=A","Days=T","Fill=B") | J4: =BDH(J$1,K$3:Q$3,Settings!$B$3,IF(Settings!$B$4="","",Settings!$B$4),"Dir=V","Dts=S","Sort=A","Days=T","Fill=B") | S4: =BDH(S$1,T$3:Z$3,Settings!$B$3,IF(Settings!$B$4="","",Settings!$B$4),"Dir=V","Dts=S","Sort=A","Days=T","Fill=B") | AB4: =BDH(AB$1,AC$3:AI$3,Settings!$B$3,IF(Settings!$B$4="","",Settings!$B$4),"Dir=V","Dts=S","Sort=A","Days=T","Fill=B") | AK4: =BDH(AK$1,AL$3:AR$3,Settings!$B$3,IF(Settings!$B$4="","",Settings!$B$4),"Dir=V","Dts=S","Sort=A","Days=T","Fill=B") | AT4: =BDH(AT$1,AU$3:BA$3,Settings!$B$3,IF(Settings!$B$4="","",Settings!$B$4),"Dir=V","Dts=S","Sort=A","Days=T","Fill=B") | BC4: =BDH(BC$1,BD$3:BJ$3,Settings!$B$3,IF(Settings!$B$4="","",Settings!$B$4),"Dir=V","Dts=S","Sort=A","Days=T","Fill=B") | BL4: =BDH(BL$1,BM$3:BS$3,Settings!$B$3,IF(Settings!$B$4="","",Settings!$B$4),"Dir=V","Dts=S","Sort=A","Days=T","Fill=B") | BU4: =BDH(BU$1,BV$3:CB$3,Settings!$B$3,IF(Settings!$B$4="","",Settings!$B$4),"Dir=V","Dts=S","Sort=A","Days=T","Fill=B") | CD4: =BDH(CD$1,CE$3:CK$3,Settings!$B$3,IF(Settings!$B$4="","",Settings!$B$4),"Dir=V","Dts=S","Sort=A","Days=T","Fill=B") | CM4: =BDH(CM$1,CN$3:CT$3,Settings!$B$3,IF(Settings!$B$4="","",Settings!$B$4),"Dir=V","Dts=S","Sort=A","Days=T","Fill=B") | CV4: =BDH(CV$1,CW$3:DC$3,Settings!$B$3,IF(Settings!$B$4="","",Settings!$B$4),"Dir=V","Dts=S","Sort=A","Days=T","Fill=B")

Sheet CL 2021
A1: ="CLF"&IF(A2<Settings!$B$5,"21","1")&" Comdty" | J1: ="CLG"&IF(J2<Settings!$B$5,"21","1")&" Comdty" | S1: ="CLH"&IF(S2<Settings!$B$5,"21","1")&" Comdty" | AB1: ="CLJ"&IF(AB2<Settings!$B$5,"21","1")&" Comdty" | AK1: ="CLK"&IF(AK2<Settings!$B$5,"21","1")&" Comdty" | AT1: ="CLM"&IF(AT2<Settings!$B$5,"21","1")&" Comdty" | BC1: ="CLN"&IF(BC2<Settings!$B$5,"21","1")&" Comdty" | BL1: ="CLQ"&IF(BL2<Settings!$B$5,"21","1")&" Comdty" | BU1: ="CLU"&IF(BU2<Settings!$B$5,"21","1")&" Comdty" | CD1: ="CLV"&IF(CD2<Settings!$B$5,"21","1")&" Comdty" | CM1: ="CLX"&IF(CM2<Settings!$B$5,"21","1")&" Comdty" | CV1: ="CLZ"&IF(CV2<Settings!$B$5,"21","1")&" Comdty"
A2: =WORKDAY(DATE(2021,0,25),-3) | B2: =BDP(A$1,"LAST_TRADEABLE_DT") | J2: =WORKDAY(DATE(2021,1,25),-3) | K2: =BDP(J$1,"LAST_TRADEABLE_DT") | S2: =WORKDAY(DATE(2021,2,25),-3) | T2: =BDP(S$1,"LAST_TRADEABLE_DT") | AB2: =WORKDAY(DATE(2021,3,25),-3) | AC2: =BDP(AB$1,"LAST_TRADEABLE_DT") | AK2: =WORKDAY(DATE(2021,4,25),-3) | AL2: =BDP(AK$1,"LAST_TRADEABLE_DT") | AT2: =WORKDAY(DATE(2021,5,25),-3) | AU2: =BDP(AT$1,"LAST_TRADEABLE_DT") | BC2: =WORKDAY(DATE(2021,6,25),-3) | BD2: =BDP(BC$1,"LAST_TRADEABLE_DT") | BL2: =WORKDAY(DATE(2021,7,25),-3) | BM2: =BDP(BL$1,"LAST_TRADEABLE_DT") | BU2: =WORKDAY(DATE(2021,8,25),-3) | BV2: =BDP(BU$1,"LAST_TRADEABLE_DT") | CD2: =WORKDAY(DATE(2021,9,25),-3) | CE2: =BDP(CD$1,"LAST_TRADEABLE_DT") | CM2: =WORKDAY(DATE(2021,10,25),-3) | CN2: =BDP(CM$1,"LAST_TRADEABLE_DT") | CV2: =WORKDAY(DATE(2021,11,25),-3) | CW2: =BDP(CV$1,"LAST_TRADEABLE_DT")
A3: Date | B3: PX_OPEN | C3: PX_HIGH | D3: PX_LOW | E3: PX_LAST | F3: PX_SETTLE | G3: PX_VOLUME | H3: OPEN_INT | J3: Date | K3: PX_OPEN | L3: PX_HIGH | M3: PX_LOW | N3: PX_LAST | O3: PX_SETTLE | P3: PX_VOLUME | Q3: OPEN_INT | S3: Date | T3: PX_OPEN | U3: PX_HIGH | V3: PX_LOW | W3: PX_LAST | X3: PX_SETTLE | Y3: PX_VOLUME | Z3: OPEN_INT | AB3: Date | AC3: PX_OPEN | AD3: PX_HIGH | AE3: PX_LOW | AF3: PX_LAST | AG3: PX_SETTLE | AH3: PX_VOLUME | AI3: OPEN_INT | AK3: Date | AL3: PX_OPEN | AM3: PX_HIGH | AN3: PX_LOW | AO3: PX_LAST | AP3: PX_SETTLE | AQ3: PX_VOLUME | AR3: OPEN_INT | AT3: Date | AU3: PX_OPEN | AV3: PX_HIGH | AW3: PX_LOW | AX3: PX_LAST | AY3: PX_SETTLE | AZ3: PX_VOLUME | BA3: OPEN_INT | BC3: Date | BD3: PX_OPEN | BE3: PX_HIGH | BF3: PX_LOW | BG3: PX_LAST | BH3: PX_SETTLE | BI3: PX_VOLUME | BJ3: OPEN_INT | BL3: Date | BM3: PX_OPEN | BN3: PX_HIGH | BO3: PX_LOW | BP3: PX_LAST | BQ3: PX_SETTLE | BR3: PX_VOLUME | BS3: OPEN_INT | BU3: Date | BV3: PX_OPEN | BW3: PX_HIGH | BX3: PX_LOW | BY3: PX_LAST | BZ3: PX_SETTLE | CA3: PX_VOLUME | CB3: OPEN_INT | CD3: Date | CE3: PX_OPEN | CF3: PX_HIGH | CG3: PX_LOW | CH3: PX_LAST | CI3: PX_SETTLE | CJ3: PX_VOLUME | CK3: OPEN_INT | CM3: Date | CN3: PX_OPEN | CO3: PX_HIGH | CP3: PX_LOW | CQ3: PX_LAST | CR3: PX_SETTLE | CS3: PX_VOLUME | CT3: OPEN_INT | CV3: Date | CW3: PX_OPEN | CX3: PX_HIGH | CY3: PX_LOW | CZ3: PX_LAST | DA3: PX_SETTLE | DB3: PX_VOLUME | DC3: OPEN_INT
A4: =BDH(A$1,B$3:H$3,Settings!$B$3,IF(Settings!$B$4="","",Settings!$B$4),"Dir=V","Dts=S","Sort=A","Days=T","Fill=B") | J4: =BDH(J$1,K$3:Q$3,Settings!$B$3,IF(Settings!$B$4="","",Settings!$B$4),"Dir=V","Dts=S","Sort=A","Days=T","Fill=B") | S4: =BDH(S$1,T$3:Z$3,Settings!$B$3,IF(Settings!$B$4="","",Settings!$B$4),"Dir=V","Dts=S","Sort=A","Days=T","Fill=B") | AB4: =BDH(AB$1,AC$3:AI$3,Settings!$B$3,IF(Settings!$B$4="","",Settings!$B$4),"Dir=V","Dts=S","Sort=A","Days=T","Fill=B") | AK4: =BDH(AK$1,AL$3:AR$3,Settings!$B$3,IF(Settings!$B$4="","",Settings!$B$4),"Dir=V","Dts=S","Sort=A","Days=T","Fill=B") | AT4: =BDH(AT$1,AU$3:BA$3,Settings!$B$3,IF(Settings!$B$4="","",Settings!$B$4),"Dir=V","Dts=S","Sort=A","Days=T","Fill=B") | BC4: =BDH(BC$1,BD$3:BJ$3,Settings!$B$3,IF(Settings!$B$4="","",Settings!$B$4),"Dir=V","Dts=S","Sort=A","Days=T","Fill=B") | BL4: =BDH(BL$1,BM$3:BS$3,Settings!$B$3,IF(Settings!$B$4="","",Settings!$B$4),"Dir=V","Dts=S","Sort=A","Days=T","Fill=B") | BU4: =BDH(BU$1,BV$3:CB$3,Settings!$B$3,IF(Settings!$B$4="","",Settings!$B$4),"Dir=V","Dts=S","Sort=A","Days=T","Fill=B") | CD4: =BDH(CD$1,CE$3:CK$3,Settings!$B$3,IF(Settings!$B$4="","",Settings!$B$4),"Dir=V","Dts=S","Sort=A","Days=T","Fill=B") | CM4: =BDH(CM$1,CN$3:CT$3,Settings!$B$3,IF(Settings!$B$4="","",Settings!$B$4),"Dir=V","Dts=S","Sort=A","Days=T","Fill=B") | CV4: =BDH(CV$1,CW$3:DC$3,Settings!$B$3,IF(Settings!$B$4="","",Settings!$B$4),"Dir=V","Dts=S","Sort=A","Days=T","Fill=B")

Sheet CL 2022
A1: ="CLF"&IF(A2<Settings!$B$5,"22","2")&" Comdty" | J1: ="CLG"&IF(J2<Settings!$B$5,"22","2")&" Comdty" | S1: ="CLH"&IF(S2<Settings!$B$5,"22","2")&" Comdty" | AB1: ="CLJ"&IF(AB2<Settings!$B$5,"22","2")&" Comdty" | AK1: ="CLK"&IF(AK2<Settings!$B$5,"22","2")&" Comdty" | AT1: ="CLM"&IF(AT2<Settings!$B$5,"22","2")&" Comdty" | BC1: ="CLN"&IF(BC2<Settings!$B$5,"22","2")&" Comdty" | BL1: ="CLQ"&IF(BL2<Settings!$B$5,"22","2")&" Comdty" | BU1: ="CLU"&IF(BU2<Settings!$B$5,"22","2")&" Comdty" | CD1: ="CLV"&IF(CD2<Settings!$B$5,"22","2")&" Comdty" | CM1: ="CLX"&IF(CM2<Settings!$B$5,"22","2")&" Comdty" | CV1: ="CLZ"&IF(CV2<Settings!$B$5,"22","2")&" Comdty"
A2: =WORKDAY(DATE(2022,0,25),-3) | B2: =BDP(A$1,"LAST_TRADEABLE_DT") | J2: =WORKDAY(DATE(2022,1,25),-3) | K2: =BDP(J$1,"LAST_TRADEABLE_DT") | S2: =WORKDAY(DATE(2022,2,25),-3) | T2: =BDP(S$1,"LAST_TRADEABLE_DT") | AB2: =WORKDAY(DATE(2022,3,25),-3) | AC2: =BDP(AB$1,"LAST_TRADEABLE_DT") | AK2: =WORKDAY(DATE(2022,4,25),-3) | AL2: =BDP(AK$1,"LAST_TRADEABLE_DT") | AT2: =WORKDAY(DATE(2022,5,25),-3) | AU2: =BDP(AT$1,"LAST_TRADEABLE_DT") | BC2: =WORKDAY(DATE(2022,6,25),-3) | BD2: =BDP(BC$1,"LAST_TRADEABLE_DT") | BL2: =WORKDAY(DATE(2022,7,25),-3) | BM2: =BDP(BL$1,"LAST_TRADEABLE_DT") | BU2: =WORKDAY(DATE(2022,8,25),-3) | BV2: =BDP(BU$1,"LAST_TRADEABLE_DT") | CD2: =WORKDAY(DATE(2022,9,25),-3) | CE2: =BDP(CD$1,"LAST_TRADEABLE_DT") | CM2: =WORKDAY(DATE(2022,10,25),-3) | CN2: =BDP(CM$1,"LAST_TRADEABLE_DT") | CV2: =WORKDAY(DATE(2022,11,25),-3) | CW2: =BDP(CV$1,"LAST_TRADEABLE_DT")
A3: Date | B3: PX_OPEN | C3: PX_HIGH | D3: PX_LOW | E3: PX_LAST | F3: PX_SETTLE | G3: PX_VOLUME | H3: OPEN_INT | J3: Date | K3: PX_OPEN | L3: PX_HIGH | M3: PX_LOW | N3: PX_LAST | O3: PX_SETTLE | P3: PX_VOLUME | Q3: OPEN_INT | S3: Date | T3: PX_OPEN | U3: PX_HIGH | V3: PX_LOW | W3: PX_LAST | X3: PX_SETTLE | Y3: PX_VOLUME | Z3: OPEN_INT | AB3: Date | AC3: PX_OPEN | AD3: PX_HIGH | AE3: PX_LOW | AF3: PX_LAST | AG3: PX_SETTLE | AH3: PX_VOLUME | AI3: OPEN_INT | AK3: Date | AL3: PX_OPEN | AM3: PX_HIGH | AN3: PX_LOW | AO3: PX_LAST | AP3: PX_SETTLE | AQ3: PX_VOLUME | AR3: OPEN_INT | AT3: Date | AU3: PX_OPEN | AV3: PX_HIGH | AW3: PX_LOW | AX3: PX_LAST | AY3: PX_SETTLE | AZ3: PX_VOLUME | BA3: OPEN_INT | BC3: Date | BD3: PX_OPEN | BE3: PX_HIGH | BF3: PX_LOW | BG3: PX_LAST | BH3: PX_SETTLE | BI3: PX_VOLUME | BJ3: OPEN_INT | BL3: Date | BM3: PX_OPEN | BN3: PX_HIGH | BO3: PX_LOW | BP3: PX_LAST | BQ3: PX_SETTLE | BR3: PX_VOLUME | BS3: OPEN_INT | BU3: Date | BV3: PX_OPEN | BW3: PX_HIGH | BX3: PX_LOW | BY3: PX_LAST | BZ3: PX_SETTLE | CA3: PX_VOLUME | CB3: OPEN_INT | CD3: Date | CE3: PX_OPEN | CF3: PX_HIGH | CG3: PX_LOW | CH3: PX_LAST | CI3: PX_SETTLE | CJ3: PX_VOLUME | CK3: OPEN_INT | CM3: Date | CN3: PX_OPEN | CO3: PX_HIGH | CP3: PX_LOW | CQ3: PX_LAST | CR3: PX_SETTLE | CS3: PX_VOLUME | CT3: OPEN_INT | CV3: Date | CW3: PX_OPEN | CX3: PX_HIGH | CY3: PX_LOW | CZ3: PX_LAST | DA3: PX_SETTLE | DB3: PX_VOLUME | DC3: OPEN_INT
A4: =BDH(A$1,B$3:H$3,Settings!$B$3,IF(Settings!$B$4="","",Settings!$B$4),"Dir=V","Dts=S","Sort=A","Days=T","Fill=B") | J4: =BDH(J$1,K$3:Q$3,Settings!$B$3,IF(Settings!$B$4="","",Settings!$B$4),"Dir=V","Dts=S","Sort=A","Days=T","Fill=B") | S4: =BDH(S$1,T$3:Z$3,Settings!$B$3,IF(Settings!$B$4="","",Settings!$B$4),"Dir=V","Dts=S","Sort=A","Days=T","Fill=B") | AB4: =BDH(AB$1,AC$3:AI$3,Settings!$B$3,IF(Settings!$B$4="","",Settings!$B$4),"Dir=V","Dts=S","Sort=A","Days=T","Fill=B") | AK4: =BDH(AK$1,AL$3:AR$3,Settings!$B$3,IF(Settings!$B$4="","",Settings!$B$4),"Dir=V","Dts=S","Sort=A","Days=T","Fill=B") | AT4: =BDH(AT$1,AU$3:BA$3,Settings!$B$3,IF(Settings!$B$4="","",Settings!$B$4),"Dir=V","Dts=S","Sort=A","Days=T","Fill=B") | BC4: =BDH(BC$1,BD$3:BJ$3,Settings!$B$3,IF(Settings!$B$4="","",Settings!$B$4),"Dir=V","Dts=S","Sort=A","Days=T","Fill=B") | BL4: =BDH(BL$1,BM$3:BS$3,Settings!$B$3,IF(Settings!$B$4="","",Settings!$B$4),"Dir=V","Dts=S","Sort=A","Days=T","Fill=B") | BU4: =BDH(BU$1,BV$3:CB$3,Settings!$B$3,IF(Settings!$B$4="","",Settings!$B$4),"Dir=V","Dts=S","Sort=A","Days=T","Fill=B") | CD4: =BDH(CD$1,CE$3:CK$3,Settings!$B$3,IF(Settings!$B$4="","",Settings!$B$4),"Dir=V","Dts=S","Sort=A","Days=T","Fill=B") | CM4: =BDH(CM$1,CN$3:CT$3,Settings!$B$3,IF(Settings!$B$4="","",Settings!$B$4),"Dir=V","Dts=S","Sort=A","Days=T","Fill=B") | CV4: =BDH(CV$1,CW$3:DC$3,Settings!$B$3,IF(Settings!$B$4="","",Settings!$B$4),"Dir=V","Dts=S","Sort=A","Days=T","Fill=B")

Sheet CL 2023
A1: ="CLF"&IF(A2<Settings!$B$5,"23","3")&" Comdty" | J1: ="CLG"&IF(J2<Settings!$B$5,"23","3")&" Comdty" | S1: ="CLH"&IF(S2<Settings!$B$5,"23","3")&" Comdty" | AB1: ="CLJ"&IF(AB2<Settings!$B$5,"23","3")&" Comdty" | AK1: ="CLK"&IF(AK2<Settings!$B$5,"23","3")&" Comdty" | AT1: ="CLM"&IF(AT2<Settings!$B$5,"23","3")&" Comdty" | BC1: ="CLN"&IF(BC2<Settings!$B$5,"23","3")&" Comdty" | BL1: ="CLQ"&IF(BL2<Settings!$B$5,"23","3")&" Comdty" | BU1: ="CLU"&IF(BU2<Settings!$B$5,"23","3")&" Comdty" | CD1: ="CLV"&IF(CD2<Settings!$B$5,"23","3")&" Comdty" | CM1: ="CLX"&IF(CM2<Settings!$B$5,"23","3")&" Comdty" | CV1: ="CLZ"&IF(CV2<Settings!$B$5,"23","3")&" Comdty"
A2: =WORKDAY(DATE(2023,0,25),-3) | B2: =BDP(A$1,"LAST_TRADEABLE_DT") | J2: =WORKDAY(DATE(2023,1,25),-3) | K2: =BDP(J$1,"LAST_TRADEABLE_DT") | S2: =WORKDAY(DATE(2023,2,25),-3) | T2: =BDP(S$1,"LAST_TRADEABLE_DT") | AB2: =WORKDAY(DATE(2023,3,25),-3) | AC2: =BDP(AB$1,"LAST_TRADEABLE_DT") | AK2: =WORKDAY(DATE(2023,4,25),-3) | AL2: =BDP(AK$1,"LAST_TRADEABLE_DT") | AT2: =WORKDAY(DATE(2023,5,25),-3) | AU2: =BDP(AT$1,"LAST_TRADEABLE_DT") | BC2: =WORKDAY(DATE(2023,6,25),-3) | BD2: =BDP(BC$1,"LAST_TRADEABLE_DT") | BL2: =WORKDAY(DATE(2023,7,25),-3) | BM2: =BDP(BL$1,"LAST_TRADEABLE_DT") | BU2: =WORKDAY(DATE(2023,8,25),-3) | BV2: =BDP(BU$1,"LAST_TRADEABLE_DT") | CD2: =WORKDAY(DATE(2023,9,25),-3) | CE2: =BDP(CD$1,"LAST_TRADEABLE_DT") | CM2: =WORKDAY(DATE(2023,10,25),-3) | CN2: =BDP(CM$1,"LAST_TRADEABLE_DT") | CV2: =WORKDAY(DATE(2023,11,25),-3) | CW2: =BDP(CV$1,"LAST_TRADEABLE_DT")
A3: Date | B3: PX_OPEN | C3: PX_HIGH | D3: PX_LOW | E3: PX_LAST | F3: PX_SETTLE | G3: PX_VOLUME | H3: OPEN_INT | J3: Date | K3: PX_OPEN | L3: PX_HIGH | M3: PX_LOW | N3: PX_LAST | O3: PX_SETTLE | P3: PX_VOLUME | Q3: OPEN_INT | S3: Date | T3: PX_OPEN | U3: PX_HIGH | V3: PX_LOW | W3: PX_LAST | X3: PX_SETTLE | Y3: PX_VOLUME | Z3: OPEN_INT | AB3: Date | AC3: PX_OPEN | AD3: PX_HIGH | AE3: PX_LOW | AF3: PX_LAST | AG3: PX_SETTLE | AH3: PX_VOLUME | AI3: OPEN_INT | AK3: Date | AL3: PX_OPEN | AM3: PX_HIGH | AN3: PX_LOW | AO3: PX_LAST | AP3: PX_SETTLE | AQ3: PX_VOLUME | AR3: OPEN_INT | AT3: Date | AU3: PX_OPEN | AV3: PX_HIGH | AW3: PX_LOW | AX3: PX_LAST | AY3: PX_SETTLE | AZ3: PX_VOLUME | BA3: OPEN_INT | BC3: Date | BD3: PX_OPEN | BE3: PX_HIGH | BF3: PX_LOW | BG3: PX_LAST | BH3: PX_SETTLE | BI3: PX_VOLUME | BJ3: OPEN_INT | BL3: Date | BM3: PX_OPEN | BN3: PX_HIGH | BO3: PX_LOW | BP3: PX_LAST | BQ3: PX_SETTLE | BR3: PX_VOLUME | BS3: OPEN_INT | BU3: Date | BV3: PX_OPEN | BW3: PX_HIGH | BX3: PX_LOW | BY3: PX_LAST | BZ3: PX_SETTLE | CA3: PX_VOLUME | CB3: OPEN_INT | CD3: Date | CE3: PX_OPEN | CF3: PX_HIGH | CG3: PX_LOW | CH3: PX_LAST | CI3: PX_SETTLE | CJ3: PX_VOLUME | CK3: OPEN_INT | CM3: Date | CN3: PX_OPEN | CO3: PX_HIGH | CP3: PX_LOW | CQ3: PX_LAST | CR3: PX_SETTLE | CS3: PX_VOLUME | CT3: OPEN_INT | CV3: Date | CW3: PX_OPEN | CX3: PX_HIGH | CY3: PX_LOW | CZ3: PX_LAST | DA3: PX_SETTLE | DB3: PX_VOLUME | DC3: OPEN_INT
A4: =BDH(A$1,B$3:H$3,Settings!$B$3,IF(Settings!$B$4="","",Settings!$B$4),"Dir=V","Dts=S","Sort=A","Days=T","Fill=B") | J4: =BDH(J$1,K$3:Q$3,Settings!$B$3,IF(Settings!$B$4="","",Settings!$B$4),"Dir=V","Dts=S","Sort=A","Days=T","Fill=B") | S4: =BDH(S$1,T$3:Z$3,Settings!$B$3,IF(Settings!$B$4="","",Settings!$B$4),"Dir=V","Dts=S","Sort=A","Days=T","Fill=B") | AB4: =BDH(AB$1,AC$3:AI$3,Settings!$B$3,IF(Settings!$B$4="","",Settings!$B$4),"Dir=V","Dts=S","Sort=A","Days=T","Fill=B") | AK4: =BDH(AK$1,AL$3:AR$3,Settings!$B$3,IF(Settings!$B$4="","",Settings!$B$4),"Dir=V","Dts=S","Sort=A","Days=T","Fill=B") | AT4: =BDH(AT$1,AU$3:BA$3,Settings!$B$3,IF(Settings!$B$4="","",Settings!$B$4),"Dir=V","Dts=S","Sort=A","Days=T","Fill=B") | BC4: =BDH(BC$1,BD$3:BJ$3,Settings!$B$3,IF(Settings!$B$4="","",Settings!$B$4),"Dir=V","Dts=S","Sort=A","Days=T","Fill=B") | BL4: =BDH(BL$1,BM$3:BS$3,Settings!$B$3,IF(Settings!$B$4="","",Settings!$B$4),"Dir=V","Dts=S","Sort=A","Days=T","Fill=B") | BU4: =BDH(BU$1,BV$3:CB$3,Settings!$B$3,IF(Settings!$B$4="","",Settings!$B$4),"Dir=V","Dts=S","Sort=A","Days=T","Fill=B") | CD4: =BDH(CD$1,CE$3:CK$3,Settings!$B$3,IF(Settings!$B$4="","",Settings!$B$4),"Dir=V","Dts=S","Sort=A","Days=T","Fill=B") | CM4: =BDH(CM$1,CN$3:CT$3,Settings!$B$3,IF(Settings!$B$4="","",Settings!$B$4),"Dir=V","Dts=S","Sort=A","Days=T","Fill=B") | CV4: =BDH(CV$1,CW$3:DC$3,Settings!$B$3,IF(Settings!$B$4="","",Settings!$B$4),"Dir=V","Dts=S","Sort=A","Days=T","Fill=B")

Sheet CL 2024
A1: ="CLF"&IF(A2<Settings!$B$5,"24","4")&" Comdty" | J1: ="CLG"&IF(J2<Settings!$B$5,"24","4")&" Comdty" | S1: ="CLH"&IF(S2<Settings!$B$5,"24","4")&" Comdty" | AB1: ="CLJ"&IF(AB2<Settings!$B$5,"24","4")&" Comdty" | AK1: ="CLK"&IF(AK2<Settings!$B$5,"24","4")&" Comdty" | AT1: ="CLM"&IF(AT2<Settings!$B$5,"24","4")&" Comdty" | BC1: ="CLN"&IF(BC2<Settings!$B$5,"24","4")&" Comdty" | BL1: ="CLQ"&IF(BL2<Settings!$B$5,"24","4")&" Comdty" | BU1: ="CLU"&IF(BU2<Settings!$B$5,"24","4")&" Comdty" | CD1: ="CLV"&IF(CD2<Settings!$B$5,"24","4")&" Comdty" | CM1: ="CLX"&IF(CM2<Settings!$B$5,"24","4")&" Comdty" | CV1: ="CLZ"&IF(CV2<Settings!$B$5,"24","4")&" Comdty"
A2: =WORKDAY(DATE(2024,0,25),-3) | B2: =BDP(A$1,"LAST_TRADEABLE_DT") | J2: =WORKDAY(DATE(2024,1,25),-3) | K2: =BDP(J$1,"LAST_TRADEABLE_DT") | S2: =WORKDAY(DATE(2024,2,25),-3) | T2: =BDP(S$1,"LAST_TRADEABLE_DT") | AB2: =WORKDAY(DATE(2024,3,25),-3) | AC2: =BDP(AB$1,"LAST_TRADEABLE_DT") | AK2: =WORKDAY(DATE(2024,4,25),-3) | AL2: =BDP(AK$1,"LAST_TRADEABLE_DT") | AT2: =WORKDAY(DATE(2024,5,25),-3) | AU2: =BDP(AT$1,"LAST_TRADEABLE_DT") | BC2: =WORKDAY(DATE(2024,6,25),-3) | BD2: =BDP(BC$1,"LAST_TRADEABLE_DT") | BL2: =WORKDAY(DATE(2024,7,25),-3) | BM2: =BDP(BL$1,"LAST_TRADEABLE_DT") | BU2: =WORKDAY(DATE(2024,8,25),-3) | BV2: =BDP(BU$1,"LAST_TRADEABLE_DT") | CD2: =WORKDAY(DATE(2024,9,25),-3) | CE2: =BDP(CD$1,"LAST_TRADEABLE_DT") | CM2: =WORKDAY(DATE(2024,10,25),-3) | CN2: =BDP(CM$1,"LAST_TRADEABLE_DT") | CV2: =WORKDAY(DATE(2024,11,25),-3) | CW2: =BDP(CV$1,"LAST_TRADEABLE_DT")
A3: Date | B3: PX_OPEN | C3: PX_HIGH | D3: PX_LOW | E3: PX_LAST | F3: PX_SETTLE | G3: PX_VOLUME | H3: OPEN_INT | J3: Date | K3: PX_OPEN | L3: PX_HIGH | M3: PX_LOW | N3: PX_LAST | O3: PX_SETTLE | P3: PX_VOLUME | Q3: OPEN_INT | S3: Date | T3: PX_OPEN | U3: PX_HIGH | V3: PX_LOW | W3: PX_LAST | X3: PX_SETTLE | Y3: PX_VOLUME | Z3: OPEN_INT | AB3: Date | AC3: PX_OPEN | AD3: PX_HIGH | AE3: PX_LOW | AF3: PX_LAST | AG3: PX_SETTLE | AH3: PX_VOLUME | AI3: OPEN_INT | AK3: Date | AL3: PX_OPEN | AM3: PX_HIGH | AN3: PX_LOW | AO3: PX_LAST | AP3: PX_SETTLE | AQ3: PX_VOLUME | AR3: OPEN_INT | AT3: Date | AU3: PX_OPEN | AV3: PX_HIGH | AW3: PX_LOW | AX3: PX_LAST | AY3: PX_SETTLE | AZ3: PX_VOLUME | BA3: OPEN_INT | BC3: Date | BD3: PX_OPEN | BE3: PX_HIGH | BF3: PX_LOW | BG3: PX_LAST | BH3: PX_SETTLE | BI3: PX_VOLUME | BJ3: OPEN_INT | BL3: Date | BM3: PX_OPEN | BN3: PX_HIGH | BO3: PX_LOW | BP3: PX_LAST | BQ3: PX_SETTLE | BR3: PX_VOLUME | BS3: OPEN_INT | BU3: Date | BV3: PX_OPEN | BW3: PX_HIGH | BX3: PX_LOW | BY3: PX_LAST | BZ3: PX_SETTLE | CA3: PX_VOLUME | CB3: OPEN_INT | CD3: Date | CE3: PX_OPEN | CF3: PX_HIGH | CG3: PX_LOW | CH3: PX_LAST | CI3: PX_SETTLE | CJ3: PX_VOLUME | CK3: OPEN_INT | CM3: Date | CN3: PX_OPEN | CO3: PX_HIGH | CP3: PX_LOW | CQ3: PX_LAST | CR3: PX_SETTLE | CS3: PX_VOLUME | CT3: OPEN_INT | CV3: Date | CW3: PX_OPEN | CX3: PX_HIGH | CY3: PX_LOW | CZ3: PX_LAST | DA3: PX_SETTLE | DB3: PX_VOLUME | DC3: OPEN_INT
A4: =BDH(A$1,B$3:H$3,Settings!$B$3,IF(Settings!$B$4="","",Settings!$B$4),"Dir=V","Dts=S","Sort=A","Days=T","Fill=B") | J4: =BDH(J$1,K$3:Q$3,Settings!$B$3,IF(Settings!$B$4="","",Settings!$B$4),"Dir=V","Dts=S","Sort=A","Days=T","Fill=B") | S4: =BDH(S$1,T$3:Z$3,Settings!$B$3,IF(Settings!$B$4="","",Settings!$B$4),"Dir=V","Dts=S","Sort=A","Days=T","Fill=B") | AB4: =BDH(AB$1,AC$3:AI$3,Settings!$B$3,IF(Settings!$B$4="","",Settings!$B$4),"Dir=V","Dts=S","Sort=A","Days=T","Fill=B") | AK4: =BDH(AK$1,AL$3:AR$3,Settings!$B$3,IF(Settings!$B$4="","",Settings!$B$4),"Dir=V","Dts=S","Sort=A","Days=T","Fill=B") | AT4: =BDH(AT$1,AU$3:BA$3,Settings!$B$3,IF(Settings!$B$4="","",Settings!$B$4),"Dir=V","Dts=S","Sort=A","Days=T","Fill=B") | BC4: =BDH(BC$1,BD$3:BJ$3,Settings!$B$3,IF(Settings!$B$4="","",Settings!$B$4),"Dir=V","Dts=S","Sort=A","Days=T","Fill=B") | BL4: =BDH(BL$1,BM$3:BS$3,Settings!$B$3,IF(Settings!$B$4="","",Settings!$B$4),"Dir=V","Dts=S","Sort=A","Days=T","Fill=B") | BU4: =BDH(BU$1,BV$3:CB$3,Settings!$B$3,IF(Settings!$B$4="","",Settings!$B$4),"Dir=V","Dts=S","Sort=A","Days=T","Fill=B") | CD4: =BDH(CD$1,CE$3:CK$3,Settings!$B$3,IF(Settings!$B$4="","",Settings!$B$4),"Dir=V","Dts=S","Sort=A","Days=T","Fill=B") | CM4: =BDH(CM$1,CN$3:CT$3,Settings!$B$3,IF(Settings!$B$4="","",Settings!$B$4),"Dir=V","Dts=S","Sort=A","Days=T","Fill=B") | CV4: =BDH(CV$1,CW$3:DC$3,Settings!$B$3,IF(Settings!$B$4="","",Settings!$B$4),"Dir=V","Dts=S","Sort=A","Days=T","Fill=B")

Sheet CL 2025
A1: ="CLF"&IF(A2<Settings!$B$5,"25","5")&" Comdty" | J1: ="CLG"&IF(J2<Settings!$B$5,"25","5")&" Comdty" | S1: ="CLH"&IF(S2<Settings!$B$5,"25","5")&" Comdty" | AB1: ="CLJ"&IF(AB2<Settings!$B$5,"25","5")&" Comdty" | AK1: ="CLK"&IF(AK2<Settings!$B$5,"25","5")&" Comdty" | AT1: ="CLM"&IF(AT2<Settings!$B$5,"25","5")&" Comdty" | BC1: ="CLN"&IF(BC2<Settings!$B$5,"25","5")&" Comdty" | BL1: ="CLQ"&IF(BL2<Settings!$B$5,"25","5")&" Comdty" | BU1: ="CLU"&IF(BU2<Settings!$B$5,"25","5")&" Comdty" | CD1: ="CLV"&IF(CD2<Settings!$B$5,"25","5")&" Comdty" | CM1: ="CLX"&IF(CM2<Settings!$B$5,"25","5")&" Comdty" | CV1: ="CLZ"&IF(CV2<Settings!$B$5,"25","5")&" Comdty"
A2: =WORKDAY(DATE(2025,0,25),-3) | B2: =BDP(A$1,"LAST_TRADEABLE_DT") | J2: =WORKDAY(DATE(2025,1,25),-3) | K2: =BDP(J$1,"LAST_TRADEABLE_DT") | S2: =WORKDAY(DATE(2025,2,25),-3) | T2: =BDP(S$1,"LAST_TRADEABLE_DT") | AB2: =WORKDAY(DATE(2025,3,25),-3) | AC2: =BDP(AB$1,"LAST_TRADEABLE_DT") | AK2: =WORKDAY(DATE(2025,4,25),-3) | AL2: =BDP(AK$1,"LAST_TRADEABLE_DT") | AT2: =WORKDAY(DATE(2025,5,25),-3) | AU2: =BDP(AT$1,"LAST_TRADEABLE_DT") | BC2: =WORKDAY(DATE(2025,6,25),-3) | BD2: =BDP(BC$1,"LAST_TRADEABLE_DT") | BL2: =WORKDAY(DATE(2025,7,25),-3) | BM2: =BDP(BL$1,"LAST_TRADEABLE_DT") | BU2: =WORKDAY(DATE(2025,8,25),-3) | BV2: =BDP(BU$1,"LAST_TRADEABLE_DT") | CD2: =WORKDAY(DATE(2025,9,25),-3) | CE2: =BDP(CD$1,"LAST_TRADEABLE_DT") | CM2: =WORKDAY(DATE(2025,10,25),-3) | CN2: =BDP(CM$1,"LAST_TRADEABLE_DT") | CV2: =WORKDAY(DATE(2025,11,25),-3) | CW2: =BDP(CV$1,"LAST_TRADEABLE_DT")
A3: Date | B3: PX_OPEN | C3: PX_HIGH | D3: PX_LOW | E3: PX_LAST | F3: PX_SETTLE | G3: PX_VOLUME | H3: OPEN_INT | J3: Date | K3: PX_OPEN | L3: PX_HIGH | M3: PX_LOW | N3: PX_LAST | O3: PX_SETTLE | P3: PX_VOLUME | Q3: OPEN_INT | S3: Date | T3: PX_OPEN | U3: PX_HIGH | V3: PX_LOW | W3: PX_LAST | X3: PX_SETTLE | Y3: PX_VOLUME | Z3: OPEN_INT | AB3: Date | AC3: PX_OPEN | AD3: PX_HIGH | AE3: PX_LOW | AF3: PX_LAST | AG3: PX_SETTLE | AH3: PX_VOLUME | AI3: OPEN_INT | AK3: Date | AL3: PX_OPEN | AM3: PX_HIGH | AN3: PX_LOW | AO3: PX_LAST | AP3: PX_SETTLE | AQ3: PX_VOLUME | AR3: OPEN_INT | AT3: Date | AU3: PX_OPEN | AV3: PX_HIGH | AW3: PX_LOW | AX3: PX_LAST | AY3: PX_SETTLE | AZ3: PX_VOLUME | BA3: OPEN_INT | BC3: Date | BD3: PX_OPEN | BE3: PX_HIGH | BF3: PX_LOW | BG3: PX_LAST | BH3: PX_SETTLE | BI3: PX_VOLUME | BJ3: OPEN_INT | BL3: Date | BM3: PX_OPEN | BN3: PX_HIGH | BO3: PX_LOW | BP3: PX_LAST | BQ3: PX_SETTLE | BR3: PX_VOLUME | BS3: OPEN_INT | BU3: Date | BV3: PX_OPEN | BW3: PX_HIGH | BX3: PX_LOW | BY3: PX_LAST | BZ3: PX_SETTLE | CA3: PX_VOLUME | CB3: OPEN_INT | CD3: Date | CE3: PX_OPEN | CF3: PX_HIGH | CG3: PX_LOW | CH3: PX_LAST | CI3: PX_SETTLE | CJ3: PX_VOLUME | CK3: OPEN_INT | CM3: Date | CN3: PX_OPEN | CO3: PX_HIGH | CP3: PX_LOW | CQ3: PX_LAST | CR3: PX_SETTLE | CS3: PX_VOLUME | CT3: OPEN_INT | CV3: Date | CW3: PX_OPEN | CX3: PX_HIGH | CY3: PX_LOW | CZ3: PX_LAST | DA3: PX_SETTLE | DB3: PX_VOLUME | DC3: OPEN_INT
A4: =BDH(A$1,B$3:H$3,Settings!$B$3,IF(Settings!$B$4="","",Settings!$B$4),"Dir=V","Dts=S","Sort=A","Days=T","Fill=B") | J4: =BDH(J$1,K$3:Q$3,Settings!$B$3,IF(Settings!$B$4="","",Settings!$B$4),"Dir=V","Dts=S","Sort=A","Days=T","Fill=B") | S4: =BDH(S$1,T$3:Z$3,Settings!$B$3,IF(Settings!$B$4="","",Settings!$B$4),"Dir=V","Dts=S","Sort=A","Days=T","Fill=B") | AB4: =BDH(AB$1,AC$3:AI$3,Settings!$B$3,IF(Settings!$B$4="","",Settings!$B$4),"Dir=V","Dts=S","Sort=A","Days=T","Fill=B") | AK4: =BDH(AK$1,AL$3:AR$3,Settings!$B$3,IF(Settings!$B$4="","",Settings!$B$4),"Dir=V","Dts=S","Sort=A","Days=T","Fill=B") | AT4: =BDH(AT$1,AU$3:BA$3,Settings!$B$3,IF(Settings!$B$4="","",Settings!$B$4),"Dir=V","Dts=S","Sort=A","Days=T","Fill=B") | BC4: =BDH(BC$1,BD$3:BJ$3,Settings!$B$3,IF(Settings!$B$4="","",Settings!$B$4),"Dir=V","Dts=S","Sort=A","Days=T","Fill=B") | BL4: =BDH(BL$1,BM$3:BS$3,Settings!$B$3,IF(Settings!$B$4="","",Settings!$B$4),"Dir=V","Dts=S","Sort=A","Days=T","Fill=B") | BU4: =BDH(BU$1,BV$3:CB$3,Settings!$B$3,IF(Settings!$B$4="","",Settings!$B$4),"Dir=V","Dts=S","Sort=A","Days=T","Fill=B") | CD4: =BDH(CD$1,CE$3:CK$3,Settings!$B$3,IF(Settings!$B$4="","",Settings!$B$4),"Dir=V","Dts=S","Sort=A","Days=T","Fill=B") | CM4: =BDH(CM$1,CN$3:CT$3,Settings!$B$3,IF(Settings!$B$4="","",Settings!$B$4),"Dir=V","Dts=S","Sort=A","Days=T","Fill=B") | CV4: =BDH(CV$1,CW$3:DC$3,Settings!$B$3,IF(Settings!$B$4="","",Settings!$B$4),"Dir=V","Dts=S","Sort=A","Days=T","Fill=B")

Sheet CL 2026
A1: ="CLF"&IF(A2<Settings!$B$5,"26","6")&" Comdty" | J1: ="CLG"&IF(J2<Settings!$B$5,"26","6")&" Comdty" | S1: ="CLH"&IF(S2<Settings!$B$5,"26","6")&" Comdty" | AB1: ="CLJ"&IF(AB2<Settings!$B$5,"26","6")&" Comdty" | AK1: ="CLK"&IF(AK2<Settings!$B$5,"26","6")&" Comdty" | AT1: ="CLM"&IF(AT2<Settings!$B$5,"26","6")&" Comdty" | BC1: ="CLN"&IF(BC2<Settings!$B$5,"26","6")&" Comdty" | BL1: ="CLQ"&IF(BL2<Settings!$B$5,"26","6")&" Comdty" | BU1: ="CLU"&IF(BU2<Settings!$B$5,"26","6")&" Comdty" | CD1: ="CLV"&IF(CD2<Settings!$B$5,"26","6")&" Comdty" | CM1: ="CLX"&IF(CM2<Settings!$B$5,"26","6")&" Comdty" | CV1: ="CLZ"&IF(CV2<Settings!$B$5,"26","6")&" Comdty"
A2: =WORKDAY(DATE(2026,0,25),-3) | B2: =BDP(A$1,"LAST_TRADEABLE_DT") | J2: =WORKDAY(DATE(2026,1,25),-3) | K2: =BDP(J$1,"LAST_TRADEABLE_DT") | S2: =WORKDAY(DATE(2026,2,25),-3) | T2: =BDP(S$1,"LAST_TRADEABLE_DT") | AB2: =WORKDAY(DATE(2026,3,25),-3) | AC2: =BDP(AB$1,"LAST_TRADEABLE_DT") | AK2: =WORKDAY(DATE(2026,4,25),-3) | AL2: =BDP(AK$1,"LAST_TRADEABLE_DT") | AT2: =WORKDAY(DATE(2026,5,25),-3) | AU2: =BDP(AT$1,"LAST_TRADEABLE_DT") | BC2: =WORKDAY(DATE(2026,6,25),-3) | BD2: =BDP(BC$1,"LAST_TRADEABLE_DT") | BL2: =WORKDAY(DATE(2026,7,25),-3) | BM2: =BDP(BL$1,"LAST_TRADEABLE_DT") | BU2: =WORKDAY(DATE(2026,8,25),-3) | BV2: =BDP(BU$1,"LAST_TRADEABLE_DT") | CD2: =WORKDAY(DATE(2026,9,25),-3) | CE2: =BDP(CD$1,"LAST_TRADEABLE_DT") | CM2: =WORKDAY(DATE(2026,10,25),-3) | CN2: =BDP(CM$1,"LAST_TRADEABLE_DT") | CV2: =WORKDAY(DATE(2026,11,25),-3) | CW2: =BDP(CV$1,"LAST_TRADEABLE_DT")
A3: Date | B3: PX_OPEN | C3: PX_HIGH | D3: PX_LOW | E3: PX_LAST | F3: PX_SETTLE | G3: PX_VOLUME | H3: OPEN_INT | J3: Date | K3: PX_OPEN | L3: PX_HIGH | M3: PX_LOW | N3: PX_LAST | O3: PX_SETTLE | P3: PX_VOLUME | Q3: OPEN_INT | S3: Date | T3: PX_OPEN | U3: PX_HIGH | V3: PX_LOW | W3: PX_LAST | X3: PX_SETTLE | Y3: PX_VOLUME | Z3: OPEN_INT | AB3: Date | AC3: PX_OPEN | AD3: PX_HIGH | AE3: PX_LOW | AF3: PX_LAST | AG3: PX_SETTLE | AH3: PX_VOLUME | AI3: OPEN_INT | AK3: Date | AL3: PX_OPEN | AM3: PX_HIGH | AN3: PX_LOW | AO3: PX_LAST | AP3: PX_SETTLE | AQ3: PX_VOLUME | AR3: OPEN_INT | AT3: Date | AU3: PX_OPEN | AV3: PX_HIGH | AW3: PX_LOW | AX3: PX_LAST | AY3: PX_SETTLE | AZ3: PX_VOLUME | BA3: OPEN_INT | BC3: Date | BD3: PX_OPEN | BE3: PX_HIGH | BF3: PX_LOW | BG3: PX_LAST | BH3: PX_SETTLE | BI3: PX_VOLUME | BJ3: OPEN_INT | BL3: Date | BM3: PX_OPEN | BN3: PX_HIGH | BO3: PX_LOW | BP3: PX_LAST | BQ3: PX_SETTLE | BR3: PX_VOLUME | BS3: OPEN_INT | BU3: Date | BV3: PX_OPEN | BW3: PX_HIGH | BX3: PX_LOW | BY3: PX_LAST | BZ3: PX_SETTLE | CA3: PX_VOLUME | CB3: OPEN_INT | CD3: Date | CE3: PX_OPEN | CF3: PX_HIGH | CG3: PX_LOW | CH3: PX_LAST | CI3: PX_SETTLE | CJ3: PX_VOLUME | CK3: OPEN_INT | CM3: Date | CN3: PX_OPEN | CO3: PX_HIGH | CP3: PX_LOW | CQ3: PX_LAST | CR3: PX_SETTLE | CS3: PX_VOLUME | CT3: OPEN_INT | CV3: Date | CW3: PX_OPEN | CX3: PX_HIGH | CY3: PX_LOW | CZ3: PX_LAST | DA3: PX_SETTLE | DB3: PX_VOLUME | DC3: OPEN_INT
A4: =BDH(A$1,B$3:H$3,Settings!$B$3,IF(Settings!$B$4="","",Settings!$B$4),"Dir=V","Dts=S","Sort=A","Days=T","Fill=B") | J4: =BDH(J$1,K$3:Q$3,Settings!$B$3,IF(Settings!$B$4="","",Settings!$B$4),"Dir=V","Dts=S","Sort=A","Days=T","Fill=B") | S4: =BDH(S$1,T$3:Z$3,Settings!$B$3,IF(Settings!$B$4="","",Settings!$B$4),"Dir=V","Dts=S","Sort=A","Days=T","Fill=B") | AB4: =BDH(AB$1,AC$3:AI$3,Settings!$B$3,IF(Settings!$B$4="","",Settings!$B$4),"Dir=V","Dts=S","Sort=A","Days=T","Fill=B") | AK4: =BDH(AK$1,AL$3:AR$3,Settings!$B$3,IF(Settings!$B$4="","",Settings!$B$4),"Dir=V","Dts=S","Sort=A","Days=T","Fill=B") | AT4: =BDH(AT$1,AU$3:BA$3,Settings!$B$3,IF(Settings!$B$4="","",Settings!$B$4),"Dir=V","Dts=S","Sort=A","Days=T","Fill=B") | BC4: =BDH(BC$1,BD$3:BJ$3,Settings!$B$3,IF(Settings!$B$4="","",Settings!$B$4),"Dir=V","Dts=S","Sort=A","Days=T","Fill=B") | BL4: =BDH(BL$1,BM$3:BS$3,Settings!$B$3,IF(Settings!$B$4="","",Settings!$B$4),"Dir=V","Dts=S","Sort=A","Days=T","Fill=B") | BU4: =BDH(BU$1,BV$3:CB$3,Settings!$B$3,IF(Settings!$B$4="","",Settings!$B$4),"Dir=V","Dts=S","Sort=A","Days=T","Fill=B") | CD4: =BDH(CD$1,CE$3:CK$3,Settings!$B$3,IF(Settings!$B$4="","",Settings!$B$4),"Dir=V","Dts=S","Sort=A","Days=T","Fill=B") | CM4: =BDH(CM$1,CN$3:CT$3,Settings!$B$3,IF(Settings!$B$4="","",Settings!$B$4),"Dir=V","Dts=S","Sort=A","Days=T","Fill=B") | CV4: =BDH(CV$1,CW$3:DC$3,Settings!$B$3,IF(Settings!$B$4="","",Settings!$B$4),"Dir=V","Dts=S","Sort=A","Days=T","Fill=B")

Sheet CL 2027
A1: ="CLF"&IF(A2<Settings!$B$5,"27","7")&" Comdty" | J1: ="CLG"&IF(J2<Settings!$B$5,"27","7")&" Comdty" | S1: ="CLH"&IF(S2<Settings!$B$5,"27","7")&" Comdty" | AB1: ="CLJ"&IF(AB2<Settings!$B$5,"27","7")&" Comdty" | AK1: ="CLK"&IF(AK2<Settings!$B$5,"27","7")&" Comdty" | AT1: ="CLM"&IF(AT2<Settings!$B$5,"27","7")&" Comdty" | BC1: ="CLN"&IF(BC2<Settings!$B$5,"27","7")&" Comdty" | BL1: ="CLQ"&IF(BL2<Settings!$B$5,"27","7")&" Comdty" | BU1: ="CLU"&IF(BU2<Settings!$B$5,"27","7")&" Comdty" | CD1: ="CLV"&IF(CD2<Settings!$B$5,"27","7")&" Comdty" | CM1: ="CLX"&IF(CM2<Settings!$B$5,"27","7")&" Comdty" | CV1: ="CLZ"&IF(CV2<Settings!$B$5,"27","7")&" Comdty"
A2: =WORKDAY(DATE(2027,0,25),-3) | B2: =BDP(A$1,"LAST_TRADEABLE_DT") | J2: =WORKDAY(DATE(2027,1,25),-3) | K2: =BDP(J$1,"LAST_TRADEABLE_DT") | S2: =WORKDAY(DATE(2027,2,25),-3) | T2: =BDP(S$1,"LAST_TRADEABLE_DT") | AB2: =WORKDAY(DATE(2027,3,25),-3) | AC2: =BDP(AB$1,"LAST_TRADEABLE_DT") | AK2: =WORKDAY(DATE(2027,4,25),-3) | AL2: =BDP(AK$1,"LAST_TRADEABLE_DT") | AT2: =WORKDAY(DATE(2027,5,25),-3) | AU2: =BDP(AT$1,"LAST_TRADEABLE_DT") | BC2: =WORKDAY(DATE(2027,6,25),-3) | BD2: =BDP(BC$1,"LAST_TRADEABLE_DT") | BL2: =WORKDAY(DATE(2027,7,25),-3) | BM2: =BDP(BL$1,"LAST_TRADEABLE_DT") | BU2: =WORKDAY(DATE(2027,8,25),-3) | BV2: =BDP(BU$1,"LAST_TRADEABLE_DT") | CD2: =WORKDAY(DATE(2027,9,25),-3) | CE2: =BDP(CD$1,"LAST_TRADEABLE_DT") | CM2: =WORKDAY(DATE(2027,10,25),-3) | CN2: =BDP(CM$1,"LAST_TRADEABLE_DT") | CV2: =WORKDAY(DATE(2027,11,25),-3) | CW2: =BDP(CV$1,"LAST_TRADEABLE_DT")
A3: Date | B3: PX_OPEN | C3: PX_HIGH | D3: PX_LOW | E3: PX_LAST | F3: PX_SETTLE | G3: PX_VOLUME | H3: OPEN_INT | J3: Date | K3: PX_OPEN | L3: PX_HIGH | M3: PX_LOW | N3: PX_LAST | O3: PX_SETTLE | P3: PX_VOLUME | Q3: OPEN_INT | S3: Date | T3: PX_OPEN | U3: PX_HIGH | V3: PX_LOW | W3: PX_LAST | X3: PX_SETTLE | Y3: PX_VOLUME | Z3: OPEN_INT | AB3: Date | AC3: PX_OPEN | AD3: PX_HIGH | AE3: PX_LOW | AF3: PX_LAST | AG3: PX_SETTLE | AH3: PX_VOLUME | AI3: OPEN_INT | AK3: Date | AL3: PX_OPEN | AM3: PX_HIGH | AN3: PX_LOW | AO3: PX_LAST | AP3: PX_SETTLE | AQ3: PX_VOLUME | AR3: OPEN_INT | AT3: Date | AU3: PX_OPEN | AV3: PX_HIGH | AW3: PX_LOW | AX3: PX_LAST | AY3: PX_SETTLE | AZ3: PX_VOLUME | BA3: OPEN_INT | BC3: Date | BD3: PX_OPEN | BE3: PX_HIGH | BF3: PX_LOW | BG3: PX_LAST | BH3: PX_SETTLE | BI3: PX_VOLUME | BJ3: OPEN_INT | BL3: Date | BM3: PX_OPEN | BN3: PX_HIGH | BO3: PX_LOW | BP3: PX_LAST | BQ3: PX_SETTLE | BR3: PX_VOLUME | BS3: OPEN_INT | BU3: Date | BV3: PX_OPEN | BW3: PX_HIGH | BX3: PX_LOW | BY3: PX_LAST | BZ3: PX_SETTLE | CA3: PX_VOLUME | CB3: OPEN_INT | CD3: Date | CE3: PX_OPEN | CF3: PX_HIGH | CG3: PX_LOW | CH3: PX_LAST | CI3: PX_SETTLE | CJ3: PX_VOLUME | CK3: OPEN_INT | CM3: Date | CN3: PX_OPEN | CO3: PX_HIGH | CP3: PX_LOW | CQ3: PX_LAST | CR3: PX_SETTLE | CS3: PX_VOLUME | CT3: OPEN_INT | CV3: Date | CW3: PX_OPEN | CX3: PX_HIGH | CY3: PX_LOW | CZ3: PX_LAST | DA3: PX_SETTLE | DB3: PX_VOLUME | DC3: OPEN_INT
A4: =BDH(A$1,B$3:H$3,Settings!$B$3,IF(Settings!$B$4="","",Settings!$B$4),"Dir=V","Dts=S","Sort=A","Days=T","Fill=B") | J4: =BDH(J$1,K$3:Q$3,Settings!$B$3,IF(Settings!$B$4="","",Settings!$B$4),"Dir=V","Dts=S","Sort=A","Days=T","Fill=B") | S4: =BDH(S$1,T$3:Z$3,Settings!$B$3,IF(Settings!$B$4="","",Settings!$B$4),"Dir=V","Dts=S","Sort=A","Days=T","Fill=B") | AB4: =BDH(AB$1,AC$3:AI$3,Settings!$B$3,IF(Settings!$B$4="","",Settings!$B$4),"Dir=V","Dts=S","Sort=A","Days=T","Fill=B") | AK4: =BDH(AK$1,AL$3:AR$3,Settings!$B$3,IF(Settings!$B$4="","",Settings!$B$4),"Dir=V","Dts=S","Sort=A","Days=T","Fill=B") | AT4: =BDH(AT$1,AU$3:BA$3,Settings!$B$3,IF(Settings!$B$4="","",Settings!$B$4),"Dir=V","Dts=S","Sort=A","Days=T","Fill=B") | BC4: =BDH(BC$1,BD$3:BJ$3,Settings!$B$3,IF(Settings!$B$4="","",Settings!$B$4),"Dir=V","Dts=S","Sort=A","Days=T","Fill=B") | BL4: =BDH(BL$1,BM$3:BS$3,Settings!$B$3,IF(Settings!$B$4="","",Settings!$B$4),"Dir=V","Dts=S","Sort=A","Days=T","Fill=B") | BU4: =BDH(BU$1,BV$3:CB$3,Settings!$B$3,IF(Settings!$B$4="","",Settings!$B$4),"Dir=V","Dts=S","Sort=A","Days=T","Fill=B") | CD4: =BDH(CD$1,CE$3:CK$3,Settings!$B$3,IF(Settings!$B$4="","",Settings!$B$4),"Dir=V","Dts=S","Sort=A","Days=T","Fill=B") | CM4: =BDH(CM$1,CN$3:CT$3,Settings!$B$3,IF(Settings!$B$4="","",Settings!$B$4),"Dir=V","Dts=S","Sort=A","Days=T","Fill=B") | CV4: =BDH(CV$1,CW$3:DC$3,Settings!$B$3,IF(Settings!$B$4="","",Settings!$B$4),"Dir=V","Dts=S","Sort=A","Days=T","Fill=B")

Sheet CL 2028
A1: ="CLF"&IF(A2<Settings!$B$5,"28","8")&" Comdty" | J1: ="CLG"&IF(J2<Settings!$B$5,"28","8")&" Comdty" | S1: ="CLH"&IF(S2<Settings!$B$5,"28","8")&" Comdty" | AB1: ="CLJ"&IF(AB2<Settings!$B$5,"28","8")&" Comdty" | AK1: ="CLK"&IF(AK2<Settings!$B$5,"28","8")&" Comdty" | AT1: ="CLM"&IF(AT2<Settings!$B$5,"28","8")&" Comdty" | BC1: ="CLN"&IF(BC2<Settings!$B$5,"28","8")&" Comdty" | BL1: ="CLQ"&IF(BL2<Settings!$B$5,"28","8")&" Comdty" | BU1: ="CLU"&IF(BU2<Settings!$B$5,"28","8")&" Comdty" | CD1: ="CLV"&IF(CD2<Settings!$B$5,"28","8")&" Comdty" | CM1: ="CLX"&IF(CM2<Settings!$B$5,"28","8")&" Comdty" | CV1: ="CLZ"&IF(CV2<Settings!$B$5,"28","8")&" Comdty"
A2: =WORKDAY(DATE(2028,0,25),-3) | B2: =BDP(A$1,"LAST_TRADEABLE_DT") | J2: =WORKDAY(DATE(2028,1,25),-3) | K2: =BDP(J$1,"LAST_TRADEABLE_DT") | S2: =WORKDAY(DATE(2028,2,25),-3) | T2: =BDP(S$1,"LAST_TRADEABLE_DT") | AB2: =WORKDAY(DATE(2028,3,25),-3) | AC2: =BDP(AB$1,"LAST_TRADEABLE_DT") | AK2: =WORKDAY(DATE(2028,4,25),-3) | AL2: =BDP(AK$1,"LAST_TRADEABLE_DT") | AT2: =WORKDAY(DATE(2028,5,25),-3) | AU2: =BDP(AT$1,"LAST_TRADEABLE_DT") | BC2: =WORKDAY(DATE(2028,6,25),-3) | BD2: =BDP(BC$1,"LAST_TRADEABLE_DT") | BL2: =WORKDAY(DATE(2028,7,25),-3) | BM2: =BDP(BL$1,"LAST_TRADEABLE_DT") | BU2: =WORKDAY(DATE(2028,8,25),-3) | BV2: =BDP(BU$1,"LAST_TRADEABLE_DT") | CD2: =WORKDAY(DATE(2028,9,25),-3) | CE2: =BDP(CD$1,"LAST_TRADEABLE_DT") | CM2: =WORKDAY(DATE(2028,10,25),-3) | CN2: =BDP(CM$1,"LAST_TRADEABLE_DT") | CV2: =WORKDAY(DATE(2028,11,25),-3) | CW2: =BDP(CV$1,"LAST_TRADEABLE_DT")
A3: Date | B3: PX_OPEN | C3: PX_HIGH | D3: PX_LOW | E3: PX_LAST | F3: PX_SETTLE | G3: PX_VOLUME | H3: OPEN_INT | J3: Date | K3: PX_OPEN | L3: PX_HIGH | M3: PX_LOW | N3: PX_LAST | O3: PX_SETTLE | P3: PX_VOLUME | Q3: OPEN_INT | S3: Date | T3: PX_OPEN | U3: PX_HIGH | V3: PX_LOW | W3: PX_LAST | X3: PX_SETTLE | Y3: PX_VOLUME | Z3: OPEN_INT | AB3: Date | AC3: PX_OPEN | AD3: PX_HIGH | AE3: PX_LOW | AF3: PX_LAST | AG3: PX_SETTLE | AH3: PX_VOLUME | AI3: OPEN_INT | AK3: Date | AL3: PX_OPEN | AM3: PX_HIGH | AN3: PX_LOW | AO3: PX_LAST | AP3: PX_SETTLE | AQ3: PX_VOLUME | AR3: OPEN_INT | AT3: Date | AU3: PX_OPEN | AV3: PX_HIGH | AW3: PX_LOW | AX3: PX_LAST | AY3: PX_SETTLE | AZ3: PX_VOLUME | BA3: OPEN_INT | BC3: Date | BD3: PX_OPEN | BE3: PX_HIGH | BF3: PX_LOW | BG3: PX_LAST | BH3: PX_SETTLE | BI3: PX_VOLUME | BJ3: OPEN_INT | BL3: Date | BM3: PX_OPEN | BN3: PX_HIGH | BO3: PX_LOW | BP3: PX_LAST | BQ3: PX_SETTLE | BR3: PX_VOLUME | BS3: OPEN_INT | BU3: Date | BV3: PX_OPEN | BW3: PX_HIGH | BX3: PX_LOW | BY3: PX_LAST | BZ3: PX_SETTLE | CA3: PX_VOLUME | CB3: OPEN_INT | CD3: Date | CE3: PX_OPEN | CF3: PX_HIGH | CG3: PX_LOW | CH3: PX_LAST | CI3: PX_SETTLE | CJ3: PX_VOLUME | CK3: OPEN_INT | CM3: Date | CN3: PX_OPEN | CO3: PX_HIGH | CP3: PX_LOW | CQ3: PX_LAST | CR3: PX_SETTLE | CS3: PX_VOLUME | CT3: OPEN_INT | CV3: Date | CW3: PX_OPEN | CX3: PX_HIGH | CY3: PX_LOW | CZ3: PX_LAST | DA3: PX_SETTLE | DB3: PX_VOLUME | DC3: OPEN_INT
A4: =BDH(A$1,B$3:H$3,Settings!$B$3,IF(Settings!$B$4="","",Settings!$B$4),"Dir=V","Dts=S","Sort=A","Days=T","Fill=B") | J4: =BDH(J$1,K$3:Q$3,Settings!$B$3,IF(Settings!$B$4="","",Settings!$B$4),"Dir=V","Dts=S","Sort=A","Days=T","Fill=B") | S4: =BDH(S$1,T$3:Z$3,Settings!$B$3,IF(Settings!$B$4="","",Settings!$B$4),"Dir=V","Dts=S","Sort=A","Days=T","Fill=B") | AB4: =BDH(AB$1,AC$3:AI$3,Settings!$B$3,IF(Settings!$B$4="","",Settings!$B$4),"Dir=V","Dts=S","Sort=A","Days=T","Fill=B") | AK4: =BDH(AK$1,AL$3:AR$3,Settings!$B$3,IF(Settings!$B$4="","",Settings!$B$4),"Dir=V","Dts=S","Sort=A","Days=T","Fill=B") | AT4: =BDH(AT$1,AU$3:BA$3,Settings!$B$3,IF(Settings!$B$4="","",Settings!$B$4),"Dir=V","Dts=S","Sort=A","Days=T","Fill=B") | BC4: =BDH(BC$1,BD$3:BJ$3,Settings!$B$3,IF(Settings!$B$4="","",Settings!$B$4),"Dir=V","Dts=S","Sort=A","Days=T","Fill=B") | BL4: =BDH(BL$1,BM$3:BS$3,Settings!$B$3,IF(Settings!$B$4="","",Settings!$B$4),"Dir=V","Dts=S","Sort=A","Days=T","Fill=B") | BU4: =BDH(BU$1,BV$3:CB$3,Settings!$B$3,IF(Settings!$B$4="","",Settings!$B$4),"Dir=V","Dts=S","Sort=A","Days=T","Fill=B") | CD4: =BDH(CD$1,CE$3:CK$3,Settings!$B$3,IF(Settings!$B$4="","",Settings!$B$4),"Dir=V","Dts=S","Sort=A","Days=T","Fill=B") | CM4: =BDH(CM$1,CN$3:CT$3,Settings!$B$3,IF(Settings!$B$4="","",Settings!$B$4),"Dir=V","Dts=S","Sort=A","Days=T","Fill=B") | CV4: =BDH(CV$1,CW$3:DC$3,Settings!$B$3,IF(Settings!$B$4="","",Settings!$B$4),"Dir=V","Dts=S","Sort=A","Days=T","Fill=B")

Sheet CL 2029
A1: ="CLF"&IF(A2<Settings!$B$5,"29","9")&" Comdty" | J1: ="CLG"&IF(J2<Settings!$B$5,"29","9")&" Comdty" | S1: ="CLH"&IF(S2<Settings!$B$5,"29","9")&" Comdty" | AB1: ="CLJ"&IF(AB2<Settings!$B$5,"29","9")&" Comdty" | AK1: ="CLK"&IF(AK2<Settings!$B$5,"29","9")&" Comdty" | AT1: ="CLM"&IF(AT2<Settings!$B$5,"29","9")&" Comdty" | BC1: ="CLN"&IF(BC2<Settings!$B$5,"29","9")&" Comdty" | BL1: ="CLQ"&IF(BL2<Settings!$B$5,"29","9")&" Comdty" | BU1: ="CLU"&IF(BU2<Settings!$B$5,"29","9")&" Comdty" | CD1: ="CLV"&IF(CD2<Settings!$B$5,"29","9")&" Comdty" | CM1: ="CLX"&IF(CM2<Settings!$B$5,"29","9")&" Comdty" | CV1: ="CLZ"&IF(CV2<Settings!$B$5,"29","9")&" Comdty"
