Workbook

Sheet Settings
A1: CL (WTI) monthly options: ATM +/- 8 strikes, last 100 days before expiry (oil-options)
A3: Year | B3: 2026 | C3: Contract year (delivery month) to pull
A4: Strike format | B4: 1 | C4: 1 = '70', 2 = '70.00'
A5: As-of date | B5: 46308 | C5: Set to today's date; decides expired vs live tickers
A7: Legend
A8: Yellow cells with blue text | B8: inputs you may change; everything else is a formula
A10: How to use
A11: 1. Open this file in Excel on the Bloomberg PC with the Terminal logged in. Click Enable Editing / Enable Content.
A12: 2. Wait until no cell says 'Requesting Data...'. If nothing loads: Bloomberg tab > Refresh > Refresh Workbook.
A13: 3. A cell reading '#N/A Invalid Security' or '#N/A Field Not Applicable' just means that item is unavailable.
A14: 4. Each sheet is one futures contract month of the Year below. Strikes are centred on the futures price 45 days before expiry.
A15: 5. Save As CL_Options_<year>.xlsx, then change Year, wait for it to reload, and Save As again. Do this for each year 2018-2026.
A16: 6. If every option shows '#N/A Invalid Security', change Strike format to 2 (e.g. 'CLZ5C 70.00') and check one ticker on the Terminal: CLA Comdty OMON <GO>.

Sheet Jan
A1: Contract month | B1: 1 | D1: ="CL"&MID("FGHJKMNQUVXZ",B$1,1)&B$4&"C "&IF(Settings!$B$4=2,TEXT((B$8-8),"0.00"),(B$8-8))&" Comdty" | U1: ="CL"&MID("FGHJKMNQUVXZ",B$1,1)&B$4&"P "&IF(Settings!$B$4=2,TEXT((B$8-8),"0.00"),(B$8-8))&" Comdty" | AL1: ="CL"&MID("FGHJKMNQUVXZ",B$1,1)&B$4&"C "&IF(Settings!$B$4=2,TEXT((B$8-7),"0.00"),(B$8-7))&" Comdty" | BC1: ="CL"&MID("FGHJKMNQUVXZ",B$1,1)&B$4&"P "&IF(Settings!$B$4=2,TEXT((B$8-7),"0.00"),(B$8-7))&" Comdty" | BT1: ="CL"&MID("FGHJKMNQUVXZ",B$1,1)&B$4&"C "&IF(Settings!$B$4=2,TEXT((B$8-6),"0.00"),(B$8-6))&" Comdty" | CK1: ="CL"&MID("FGHJKMNQUVXZ",B$1,1)&B$4&"P "&IF(Settings!$B$4=2,TEXT((B$8-6),"0.00"),(B$8-6))&" Comdty" | DB1: ="CL"&MID("FGHJKMNQUVXZ",B$1,1)&B$4&"C "&IF(Settings!$B$4=2,TEXT((B$8-5),"0.00"),(B$8-5))&" Comdty" | DS1: ="CL"&MID("FGHJKMNQUVXZ",B$1,1)&B$4&"P "&IF(Settings!$B$4=2,TEXT((B$8-5),"0.00"),(B$8-5))&" Comdty" | EJ1: ="CL"&MID("FGHJKMNQUVXZ",B$1,1)&B$4&"C "&IF(Settings!$B$4=2,TEXT((B$8-4),"0.00"),(B$8-4))&" Comdty" | FA1: ="CL"&MID("FGHJKMNQUVXZ",B$1,1)&B$4&"P "&IF(Settings!$B$4=2,TEXT((B$8-4),"0.00"),(B$8-4))&" Comdty" | FR1: ="CL"&MID("FGHJKMNQUVXZ",B$1,1)&B$4&"C "&IF(Settings!$B$4=2,TEXT((B$8-3),"0.00"),(B$8-3))&" Comdty" | GI1: ="CL"&MID("FGHJKMNQUVXZ",B$1,1)&B$4&"P "&IF(Settings!$B$4=2,TEXT((B$8-3),"0.00"),(B$8-3))&" Comdty" | GZ1: ="CL"&MID("FGHJKMNQUVXZ",B$1,1)&B$4&"C "&IF(Settings!$B$4=2,TEXT((B$8-2),"0.00"),(B$8-2))&" Comdty" | HQ1: ="CL"&MID("FGHJKMNQUVXZ",B$1,1)&B$4&"P "&IF(Settings!$B$4=2,TEXT((B$8-2),"0.00"),(B$8-2))&" Comdty" | IH1: ="CL"&MID("FGHJKMNQUVXZ",B$1,1)&B$4&"C "&IF(Settings!$B$4=2,TEXT((B$8-1),"0.00"),(B$8-1))&" Comdty" | IY1: ="CL"&MID("FGHJKMNQUVXZ",B$1,1)&B$4&"P "&IF(Settings!$B$4=2,TEXT((B$8-1),"0.00"),(B$8-1))&" Comdty" | JP1: ="CL"&MID("FGHJKMNQUVXZ",B$1,1)&B$4&"C "&IF(Settings!$B$4=2,TEXT(B$8,"0.00"),B$8)&" Comdty" | KG1: ="CL"&MID("FGHJKMNQUVXZ",B$1,1)&B$4&"P "&IF(Settings!$B$4=2,TEXT(B$8,"0.00"),B$8)&" Comdty" | KX1: ="CL"&MID("FGHJKMNQUVXZ",B$1,1)&B$4&"C "&IF(Settings!$B$4=2,TEXT((B$8+1),"0.00"),(B$8+1))&" Comdty" | LO1: ="CL"&MID("FGHJKMNQUVXZ",B$1,1)&B$4&"P "&IF(Settings!$B$4=2,TEXT((B$8+1),"0.00"),(B$8+1))&" Comdty" | MF1: ="CL"&MID("FGHJKMNQUVXZ",B$1,1)&B$4&"C "&IF(Settings!$B$4=2,TEXT((B$8+2),"0.00"),(B$8+2))&" Comdty" | MW1: ="CL"&MID("FGHJKMNQUVXZ",B$1,1)&B$4&"P "&IF(Settings!$B$4=2,TEXT((B$8+2),"0.00"),(B$8+2))&" Comdty" | NN1: ="CL"&MID("FGHJKMNQUVXZ",B$1,1)&B$4&"C "&IF(Settings!$B$4=2,TEXT((B$8+3),"0.00"),(B$8+3))&" Comdty" | OE1: ="CL"&MID("FGHJKMNQUVXZ",B$1,1)&B$4&"P "&IF(Settings!$B$4=2,TEXT((B$8+3),"0.00"),(B$8+3))&" Comdty" | OV1: ="CL"&MID("FGHJKMNQUVXZ",B$1,1)&B$4&"C "&IF(Settings!$B$4=2,TEXT((B$8+4),"0.00"),(B$8+4))&" Comdty" | PM1: ="CL"&MID("FGHJKMNQUVXZ",B$1,1)&B$4&"P "&IF(Settings!$B$4=2,TEXT((B$8+4),"0.00"),(B$8+4))&" Comdty" | QD1: ="CL"&MID("FGHJKMNQUVXZ",B$1,1)&B$4&"C "&IF(Settings!$B$4=2,TEXT((B$8+5),"0.00"),(B$8+5))&" Comdty" | QU1: ="CL"&MID("FGHJKMNQUVXZ",B$1,1)&B$4&"P "&IF(Settings!$B$4=2,TEXT((B$8+5),"0.00"),(B$8+5))&" Comdty" | RL1: ="CL"&MID("FGHJKMNQUVXZ",B$1,1)&B$4&"C "&IF(Settings!$B$4=2,TEXT((B$8+6),"0.00"),(B$8+6))&" Comdty" | SC1: ="CL"&MID("FGHJKMNQUVXZ",B$1,1)&B$4&"P "&IF(Settings!$B$4=2,TEXT((B$8+6),"0.00"),(B$8+6))&" Comdty" | ST1: ="CL"&MID("FGHJKMNQUVXZ",B$1,1)&B$4&"C "&IF(Settings!$B$4=2,TEXT((B$8+7),"0.00"),(B$8+7))&" Comdty" | TK1: ="CL"&MID("FGHJKMNQUVXZ",B$1,1)&B$4&"P "&IF(Settings!$B$4=2,TEXT((B$8+7),"0.00"),(B$8+7))&" Comdty" | UB1: ="CL"&MID("FGHJKMNQUVXZ",B$1,1)&B$4&"C "&IF(Settings!$B$4=2,TEXT((B$8+8),"0.00"),(B$8+8))&" Comdty" | US1: ="CL"&MID("FGHJKMNQUVXZ",B$1,1)&B$4&"P "&IF(Settings!$B$4=2,TEXT((B$8+8),"0.00"),(B$8+8))&" Comdty"
A2: Futures last trade | B2: =WORKDAY(DATE(Settings!$B$3,B1-1,25),-3) | D2: call -8 from ATM | U2: put -8 from ATM | AL2: call -7 from ATM | BC2: put -7 from ATM | BT2: call -6 from ATM | CK2: put -6 from ATM | DB2: call -5 from ATM | DS2: put -5 from ATM | EJ2: call -4 from ATM | FA2: put -4 from ATM | FR2: call -3 from ATM | GI2: put -3 from ATM | GZ2: call -2 from ATM | HQ2: put -2 from ATM | IH2: call -1 from ATM | IY2: put -1 from ATM | JP2: call +0 from ATM | KG2: put +0 from ATM | KX2: call +1 from ATM | LO2: put +1 from ATM | MF2: call +2 from ATM | MW2: put +2 from ATM | NN2: call +3 from ATM | OE2: put +3 from ATM | OV2: call +4 from ATM | PM2: put +4 from ATM | QD2: call +5 from ATM | QU2: put +5 from ATM | RL2: call +6 from ATM | SC2: put +6 from ATM | ST2: call +7 from ATM | TK2: put +7 from ATM | UB2: call +8 from ATM | US2: put +8 from ATM
A3: Option expiry (approx) | B3: =WORKDAY(B2,-1) | D3: Date | E3: PX_BID | F3: PX_ASK | G3: PX_MID | H3: PX_LAST | I3: PX_SETTLE | J3: PX_VOLUME | K3: OPEN_INT | L3: IVOL_MID | M3: IVOL_BID | N3: IVOL_ASK | O3: DELTA_MID | P3: GAMMA_MID | Q3: VEGA_MID | R3: THETA_MID | S3: OPT_UNDL_PX | U3: Date | V3: PX_BID | W3: PX_ASK | X3: PX_MID | Y3: PX_LAST | Z3: PX_SETTLE | AA3: PX_VOLUME | AB3: OPEN_INT | AC3: IVOL_MID | AD3: IVOL_BID | AE3: IVOL_ASK | AF3: DELTA_MID | AG3: GAMMA_MID | AH3: VEGA_MID | AI3: THETA_MID | AJ3: OPT_UNDL_PX | AL3: Date | AM3: PX_BID | AN3: PX_ASK | AO3: PX_MID | AP3: PX_LAST | AQ3: PX_SETTLE | AR3: PX_VOLUME | AS3: OPEN_INT | AT3: IVOL_MID | AU3: IVOL_BID | AV3: IVOL_ASK | AW3: DELTA_MID | AX3: GAMMA_MID | AY3: VEGA_MID | AZ3: THETA_MID | BA3: OPT_UNDL_PX | BC3: Date | BD3: PX_BID | BE3: PX_ASK | BF3: PX_MID | BG3: PX_LAST | BH3: PX_SETTLE | BI3: PX_VOLUME | BJ3: OPEN_INT | BK3: IVOL_MID | BL3: IVOL_BID | BM3: IVOL_ASK | BN3: DELTA_MID | BO3: GAMMA_MID | BP3: VEGA_MID | BQ3: THETA_MID | BR3: OPT_UNDL_PX | BT3: Date | BU3: PX_BID | BV3: PX_ASK | BW3: PX_MID | BX3: PX_LAST | BY3: PX_SETTLE | BZ3: PX_VOLUME | CA3: OPEN_INT | CB3: IVOL_MID | CC3: IVOL_BID | CD3: IVOL_ASK | CE3: DELTA_MID | CF3: GAMMA_MID | CG3: VEGA_MID | CH3: THETA_MID | CI3: OPT_UNDL_PX | CK3: Date | CL3: PX_BID | CM3: PX_ASK | CN3: PX_MID | CO3: PX_LAST | CP3: PX_SETTLE | CQ3: PX_VOLUME | CR3: OPEN_INT | CS3: IVOL_MID | CT3: IVOL_BID | CU3: IVOL_ASK | CV3: DELTA_MID | CW3: GAMMA_MID | CX3: VEGA_MID | CY3: THETA_MID | CZ3: OPT_UNDL_PX | DB3: Date | DC3: PX_BID | DD3: PX_ASK | DE3: PX_MID | DF3: PX_LAST | DG3: PX_SETTLE | DH3: PX_VOLUME | DI3: OPEN_INT | DJ3: IVOL_MID | DK3: IVOL_BID | DL3: IVOL_ASK | DM3: DELTA_MID | DN3: GAMMA_MID | DO3: VEGA_MID | DP3: THETA_MID | DQ3: OPT_UNDL_PX | DS3: Date | DT3: PX_BID | DU3: PX_ASK | DV3: PX_MID | DW3: PX_LAST | DX3: PX_SETTLE | DY3: PX_VOLUME | DZ3: OPEN_INT | EA3: IVOL_MID | EB3: IVOL_BID | EC3: IVOL_ASK | ED3: DELTA_MID | EE3: GAMMA_MID | EF3: VEGA_MID | EG3: THETA_MID | EH3: OPT_UNDL_PX | EJ3: Date | EK3: PX_BID | EL3: PX_ASK | EM3: PX_MID | EN3: PX_LAST | EO3: PX_SETTLE | EP3: PX_VOLUME | EQ3: OPEN_INT | ER3: IVOL_MID | ES3: IVOL_BID | ET3: IVOL_ASK | EU3: DELTA_MID | EV3: GAMMA_MID | EW3: VEGA_MID | EX3: THETA_MID | EY3: OPT_UNDL_PX | FA3: Date | FB3: PX_BID | FC3: PX_ASK | FD3: PX_MID | FE3: PX_LAST | FF3: PX_SETTLE | FG3: PX_VOLUME | FH3: OPEN_INT | FI3: IVOL_MID | FJ3: IVOL_BID | FK3: IVOL_ASK | FL3: DELTA_MID | FM3: GAMMA_MID | FN3: VEGA_MID | FO3: THETA_MID | FP3: OPT_UNDL_PX | FR3: Date | FS3: PX_BID | FT3: PX_ASK | FU3: PX_MID | FV3: PX_LAST | FW3: PX_SETTLE | FX3: PX_VOLUME | FY3: OPEN_INT | FZ3: IVOL_MID | GA3: IVOL_BID | GB3: IVOL_ASK | GC3: DELTA_MID | GD3: GAMMA_MID | GE3: VEGA_MID | GF3: THETA_MID | GG3: OPT_UNDL_PX | GI3: Date | GJ3: PX_BID | GK3: PX_ASK | GL3: PX_MID | GM3: PX_LAST | GN3: PX_SETTLE | GO3: PX_VOLUME | GP3: OPEN_INT | GQ3: IVOL_MID | GR3: IVOL_BID | GS3: IVOL_ASK | GT3: DELTA_MID | GU3: GAMMA_MID | GV3: VEGA_MID | GW3: THETA_MID | GX3: OPT_UNDL_PX | GZ3: Date | HA3: PX_BID | HB3: PX_ASK | HC3: PX_MID | HD3: PX_LAST | HE3: PX_SETTLE | HF3: PX_VOLUME | HG3: OPEN_INT | HH3: IVOL_MID | HI3: IVOL_BID | HJ3: IVOL_ASK | HK3: DELTA_MID | HL3: GAMMA_MID | HM3: VEGA_MID | HN3: THETA_MID | HO3: OPT_UNDL_PX | HQ3: Date | HR3: PX_BID | HS3: PX_ASK | HT3: PX_MID | HU3: PX_LAST | HV3: PX_SETTLE | HW3: PX_VOLUME | HX3: OPEN_INT | HY3: IVOL_MID | HZ3: IVOL_BID | IA3: IVOL_ASK | IB3: DELTA_MID | IC3: GAMMA_MID | ID3: VEGA_MID | IE3: THETA_MID | IF3: OPT_UNDL_PX | IH3: Date | II3: PX_BID | IJ3: PX_ASK | IK3: PX_MID | IL3: PX_LAST | IM3: PX_SETTLE | IN3: PX_VOLUME | IO3: OPEN_INT | IP3: IVOL_MID | IQ3: IVOL_BID | IR3: IVOL_ASK | IS3: DELTA_MID | IT3: GAMMA_MID | IU3: VEGA_MID | IV3: THETA_MID | IW3: OPT_UNDL_PX | IY3: Date | IZ3: PX_BID | JA3: PX_ASK | JB3: PX_MID | JC3: PX_LAST | JD3: PX_SETTLE | JE3: PX_VOLUME | JF3: OPEN_INT | JG3: IVOL_MID | JH3: IVOL_BID | JI3: IVOL_ASK | JJ3: DELTA_MID | JK3: GAMMA_MID | JL3: VEGA_MID | JM3: THETA_MID | JN3: OPT_UNDL_PX | JP3: Date | JQ3: PX_BID | JR3: PX_ASK | JS3: PX_MID | JT3: PX_LAST | JU3: PX_SETTLE | JV3: PX_VOLUME | JW3: OPEN_INT | JX3: IVOL_MID | JY3: IVOL_BID | JZ3: IVOL_ASK | KA3: DELTA_MID | KB3: GAMMA_MID | KC3: VEGA_MID | KD3: THETA_MID | KE3: OPT_UNDL_PX | KG3: Date | KH3: PX_BID | KI3: PX_ASK | KJ3: PX_MID | KK3: PX_LAST | KL3: PX_SETTLE | KM3: PX_VOLUME | KN3: OPEN_INT | KO3: IVOL_MID | KP3: IVOL_BID | KQ3: IVOL_ASK | KR3: DELTA_MID | KS3: GAMMA_MID | KT3: VEGA_MID | KU3: THETA_MID | KV3: OPT_UNDL_PX | KX3: Date | KY3: PX_BID | KZ3: PX_ASK | LA3: PX_MID | LB3: PX_LAST | LC3: PX_SETTLE | LD3: PX_VOLUME | LE3: OPEN_INT | LF3: IVOL_MID | LG3: IVOL_BID | LH3: IVOL_ASK | LI3: DELTA_MID | LJ3: GAMMA_MID | LK3: VEGA_MID | LL3: THETA_MID | LM3: OPT_UNDL_PX | LO3: Date | LP3: PX_BID | LQ3: PX_ASK | LR3: PX_MID | LS3: PX_LAST | LT3: PX_SETTLE | LU3: PX_VOLUME | LV3: OPEN_INT | LW3: IVOL_MID | LX3: IVOL_BID | LY3: IVOL_ASK | LZ3: DELTA_MID | MA3: GAMMA_MID | MB3: VEGA_MID | MC3: THETA_MID | MD3: OPT_UNDL_PX | MF3: Date | MG3: PX_BID | MH3: PX_ASK | MI3: PX_MID | MJ3: PX_LAST | MK3: PX_SETTLE | ML3: PX_VOLUME | MM3: OPEN_INT | MN3: IVOL_MID | MO3: IVOL_BID | MP3: IVOL_ASK | MQ3: DELTA_MID | MR3: GAMMA_MID | MS3: VEGA_MID | MT3: THETA_MID | MU3: OPT_UNDL_PX | MW3: Date | MX3: PX_BID | MY3: PX_ASK | MZ3: PX_MID | NA3: PX_LAST | NB3: PX_SETTLE | NC3: PX_VOLUME | ND3: OPEN_INT | NE3: IVOL_MID | NF3: IVOL_BID | NG3: IVOL_ASK | NH3: DELTA_MID | NI3: GAMMA_MID | NJ3: VEGA_MID | NK3: THETA_MID | NL3: OPT_UNDL_PX | NN3: Date | NO3: PX_BID | NP3: PX_ASK | NQ3: PX_MID | NR3: PX_LAST | NS3: PX_SETTLE | NT3: PX_VOLUME | NU3: OPEN_INT | NV3: IVOL_MID | NW3: IVOL_BID | NX3: IVOL_ASK | NY3: DELTA_MID | NZ3: GAMMA_MID | OA3: VEGA_MID | OB3: THETA_MID | OC3: OPT_UNDL_PX | OE3: Date | OF3: PX_BID | OG3: PX_ASK | OH3: PX_MID | OI3: PX_LAST | OJ3: PX_SETTLE | OK3: PX_VOLUME | OL3: OPEN_INT | OM3: IVOL_MID | ON3: IVOL_BID | OO3: IVOL_ASK | OP3: DELTA_MID | OQ3: GAMMA_MID | OR3: VEGA_MID | OS3: THETA_MID | OT3: OPT_UNDL_PX | OV3: Date | OW3: PX_BID | OX3: PX_ASK | OY3: PX_MID | OZ3: PX_LAST | PA3: PX_SETTLE | PB3: PX_VOLUME | PC3: OPEN_INT | PD3: IVOL_MID | PE3: IVOL_BID | PF3: IVOL_ASK | PG3: DELTA_MID | PH3: GAMMA_MID | PI3: VEGA_MID | PJ3: THETA_MID | PK3: OPT_UNDL_PX | PM3: Date | PN3: PX_BID | PO3: PX_ASK | PP3: PX_MID | PQ3: PX_LAST | PR3: PX_SETTLE | PS3: PX_VOLUME | PT3: OPEN_INT | PU3: IVOL_MID | PV3: IVOL_BID | PW3: IVOL_ASK | PX3: DELTA_MID | PY3: GAMMA_MID | PZ3: VEGA_MID | QA3: THETA_MID | QB3: OPT_UNDL_PX | QD3: Date | QE3: PX_BID | QF3: PX_ASK | QG3: PX_MID | QH3: PX_LAST | QI3: PX_SETTLE | QJ3: PX_VOLUME | QK3: OPEN_INT | QL3: IVOL_MID | QM3: IVOL_BID | QN3: IVOL_ASK | QO3: DELTA_MID | QP3: GAMMA_MID | QQ3: VEGA_MID | QR3: THETA_MID | QS3: OPT_UNDL_PX | QU3: Date | QV3: PX_BID | QW3: PX_ASK | QX3: PX_MID | QY3: PX_LAST | QZ3: PX_SETTLE | RA3: PX_VOLUME | RB3: OPEN_INT | RC3: IVOL_MID | RD3: IVOL_BID | RE3: IVOL_ASK | RF3: DELTA_MID | RG3: GAMMA_MID | RH3: VEGA_MID | RI3: THETA_MID | RJ3: OPT_UNDL_PX | RL3: Date | RM3: PX_BID | RN3: PX_ASK | RO3: PX_MID | RP3: PX_LAST | RQ3: PX_SETTLE | RR3: PX_VOLUME | RS3: OPEN_INT | RT3: IVOL_MID | RU3: IVOL_BID | RV3: IVOL_ASK | RW3: DELTA_MID | RX3: GAMMA_MID | RY3: VEGA_MID | RZ3: THETA_MID | SA3: OPT_UNDL_PX | SC3: Date | SD3: PX_BID | SE3: PX_ASK | SF3: PX_MID | SG3: PX_LAST | SH3: PX_SETTLE | SI3: PX_VOLUME | SJ3: OPEN_INT | SK3: IVOL_MID | SL3: IVOL_BID | SM3: IVOL_ASK | SN3: DELTA_MID | SO3: GAMMA_MID | SP3: VEGA_MID | SQ3: THETA_MID | SR3: OPT_UNDL_PX | ST3: Date | SU3: PX_BID | SV3: PX_ASK | SW3: PX_MID | SX3: PX_LAST | SY3: PX_SETTLE | SZ3: PX_VOLUME | TA3: OPEN_INT | TB3: IVOL_MID | TC3: IVOL_BID | TD3: IVOL_ASK | TE3: DELTA_MID | TF3: GAMMA_MID | TG3: VEGA_MID | TH3: THETA_MID | TI3: OPT_UNDL_PX | TK3: Date | TL3: PX_BID | TM3: PX_ASK | TN3: PX_MID | TO3: PX_LAST | TP3: PX_SETTLE | TQ3: PX_VOLUME | TR3: OPEN_INT | TS3: IVOL_MID | TT3: IVOL_BID | TU3: IVOL_ASK | TV3: DELTA_MID | TW3: GAMMA_MID | TX3: VEGA_MID | TY3: THETA_MID | TZ3: OPT_UNDL_PX | UB3: Date | UC3: PX_BID | UD3: PX_ASK | UE3: PX_MID | UF3: PX_LAST | UG3: PX_SETTLE | UH3: PX_VOLUME | UI3: OPEN_INT | UJ3: IVOL_MID | UK3: IVOL_BID | UL3: IVOL_ASK | UM3: DELTA_MID | UN3: GAMMA_MID | UO3: VEGA_MID | UP3: THETA_MID | UQ3: OPT_UNDL_PX | US3: Date | UT3: PX_BID | UU3: PX_ASK | UV3: PX_MID | UW3: PX_LAST | UX3: PX_SETTLE | UY3: PX_VOLUME | UZ3: OPEN_INT | VA3: IVOL_MID | VB3: IVOL_BID | VC3: IVOL_ASK | VD3: DELTA_MID | VE3: GAMMA_MID | VF3: VEGA_MID | VG3: THETA_MID | VH3: OPT_UNDL_PX
A4: Year in ticker | B4: =IF(B2<Settings!$B$5,TEXT(MOD(Settings!$B$3,100),"00"),TEXT(MOD(Settings!$B$3,10),"0")) | D4: =BDH(D$1,E$3:S$3,$B$9,$B$10,"Dir=V","Dts=S","Sort=A","Days=T","Fill=B") | U4: =BDH(U$1,V$3:AJ$3,$B$9,$B$10,"Dir=V","Dts=S","Sort=A","Days=T","Fill=B") | AL4: =BDH(AL$1,AM$3:BA$3,$B$9,$B$10,"Dir=V","Dts=S","Sort=A","Days=T","Fill=B") | BC4: =BDH(BC$1,BD$3:BR$3,$B$9,$B$10,"Dir=V","Dts=S","Sort=A","Days=T","Fill=B") | BT4: =BDH(BT$1,BU$3:CI$3,$B$9,$B$10,"Dir=V","Dts=S","Sort=A","Days=T","Fill=B") | CK4: =BDH(CK$1,CL$3:CZ$3,$B$9,$B$10,"Dir=V","Dts=S","Sort=A","Days=T","Fill=B") | DB4: =BDH(DB$1,DC$3:DQ$3,$B$9,$B$10,"Dir=V","Dts=S","Sort=A","Days=T","Fill=B") | DS4: =BDH(DS$1,DT$3:EH$3,$B$9,$B$10,"Dir=V","Dts=S","Sort=A","Days=T","Fill=B") | EJ4: =BDH(EJ$1,EK$3:EY$3,$B$9,$B$10,"Dir=V","Dts=S","Sort=A","Days=T","Fill=B") | FA4: =BDH(FA$1,FB$3:FP$3,$B$9,$B$10,"Dir=V","Dts=S","Sort=A","Days=T","Fill=B") | FR4: =BDH(FR$1,FS$3:GG$3,$B$9,$B$10,"Dir=V","Dts=S","Sort=A","Days=T","Fill=B") | GI4: =BDH(GI$1,GJ$3:GX$3,$B$9,$B$10,"Dir=V","Dts=S","Sort=A","Days=T","Fill=B") | GZ4: =BDH(GZ$1,HA$3:HO$3,$B$9,$B$10,"Dir=V","Dts=S","Sort=A","Days=T","Fill=B") | HQ4: =BDH(HQ$1,HR$3:IF$3,$B$9,$B$10,"Dir=V","Dts=S","Sort=A","Days=T","Fill=B") | IH4: =BDH(IH$1,II$3:IW$3,$B$9,$B$10,"Dir=V","Dts=S","Sort=A","Days=T","Fill=B") | IY4: =BDH(IY$1,IZ$3:JN$3,$B$9,$B$10,"Dir=V","Dts=S","Sort=A","Days=T","Fill=B") | JP4: =BDH(JP$1,JQ$3:KE$3,$B$9,$B$10,"Dir=V","Dts=S","Sort=A","Days=T","Fill=B") | KG4: =BDH(KG$1,KH$3:KV$3,$B$9,$B$10,"Dir=V","Dts=S","Sort=A","Days=T","Fill=B") | KX4: =BDH(KX$1,KY$3:LM$3,$B$9,$B$10,"Dir=V","Dts=S","Sort=A","Days=T","Fill=B") | LO4: =BDH(LO$1,LP$3:MD$3,$B$9,$B$10,"Dir=V","Dts=S","Sort=A","Days=T","Fill=B") | MF4: =BDH(MF$1,MG$3:MU$3,$B$9,$B$10,"Dir=V","Dts=S","Sort=A","Days=T","Fill=B") | MW4: =BDH(MW$1,MX$3:NL$3,$B$9,$B$10,"Dir=V","Dts=S","Sort=A","Days=T","Fill=B") | NN4: =BDH(NN$1,NO$3:OC$3,$B$9,$B$10,"Dir=V","Dts=S","Sort=A","Days=T","Fill=B") | OE4: =BDH(OE$1,OF$3:OT$3,$B$9,$B$10,"Dir=V","Dts=S","Sort=A","Days=T","Fill=B") | OV4: =BDH(OV$1,OW$3:PK$3,$B$9,$B$10,"Dir=V","Dts=S","Sort=A","Days=T","Fill=B") | PM4: =BDH(PM$1,PN$3:QB$3,$B$9,$B$10,"Dir=V","Dts=S","Sort=A","Days=T","Fill=B") | QD4: =BDH(QD$1,QE$3:QS$3,$B$9,$B$10,"Dir=V","Dts=S","Sort=A","Days=T","Fill=B") | QU4: =BDH(QU$1,QV$3:RJ$3,$B$9,$B$10,"Dir=V","Dts=S","Sort=A","Days=T","Fill=B") | RL4: =BDH(RL$1,RM$3:SA$3,$B$9,$B$10,"Dir=V","Dts=S","Sort=A","Days=T","Fill=B") | SC4: =BDH(SC$1,SD$3:SR$3,$B$9,$B$10,"Dir=V","Dts=S","Sort=A","Days=T","Fill=B") | ST4: =BDH(ST$1,SU$3:TI$3,$B$9,$B$10,"Dir=V","Dts=S","Sort=A","Days=T","Fill=B") | TK4: =BDH(TK$1,TL$3:TZ$3,$B$9,$B$10,"Dir=V","Dts=S","Sort=A","Days=T","Fill=B") | UB4: =BDH(UB$1,UC$3:UQ$3,$B$9,$B$10,"Dir=V","Dts=S","Sort=A","Days=T","Fill=B") | US4: =BDH(US$1,UT$3:VH$3,$B$9,$B$10,"Dir=V","Dts=S","Sort=A","Days=T","Fill=B")
A5: Futures ticker | B5: ="CL"&MID("FGHJKMNQUVXZ",B1,1)&B4&" Comdty"
A6: Strike reference date | B6: =B3-45
A7: Futures price on that date | B7: =BDH(B5,"PX_LAST",B6,B6,"Days=A","Fill=P","Dts=H")
A8: ATM strike | B8: =ROUND(B7,0)
A9: History start | B9: =B3-100
A10: History end | B10: =B3

Sheet Feb
A1: Contract month | B1: 2 | D1: ="CL"&MID("FGHJKMNQUVXZ",B$1,1)&B$4&"C "&IF(Settings!$B$4=2,TEXT((B$8-8),"0.00"),(B$8-8))&" Comdty" | U1: ="CL"&MID("FGHJKMNQUVXZ",B$1,1)&B$4&"P "&IF(Settings!$B$4=2,TEXT((B$8-8),"0.00"),(B$8-8))&" Comdty" | AL1: ="CL"&MID("FGHJKMNQUVXZ",B$1,1)&B$4&"C "&IF(Settings!$B$4=2,TEXT((B$8-7),"0.00"),(B$8-7))&" Comdty" | BC1: ="CL"&MID("FGHJKMNQUVXZ",B$1,1)&B$4&"P "&IF(Settings!$B$4=2,TEXT((B$8-7),"0.00"),(B$8-7))&" Comdty" | BT1: ="CL"&MID("FGHJKMNQUVXZ",B$1,1)&B$4&"C "&IF(Settings!$B$4=2,TEXT((B$8-6),"0.00"),(B$8-6))&" Comdty" | CK1: ="CL"&MID("FGHJKMNQUVXZ",B$1,1)&B$4&"P "&IF(Settings!$B$4=2,TEXT((B$8-6),"0.00"),(B$8-6))&" Comdty" | DB1: ="CL"&MID("FGHJKMNQUVXZ",B$1,1)&B$4&"C "&IF(Settings!$B$4=2,TEXT((B$8-5),"0.00"),(B$8-5))&" Comdty" | DS1: ="CL"&MID("FGHJKMNQUVXZ",B$1,1)&B$4&"P "&IF(Settings!$B$4=2,TEXT((B$8-5),"0.00"),(B$8-5))&" Comdty" | EJ1: ="CL"&MID("FGHJKMNQUVXZ",B$1,1)&B$4&"C "&IF(Settings!$B$4=2,TEXT((B$8-4),"0.00"),(B$8-4))&" Comdty" | FA1: ="CL"&MID("FGHJKMNQUVXZ",B$1,1)&B$4&"P "&IF(Settings!$B$4=2,TEXT((B$8-4),"0.00"),(B$8-4))&" Comdty" | FR1: ="CL"&MID("FGHJKMNQUVXZ",B$1,1)&B$4&"C "&IF(Settings!$B$4=2,TEXT((B$8-3),"0.00"),(B$8-3))&" Comdty" | GI1: ="CL"&MID("FGHJKMNQUVXZ",B$1,1)&B$4&"P "&IF(Settings!$B$4=2,TEXT((B$8-3),"0.00"),(B$8-3))&" Comdty" | GZ1: ="CL"&MID("FGHJKMNQUVXZ",B$1,1)&B$4&"C "&IF(Settings!$B$4=2,TEXT((B$8-2),"0.00"),(B$8-2))&" Comdty" | HQ1: ="CL"&MID("FGHJKMNQUVXZ",B$1,1)&B$4&"P "&IF(Settings!$B$4=2,TEXT((B$8-2),"0.00"),(B$8-2))&" Comdty" | IH1: ="CL"&MID("FGHJKMNQUVXZ",B$1,1)&B$4&"C "&IF(Settings!$B$4=2,TEXT((B$8-1),"0.00"),(B$8-1))&" Comdty" | IY1: ="CL"&MID("FGHJKMNQUVXZ",B$1,1)&B$4&"P "&IF(Settings!$B$4=2,TEXT((B$8-1),"0.00"),(B$8-1))&" Comdty" | JP1: ="CL"&MID("FGHJKMNQUVXZ",B$1,1)&B$4&"C "&IF(Settings!$B$4=2,TEXT(B$8,"0.00"),B$8)&" Comdty" | KG1: ="CL"&MID("FGHJKMNQUVXZ",B$1,1)&B$4&"P "&IF(Settings!$B$4=2,TEXT(B$8,"0.00"),B$8)&" Comdty" | KX1: ="CL"&MID("FGHJKMNQUVXZ",B$1,1)&B$4&"C "&IF(Settings!$B$4=2,TEXT((B$8+1),"0.00"),(B$8+1))&" Comdty" | LO1: ="CL"&MID("FGHJKMNQUVXZ",B$1,1)&B$4&"P "&IF(Settings!$B$4=2,TEXT((B$8+1),"0.00"),(B$8+1))&" Comdty" | MF1: ="CL"&MID("FGHJKMNQUVXZ",B$1,1)&B$4&"C "&IF(Settings!$B$4=2,TEXT((B$8+2),"0.00"),(B$8+2))&" Comdty" | MW1: ="CL"&MID("FGHJKMNQUVXZ",B$1,1)&B$4&"P "&IF(Settings!$B$4=2,TEXT((B$8+2),"0.00"),(B$8+2))&" Comdty" | NN1: ="CL"&MID("FGHJKMNQUVXZ",B$1,1)&B$4&"C "&IF(Settings!$B$4=2,TEXT((B$8+3),"0.00"),(B$8+3))&" Comdty" | OE1: ="CL"&MID("FGHJKMNQUVXZ",B$1,1)&B$4&"P "&IF(Settings!$B$4=2,TEXT((B$8+3),"0.00"),(B$8+3))&" Comdty" | OV1: ="CL"&MID("FGHJKMNQUVXZ",B$1,1)&B$4&"C "&IF(Settings!$B$4=2,TEXT((B$8+4),"0.00"),(B$8+4))&" Comdty" | PM1: ="CL"&MID("FGHJKMNQUVXZ",B$1,1)&B$4&"P "&IF(Settings!$B$4=2,TEXT((B$8+4),"0.00"),(B$8+4))&" Comdty" | QD1: ="CL"&MID("FGHJKMNQUVXZ",B$1,1)&B$4&"C "&IF(Settings!$B$4=2,TEXT((B$8+5),"0.00"),(B$8+5))&" Comdty" | QU1: ="CL"&MID("FGHJKMNQUVXZ",B$1,1)&B$4&"P "&IF(Settings!$B$4=2,TEXT((B$8+5),"0.00"),(B$8+5))&" Comdty" | RL1: ="CL"&MID("FGHJKMNQUVXZ",B$1,1)&B$4&"C "&IF(Settings!$B$4=2,TEXT((B$8+6),"0.00"),(B$8+6))&" Comdty" | SC1: ="CL"&MID("FGHJKMNQUVXZ",B$1,1)&B$4&"P "&IF(Settings!$B$4=2,TEXT((B$8+6),"0.00"),(B$8+6))&" Comdty" | ST1: ="CL"&MID("FGHJKMNQUVXZ",B$1,1)&B$4&"C "&IF(Settings!$B$4=2,TEXT((B$8+7),"0.00"),(B$8+7))&" Comdty" | TK1: ="CL"&MID("FGHJKMNQUVXZ",B$1,1)&B$4&"P "&IF(Settings!$B$4=2,TEXT((B$8+7),"0.00"),(B$8+7))&" Comdty" | UB1: ="CL"&MID("FGHJKMNQUVXZ",B$1,1)&B$4&"C "&IF(Settings!$B$4=2,TEXT((B$8+8),"0.00"),(B$8+8))&" Comdty" | US1: ="CL"&MID("FGHJKMNQUVXZ",B$1,1)&B$4&"P "&IF(Settings!$B$4=2,TEXT((B$8+8),"0.00"),(B$8+8))&" Comdty"
A2: Futures last trade | B2: =WORKDAY(DATE(Settings!$B$3,B1-1,25),-3) | D2: call -8 from ATM | U2: put -8 from ATM | AL2: call -7 from ATM | BC2: put -7 from ATM | BT2: call -6 from ATM | CK2: put -6 from ATM | DB2: call -5 from ATM | DS2: put -5 from ATM | EJ2: call -4 from ATM | FA2: put -4 from ATM | FR2: call -3 from ATM | GI2: put -3 from ATM | GZ2: call -2 from ATM | HQ2: put -2 from ATM | IH2: call -1 from ATM | IY2: put -1 from ATM | JP2: call +0 from ATM | KG2: put +0 from ATM | KX2: call +1 from ATM | LO2: put +1 from ATM | MF2: call +2 from ATM | MW2: put +2 from ATM | NN2: call +3 from ATM | OE2: put +3 from ATM | OV2: call +4 from ATM | PM2: put +4 from ATM | QD2: call +5 from ATM | QU2: put +5 from ATM | RL2: call +6 from ATM | SC2: put +6 from ATM | ST2: call +7 from ATM | TK2: put +7 from ATM | UB2: call +8 from ATM | US2: put +8 from ATM
A3: Option expiry (approx) | B3: =WORKDAY(B2,-1) | D3: Date | E3: PX_BID | F3: PX_ASK | G3: PX_MID | H3: PX_LAST | I3: PX_SETTLE | J3: PX_VOLUME | K3: OPEN_INT | L3: IVOL_MID | M3: IVOL_BID | N3: IVOL_ASK | O3: DELTA_MID | P3: GAMMA_MID | Q3: VEGA_MID | R3: THETA_MID | S3: OPT_UNDL_PX | U3: Date | V3: PX_BID | W3: PX_ASK | X3: PX_MID | Y3: PX_LAST | Z3: PX_SETTLE | AA3: PX_VOLUME | AB3: OPEN_INT | AC3: IVOL_MID | AD3: IVOL_BID | AE3: IVOL_ASK | AF3: DELTA_MID | AG3: GAMMA_MID | AH3: VEGA_MID | AI3: THETA_MID | AJ3: OPT_UNDL_PX | AL3: Date | AM3: PX_BID | AN3: PX_ASK | AO3: PX_MID | AP3: PX_LAST | AQ3: PX_SETTLE | AR3: PX_VOLUME | AS3: OPEN_INT | AT3: IVOL_MID | AU3: IVOL_BID | AV3: IVOL_ASK | AW3: DELTA_MID | AX3: GAMMA_MID | AY3: VEGA_MID | AZ3: THETA_MID | BA3: OPT_UNDL_PX | BC3: Date | BD3: PX_BID | BE3: PX_ASK | BF3: PX_MID | BG3: PX_LAST | BH3: PX_SETTLE | BI3: PX_VOLUME | BJ3: OPEN_INT | BK3: IVOL_MID | BL3: IVOL_BID | BM3: IVOL_ASK | BN3: DELTA_MID | BO3: GAMMA_MID | BP3: VEGA_MID | BQ3: THETA_MID | BR3: OPT_UNDL_PX | BT3: Date | BU3: PX_BID | BV3: PX_ASK | BW3: PX_MID | BX3: PX_LAST | BY3: PX_SETTLE | BZ3: PX_VOLUME | CA3: OPEN_INT | CB3: IVOL_MID | CC3: IVOL_BID | CD3: IVOL_ASK | CE3: DELTA_MID | CF3: GAMMA_MID | CG3: VEGA_MID | CH3: THETA_MID | CI3: OPT_UNDL_PX | CK3: Date | CL3: PX_BID | CM3: PX_ASK | CN3: PX_MID | CO3: PX_LAST | CP3: PX_SETTLE | CQ3: PX_VOLUME | CR3: OPEN_INT | CS3: IVOL_MID | CT3: IVOL_BID | CU3: IVOL_ASK | CV3: DELTA_MID | CW3: GAMMA_MID | CX3: VEGA_MID | CY3: THETA_MID | CZ3: OPT_UNDL_PX | DB3: Date | DC3: PX_BID | DD3: PX_ASK | DE3: PX_MID | DF3: PX_LAST | DG3: PX_SETTLE | DH3: PX_VOLUME | DI3: OPEN_INT | DJ3: IVOL_MID | DK3: IVOL_BID | DL3: IVOL_ASK | DM3: DELTA_MID | DN3: GAMMA_MID | DO3: VEGA_MID | DP3: THETA_MID | DQ3: OPT_UNDL_PX | DS3: Date | DT3: PX_BID | DU3: PX_ASK | DV3: PX_MID | DW3: PX_LAST | DX3: PX_SETTLE | DY3: PX_VOLUME | DZ3: OPEN_INT | EA3: IVOL_MID | EB3: IVOL_BID | EC3: IVOL_ASK | ED3: DELTA_MID | EE3: GAMMA_MID | EF3: VEGA_MID | EG3: THETA_MID | EH3: OPT_UNDL_PX | EJ3: Date | EK3: PX_BID | EL3: PX_ASK | EM3: PX_MID | EN3: PX_LAST | EO3: PX_SETTLE | EP3: PX_VOLUME | EQ3: OPEN_INT | ER3: IVOL_MID | ES3: IVOL_BID | ET3: IVOL_ASK | EU3: DELTA_MID | EV3: GAMMA_MID | EW3: VEGA_MID | EX3: THETA_MID | EY3: OPT_UNDL_PX | FA3: Date | FB3: PX_BID | FC3: PX_ASK | FD3: PX_MID | FE3: PX_LAST | FF3: PX_SETTLE | FG3: PX_VOLUME | FH3: OPEN_INT | FI3: IVOL_MID | FJ3: IVOL_BID | FK3: IVOL_ASK | FL3: DELTA_MID | FM3: GAMMA_MID | FN3: VEGA_MID | FO3: THETA_MID | FP3: OPT_UNDL_PX | FR3: Date | FS3: PX_BID | FT3: PX_ASK | FU3: PX_MID | FV3: PX_LAST | FW3: PX_SETTLE | FX3: PX_VOLUME | FY3: OPEN_INT | FZ3: IVOL_MID | GA3: IVOL_BID | GB3: IVOL_ASK | GC3: DELTA_MID | GD3: GAMMA_MID | GE3: VEGA_MID | GF3: THETA_MID | GG3: OPT_UNDL_PX | GI3: Date | GJ3: PX_BID | GK3: PX_ASK | GL3: PX_MID | GM3: PX_LAST | GN3: PX_SETTLE | GO3: PX_VOLUME | GP3: OPEN_INT | GQ3: IVOL_MID | GR3: IVOL_BID | GS3: IVOL_ASK | GT3: DELTA_MID | GU3: GAMMA_MID | GV3: VEGA_MID | GW3: THETA_MID | GX3: OPT_UNDL_PX | GZ3: Date | HA3: PX_BID | HB3: PX_ASK | HC3: PX_MID | HD3: PX_LAST | HE3: PX_SETTLE | HF3: PX_VOLUME | HG3: OPEN_INT | HH3: IVOL_MID | HI3: IVOL_BID | HJ3: IVOL_ASK | HK3: DELTA_MID | HL3: GAMMA_MID | HM3: VEGA_MID | HN3: THETA_MID | HO3: OPT_UNDL_PX | HQ3: Date | HR3: PX_BID | HS3: PX_ASK | HT3: PX_MID | HU3: PX_LAST | HV3: PX_SETTLE | HW3: PX_VOLUME | HX3: OPEN_INT | HY3: IVOL_MID | HZ3: IVOL_BID | IA3: IVOL_ASK | IB3: DELTA_MID | IC3: GAMMA_MID | ID3: VEGA_MID | IE3: THETA_MID | IF3: OPT_UNDL_PX | IH3: Date | II3: PX_BID | IJ3: PX_ASK | IK3: PX_MID | IL3: PX_LAST | IM3: PX_SETTLE | IN3: PX_VOLUME | IO3: OPEN_INT | IP3: IVOL_MID | IQ3: IVOL_BID | IR3: IVOL_ASK | IS3: DELTA_MID | IT3: GAMMA_MID | IU3: VEGA_MID | IV3: THETA_MID | IW3: OPT_UNDL_PX | IY3: Date | IZ3: PX_BID | JA3: PX_ASK | JB3: PX_MID | JC3: PX_LAST | JD3: PX_SETTLE | JE3: PX_VOLUME | JF3: OPEN_INT | JG3: IVOL_MID | JH3: IVOL_BID | JI3: IVOL_ASK | JJ3: DELTA_MID | JK3: GAMMA_MID | JL3: VEGA_MID | JM3: THETA_MID | JN3: OPT_UNDL_PX | JP3: Date | JQ3: PX_BID | JR3: PX_ASK | JS3: PX_MID | JT3: PX_LAST | JU3: PX_SETTLE | JV3: PX_VOLUME | JW3: OPEN_INT | JX3: IVOL_MID | JY3: IVOL_BID | JZ3: IVOL_ASK | KA3: DELTA_MID | KB3: GAMMA_MID | KC3: VEGA_MID | KD3: THETA_MID | KE3: OPT_UNDL_PX | KG3: Date | KH3: PX_BID | KI3: PX_ASK | KJ3: PX_MID | KK3: PX_LAST | KL3: PX_SETTLE | KM3: PX_VOLUME | KN3: OPEN_INT | KO3: IVOL_MID | KP3: IVOL_BID | KQ3: IVOL_ASK | KR3: DELTA_MID | KS3: GAMMA_MID | KT3: VEGA_MID | KU3: THETA_MID | KV3: OPT_UNDL_PX | KX3: Date | KY3: PX_BID | KZ3: PX_ASK | LA3: PX_MID | LB3: PX_LAST | LC3: PX_SETTLE | LD3: PX_VOLUME | LE3: OPEN_INT | LF3: IVOL_MID | LG3: IVOL_BID | LH3: IVOL_ASK | LI3: DELTA_MID | LJ3: GAMMA_MID | LK3: VEGA_MID | LL3: THETA_MID | LM3: OPT_UNDL_PX | LO3: Date | LP3: PX_BID | LQ3: PX_ASK | LR3: PX_MID | LS3: PX_LAST | LT3: PX_SETTLE | LU3: PX_VOLUME | LV3: OPEN_INT | LW3: IVOL_MID | LX3: IVOL_BID | LY3: IVOL_ASK | LZ3: DELTA_MID | MA3: GAMMA_MID | MB3: VEGA_MID | MC3: THETA_MID | MD3: OPT_UNDL_PX | MF3: Date | MG3: PX_BID | MH3: PX_ASK | MI3: PX_MID | MJ3: PX_LAST | MK3: PX_SETTLE | ML3: PX_VOLUME | MM3: OPEN_INT | MN3: IVOL_MID | MO3: IVOL_BID | MP3: IVOL_ASK | MQ3: DELTA_MID | MR3: GAMMA_MID | MS3: VEGA_MID | MT3: THETA_MID | MU3: OPT_UNDL_PX | MW3: Date | MX3: PX_BID | MY3: PX_ASK | MZ3: PX_MID | NA3: PX_LAST | NB3: PX_SETTLE | NC3: PX_VOLUME | ND3: OPEN_INT | NE3: IVOL_MID | NF3: IVOL_BID | NG3: IVOL_ASK | NH3: DELTA_MID | NI3: GAMMA_MID | NJ3: VEGA_MID | NK3: THETA_MID | NL3: OPT_UNDL_PX | NN3: Date | NO3: PX_BID | NP3: PX_ASK | NQ3: PX_MID | NR3: PX_LAST | NS3: PX_SETTLE | NT3: PX_VOLUME | NU3: OPEN_INT | NV3: IVOL_MID | NW3: IVOL_BID | NX3: IVOL_ASK | NY3: DELTA_MID | NZ3: GAMMA_MID | OA3: VEGA_MID | OB3: THETA_MID | OC3: OPT_UNDL_PX | OE3: Date | OF3: PX_BID | OG3: PX_ASK | OH3: PX_MID | OI3: PX_LAST | OJ3: PX_SETTLE | OK3: PX_VOLUME | OL3: OPEN_INT | OM3: IVOL_MID | ON3: IVOL_BID | OO3: IVOL_ASK | OP3: DELTA_MID | OQ3: GAMMA_MID | OR3: VEGA_MID | OS3: THETA_MID | OT3: OPT_UNDL_PX | OV3: Date | OW3: PX_BID | OX3: PX_ASK | OY3: PX_MID | OZ3: PX_LAST | PA3: PX_SETTLE | PB3: PX_VOLUME | PC3: OPEN_INT | PD3: IVOL_MID | PE3: IVOL_BID | PF3: IVOL_ASK | PG3: DELTA_MID | PH3: GAMMA_MID | PI3: VEGA_MID | PJ3: THETA_MID | PK3: OPT_UNDL_PX | PM3: Date | PN3: PX_BID | PO3: PX_ASK | PP3: PX_MID | PQ3: PX_LAST | PR3: PX_SETTLE | PS3: PX_VOLUME | PT3: OPEN_INT | PU3: IVOL_MID | PV3: IVOL_BID | PW3: IVOL_ASK | PX3: DELTA_MID | PY3: GAMMA_MID | PZ3: VEGA_MID | QA3: THETA_MID | QB3: OPT_UNDL_PX | QD3: Date | QE3: PX_BID | QF3: PX_ASK | QG3: PX_MID | QH3: PX_LAST | QI3: PX_SETTLE | QJ3: PX_VOLUME | QK3: OPEN_INT | QL3: IVOL_MID | QM3: IVOL_BID | QN3: IVOL_ASK | QO3: DELTA_MID | QP3: GAMMA_MID | QQ3: VEGA_MID | QR3: THETA_MID | QS3: OPT_UNDL_PX | QU3: Date | QV3: PX_BID | QW3: PX_ASK | QX3: PX_MID | QY3: PX_LAST | QZ3: PX_SETTLE | RA3: PX_VOLUME | RB3: OPEN_INT | RC3: IVOL_MID | RD3: IVOL_BID | RE3: IVOL_ASK | RF3: DELTA_MID | RG3: GAMMA_MID | RH3: VEGA_MID | RI3: THETA_MID | RJ3: OPT_UNDL_PX | RL3: Date | RM3: PX_BID | RN3: PX_ASK | RO3: PX_MID | RP3: PX_LAST | RQ3: PX_SETTLE | RR3: PX_VOLUME | RS3: OPEN_INT | RT3: IVOL_MID | RU3: IVOL_BID | RV3: IVOL_ASK | RW3: DELTA_MID | RX3: GAMMA_MID | RY3: VEGA_MID | RZ3: THETA_MID | SA3: OPT_UNDL_PX | SC3: Date | SD3: PX_BID | SE3: PX_ASK | SF3: PX_MID | SG3: PX_LAST | SH3: PX_SETTLE | SI3: PX_VOLUME | SJ3: OPEN_INT | SK3: IVOL_MID | SL3: IVOL_BID | SM3: IVOL_ASK | SN3: DELTA_MID | SO3: GAMMA_MID | SP3: VEGA_MID | SQ3: THETA_MID | SR3: OPT_UNDL_PX | ST3: Date | SU3: PX_BID | SV3: PX_ASK | SW3: PX_MID | SX3: PX_LAST | SY3: PX_SETTLE | SZ3: PX_VOLUME | TA3: OPEN_INT | TB3: IVOL_MID | TC3: IVOL_BID | TD3: IVOL_ASK | TE3: DELTA_MID | TF3: GAMMA_MID | TG3: VEGA_MID | TH3: THETA_MID | TI3: OPT_UNDL_PX | TK3: Date | TL3: PX_BID | TM3: PX_ASK | TN3: PX_MID | TO3: PX_LAST | TP3: PX_SETTLE | TQ3: PX_VOLUME | TR3: OPEN_INT | TS3: IVOL_MID | TT3: IVOL_BID | TU3: IVOL_ASK | TV3: DELTA_MID | TW3: GAMMA_MID | TX3: VEGA_MID | TY3: THETA_MID | TZ3: OPT_UNDL_PX | UB3: Date | UC3: PX_BID | UD3: PX_ASK | UE3: PX_MID | UF3: PX_LAST | UG3: PX_SETTLE | UH3: PX_VOLUME | UI3: OPEN_INT | UJ3: IVOL_MID | UK3: IVOL_BID | UL3: IVOL_ASK | UM3: DELTA_MID | UN3: GAMMA_MID | UO3: VEGA_MID | UP3: THETA_MID | UQ3: OPT_UNDL_PX | US3: Date | UT3: PX_BID | UU3: PX_ASK | UV3: PX_MID | UW3: PX_LAST | UX3: PX_SETTLE | UY3: PX_VOLUME | UZ3: OPEN_INT | VA3: IVOL_MID | VB3: IVOL_BID | VC3: IVOL_ASK | VD3: DELTA_MID | VE3: GAMMA_MID | VF3: VEGA_MID | VG3: THETA_MID | VH3: OPT_UNDL_PX
A4: Year in ticker | B4: =IF(B2<Settings!$B$5,TEXT(MOD(Settings!$B$3,100),"00"),TEXT(MOD(Settings!$B$3,10),"0")) | D4: =BDH(D$1,E$3:S$3,$B$9,$B$10,"Dir=V","Dts=S","Sort=A","Days=T","Fill=B") | U4: =BDH(U$1,V$3:AJ$3,$B$9,$B$10,"Dir=V","Dts=S","Sort=A","Days=T","Fill=B") | AL4: =BDH(AL$1,AM$3:BA$3,$B$9,$B$10,"Dir=V","Dts=S","Sort=A","Days=T","Fill=B") | BC4: =BDH(BC$1,BD$3:BR$3,$B$9,$B$10,"Dir=V","Dts=S","Sort=A","Days=T","Fill=B") | BT4: =BDH(BT$1,BU$3:CI$3,$B$9,$B$10,"Dir=V","Dts=S","Sort=A","Days=T","Fill=B") | CK4: =BDH(CK$1,CL$3:CZ$3,$B$9,$B$10,"Dir=V","Dts=S","Sort=A","Days=T","Fill=B") | DB4: =BDH(DB$1,DC$3:DQ$3,$B$9,$B$10,"Dir=V","Dts=S","Sort=A","Days=T","Fill=B") | DS4: =BDH(DS$1,DT$3:EH$3,$B$9,$B$10,"Dir=V","Dts=S","Sort=A","Days=T","Fill=B") | EJ4: =BDH(EJ$1,EK$3:EY$3,$B$9,$B$10,"Dir=V","Dts=S","Sort=A","Days=T","Fill=B") | FA4: =BDH(FA$1,FB$3:FP$3,$B$9,$B$10,"Dir=V","Dts=S","Sort=A","Days=T","Fill=B") | FR4: =BDH(FR$1,FS$3:GG$3,$B$9,$B$10,"Dir=V","Dts=S","Sort=A","Days=T","Fill=B") | GI4: =BDH(GI$1,GJ$3:GX$3,$B$9,$B$10,"Dir=V","Dts=S","Sort=A","Days=T","Fill=B") | GZ4: =BDH(GZ$1,HA$3:HO$3,$B$9,$B$10,"Dir=V","Dts=S","Sort=A","Days=T","Fill=B") | HQ4: =BDH(HQ$1,HR$3:IF$3,$B$9,$B$10,"Dir=V","Dts=S","Sort=A","Days=T","Fill=B") | IH4: =BDH(IH$1,II$3:IW$3,$B$9,$B$10,"Dir=V","Dts=S","Sort=A","Days=T","Fill=B") | IY4: =BDH(IY$1,IZ$3:JN$3,$B$9,$B$10,"Dir=V","Dts=S","Sort=A","Days=T","Fill=B") | JP4: =BDH(JP$1,JQ$3:KE$3,$B$9,$B$10,"Dir=V","Dts=S","Sort=A","Days=T","Fill=B") | KG4: =BDH(KG$1,KH$3:KV$3,$B$9,$B$10,"Dir=V","Dts=S","Sort=A","Days=T","Fill=B") | KX4: =BDH(KX$1,KY$3:LM$3,$B$9,$B$10,"Dir=V","Dts=S","Sort=A","Days=T","Fill=B") | LO4: =BDH(LO$1,LP$3:MD$3,$B$9,$B$10,"Dir=V","Dts=S","Sort=A","Days=T","Fill=B") | MF4: =BDH(MF$1,MG$3:MU$3,$B$9,$B$10,"Dir=V","Dts=S","Sort=A","Days=T","Fill=B") | MW4: =BDH(MW$1,MX$3:NL$3,$B$9,$B$10,"Dir=V","Dts=S","Sort=A","Days=T","Fill=B") | NN4: =BDH(NN$1,NO$3:OC$3,$B$9,$B$10,"Dir=V","Dts=S","Sort=A","Days=T","Fill=B") | OE4: =BDH(OE$1,OF$3:OT$3,$B$9,$B$10,"Dir=V","Dts=S","Sort=A","Days=T","Fill=B") | OV4: =BDH(OV$1,OW$3:PK$3,$B$9,$B$10,"Dir=V","Dts=S","Sort=A","Days=T","Fill=B") | PM4: =BDH(PM$1,PN$3:QB$3,$B$9,$B$10,"Dir=V","Dts=S","Sort=A","Days=T","Fill=B") | QD4: =BDH(QD$1,QE$3:QS$3,$B$9,$B$10,"Dir=V","Dts=S","Sort=A","Days=T","Fill=B") | QU4: =BDH(QU$1,QV$3:RJ$3,$B$9,$B$10,"Dir=V","Dts=S","Sort=A","Days=T","Fill=B") | RL4: =BDH(RL$1,RM$3:SA$3,$B$9,$B$10,"Dir=V","Dts=S","Sort=A","Days=T","Fill=B") | SC4: =BDH(SC$1,SD$3:SR$3,$B$9,$B$10,"Dir=V","Dts=S","Sort=A","Days=T","Fill=B") | ST4: =BDH(ST$1,SU$3:TI$3,$B$9,$B$10,"Dir=V","Dts=S","Sort=A","Days=T","Fill=B") | TK4: =BDH(TK$1,TL$3:TZ$3,$B$9,$B$10,"Dir=V","Dts=S","Sort=A","Days=T","Fill=B") | UB4: =BDH(UB$1,UC$3:UQ$3,$B$9,$B$10,"Dir=V","Dts=S","Sort=A","Days=T","Fill=B") | US4: =BDH(US$1,UT$3:VH$3,$B$9,$B$10,"Dir=V","Dts=S","Sort=A","Days=T","Fill=B")
A5: Futures ticker | B5: ="CL"&MID("FGHJKMNQUVXZ",B1,1)&B4&" Comdty"
A6: Strike reference date | B6: =B3-45
A7: Futures price on that date | B7: =BDH(B5,"PX_LAST",B6,B6,"Days=A","Fill=P","Dts=H")
A8: ATM strike | B8: =ROUND(B7,0)
A9: History start | B9: =B3-100
A10: History end | B10: =B3

Sheet Mar
A1: Contract month | B1: 3 | D1: ="CL"&MID("FGHJKMNQUVXZ",B$1,1)&B$4&"C "&IF(Settings!$B$4=2,TEXT((B$8-8),"0.00"),(B$8-8))&" Comdty" | U1: ="CL"&MID("FGHJKMNQUVXZ",B$1,1)&B$4&"P "&IF(Settings!$B$4=2,TEXT((B$8-8),"0.00"),(B$8-8))&" Comdty" | AL1: ="CL"&MID("FGHJKMNQUVXZ",B$1,1)&B$4&"C "&IF(Settings!$B$4=2,TEXT((B$8-7),"0.00"),(B$8-7))&" Comdty" | BC1: ="CL"&MID("FGHJKMNQUVXZ",B$1,1)&B$4&"P "&IF(Settings!$B$4=2,TEXT((B$8-7),"0.00"),(B$8-7))&" Comdty" | BT1: ="CL"&MID("FGHJKMNQUVXZ",B$1,1)&B$4&"C "&IF(Settings!$B$4=2,TEXT((B$8-6),"0.00"),(B$8-6))&" Comdty" | CK1: ="CL"&MID("FGHJKMNQUVXZ",B$1,1)&B$4&"P "&IF(Settings!$B$4=2,TEXT((B$8-6),"0.00"),(B$8-6))&" Comdty" | DB1: ="CL"&MID("FGHJKMNQUVXZ",B$1,1)&B$4&"C "&IF(Settings!$B$4=2,TEXT((B$8-5),"0.00"),(B$8-5))&" Comdty" | DS1: ="CL"&MID("FGHJKMNQUVXZ",B$1,1)&B$4&"P "&IF(Settings!$B$4=2,TEXT((B$8-5),"0.00"),(B$8-5))&" Comdty" | EJ1: ="CL"&MID("FGHJKMNQUVXZ",B$1,1)&B$4&"C "&IF(Settings!$B$4=2,TEXT((B$8-4),"0.00"),(B$8-4))&" Comdty" | FA1: ="CL"&MID("FGHJKMNQUVXZ",B$1,1)&B$4&"P "&IF(Settings!$B$4=2,TEXT((B$8-4),"0.00"),(B$8-4))&" Comdty" | FR1: ="CL"&MID("FGHJKMNQUVXZ",B$1,1)&B$4&"C "&IF(Settings!$B$4=2,TEXT((B$8-3),"0.00"),(B$8-3))&" Comdty" | GI1: ="CL"&MID("FGHJKMNQUVXZ",B$1,1)&B$4&"P "&IF(Settings!$B$4=2,TEXT((B$8-3),"0.00"),(B$8-3))&" Comdty" | GZ1: ="CL"&MID("FGHJKMNQUVXZ",B$1,1)&B$4&"C "&IF(Settings!$B$4=2,TEXT((B$8-2),"0.00"),(B$8-2))&" Comdty" | HQ1: ="CL"&MID("FGHJKMNQUVXZ",B$1,1)&B$4&"P "&IF(Settings!$B$4=2,TEXT((B$8-2),"0.00"),(B$8-2))&" Comdty" | IH1: ="CL"&MID("FGHJKMNQUVXZ",B$1,1)&B$4&"C "&IF(Settings!$B$4=2,TEXT((B$8-1),"0.00"),(B$8-1))&" Comdty" | IY1: ="CL"&MID("FGHJKMNQUVXZ",B$1,1)&B$4&"P "&IF(Settings!$B$4=2,TEXT((B$8-1),"0.00"),(B$8-1))&" Comdty" | JP1: ="CL"&MID("FGHJKMNQUVXZ",B$1,1)&B$4&"C "&IF(Settings!$B$4=2,TEXT(B$8,"0.00"),B$8)&" Comdty" | KG1: ="CL"&MID("FGHJKMNQUVXZ",B$1,1)&B$4&"P "&IF(Settings!$B$4=2,TEXT(B$8,"0.00"),B$8)&" Comdty" | KX1: ="CL"&MID("FGHJKMNQUVXZ",B$1,1)&B$4&"C "&IF(Settings!$B$4=2,TEXT((B$8+1),"0.00"),(B$8+1))&" Comdty" | LO1: ="CL"&MID("FGHJKMNQUVXZ",B$1,1)&B$4&"P "&IF(Settings!$B$4=2,TEXT((B$8+1),"0.00"),(B$8+1))&" Comdty" | MF1: ="CL"&MID("FGHJKMNQUVXZ",B$1,1)&B$4&"C "&IF(Settings!$B$4=2,TEXT((B$8+2),"0.00"),(B$8+2))&" Comdty" | MW1: ="CL"&MID("FGHJKMNQUVXZ",B$1,1)&B$4&"P "&IF(Settings!$B$4=2,TEXT((B$8+2),"0.00"),(B$8+2))&" Comdty" | NN1: ="CL"&MID("FGHJKMNQUVXZ",B$1,1)&B$4&"C "&IF(Settings!$B$4=2,TEXT((B$8+3),"0.00"),(B$8+3))&" Comdty" | OE1: ="CL"&MID("FGHJKMNQUVXZ",B$1,1)&B$4&"P "&IF(Settings!$B$4=2,TEXT((B$8+3),"0.00"),(B$8+3))&" Comdty" | OV1: ="CL"&MID("FGHJKMNQUVXZ",B$1,1)&B$4&"C "&IF(Settings!$B$4=2,TEXT((B$8+4),"0.00"),(B$8+4))&" Comdty" | PM1: ="CL"&MID("FGHJKMNQUVXZ",B$1,1)&B$4&"P "&IF(Settings!$B$4=2,TEXT((B$8+4),"0.00"),(B$8+4))&" Comdty" | QD1: ="CL"&MID("FGHJKMNQUVXZ",B$1,1)&B$4&"C "&IF(Settings!$B$4=2,TEXT((B$8+5),"0.00"),(B$8+5))&" Comdty" | QU1: ="CL"&MID("FGHJKMNQUVXZ",B$1,1)&B$4&"P "&IF(Settings!$B$4=2,TEXT((B$8+5),"0.00"),(B$8+5))&" Comdty" | RL1: ="CL"&MID("FGHJKMNQUVXZ",B$1,1)&B$4&"C "&IF(Settings!$B$4=2,TEXT((B$8+6),"0.00"),(B$8+6))&" Comdty" | SC1: ="CL"&MID("FGHJKMNQUVXZ",B$1,1)&B$4&"P "&IF(Settings!$B$4=2,TEXT((B$8+6),"0.00"),(B$8+6))&" Comdty" | ST1: ="CL"&MID("FGHJKMNQUVXZ",B$1,1)&B$4&"C "&IF(Settings!$B$4=2,TEXT((B$8+7),"0.00"),(B$8+7))&" Comdty" | TK1: ="CL"&MID("FGHJKMNQUVXZ",B$1,1)&B$4&"P "&IF(Settings!$B$4=2,TEXT((B$8+7),"0.00"),(B$8+7))&" Comdty" | UB1: ="CL"&MID("FGHJKMNQUVXZ",B$1,1)&B$4&"C "&IF(Settings!$B$4=2,TEXT((B$8+8),"0.00"),(B$8+8))&" Comdty" | US1: ="CL"&MID("FGHJKMNQUVXZ",B$1,1)&B$4&"P "&IF(Settings!$B$4=2,TEXT((B$8+8),"0.00"),(B$8+8))&" Comdty"
A2: Futures last trade | B2: =WORKDAY(DATE(Settings!$B$3,B1-1,25),-3) | D2: call -8 from ATM | U2: put -8 from ATM | AL2: call -7 from ATM | BC2: put -7 from ATM | BT2: call -6 from ATM | CK2: put -6 from ATM | DB2: call -5 from ATM | DS2: put -5 from ATM | EJ2: call -4 from ATM | FA2: put -4 from ATM | FR2: call -3 from ATM | GI2: put -3 from ATM | GZ2: call -2 from ATM | HQ2: put -2 from ATM | IH2: call -1 from ATM | IY2: put -1 from ATM | JP2: call +0 from ATM | KG2: put +0 from ATM | KX2: call +1 from ATM | LO2: put +1 from ATM | MF2: call +2 from ATM | MW2: put +2 from ATM | NN2: call +3 from ATM | OE2: put +3 from ATM | OV2: call +4 from ATM | PM2: put +4 from ATM | QD2: call +5 from ATM | QU2: put +5 from ATM | RL2: call +6 from ATM | SC2: put +6 from ATM | ST2: call +7 from ATM | TK2: put +7 from ATM | UB2: call +8 from ATM | US2: put +8 from ATM
A3: Option expiry (approx) | B3: =WORKDAY(B2,-1) | D3: Date | E3: PX_BID | F3: PX_ASK | G3: PX_MID | H3: PX_LAST | I3: PX_SETTLE | J3: PX_VOLUME | K3: OPEN_INT | L3: IVOL_MID | M3: IVOL_BID | N3: IVOL_ASK | O3: DELTA_MID | P3: GAMMA_MID | Q3: VEGA_MID | R3: THETA_MID | S3: OPT_UNDL_PX | U3: Date | V3: PX_BID | W3: PX_ASK | X3: PX_MID | Y3: PX_LAST | Z3: PX_SETTLE | AA3: PX_VOLUME | AB3: OPEN_INT | AC3: IVOL_MID | AD3: IVOL_BID | AE3: IVOL_ASK | AF3: DELTA_MID | AG3: GAMMA_MID | AH3: VEGA_MID | AI3: THETA_MID | AJ3: OPT_UNDL_PX | AL3: Date | AM3: PX_BID | AN3: PX_ASK | AO3: PX_MID | AP3: PX_LAST | AQ3: PX_SETTLE | AR3: PX_VOLUME | AS3: OPEN_INT | AT3: IVOL_MID | AU3: IVOL_BID | AV3: IVOL_ASK | AW3: DELTA_MID | AX3: GAMMA_MID | AY3: VEGA_MID | AZ3: THETA_MID | BA3: OPT_UNDL_PX | BC3: Date | BD3: PX_BID | BE3: PX_ASK | BF3: PX_MID | BG3: PX_LAST | BH3: PX_SETTLE | BI3: PX_VOLUME | BJ3: OPEN_INT | BK3: IVOL_MID | BL3: IVOL_BID | BM3: IVOL_ASK | BN3: DELTA_MID | BO3: GAMMA_MID | BP3: VEGA_MID | BQ3: THETA_MID | BR3: OPT_UNDL_PX | BT3: Date | BU3: PX_BID | BV3: PX_ASK | BW3: PX_MID | BX3: PX_LAST | BY3: PX_SETTLE | BZ3: PX_VOLUME | CA3: OPEN_INT | CB3: IVOL_MID | CC3: IVOL_BID | CD3: IVOL_ASK | CE3: DELTA_MID | CF3: GAMMA_MID | CG3: VEGA_MID | CH3: THETA_MID | CI3: OPT_UNDL_PX | CK3: Date | CL3: PX_BID | CM3: PX_ASK | CN3: PX_MID | CO3: PX_LAST | CP3: PX_SETTLE | CQ3: PX_VOLUME | CR3: OPEN_INT | CS3: IVOL_MID | CT3: IVOL_BID | CU3: IVOL_ASK | CV3: DELTA_MID | CW3: GAMMA_MID | CX3: VEGA_MID | CY3: THETA_MID | CZ3: OPT_UNDL_PX | DB3: Date | DC3: PX_BID | DD3: PX_ASK | DE3: PX_MID | DF3: PX_LAST | DG3: PX_SETTLE | DH3: PX_VOLUME | DI3: OPEN_INT | DJ3: IVOL_MID | DK3: IVOL_BID | DL3: IVOL_ASK | DM3: DELTA_MID | DN3: GAMMA_MID | DO3: VEGA_MID | DP3: THETA_MID | DQ3: OPT_UNDL_PX | DS3: Date | DT3: PX_BID | DU3: PX_ASK | DV3: PX_MID | DW3: PX_LAST | DX3: PX_SETTLE | DY3: PX_VOLUME | DZ3: OPEN_INT | EA3: IVOL_MID | EB3: IVOL_BID | EC3: IVOL_ASK | ED3: DELTA_MID | EE3: GAMMA_MID | EF3: VEGA_MID | EG3: THETA_MID | EH3: OPT_UNDL_PX | EJ3: Date | EK3: PX_BID | EL3: PX_ASK | EM3: PX_MID | EN3: PX_LAST | EO3: PX_SETTLE | EP3: PX_VOLUME | EQ3: OPEN_INT | ER3: IVOL_MID | ES3: IVOL_BID | ET3: IVOL_ASK | EU3: DELTA_MID | EV3: GAMMA_MID | EW3: VEGA_MID | EX3: THETA_MID | EY3: OPT_UNDL_PX | FA3: Date | FB3: PX_BID | FC3: PX_ASK | FD3: PX_MID | FE3: PX_LAST | FF3: PX_SETTLE | FG3: PX_VOLUME | FH3: OPEN_INT | FI3: IVOL_MID | FJ3: IVOL_BID | FK3: IVOL_ASK | FL3: DELTA_MID | FM3: GAMMA_MID | FN3: VEGA_MID | FO3: THETA_MID | FP3: OPT_UNDL_PX | FR3: Date | FS3: PX_BID | FT3: PX_ASK | FU3: PX_MID | FV3: PX_LAST | FW3: PX_SETTLE | FX3: PX_VOLUME | FY3: OPEN_INT | FZ3: IVOL_MID | GA3: IVOL_BID | GB3: IVOL_ASK | GC3: DELTA_MID | GD3: GAMMA_MID | GE3: VEGA_MID | GF3: THETA_MID | GG3: OPT_UNDL_PX | GI3: Date | GJ3: PX_BID | GK3: PX_ASK | GL3: PX_MID | GM3: PX_LAST | GN3: PX_SETTLE | GO3: PX_VOLUME | GP3: OPEN_INT | GQ3: IVOL_MID | GR3: IVOL_BID | GS3: IVOL_ASK | GT3: DELTA_MID | GU3: GAMMA_MID | GV3: VEGA_MID | GW3: THETA_MID | GX3: OPT_UNDL_PX | GZ3: Date | HA3: PX_BID | HB3: PX_ASK | HC3: PX_MID | HD3: PX_LAST | HE3: PX_SETTLE | HF3: PX_VOLUME | HG3: OPEN_INT | HH3: IVOL_MID | HI3: IVOL_BID | HJ3: IVOL_ASK | HK3: DELTA_MID | HL3: GAMMA_MID | HM3: VEGA_MID | HN3: THETA_MID | HO3: OPT_UNDL_PX | HQ3: Date | HR3: PX_BID | HS3: PX_ASK | HT3: PX_MID | HU3: PX_LAST | HV3: PX_SETTLE | HW3: PX_VOLUME | HX3: OPEN_INT | HY3: IVOL_MID | HZ3: IVOL_BID | IA3: IVOL_ASK | IB3: DELTA_MID | IC3: GAMMA_MID | ID3: VEGA_MID | IE3: THETA_MID | IF3: OPT_UNDL_PX | IH3: Date | II3: PX_BID | IJ3: PX_ASK | IK3: PX_MID | IL3: PX_LAST | IM3: PX_SETTLE | IN3: PX_VOLUME | IO3: OPEN_INT | IP3: IVOL_MID | IQ3: IVOL_BID | IR3: IVOL_ASK | IS3: DELTA_MID | IT3: GAMMA_MID | IU3: VEGA_MID | IV3: THETA_MID | IW3: OPT_UNDL_PX | IY3: Date | IZ3: PX_BID | JA3: PX_ASK | JB3: PX_MID | JC3: PX_LAST | JD3: PX_SETTLE | JE3: PX_VOLUME | JF3: OPEN_INT | JG3: IVOL_MID | JH3: IVOL_BID | JI3: IVOL_ASK | JJ3: DELTA_MID | JK3: GAMMA_MID | JL3: VEGA_MID | JM3: THETA_MID | JN3: OPT_UNDL_PX | JP3: Date | JQ3: PX_BID | JR3: PX_ASK | JS3: PX_MID | JT3: PX_LAST | JU3: PX_SETTLE | JV3: PX_VOLUME | JW3: OPEN_INT | JX3: IVOL_MID | JY3: IVOL_BID | JZ3: IVOL_ASK | KA3: DELTA_MID | KB3: GAMMA_MID | KC3: VEGA_MID | KD3: THETA_MID | KE3: OPT_UNDL_PX | KG3: Date | KH3: PX_BID | KI3: PX_ASK | KJ3: PX_MID | KK3: PX_LAST | KL3: PX_SETTLE | KM3: PX_VOLUME | KN3: OPEN_INT | KO3: IVOL_MID | KP3: IVOL_BID | KQ3: IVOL_ASK | KR3: DELTA_MID | KS3: GAMMA_MID | KT3: VEGA_MID | KU3: THETA_MID | KV3: OPT_UNDL_PX | KX3: Date | KY3: PX_BID | KZ3: PX_ASK | LA3: PX_MID | LB3: PX_LAST | LC3: PX_SETTLE | LD3: PX_VOLUME | LE3: OPEN_INT | LF3: IVOL_MID | LG3: IVOL_BID | LH3: IVOL_ASK | LI3: DELTA_MID | LJ3: GAMMA_MID | LK3: VEGA_MID | LL3: THETA_MID | LM3: OPT_UNDL_PX | LO3: Date | LP3: PX_BID | LQ3: PX_ASK | LR3: PX_MID | LS3: PX_LAST | LT3: PX_SETTLE | LU3: PX_VOLUME | LV3: OPEN_INT | LW3: IVOL_MID | LX3: IVOL_BID | LY3: IVOL_ASK | LZ3: DELTA_MID | MA3: GAMMA_MID | MB3: VEGA_MID | MC3: THETA_MID | MD3: OPT_UNDL_PX | MF3: Date | MG3: PX_BID | MH3: PX_ASK | MI3: PX_MID | MJ3: PX_LAST | MK3: PX_SETTLE | ML3: PX_VOLUME | MM3: OPEN_INT | MN3: IVOL_MID | MO3: IVOL_BID | MP3: IVOL_ASK | MQ3: DELTA_MID | MR3: GAMMA_MID | MS3: VEGA_MID | MT3: THETA_MID | MU3: OPT_UNDL_PX | MW3: Date | MX3: PX_BID | MY3: PX_ASK | MZ3: PX_MID | NA3: PX_LAST | NB3: PX_SETTLE | NC3: PX_VOLUME | ND3: OPEN_INT | NE3: IVOL_MID | NF3: IVOL_BID | NG3: IVOL_ASK | NH3: DELTA_MID | NI3: GAMMA_MID | NJ3: VEGA_MID | NK3: THETA_MID | NL3: OPT_UNDL_PX | NN3: Date | NO3: PX_BID | NP3: PX_ASK | NQ3: PX_MID | NR3: PX_LAST | NS3: PX_SETTLE | NT3: PX_VOLUME | NU3: OPEN_INT | NV3: IVOL_MID | NW3: IVOL_BID | NX3: IVOL_ASK | NY3: DELTA_MID | NZ3: GAMMA_MID | OA3: VEGA_MID | OB3: THETA_MID | OC3: OPT_UNDL_PX | OE3: Date | OF3: PX_BID | OG3: PX_ASK | OH3: PX_MID | OI3: PX_LAST | OJ3: PX_SETTLE | OK3: PX_VOLUME | OL3: OPEN_INT | OM3: IVOL_MID | ON3: IVOL_BID | OO3: IVOL_ASK | OP3: DELTA_MID | OQ3: GAMMA_MID | OR3: VEGA_MID | OS3: THETA_MID | OT3: OPT_UNDL_PX | OV3: Date | OW3: PX_BID | OX3: PX_ASK | OY3: PX_MID | OZ3: PX_LAST | PA3: PX_SETTLE | PB3: PX_VOLUME | PC3: OPEN_INT | PD3: IVOL_MID | PE3: IVOL_BID | PF3: IVOL_ASK | PG3: DELTA_MID | PH3: GAMMA_MID | PI3: VEGA_MID | PJ3: THETA_MID | PK3: OPT_UNDL_PX | PM3: Date | PN3: PX_BID | PO3: PX_ASK | PP3: PX_MID | PQ3: PX_LAST | PR3: PX_SETTLE | PS3: PX_VOLUME | PT3: OPEN_INT | PU3: IVOL_MID | PV3: IVOL_BID | PW3: IVOL_ASK | PX3: DELTA_MID | PY3: GAMMA_MID | PZ3: VEGA_MID | QA3: THETA_MID | QB3: OPT_UNDL_PX | QD3: Date | QE3: PX_BID | QF3: PX_ASK | QG3: PX_MID | QH3: PX_LAST | QI3: PX_SETTLE | QJ3: PX_VOLUME | QK3: OPEN_INT | QL3: IVOL_MID | QM3: IVOL_BID | QN3: IVOL_ASK | QO3: DELTA_MID | QP3: GAMMA_MID | QQ3: VEGA_MID | QR3: THETA_MID | QS3: OPT_UNDL_PX | QU3: Date | QV3: PX_BID | QW3: PX_ASK | QX3: PX_MID | QY3: PX_LAST | QZ3: PX_SETTLE | RA3: PX_VOLUME | RB3: OPEN_INT | RC3: IVOL_MID | RD3: IVOL_BID | RE3: IVOL_ASK | RF3: DELTA_MID | RG3: GAMMA_MID | RH3: VEGA_MID | RI3: THETA_MID | RJ3: OPT_UNDL_PX | RL3: Date | RM3: PX_BID | RN3: PX_ASK | RO3: PX_MID | RP3: PX_LAST | RQ3: PX_SETTLE | RR3: PX_VOLUME | RS3: OPEN_INT | RT3: IVOL_MID | RU3: IVOL_BID | RV3: IVOL_ASK | RW3: DELTA_MID | RX3: GAMMA_MID | RY3: VEGA_MID | RZ3: THETA_MID | SA3: OPT_UNDL_PX | SC3: Date | SD3: PX_BID | SE3: PX_ASK | SF3: PX_MID | SG3: PX_LAST | SH3: PX_SETTLE | SI3: PX_VOLUME | SJ3: OPEN_INT | SK3: IVOL_MID | SL3: IVOL_BID | SM3: IVOL_ASK | SN3: DELTA_MID | SO3: GAMMA_MID | SP3: VEGA_MID | SQ3: THETA_MID | SR3: OPT_UNDL_PX | ST3: Date | SU3: PX_BID | SV3: PX_ASK | SW3: PX_MID | SX3: PX_LAST | SY3: PX_SETTLE | SZ3: PX_VOLUME | TA3: OPEN_INT | TB3: IVOL_MID | TC3: IVOL_BID | TD3: IVOL_ASK | TE3: DELTA_MID | TF3: GAMMA_MID | TG3: VEGA_MID | TH3: THETA_MID | TI3: OPT_UNDL_PX | TK3: Date | TL3: PX_BID | TM3: PX_ASK | TN3: PX_MID | TO3: PX_LAST | TP3: PX_SETTLE | TQ3: PX_VOLUME | TR3: OPEN_INT | TS3: IVOL_MID | TT3: IVOL_BID | TU3: IVOL_ASK | TV3: DELTA_MID | TW3: GAMMA_MID | TX3: VEGA_MID | TY3: THETA_MID | TZ3: OPT_UNDL_PX | UB3: Date | UC3: PX_BID | UD3: PX_ASK | UE3: PX_MID | UF3: PX_LAST | UG3: PX_SETTLE | UH3: PX_VOLUME | UI3: OPEN_INT | UJ3: IVOL_MID | UK3: IVOL_BID | UL3: IVOL_ASK | UM3: DELTA_MID | UN3: GAMMA_MID | UO3: VEGA_MID | UP3: THETA_MID | UQ3: OPT_UNDL_PX | US3: Date | UT3: PX_BID | UU3: PX_ASK | UV3: PX_MID | UW3: PX_LAST | UX3: PX_SETTLE | UY3: PX_VOLUME | UZ3: OPEN_INT | VA3: IVOL_MID | VB3: IVOL_BID | VC3: IVOL_ASK | VD3: DELTA_MID | VE3: GAMMA_MID | VF3: VEGA_MID | VG3: THETA_MID | VH3: OPT_UNDL_PX
A4: Year in ticker | B4: =IF(B2<Settings!$B$5,TEXT(MOD(Settings!$B$3,100),"00"),TEXT(MOD(Settings!$B$3,10),"0")) | D4: =BDH(D$1,E$3:S$3,$B$9,$B$10,"Dir=V","Dts=S","Sort=A","Days=T","Fill=B") | U4: =BDH(U$1,V$3:AJ$3,$B$9,$B$10,"Dir=V","Dts=S","Sort=A","Days=T","Fill=B") | AL4: =BDH(AL$1,AM$3:BA$3,$B$9,$B$10,"Dir=V","Dts=S","Sort=A","Days=T","Fill=B") | BC4: =BDH(BC$1,BD$3:BR$3,$B$9,$B$10,"Dir=V","Dts=S","Sort=A","Days=T","Fill=B") | BT4: =BDH(BT$1,BU$3:CI$3,$B$9,$B$10,"Dir=V","Dts=S","Sort=A","Days=T","Fill=B") | CK4: =BDH(CK$1,CL$3:CZ$3,$B$9,$B$10,"Dir=V","Dts=S","Sort=A","Days=T","Fill=B") | DB4: =BDH(DB$1,DC$3:DQ$3,$B$9,$B$10,"Dir=V","Dts=S","Sort=A","Days=T","Fill=B") | DS4: =BDH(DS$1,DT$3:EH$3,$B$9,$B$10,"Dir=V","Dts=S","Sort=A","Days=T","Fill=B") | EJ4: =BDH(EJ$1,EK$3:EY$3,$B$9,$B$10,"Dir=V","Dts=S","Sort=A","Days=T","Fill=B") | FA4: =BDH(FA$1,FB$3:FP$3,$B$9,$B$10,"Dir=V","Dts=S","Sort=A","Days=T","Fill=B") | FR4: =BDH(FR$1,FS$3:GG$3,$B$9,$B$10,"Dir=V","Dts=S","Sort=A","Days=T","Fill=B") | GI4: =BDH(GI$1,GJ$3:GX$3,$B$9,$B$10,"Dir=V","Dts=S","Sort=A","Days=T","Fill=B") | GZ4: =BDH(GZ$1,HA$3:HO$3,$B$9,$B$10,"Dir=V","Dts=S","Sort=A","Days=T","Fill=B") | HQ4: =BDH(HQ$1,HR$3:IF$3,$B$9,$B$10,"Dir=V","Dts=S","Sort=A","Days=T","Fill=B") | IH4: =BDH(IH$1,II$3:IW$3,$B$9,$B$10,"Dir=V","Dts=S","Sort=A","Days=T","Fill=B") | IY4: =BDH(IY$1,IZ$3:JN$3,$B$9,$B$10,"Dir=V","Dts=S","Sort=A","Days=T","Fill=B") | JP4: =BDH(JP$1,JQ$3:KE$3,$B$9,$B$10,"Dir=V","Dts=S","Sort=A","Days=T","Fill=B") | KG4: =BDH(KG$1,KH$3:KV$3,$B$9,$B$10,"Dir=V","Dts=S","Sort=A","Days=T","Fill=B") | KX4: =BDH(KX$1,KY$3:LM$3,$B$9,$B$10,"Dir=V","Dts=S","Sort=A","Days=T","Fill=B") | LO4: =BDH(LO$1,LP$3:MD$3,$B$9,$B$10,"Dir=V","Dts=S","Sort=A","Days=T","Fill=B") | MF4: =BDH(MF$1,MG$3:MU$3,$B$9,$B$10,"Dir=V","Dts=S","Sort=A","Days=T","Fill=B") | MW4: =BDH(MW$1,MX$3:NL$3,$B$9,$B$10,"Dir=V","Dts=S","Sort=A","Days=T","Fill=B") | NN4: =BDH(NN$1,NO$3:OC$3,$B$9,$B$10,"Dir=V","Dts=S","Sort=A","Days=T","Fill=B") | OE4: =BDH(OE$1,OF$3:OT$3,$B$9,$B$10,"Dir=V","Dts=S","Sort=A","Days=T","Fill=B") | OV4: =BDH(OV$1,OW$3:PK$3,$B$9,$B$10,"Dir=V","Dts=S","Sort=A","Days=T","Fill=B") | PM4: =BDH(PM$1,PN$3:QB$3,$B$9,$B$10,"Dir=V","Dts=S","Sort=A","Days=T","Fill=B") | QD4: =BDH(QD$1,QE$3:QS$3,$B$9,$B$10,"Dir=V","Dts=S","Sort=A","Days=T","Fill=B") | QU4: =BDH(QU$1,QV$3:RJ$3,$B$9,$B$10,"Dir=V","Dts=S","Sort=A","Days=T","Fill=B") | RL4: =BDH(RL$1,RM$3:SA$3,$B$9,$B$10,"Dir=V","Dts=S","Sort=A","Days=T","Fill=B") | SC4: =BDH(SC$1,SD$3:SR$3,$B$9,$B$10,"Dir=V","Dts=S","Sort=A","Days=T","Fill=B") | ST4: =BDH(ST$1,SU$3:TI$3,$B$9,$B$10,"Dir=V","Dts=S","Sort=A","Days=T","Fill=B") | TK4: =BDH(TK$1,TL$3:TZ$3,$B$9,$B$10,"Dir=V","Dts=S","Sort=A","Days=T","Fill=B") | UB4: =BDH(UB$1,UC$3:UQ$3,$B$9,$B$10,"Dir=V","Dts=S","Sort=A","Days=T","Fill=B") | US4: =BDH(US$1,UT$3:VH$3,$B$9,$B$10,"Dir=V","Dts=S","Sort=A","Days=T","Fill=B")
A5: Futures ticker | B5: ="CL"&MID("FGHJKMNQUVXZ",B1,1)&B4&" Comdty"
A6: Strike reference date | B6: =B3-45
A7: Futures price on that date | B7: =BDH(B5,"PX_LAST",B6,B6,"Days=A","Fill=P","Dts=H")
A8: ATM strike | B8: =ROUND(B7,0)
A9: History start | B9: =B3-100
A10: History end | B10: =B3

Sheet Apr
A1: Contract month | B1: 4 | D1: ="CL"&MID("FGHJKMNQUVXZ",B$1,1)&B$4&"C "&IF(Settings!$B$4=2,TEXT((B$8-8),"0.00"),(B$8-8))&" Comdty" | U1: ="CL"&MID("FGHJKMNQUVXZ",B$1,1)&B$4&"P "&IF(Settings!$B$4=2,TEXT((B$8-8),"0.00"),(B$8-8))&" Comdty" | AL1: ="CL"&MID("FGHJKMNQUVXZ",B$1,1)&B$4&"C "&IF(Settings!$B$4=2,TEXT((B$8-7),"0.00"),(B$8-7))&" Comdty" | BC1: ="CL"&MID("FGHJKMNQUVXZ",B$1,1)&B$4&"P "&IF(Settings!$B$4=2,TEXT((B$8-7),"0.00"),(B$8-7))&" Comdty" | BT1: ="CL"&MID("FGHJKMNQUVXZ",B$1,1)&B$4&"C "&IF(Settings!$B$4=2,TEXT((B$8-6),"0.00"),(B$8-6))&" Comdty" | CK1: ="CL"&MID("FGHJKMNQUVXZ",B$1,1)&B$4&"P "&IF(Settings!$B$4=2,TEXT((B$8-6),"0.00"),(B$8-6))&" Comdty" | DB1: ="CL"&MID("FGHJKMNQUVXZ",B$1,1)&B$4&"C "&IF(Settings!$B$4=2,TEXT((B$8-5),"0.00"),(B$8-5))&" Comdty" | DS1: ="CL"&MID("FGHJKMNQUVXZ",B$1,1)&B$4&"P "&IF(Settings!$B$4=2,TEXT((B$8-5),"0.00"),(B$8-5))&" Comdty" | EJ1: ="CL"&MID("FGHJKMNQUVXZ",B$1,1)&B$4&"C "&IF(Settings!$B$4=2,TEXT((B$8-4),"0.00"),(B$8-4))&" Comdty" | FA1: ="CL"&MID("FGHJKMNQUVXZ",B$1,1)&B$4&"P "&IF(Settings!$B$4=2,TEXT((B$8-4),"0.00"),(B$8-4))&" Comdty" | FR1: ="CL"&MID("FGHJKMNQUVXZ",B$1,1)&B$4&"C "&IF(Settings!$B$4=2,TEXT((B$8-3),"0.00"),(B$8-3))&" Comdty" | GI1: ="CL"&MID("FGHJKMNQUVXZ",B$1,1)&B$4&"P "&IF(Settings!$B$4=2,TEXT((B$8-3),"0.00"),(B$8-3))&" Comdty" | GZ1: ="CL"&MID("FGHJKMNQUVXZ",B$1,1)&B$4&"C "&IF(Settings!$B$4=2,TEXT((B$8-2),"0.00"),(B$8-2))&" Comdty" | HQ1: ="CL"&MID("FGHJKMNQUVXZ",B$1,1)&B$4&"P "&IF(Settings!$B$4=2,TEXT((B$8-2),"0.00"),(B$8-2))&" Comdty" | IH1: ="CL"&MID("FGHJKMNQUVXZ",B$1,1)&B$4&"C "&IF(Settings!$B$4=2,TEXT((B$8-1),"0.00"),(B$8-1))&" Comdty" | IY1: ="CL"&MID("FGHJKMNQUVXZ",B$1,1)&B$4&"P "&IF(Settings!$B$4=2,TEXT((B$8-1),"0.00"),(B$8-1))&" Comdty" | JP1: ="CL"&MID("FGHJKMNQUVXZ",B$1,1)&B$4&"C "&IF(Settings!$B$4=2,TEXT(B$8,"0.00"),B$8)&" Comdty" | KG1: ="CL"&MID("FGHJKMNQUVXZ",B$1,1)&B$4&"P "&IF(Settings!$B$4=2,TEXT(B$8,"0.00"),B$8)&" Comdty" | KX1: ="CL"&MID("FGHJKMNQUVXZ",B$1,1)&B$4&"C "&IF(Settings!$B$4=2,TEXT((B$8+1),"0.00"),(B$8+1))&" Comdty" | LO1: ="CL"&MID("FGHJKMNQUVXZ",B$1,1)&B$4&"P "&IF(Settings!$B$4=2,TEXT((B$8+1),"0.00"),(B$8+1))&" Comdty" | MF1: ="CL"&MID("FGHJKMNQUVXZ",B$1,1)&B$4&"C "&IF(Settings!$B$4=2,TEXT((B$8+2),"0.00"),(B$8+2))&" Comdty" | MW1: ="CL"&MID("FGHJKMNQUVXZ",B$1,1)&B$4&"P "&IF(Settings!$B$4=2,TEXT((B$8+2),"0.00"),(B$8+2))&" Comdty" | NN1: ="CL"&MID("FGHJKMNQUVXZ",B$1,1)&B$4&"C "&IF(Settings!$B$4=2,TEXT((B$8+3),"0.00"),(B$8+3))&" Comdty" | OE1: ="CL"&MID("FGHJKMNQUVXZ",B$1,1)&B$4&"P "&IF(Settings!$B$4=2,TEXT((B$8+3),"0.00"),(B$8+3))&" Comdty" | OV1: ="CL"&MID("FGHJKMNQUVXZ",B$1,1)&B$4&"C "&IF(Settings!$B$4=2,TEXT((B$8+4),"0.00"),(B$8+4))&" Comdty" | PM1: ="CL"&MID("FGHJKMNQUVXZ",B$1,1)&B$4&"P "&IF(Settings!$B$4=2,TEXT((B$8+4),"0.00"),(B$8+4))&" Comdty" | QD1: ="CL"&MID("FGHJKMNQUVXZ",B$1,1)&B$4&"C "&IF(Settings!$B$4=2,TEXT((B$8+5),"0.00"),(B$8+5))&" Comdty" | QU1: ="CL"&MID("FGHJKMNQUVXZ",B$1,1)&B$4&"P "&IF(Settings!$B$4=2,TEXT((B$8+5),"0.00"),(B$8+5))&" Comdty" | RL1: ="CL"&MID("FGHJKMNQUVXZ",B$1,1)&B$4&"C "&IF(Settings!$B$4=2,TEXT((B$8+6),"0.00"),(B$8+6))&" Comdty" | SC1: ="CL"&MID("FGHJKMNQUVXZ",B$1,1)&B$4&"P "&IF(Settings!$B$4=2,TEXT((B$8+6),"0.00"),(B$8+6))&" Comdty" | ST1: ="CL"&MID("FGHJKMNQUVXZ",B$1,1)&B$4&"C "&IF(Settings!$B$4=2,TEXT((B$8+7),"0.00"),(B$8+7))&" Comdty" | TK1: ="CL"&MID("FGHJKMNQUVXZ",B$1,1)&B$4&"P "&IF(Settings!$B$4=2,TEXT((B$8+7),"0.00"),(B$8+7))&" Comdty" | UB1: ="CL"&MID("FGHJKMNQUVXZ",B$1,1)&B$4&"C "&IF(Settings!$B$4=2,TEXT((B$8+8),"0.00"),(B$8+8))&" Comdty" | US1: ="CL"&MID("FGHJKMNQUVXZ",B$1,1)&B$4&"P "&IF(Settings!$B$4=2,TEXT((B$8+8),"0.00"),(B$8+8))&" Comdty"
A2: Futures last trade | B2: =WORKDAY(DATE(Settings!$B$3,B1-1,25),-3) | D2: call -8 from ATM | U2: put -8 from ATM | AL2: call -7 from ATM | BC2: put -7 from ATM | BT2: call -6 from ATM | CK2: put -6 from ATM | DB2: call -5 from ATM | DS2: put -5 from ATM | EJ2: call -4 from ATM | FA2: put -4 from ATM | FR2: call -3 from ATM | GI2: put -3 from ATM | GZ2: call -2 from ATM | HQ2: put -2 from ATM | IH2: call -1 from ATM | IY2: put -1 from ATM | JP2: call +0 from ATM | KG2: put +0 from ATM | KX2: call +1 from ATM | LO2: put +1 from ATM | MF2: call +2 from ATM | MW2: put +2 from ATM | NN2: call +3 from ATM | OE2: put +3 from ATM | OV2: call +4 from ATM | PM2: put +4 from ATM | QD2: call +5 from ATM | QU2: put +5 from ATM | RL2: call +6 from ATM | SC2: put +6 from ATM | ST2: call +7 from ATM | TK2: put +7 from ATM | UB2: call +8 from ATM | US2: put +8 from ATM
