Workbook

Sheet Settings
A1: XLE monthly options: ATM +/- 5 strikes, last 100 days before expiry (oil-equity-options)
A3: Year | B3: 2026 | C3: Expiry year to pull
A4: Underlying | B4: XLE | C4: US ticker
A6: Legend
A7: Yellow cells with blue text | B7: inputs you may change; everything else is a formula
A9: How to use
A10: 1. Open this file in Excel on the Bloomberg PC with the Terminal logged in. Click Enable Editing / Enable Content.
A11: 2. Wait until no cell says 'Requesting Data...'. If nothing loads: Bloomberg tab > Refresh > Refresh Workbook.
A12: 3. A cell reading '#N/A Invalid Security' or '#N/A Field Not Applicable' just means that item is unavailable.
A13: 4. Each sheet is one monthly expiry (3rd Friday) of the Year below. Strikes are centred on the unadjusted close 45 days before expiry.
A14: 5. Save As XLE_Options_<year>.xlsx, then change Year, wait for it to reload, and Save As again. Do this for each year 2018-2026.
A15: 6. If a whole sheet shows '#N/A Invalid Security', that Friday was a holiday: type the Thursday date over the Expiry cell (B3) on that sheet.

Sheet Jan
A1: Month | B1: 1 | D1: =Settings!$B$4&" US "&TEXT(B$3,"mm/dd/yy")&" C"&(B$7-5*B$6)&" Equity" | U1: =Settings!$B$4&" US "&TEXT(B$3,"mm/dd/yy")&" P"&(B$7-5*B$6)&" Equity" | AL1: =Settings!$B$4&" US "&TEXT(B$3,"mm/dd/yy")&" C"&(B$7-4*B$6)&" Equity" | BC1: =Settings!$B$4&" US "&TEXT(B$3,"mm/dd/yy")&" P"&(B$7-4*B$6)&" Equity" | BT1: =Settings!$B$4&" US "&TEXT(B$3,"mm/dd/yy")&" C"&(B$7-3*B$6)&" Equity" | CK1: =Settings!$B$4&" US "&TEXT(B$3,"mm/dd/yy")&" P"&(B$7-3*B$6)&" Equity" | DB1: =Settings!$B$4&" US "&TEXT(B$3,"mm/dd/yy")&" C"&(B$7-2*B$6)&" Equity" | DS1: =Settings!$B$4&" US "&TEXT(B$3,"mm/dd/yy")&" P"&(B$7-2*B$6)&" Equity" | EJ1: =Settings!$B$4&" US "&TEXT(B$3,"mm/dd/yy")&" C"&(B$7-1*B$6)&" Equity" | FA1: =Settings!$B$4&" US "&TEXT(B$3,"mm/dd/yy")&" P"&(B$7-1*B$6)&" Equity" | FR1: =Settings!$B$4&" US "&TEXT(B$3,"mm/dd/yy")&" C"&B$7&" Equity" | GI1: =Settings!$B$4&" US "&TEXT(B$3,"mm/dd/yy")&" P"&B$7&" Equity" | GZ1: =Settings!$B$4&" US "&TEXT(B$3,"mm/dd/yy")&" C"&(B$7+1*B$6)&" Equity" | HQ1: =Settings!$B$4&" US "&TEXT(B$3,"mm/dd/yy")&" P"&(B$7+1*B$6)&" Equity" | IH1: =Settings!$B$4&" US "&TEXT(B$3,"mm/dd/yy")&" C"&(B$7+2*B$6)&" Equity" | IY1: =Settings!$B$4&" US "&TEXT(B$3,"mm/dd/yy")&" P"&(B$7+2*B$6)&" Equity" | JP1: =Settings!$B$4&" US "&TEXT(B$3,"mm/dd/yy")&" C"&(B$7+3*B$6)&" Equity" | KG1: =Settings!$B$4&" US "&TEXT(B$3,"mm/dd/yy")&" P"&(B$7+3*B$6)&" Equity" | KX1: =Settings!$B$4&" US "&TEXT(B$3,"mm/dd/yy")&" C"&(B$7+4*B$6)&" Equity" | LO1: =Settings!$B$4&" US "&TEXT(B$3,"mm/dd/yy")&" P"&(B$7+4*B$6)&" Equity" | MF1: =Settings!$B$4&" US "&TEXT(B$3,"mm/dd/yy")&" C"&(B$7+5*B$6)&" Equity" | MW1: =Settings!$B$4&" US "&TEXT(B$3,"mm/dd/yy")&" P"&(B$7+5*B$6)&" Equity"
A2: Underlying | B2: =Settings!$B$4&" US Equity" | D2: call -5 from ATM | U2: put -5 from ATM | AL2: call -4 from ATM | BC2: put -4 from ATM | BT2: call -3 from ATM | CK2: put -3 from ATM | DB2: call -2 from ATM | DS2: put -2 from ATM | EJ2: call -1 from ATM | FA2: put -1 from ATM | FR2: call +0 from ATM | GI2: put +0 from ATM | GZ2: call +1 from ATM | HQ2: put +1 from ATM | IH2: call +2 from ATM | IY2: put +2 from ATM | JP2: call +3 from ATM | KG2: put +3 from ATM | KX2: call +4 from ATM | LO2: put +4 from ATM | MF2: call +5 from ATM | MW2: put +5 from ATM
A3: Expiry (3rd Friday) | B3: =DATE(Settings!$B$3,B1,15)+MOD(6-WEEKDAY(DATE(Settings!$B$3,B1,15)),7) | D3: Date | E3: PX_BID | F3: PX_ASK | G3: PX_MID | H3: PX_LAST | I3: PX_SETTLE | J3: PX_VOLUME | K3: OPEN_INT | L3: IVOL_MID | M3: IVOL_BID | N3: IVOL_ASK | O3: DELTA_MID | P3: GAMMA_MID | Q3: VEGA_MID | R3: THETA_MID | S3: OPT_UNDL_PX | U3: Date | V3: PX_BID | W3: PX_ASK | X3: PX_MID | Y3: PX_LAST | Z3: PX_SETTLE | AA3: PX_VOLUME | AB3: OPEN_INT | AC3: IVOL_MID | AD3: IVOL_BID | AE3: IVOL_ASK | AF3: DELTA_MID | AG3: GAMMA_MID | AH3: VEGA_MID | AI3: THETA_MID | AJ3: OPT_UNDL_PX | AL3: Date | AM3: PX_BID | AN3: PX_ASK | AO3: PX_MID | AP3: PX_LAST | AQ3: PX_SETTLE | AR3: PX_VOLUME | AS3: OPEN_INT | AT3: IVOL_MID | AU3: IVOL_BID | AV3: IVOL_ASK | AW3: DELTA_MID | AX3: GAMMA_MID | AY3: VEGA_MID | AZ3: THETA_MID | BA3: OPT_UNDL_PX | BC3: Date | BD3: PX_BID | BE3: PX_ASK | BF3: PX_MID | BG3: PX_LAST | BH3: PX_SETTLE | BI3: PX_VOLUME | BJ3: OPEN_INT | BK3: IVOL_MID | BL3: IVOL_BID | BM3: IVOL_ASK | BN3: DELTA_MID | BO3: GAMMA_MID | BP3: VEGA_MID | BQ3: THETA_MID | BR3: OPT_UNDL_PX | BT3: Date | BU3: PX_BID | BV3: PX_ASK | BW3: PX_MID | BX3: PX_LAST | BY3: PX_SETTLE | BZ3: PX_VOLUME | CA3: OPEN_INT | CB3: IVOL_MID | CC3: IVOL_BID | CD3: IVOL_ASK | CE3: DELTA_MID | CF3: GAMMA_MID | CG3: VEGA_MID | CH3: THETA_MID | CI3: OPT_UNDL_PX | CK3: Date | CL3: PX_BID | CM3: PX_ASK | CN3: PX_MID | CO3: PX_LAST | CP3: PX_SETTLE | CQ3: PX_VOLUME | CR3: OPEN_INT | CS3: IVOL_MID | CT3: IVOL_BID | CU3: IVOL_ASK | CV3: DELTA_MID | CW3: GAMMA_MID | CX3: VEGA_MID | CY3: THETA_MID | CZ3: OPT_UNDL_PX | DB3: Date | DC3: PX_BID | DD3: PX_ASK | DE3: PX_MID | DF3: PX_LAST | DG3: PX_SETTLE | DH3: PX_VOLUME | DI3: OPEN_INT | DJ3: IVOL_MID | DK3: IVOL_BID | DL3: IVOL_ASK | DM3: DELTA_MID | DN3: GAMMA_MID | DO3: VEGA_MID | DP3: THETA_MID | DQ3: OPT_UNDL_PX | DS3: Date | DT3: PX_BID | DU3: PX_ASK | DV3: PX_MID | DW3: PX_LAST | DX3: PX_SETTLE | DY3: PX_VOLUME | DZ3: OPEN_INT | EA3: IVOL_MID | EB3: IVOL_BID | EC3: IVOL_ASK | ED3: DELTA_MID | EE3: GAMMA_MID | EF3: VEGA_MID | EG3: THETA_MID | EH3: OPT_UNDL_PX | EJ3: Date | EK3: PX_BID | EL3: PX_ASK | EM3: PX_MID | EN3: PX_LAST | EO3: PX_SETTLE | EP3: PX_VOLUME | EQ3: OPEN_INT | ER3: IVOL_MID | ES3: IVOL_BID | ET3: IVOL_ASK | EU3: DELTA_MID | EV3: GAMMA_MID | EW3: VEGA_MID | EX3: THETA_MID | EY3: OPT_UNDL_PX | FA3: Date | FB3: PX_BID | FC3: PX_ASK | FD3: PX_MID | FE3: PX_LAST | FF3: PX_SETTLE | FG3: PX_VOLUME | FH3: OPEN_INT | FI3: IVOL_MID | FJ3: IVOL_BID | FK3: IVOL_ASK | FL3: DELTA_MID | FM3: GAMMA_MID | FN3: VEGA_MID | FO3: THETA_MID | FP3: OPT_UNDL_PX | FR3: Date | FS3: PX_BID | FT3: PX_ASK | FU3: PX_MID | FV3: PX_LAST | FW3: PX_SETTLE | FX3: PX_VOLUME | FY3: OPEN_INT | FZ3: IVOL_MID | GA3: IVOL_BID | GB3: IVOL_ASK | GC3: DELTA_MID | GD3: GAMMA_MID | GE3: VEGA_MID | GF3: THETA_MID | GG3: OPT_UNDL_PX | GI3: Date | GJ3: PX_BID | GK3: PX_ASK | GL3: PX_MID | GM3: PX_LAST | GN3: PX_SETTLE | GO3: PX_VOLUME | GP3: OPEN_INT | GQ3: IVOL_MID | GR3: IVOL_BID | GS3: IVOL_ASK | GT3: DELTA_MID | GU3: GAMMA_MID | GV3: VEGA_MID | GW3: THETA_MID | GX3: OPT_UNDL_PX | GZ3: Date | HA3: PX_BID | HB3: PX_ASK | HC3: PX_MID | HD3: PX_LAST | HE3: PX_SETTLE | HF3: PX_VOLUME | HG3: OPEN_INT | HH3: IVOL_MID | HI3: IVOL_BID | HJ3: IVOL_ASK | HK3: DELTA_MID | HL3: GAMMA_MID | HM3: VEGA_MID | HN3: THETA_MID | HO3: OPT_UNDL_PX | HQ3: Date | HR3: PX_BID | HS3: PX_ASK | HT3: PX_MID | HU3: PX_LAST | HV3: PX_SETTLE | HW3: PX_VOLUME | HX3: OPEN_INT | HY3: IVOL_MID | HZ3: IVOL_BID | IA3: IVOL_ASK | IB3: DELTA_MID | IC3: GAMMA_MID | ID3: VEGA_MID | IE3: THETA_MID | IF3: OPT_UNDL_PX | IH3: Date | II3: PX_BID | IJ3: PX_ASK | IK3: PX_MID | IL3: PX_LAST | IM3: PX_SETTLE | IN3: PX_VOLUME | IO3: OPEN_INT | IP3: IVOL_MID | IQ3: IVOL_BID | IR3: IVOL_ASK | IS3: DELTA_MID | IT3: GAMMA_MID | IU3: VEGA_MID | IV3: THETA_MID | IW3: OPT_UNDL_PX | IY3: Date | IZ3: PX_BID | JA3: PX_ASK | JB3: PX_MID | JC3: PX_LAST | JD3: PX_SETTLE | JE3: PX_VOLUME | JF3: OPEN_INT | JG3: IVOL_MID | JH3: IVOL_BID | JI3: IVOL_ASK | JJ3: DELTA_MID | JK3: GAMMA_MID | JL3: VEGA_MID | JM3: THETA_MID | JN3: OPT_UNDL_PX | JP3: Date | JQ3: PX_BID | JR3: PX_ASK | JS3: PX_MID | JT3: PX_LAST | JU3: PX_SETTLE | JV3: PX_VOLUME | JW3: OPEN_INT | JX3: IVOL_MID | JY3: IVOL_BID | JZ3: IVOL_ASK | KA3: DELTA_MID | KB3: GAMMA_MID | KC3: VEGA_MID | KD3: THETA_MID | KE3: OPT_UNDL_PX | KG3: Date | KH3: PX_BID | KI3: PX_ASK | KJ3: PX_MID | KK3: PX_LAST | KL3: PX_SETTLE | KM3: PX_VOLUME | KN3: OPEN_INT | KO3: IVOL_MID | KP3: IVOL_BID | KQ3: IVOL_ASK | KR3: DELTA_MID | KS3: GAMMA_MID | KT3: VEGA_MID | KU3: THETA_MID | KV3: OPT_UNDL_PX | KX3: Date | KY3: PX_BID | KZ3: PX_ASK | LA3: PX_MID | LB3: PX_LAST | LC3: PX_SETTLE | LD3: PX_VOLUME | LE3: OPEN_INT | LF3: IVOL_MID | LG3: IVOL_BID | LH3: IVOL_ASK | LI3: DELTA_MID | LJ3: GAMMA_MID | LK3: VEGA_MID | LL3: THETA_MID | LM3: OPT_UNDL_PX | LO3: Date | LP3: PX_BID | LQ3: PX_ASK | LR3: PX_MID | LS3: PX_LAST | LT3: PX_SETTLE | LU3: PX_VOLUME | LV3: OPEN_INT | LW3: IVOL_MID | LX3: IVOL_BID | LY3: IVOL_ASK | LZ3: DELTA_MID | MA3: GAMMA_MID | MB3: VEGA_MID | MC3: THETA_MID | MD3: OPT_UNDL_PX | MF3: Date | MG3: PX_BID | MH3: PX_ASK | MI3: PX_MID | MJ3: PX_LAST | MK3: PX_SETTLE | ML3: PX_VOLUME | MM3: OPEN_INT | MN3: IVOL_MID | MO3: IVOL_BID | MP3: IVOL_ASK | MQ3: DELTA_MID | MR3: GAMMA_MID | MS3: VEGA_MID | MT3: THETA_MID | MU3: OPT_UNDL_PX | MW3: Date | MX3: PX_BID | MY3: PX_ASK | MZ3: PX_MID | NA3: PX_LAST | NB3: PX_SETTLE | NC3: PX_VOLUME | ND3: OPEN_INT | NE3: IVOL_MID | NF3: IVOL_BID | NG3: IVOL_ASK | NH3: DELTA_MID | NI3: GAMMA_MID | NJ3: VEGA_MID | NK3: THETA_MID | NL3: OPT_UNDL_PX
A4: Strike reference date | B4: =B3-45 | D4: =BDH(D$1,E$3:S$3,$B$8,$B$9,"Dir=V","Dts=S","Sort=A","Days=T","Fill=B") | U4: =BDH(U$1,V$3:AJ$3,$B$8,$B$9,"Dir=V","Dts=S","Sort=A","Days=T","Fill=B") | AL4: =BDH(AL$1,AM$3:BA$3,$B$8,$B$9,"Dir=V","Dts=S","Sort=A","Days=T","Fill=B") | BC4: =BDH(BC$1,BD$3:BR$3,$B$8,$B$9,"Dir=V","Dts=S","Sort=A","Days=T","Fill=B") | BT4: =BDH(BT$1,BU$3:CI$3,$B$8,$B$9,"Dir=V","Dts=S","Sort=A","Days=T","Fill=B") | CK4: =BDH(CK$1,CL$3:CZ$3,$B$8,$B$9,"Dir=V","Dts=S","Sort=A","Days=T","Fill=B") | DB4: =BDH(DB$1,DC$3:DQ$3,$B$8,$B$9,"Dir=V","Dts=S","Sort=A","Days=T","Fill=B") | DS4: =BDH(DS$1,DT$3:EH$3,$B$8,$B$9,"Dir=V","Dts=S","Sort=A","Days=T","Fill=B") | EJ4: =BDH(EJ$1,EK$3:EY$3,$B$8,$B$9,"Dir=V","Dts=S","Sort=A","Days=T","Fill=B") | FA4: =BDH(FA$1,FB$3:FP$3,$B$8,$B$9,"Dir=V","Dts=S","Sort=A","Days=T","Fill=B") | FR4: =BDH(FR$1,FS$3:GG$3,$B$8,$B$9,"Dir=V","Dts=S","Sort=A","Days=T","Fill=B") | GI4: =BDH(GI$1,GJ$3:GX$3,$B$8,$B$9,"Dir=V","Dts=S","Sort=A","Days=T","Fill=B") | GZ4: =BDH(GZ$1,HA$3:HO$3,$B$8,$B$9,"Dir=V","Dts=S","Sort=A","Days=T","Fill=B") | HQ4: =BDH(HQ$1,HR$3:IF$3,$B$8,$B$9,"Dir=V","Dts=S","Sort=A","Days=T","Fill=B") | IH4: =BDH(IH$1,II$3:IW$3,$B$8,$B$9,"Dir=V","Dts=S","Sort=A","Days=T","Fill=B") | IY4: =BDH(IY$1,IZ$3:JN$3,$B$8,$B$9,"Dir=V","Dts=S","Sort=A","Days=T","Fill=B") | JP4: =BDH(JP$1,JQ$3:KE$3,$B$8,$B$9,"Dir=V","Dts=S","Sort=A","Days=T","Fill=B") | KG4: =BDH(KG$1,KH$3:KV$3,$B$8,$B$9,"Dir=V","Dts=S","Sort=A","Days=T","Fill=B") | KX4: =BDH(KX$1,KY$3:LM$3,$B$8,$B$9,"Dir=V","Dts=S","Sort=A","Days=T","Fill=B") | LO4: =BDH(LO$1,LP$3:MD$3,$B$8,$B$9,"Dir=V","Dts=S","Sort=A","Days=T","Fill=B") | MF4: =BDH(MF$1,MG$3:MU$3,$B$8,$B$9,"Dir=V","Dts=S","Sort=A","Days=T","Fill=B") | MW4: =BDH(MW$1,MX$3:NL$3,$B$8,$B$9,"Dir=V","Dts=S","Sort=A","Days=T","Fill=B")
A5: Unadjusted close then | B5: =BDH(B2,"PX_LAST",B4,B4,"Days=A","Fill=P","Dts=H","CshAdjNormal=N","CshAdjAbnormal=N","CapChg=N")
A6: Strike step | B6: =IF(B5<25,0.5,IF(B5<250,1,5))
A7: ATM strike | B7: =ROUND(B5/B6,0)*B6
A8: History start | B8: =B3-100
A9: History end | B9: =B3

Sheet Feb
A1: Month | B1: 2 | D1: =Settings!$B$4&" US "&TEXT(B$3,"mm/dd/yy")&" C"&(B$7-5*B$6)&" Equity" | U1: =Settings!$B$4&" US "&TEXT(B$3,"mm/dd/yy")&" P"&(B$7-5*B$6)&" Equity" | AL1: =Settings!$B$4&" US "&TEXT(B$3,"mm/dd/yy")&" C"&(B$7-4*B$6)&" Equity" | BC1: =Settings!$B$4&" US "&TEXT(B$3,"mm/dd/yy")&" P"&(B$7-4*B$6)&" Equity" | BT1: =Settings!$B$4&" US "&TEXT(B$3,"mm/dd/yy")&" C"&(B$7-3*B$6)&" Equity" | CK1: =Settings!$B$4&" US "&TEXT(B$3,"mm/dd/yy")&" P"&(B$7-3*B$6)&" Equity" | DB1: =Settings!$B$4&" US "&TEXT(B$3,"mm/dd/yy")&" C"&(B$7-2*B$6)&" Equity" | DS1: =Settings!$B$4&" US "&TEXT(B$3,"mm/dd/yy")&" P"&(B$7-2*B$6)&" Equity" | EJ1: =Settings!$B$4&" US "&TEXT(B$3,"mm/dd/yy")&" C"&(B$7-1*B$6)&" Equity" | FA1: =Settings!$B$4&" US "&TEXT(B$3,"mm/dd/yy")&" P"&(B$7-1*B$6)&" Equity" | FR1: =Settings!$B$4&" US "&TEXT(B$3,"mm/dd/yy")&" C"&B$7&" Equity" | GI1: =Settings!$B$4&" US "&TEXT(B$3,"mm/dd/yy")&" P"&B$7&" Equity" | GZ1: =Settings!$B$4&" US "&TEXT(B$3,"mm/dd/yy")&" C"&(B$7+1*B$6)&" Equity" | HQ1: =Settings!$B$4&" US "&TEXT(B$3,"mm/dd/yy")&" P"&(B$7+1*B$6)&" Equity" | IH1: =Settings!$B$4&" US "&TEXT(B$3,"mm/dd/yy")&" C"&(B$7+2*B$6)&" Equity" | IY1: =Settings!$B$4&" US "&TEXT(B$3,"mm/dd/yy")&" P"&(B$7+2*B$6)&" Equity" | JP1: =Settings!$B$4&" US "&TEXT(B$3,"mm/dd/yy")&" C"&(B$7+3*B$6)&" Equity" | KG1: =Settings!$B$4&" US "&TEXT(B$3,"mm/dd/yy")&" P"&(B$7+3*B$6)&" Equity" | KX1: =Settings!$B$4&" US "&TEXT(B$3,"mm/dd/yy")&" C"&(B$7+4*B$6)&" Equity" | LO1: =Settings!$B$4&" US "&TEXT(B$3,"mm/dd/yy")&" P"&(B$7+4*B$6)&" Equity" | MF1: =Settings!$B$4&" US "&TEXT(B$3,"mm/dd/yy")&" C"&(B$7+5*B$6)&" Equity" | MW1: =Settings!$B$4&" US "&TEXT(B$3,"mm/dd/yy")&" P"&(B$7+5*B$6)&" Equity"
A2: Underlying | B2: =Settings!$B$4&" US Equity" | D2: call -5 from ATM | U2: put -5 from ATM | AL2: call -4 from ATM | BC2: put -4 from ATM | BT2: call -3 from ATM | CK2: put -3 from ATM | DB2: call -2 from ATM | DS2: put -2 from ATM | EJ2: call -1 from ATM | FA2: put -1 from ATM | FR2: call +0 from ATM | GI2: put +0 from ATM | GZ2: call +1 from ATM | HQ2: put +1 from ATM | IH2: call +2 from ATM | IY2: put +2 from ATM | JP2: call +3 from ATM | KG2: put +3 from ATM | KX2: call +4 from ATM | LO2: put +4 from ATM | MF2: call +5 from ATM | MW2: put +5 from ATM
A3: Expiry (3rd Friday) | B3: =DATE(Settings!$B$3,B1,15)+MOD(6-WEEKDAY(DATE(Settings!$B$3,B1,15)),7) | D3: Date | E3: PX_BID | F3: PX_ASK | G3: PX_MID | H3: PX_LAST | I3: PX_SETTLE | J3: PX_VOLUME | K3: OPEN_INT | L3: IVOL_MID | M3: IVOL_BID | N3: IVOL_ASK | O3: DELTA_MID | P3: GAMMA_MID | Q3: VEGA_MID | R3: THETA_MID | S3: OPT_UNDL_PX | U3: Date | V3: PX_BID | W3: PX_ASK | X3: PX_MID | Y3: PX_LAST | Z3: PX_SETTLE | AA3: PX_VOLUME | AB3: OPEN_INT | AC3: IVOL_MID | AD3: IVOL_BID | AE3: IVOL_ASK | AF3: DELTA_MID | AG3: GAMMA_MID | AH3: VEGA_MID | AI3: THETA_MID | AJ3: OPT_UNDL_PX | AL3: Date | AM3: PX_BID | AN3: PX_ASK | AO3: PX_MID | AP3: PX_LAST | AQ3: PX_SETTLE | AR3: PX_VOLUME | AS3: OPEN_INT | AT3: IVOL_MID | AU3: IVOL_BID | AV3: IVOL_ASK | AW3: DELTA_MID | AX3: GAMMA_MID | AY3: VEGA_MID | AZ3: THETA_MID | BA3: OPT_UNDL_PX | BC3: Date | BD3: PX_BID | BE3: PX_ASK | BF3: PX_MID | BG3: PX_LAST | BH3: PX_SETTLE | BI3: PX_VOLUME | BJ3: OPEN_INT | BK3: IVOL_MID | BL3: IVOL_BID | BM3: IVOL_ASK | BN3: DELTA_MID | BO3: GAMMA_MID | BP3: VEGA_MID | BQ3: THETA_MID | BR3: OPT_UNDL_PX | BT3: Date | BU3: PX_BID | BV3: PX_ASK | BW3: PX_MID | BX3: PX_LAST | BY3: PX_SETTLE | BZ3: PX_VOLUME | CA3: OPEN_INT | CB3: IVOL_MID | CC3: IVOL_BID | CD3: IVOL_ASK | CE3: DELTA_MID | CF3: GAMMA_MID | CG3: VEGA_MID | CH3: THETA_MID | CI3: OPT_UNDL_PX | CK3: Date | CL3: PX_BID | CM3: PX_ASK | CN3: PX_MID | CO3: PX_LAST | CP3: PX_SETTLE | CQ3: PX_VOLUME | CR3: OPEN_INT | CS3: IVOL_MID | CT3: IVOL_BID | CU3: IVOL_ASK | CV3: DELTA_MID | CW3: GAMMA_MID | CX3: VEGA_MID | CY3: THETA_MID | CZ3: OPT_UNDL_PX | DB3: Date | DC3: PX_BID | DD3: PX_ASK | DE3: PX_MID | DF3: PX_LAST | DG3: PX_SETTLE | DH3: PX_VOLUME | DI3: OPEN_INT | DJ3: IVOL_MID | DK3: IVOL_BID | DL3: IVOL_ASK | DM3: DELTA_MID | DN3: GAMMA_MID | DO3: VEGA_MID | DP3: THETA_MID | DQ3: OPT_UNDL_PX | DS3: Date | DT3: PX_BID | DU3: PX_ASK | DV3: PX_MID | DW3: PX_LAST | DX3: PX_SETTLE | DY3: PX_VOLUME | DZ3: OPEN_INT | EA3: IVOL_MID | EB3: IVOL_BID | EC3: IVOL_ASK | ED3: DELTA_MID | EE3: GAMMA_MID | EF3: VEGA_MID | EG3: THETA_MID | EH3: OPT_UNDL_PX | EJ3: Date | EK3: PX_BID | EL3: PX_ASK | EM3: PX_MID | EN3: PX_LAST | EO3: PX_SETTLE | EP3: PX_VOLUME | EQ3: OPEN_INT | ER3: IVOL_MID | ES3: IVOL_BID | ET3: IVOL_ASK | EU3: DELTA_MID | EV3: GAMMA_MID | EW3: VEGA_MID | EX3: THETA_MID | EY3: OPT_UNDL_PX | FA3: Date | FB3: PX_BID | FC3: PX_ASK | FD3: PX_MID | FE3: PX_LAST | FF3: PX_SETTLE | FG3: PX_VOLUME | FH3: OPEN_INT | FI3: IVOL_MID | FJ3: IVOL_BID | FK3: IVOL_ASK | FL3: DELTA_MID | FM3: GAMMA_MID | FN3: VEGA_MID | FO3: THETA_MID | FP3: OPT_UNDL_PX | FR3: Date | FS3: PX_BID | FT3: PX_ASK | FU3: PX_MID | FV3: PX_LAST | FW3: PX_SETTLE | FX3: PX_VOLUME | FY3: OPEN_INT | FZ3: IVOL_MID | GA3: IVOL_BID | GB3: IVOL_ASK | GC3: DELTA_MID | GD3: GAMMA_MID | GE3: VEGA_MID | GF3: THETA_MID | GG3: OPT_UNDL_PX | GI3: Date | GJ3: PX_BID | GK3: PX_ASK | GL3: PX_MID | GM3: PX_LAST | GN3: PX_SETTLE | GO3: PX_VOLUME | GP3: OPEN_INT | GQ3: IVOL_MID | GR3: IVOL_BID | GS3: IVOL_ASK | GT3: DELTA_MID | GU3: GAMMA_MID | GV3: VEGA_MID | GW3: THETA_MID | GX3: OPT_UNDL_PX | GZ3: Date | HA3: PX_BID | HB3: PX_ASK | HC3: PX_MID | HD3: PX_LAST | HE3: PX_SETTLE | HF3: PX_VOLUME | HG3: OPEN_INT | HH3: IVOL_MID | HI3: IVOL_BID | HJ3: IVOL_ASK | HK3: DELTA_MID | HL3: GAMMA_MID | HM3: VEGA_MID | HN3: THETA_MID | HO3: OPT_UNDL_PX | HQ3: Date | HR3: PX_BID | HS3: PX_ASK | HT3: PX_MID | HU3: PX_LAST | HV3: PX_SETTLE | HW3: PX_VOLUME | HX3: OPEN_INT | HY3: IVOL_MID | HZ3: IVOL_BID | IA3: IVOL_ASK | IB3: DELTA_MID | IC3: GAMMA_MID | ID3: VEGA_MID | IE3: THETA_MID | IF3: OPT_UNDL_PX | IH3: Date | II3: PX_BID | IJ3: PX_ASK | IK3: PX_MID | IL3: PX_LAST | IM3: PX_SETTLE | IN3: PX_VOLUME | IO3: OPEN_INT | IP3: IVOL_MID | IQ3: IVOL_BID | IR3: IVOL_ASK | IS3: DELTA_MID | IT3: GAMMA_MID | IU3: VEGA_MID | IV3: THETA_MID | IW3: OPT_UNDL_PX | IY3: Date | IZ3: PX_BID | JA3: PX_ASK | JB3: PX_MID | JC3: PX_LAST | JD3: PX_SETTLE | JE3: PX_VOLUME | JF3: OPEN_INT | JG3: IVOL_MID | JH3: IVOL_BID | JI3: IVOL_ASK | JJ3: DELTA_MID | JK3: GAMMA_MID | JL3: VEGA_MID | JM3: THETA_MID | JN3: OPT_UNDL_PX | JP3: Date | JQ3: PX_BID | JR3: PX_ASK | JS3: PX_MID | JT3: PX_LAST | JU3: PX_SETTLE | JV3: PX_VOLUME | JW3: OPEN_INT | JX3: IVOL_MID | JY3: IVOL_BID | JZ3: IVOL_ASK | KA3: DELTA_MID | KB3: GAMMA_MID | KC3: VEGA_MID | KD3: THETA_MID | KE3: OPT_UNDL_PX | KG3: Date | KH3: PX_BID | KI3: PX_ASK | KJ3: PX_MID | KK3: PX_LAST | KL3: PX_SETTLE | KM3: PX_VOLUME | KN3: OPEN_INT | KO3: IVOL_MID | KP3: IVOL_BID | KQ3: IVOL_ASK | KR3: DELTA_MID | KS3: GAMMA_MID | KT3: VEGA_MID | KU3: THETA_MID | KV3: OPT_UNDL_PX | KX3: Date | KY3: PX_BID | KZ3: PX_ASK | LA3: PX_MID | LB3: PX_LAST | LC3: PX_SETTLE | LD3: PX_VOLUME | LE3: OPEN_INT | LF3: IVOL_MID | LG3: IVOL_BID | LH3: IVOL_ASK | LI3: DELTA_MID | LJ3: GAMMA_MID | LK3: VEGA_MID | LL3: THETA_MID | LM3: OPT_UNDL_PX | LO3: Date | LP3: PX_BID | LQ3: PX_ASK | LR3: PX_MID | LS3: PX_LAST | LT3: PX_SETTLE | LU3: PX_VOLUME | LV3: OPEN_INT | LW3: IVOL_MID | LX3: IVOL_BID | LY3: IVOL_ASK | LZ3: DELTA_MID | MA3: GAMMA_MID | MB3: VEGA_MID | MC3: THETA_MID | MD3: OPT_UNDL_PX | MF3: Date | MG3: PX_BID | MH3: PX_ASK | MI3: PX_MID | MJ3: PX_LAST | MK3: PX_SETTLE | ML3: PX_VOLUME | MM3: OPEN_INT | MN3: IVOL_MID | MO3: IVOL_BID | MP3: IVOL_ASK | MQ3: DELTA_MID | MR3: GAMMA_MID | MS3: VEGA_MID | MT3: THETA_MID | MU3: OPT_UNDL_PX | MW3: Date | MX3: PX_BID | MY3: PX_ASK | MZ3: PX_MID | NA3: PX_LAST | NB3: PX_SETTLE | NC3: PX_VOLUME | ND3: OPEN_INT | NE3: IVOL_MID | NF3: IVOL_BID | NG3: IVOL_ASK | NH3: DELTA_MID | NI3: GAMMA_MID | NJ3: VEGA_MID | NK3: THETA_MID | NL3: OPT_UNDL_PX
A4: Strike reference date | B4: =B3-45 | D4: =BDH(D$1,E$3:S$3,$B$8,$B$9,"Dir=V","Dts=S","Sort=A","Days=T","Fill=B") | U4: =BDH(U$1,V$3:AJ$3,$B$8,$B$9,"Dir=V","Dts=S","Sort=A","Days=T","Fill=B") | AL4: =BDH(AL$1,AM$3:BA$3,$B$8,$B$9,"Dir=V","Dts=S","Sort=A","Days=T","Fill=B") | BC4: =BDH(BC$1,BD$3:BR$3,$B$8,$B$9,"Dir=V","Dts=S","Sort=A","Days=T","Fill=B") | BT4: =BDH(BT$1,BU$3:CI$3,$B$8,$B$9,"Dir=V","Dts=S","Sort=A","Days=T","Fill=B") | CK4: =BDH(CK$1,CL$3:CZ$3,$B$8,$B$9,"Dir=V","Dts=S","Sort=A","Days=T","Fill=B") | DB4: =BDH(DB$1,DC$3:DQ$3,$B$8,$B$9,"Dir=V","Dts=S","Sort=A","Days=T","Fill=B") | DS4: =BDH(DS$1,DT$3:EH$3,$B$8,$B$9,"Dir=V","Dts=S","Sort=A","Days=T","Fill=B") | EJ4: =BDH(EJ$1,EK$3:EY$3,$B$8,$B$9,"Dir=V","Dts=S","Sort=A","Days=T","Fill=B") | FA4: =BDH(FA$1,FB$3:FP$3,$B$8,$B$9,"Dir=V","Dts=S","Sort=A","Days=T","Fill=B") | FR4: =BDH(FR$1,FS$3:GG$3,$B$8,$B$9,"Dir=V","Dts=S","Sort=A","Days=T","Fill=B") | GI4: =BDH(GI$1,GJ$3:GX$3,$B$8,$B$9,"Dir=V","Dts=S","Sort=A","Days=T","Fill=B") | GZ4: =BDH(GZ$1,HA$3:HO$3,$B$8,$B$9,"Dir=V","Dts=S","Sort=A","Days=T","Fill=B") | HQ4: =BDH(HQ$1,HR$3:IF$3,$B$8,$B$9,"Dir=V","Dts=S","Sort=A","Days=T","Fill=B") | IH4: =BDH(IH$1,II$3:IW$3,$B$8,$B$9,"Dir=V","Dts=S","Sort=A","Days=T","Fill=B") | IY4: =BDH(IY$1,IZ$3:JN$3,$B$8,$B$9,"Dir=V","Dts=S","Sort=A","Days=T","Fill=B") | JP4: =BDH(JP$1,JQ$3:KE$3,$B$8,$B$9,"Dir=V","Dts=S","Sort=A","Days=T","Fill=B") | KG4: =BDH(KG$1,KH$3:KV$3,$B$8,$B$9,"Dir=V","Dts=S","Sort=A","Days=T","Fill=B") | KX4: =BDH(KX$1,KY$3:LM$3,$B$8,$B$9,"Dir=V","Dts=S","Sort=A","Days=T","Fill=B") | LO4: =BDH(LO$1,LP$3:MD$3,$B$8,$B$9,"Dir=V","Dts=S","Sort=A","Days=T","Fill=B") | MF4: =BDH(MF$1,MG$3:MU$3,$B$8,$B$9,"Dir=V","Dts=S","Sort=A","Days=T","Fill=B") | MW4: =BDH(MW$1,MX$3:NL$3,$B$8,$B$9,"Dir=V","Dts=S","Sort=A","Days=T","Fill=B")
A5: Unadjusted close then | B5: =BDH(B2,"PX_LAST",B4,B4,"Days=A","Fill=P","Dts=H","CshAdjNormal=N","CshAdjAbnormal=N","CapChg=N")
A6: Strike step | B6: =IF(B5<25,0.5,IF(B5<250,1,5))
A7: ATM strike | B7: =ROUND(B5/B6,0)*B6
A8: History start | B8: =B3-100
A9: History end | B9: =B3

Sheet Mar
A1: Month | B1: 3 | D1: =Settings!$B$4&" US "&TEXT(B$3,"mm/dd/yy")&" C"&(B$7-5*B$6)&" Equity" | U1: =Settings!$B$4&" US "&TEXT(B$3,"mm/dd/yy")&" P"&(B$7-5*B$6)&" Equity" | AL1: =Settings!$B$4&" US "&TEXT(B$3,"mm/dd/yy")&" C"&(B$7-4*B$6)&" Equity" | BC1: =Settings!$B$4&" US "&TEXT(B$3,"mm/dd/yy")&" P"&(B$7-4*B$6)&" Equity" | BT1: =Settings!$B$4&" US "&TEXT(B$3,"mm/dd/yy")&" C"&(B$7-3*B$6)&" Equity" | CK1: =Settings!$B$4&" US "&TEXT(B$3,"mm/dd/yy")&" P"&(B$7-3*B$6)&" Equity" | DB1: =Settings!$B$4&" US "&TEXT(B$3,"mm/dd/yy")&" C"&(B$7-2*B$6)&" Equity" | DS1: =Settings!$B$4&" US "&TEXT(B$3,"mm/dd/yy")&" P"&(B$7-2*B$6)&" Equity" | EJ1: =Settings!$B$4&" US "&TEXT(B$3,"mm/dd/yy")&" C"&(B$7-1*B$6)&" Equity" | FA1: =Settings!$B$4&" US "&TEXT(B$3,"mm/dd/yy")&" P"&(B$7-1*B$6)&" Equity" | FR1: =Settings!$B$4&" US "&TEXT(B$3,"mm/dd/yy")&" C"&B$7&" Equity" | GI1: =Settings!$B$4&" US "&TEXT(B$3,"mm/dd/yy")&" P"&B$7&" Equity" | GZ1: =Settings!$B$4&" US "&TEXT(B$3,"mm/dd/yy")&" C"&(B$7+1*B$6)&" Equity" | HQ1: =Settings!$B$4&" US "&TEXT(B$3,"mm/dd/yy")&" P"&(B$7+1*B$6)&" Equity" | IH1: =Settings!$B$4&" US "&TEXT(B$3,"mm/dd/yy")&" C"&(B$7+2*B$6)&" Equity" | IY1: =Settings!$B$4&" US "&TEXT(B$3,"mm/dd/yy")&" P"&(B$7+2*B$6)&" Equity" | JP1: =Settings!$B$4&" US "&TEXT(B$3,"mm/dd/yy")&" C"&(B$7+3*B$6)&" Equity" | KG1: =Settings!$B$4&" US "&TEXT(B$3,"mm/dd/yy")&" P"&(B$7+3*B$6)&" Equity" | KX1: =Settings!$B$4&" US "&TEXT(B$3,"mm/dd/yy")&" C"&(B$7+4*B$6)&" Equity" | LO1: =Settings!$B$4&" US "&TEXT(B$3,"mm/dd/yy")&" P"&(B$7+4*B$6)&" Equity" | MF1: =Settings!$B$4&" US "&TEXT(B$3,"mm/dd/yy")&" C"&(B$7+5*B$6)&" Equity" | MW1: =Settings!$B$4&" US "&TEXT(B$3,"mm/dd/yy")&" P"&(B$7+5*B$6)&" Equity"
A2: Underlying | B2: =Settings!$B$4&" US Equity" | D2: call -5 from ATM | U2: put -5 from ATM | AL2: call -4 from ATM | BC2: put -4 from ATM | BT2: call -3 from ATM | CK2: put -3 from ATM | DB2: call -2 from ATM | DS2: put -2 from ATM | EJ2: call -1 from ATM | FA2: put -1 from ATM | FR2: call +0 from ATM | GI2: put +0 from ATM | GZ2: call +1 from ATM | HQ2: put +1 from ATM | IH2: call +2 from ATM | IY2: put +2 from ATM | JP2: call +3 from ATM | KG2: put +3 from ATM | KX2: call +4 from ATM | LO2: put +4 from ATM | MF2: call +5 from ATM | MW2: put +5 from ATM
A3: Expiry (3rd Friday) | B3: =DATE(Settings!$B$3,B1,15)+MOD(6-WEEKDAY(DATE(Settings!$B$3,B1,15)),7) | D3: Date | E3: PX_BID | F3: PX_ASK | G3: PX_MID | H3: PX_LAST | I3: PX_SETTLE | J3: PX_VOLUME | K3: OPEN_INT | L3: IVOL_MID | M3: IVOL_BID | N3: IVOL_ASK | O3: DELTA_MID | P3: GAMMA_MID | Q3: VEGA_MID | R3: THETA_MID | S3: OPT_UNDL_PX | U3: Date | V3: PX_BID | W3: PX_ASK | X3: PX_MID | Y3: PX_LAST | Z3: PX_SETTLE | AA3: PX_VOLUME | AB3: OPEN_INT | AC3: IVOL_MID | AD3: IVOL_BID | AE3: IVOL_ASK | AF3: DELTA_MID | AG3: GAMMA_MID | AH3: VEGA_MID | AI3: THETA_MID | AJ3: OPT_UNDL_PX | AL3: Date | AM3: PX_BID | AN3: PX_ASK | AO3: PX_MID | AP3: PX_LAST | AQ3: PX_SETTLE | AR3: PX_VOLUME | AS3: OPEN_INT | AT3: IVOL_MID | AU3: IVOL_BID | AV3: IVOL_ASK | AW3: DELTA_MID | AX3: GAMMA_MID | AY3: VEGA_MID | AZ3: THETA_MID | BA3: OPT_UNDL_PX | BC3: Date | BD3: PX_BID | BE3: PX_ASK | BF3: PX_MID | BG3: PX_LAST | BH3: PX_SETTLE | BI3: PX_VOLUME | BJ3: OPEN_INT | BK3: IVOL_MID | BL3: IVOL_BID | BM3: IVOL_ASK | BN3: DELTA_MID | BO3: GAMMA_MID | BP3: VEGA_MID | BQ3: THETA_MID | BR3: OPT_UNDL_PX | BT3: Date | BU3: PX_BID | BV3: PX_ASK | BW3: PX_MID | BX3: PX_LAST | BY3: PX_SETTLE | BZ3: PX_VOLUME | CA3: OPEN_INT | CB3: IVOL_MID | CC3: IVOL_BID | CD3: IVOL_ASK | CE3: DELTA_MID | CF3: GAMMA_MID | CG3: VEGA_MID | CH3: THETA_MID | CI3: OPT_UNDL_PX | CK3: Date | CL3: PX_BID | CM3: PX_ASK | CN3: PX_MID | CO3: PX_LAST | CP3: PX_SETTLE | CQ3: PX_VOLUME | CR3: OPEN_INT | CS3: IVOL_MID | CT3: IVOL_BID | CU3: IVOL_ASK | CV3: DELTA_MID | CW3: GAMMA_MID | CX3: VEGA_MID | CY3: THETA_MID | CZ3: OPT_UNDL_PX | DB3: Date | DC3: PX_BID | DD3: PX_ASK | DE3: PX_MID | DF3: PX_LAST | DG3: PX_SETTLE | DH3: PX_VOLUME | DI3: OPEN_INT | DJ3: IVOL_MID | DK3: IVOL_BID | DL3: IVOL_ASK | DM3: DELTA_MID | DN3: GAMMA_MID | DO3: VEGA_MID | DP3: THETA_MID | DQ3: OPT_UNDL_PX | DS3: Date | DT3: PX_BID | DU3: PX_ASK | DV3: PX_MID | DW3: PX_LAST | DX3: PX_SETTLE | DY3: PX_VOLUME | DZ3: OPEN_INT | EA3: IVOL_MID | EB3: IVOL_BID | EC3: IVOL_ASK | ED3: DELTA_MID | EE3: GAMMA_MID | EF3: VEGA_MID | EG3: THETA_MID | EH3: OPT_UNDL_PX | EJ3: Date | EK3: PX_BID | EL3: PX_ASK | EM3: PX_MID | EN3: PX_LAST | EO3: PX_SETTLE | EP3: PX_VOLUME | EQ3: OPEN_INT | ER3: IVOL_MID | ES3: IVOL_BID | ET3: IVOL_ASK | EU3: DELTA_MID | EV3: GAMMA_MID | EW3: VEGA_MID | EX3: THETA_MID | EY3: OPT_UNDL_PX | FA3: Date | FB3: PX_BID | FC3: PX_ASK | FD3: PX_MID | FE3: PX_LAST | FF3: PX_SETTLE | FG3: PX_VOLUME | FH3: OPEN_INT | FI3: IVOL_MID | FJ3: IVOL_BID | FK3: IVOL_ASK | FL3: DELTA_MID | FM3: GAMMA_MID | FN3: VEGA_MID | FO3: THETA_MID | FP3: OPT_UNDL_PX | FR3: Date | FS3: PX_BID | FT3: PX_ASK | FU3: PX_MID | FV3: PX_LAST | FW3: PX_SETTLE | FX3: PX_VOLUME | FY3: OPEN_INT | FZ3: IVOL_MID | GA3: IVOL_BID | GB3: IVOL_ASK | GC3: DELTA_MID | GD3: GAMMA_MID | GE3: VEGA_MID | GF3: THETA_MID | GG3: OPT_UNDL_PX | GI3: Date | GJ3: PX_BID | GK3: PX_ASK | GL3: PX_MID | GM3: PX_LAST | GN3: PX_SETTLE | GO3: PX_VOLUME | GP3: OPEN_INT | GQ3: IVOL_MID | GR3: IVOL_BID | GS3: IVOL_ASK | GT3: DELTA_MID | GU3: GAMMA_MID | GV3: VEGA_MID | GW3: THETA_MID | GX3: OPT_UNDL_PX | GZ3: Date | HA3: PX_BID | HB3: PX_ASK | HC3: PX_MID | HD3: PX_LAST | HE3: PX_SETTLE | HF3: PX_VOLUME | HG3: OPEN_INT | HH3: IVOL_MID | HI3: IVOL_BID | HJ3: IVOL_ASK | HK3: DELTA_MID | HL3: GAMMA_MID | HM3: VEGA_MID | HN3: THETA_MID | HO3: OPT_UNDL_PX | HQ3: Date | HR3: PX_BID | HS3: PX_ASK | HT3: PX_MID | HU3: PX_LAST | HV3: PX_SETTLE | HW3: PX_VOLUME | HX3: OPEN_INT | HY3: IVOL_MID | HZ3: IVOL_BID | IA3: IVOL_ASK | IB3: DELTA_MID | IC3: GAMMA_MID | ID3: VEGA_MID | IE3: THETA_MID | IF3: OPT_UNDL_PX | IH3: Date | II3: PX_BID | IJ3: PX_ASK | IK3: PX_MID | IL3: PX_LAST | IM3: PX_SETTLE | IN3: PX_VOLUME | IO3: OPEN_INT | IP3: IVOL_MID | IQ3: IVOL_BID | IR3: IVOL_ASK | IS3: DELTA_MID | IT3: GAMMA_MID | IU3: VEGA_MID | IV3: THETA_MID | IW3: OPT_UNDL_PX | IY3: Date | IZ3: PX_BID | JA3: PX_ASK | JB3: PX_MID | JC3: PX_LAST | JD3: PX_SETTLE | JE3: PX_VOLUME | JF3: OPEN_INT | JG3: IVOL_MID | JH3: IVOL_BID | JI3: IVOL_ASK | JJ3: DELTA_MID | JK3: GAMMA_MID | JL3: VEGA_MID | JM3: THETA_MID | JN3: OPT_UNDL_PX | JP3: Date | JQ3: PX_BID | JR3: PX_ASK | JS3: PX_MID | JT3: PX_LAST | JU3: PX_SETTLE | JV3: PX_VOLUME | JW3: OPEN_INT | JX3: IVOL_MID | JY3: IVOL_BID | JZ3: IVOL_ASK | KA3: DELTA_MID | KB3: GAMMA_MID | KC3: VEGA_MID | KD3: THETA_MID | KE3: OPT_UNDL_PX | KG3: Date | KH3: PX_BID | KI3: PX_ASK | KJ3: PX_MID | KK3: PX_LAST | KL3: PX_SETTLE | KM3: PX_VOLUME | KN3: OPEN_INT | KO3: IVOL_MID | KP3: IVOL_BID | KQ3: IVOL_ASK | KR3: DELTA_MID | KS3: GAMMA_MID | KT3: VEGA_MID | KU3: THETA_MID | KV3: OPT_UNDL_PX | KX3: Date | KY3: PX_BID | KZ3: PX_ASK | LA3: PX_MID | LB3: PX_LAST | LC3: PX_SETTLE | LD3: PX_VOLUME | LE3: OPEN_INT | LF3: IVOL_MID | LG3: IVOL_BID | LH3: IVOL_ASK | LI3: DELTA_MID | LJ3: GAMMA_MID | LK3: VEGA_MID | LL3: THETA_MID | LM3: OPT_UNDL_PX | LO3: Date | LP3: PX_BID | LQ3: PX_ASK | LR3: PX_MID | LS3: PX_LAST | LT3: PX_SETTLE | LU3: PX_VOLUME | LV3: OPEN_INT | LW3: IVOL_MID | LX3: IVOL_BID | LY3: IVOL_ASK | LZ3: DELTA_MID | MA3: GAMMA_MID | MB3: VEGA_MID | MC3: THETA_MID | MD3: OPT_UNDL_PX | MF3: Date | MG3: PX_BID | MH3: PX_ASK | MI3: PX_MID | MJ3: PX_LAST | MK3: PX_SETTLE | ML3: PX_VOLUME | MM3: OPEN_INT | MN3: IVOL_MID | MO3: IVOL_BID | MP3: IVOL_ASK | MQ3: DELTA_MID | MR3: GAMMA_MID | MS3: VEGA_MID | MT3: THETA_MID | MU3: OPT_UNDL_PX | MW3: Date | MX3: PX_BID | MY3: PX_ASK | MZ3: PX_MID | NA3: PX_LAST | NB3: PX_SETTLE | NC3: PX_VOLUME | ND3: OPEN_INT | NE3: IVOL_MID | NF3: IVOL_BID | NG3: IVOL_ASK | NH3: DELTA_MID | NI3: GAMMA_MID | NJ3: VEGA_MID | NK3: THETA_MID | NL3: OPT_UNDL_PX
A4: Strike reference date | B4: =B3-45 | D4: =BDH(D$1,E$3:S$3,$B$8,$B$9,"Dir=V","Dts=S","Sort=A","Days=T","Fill=B") | U4: =BDH(U$1,V$3:AJ$3,$B$8,$B$9,"Dir=V","Dts=S","Sort=A","Days=T","Fill=B") | AL4: =BDH(AL$1,AM$3:BA$3,$B$8,$B$9,"Dir=V","Dts=S","Sort=A","Days=T","Fill=B") | BC4: =BDH(BC$1,BD$3:BR$3,$B$8,$B$9,"Dir=V","Dts=S","Sort=A","Days=T","Fill=B") | BT4: =BDH(BT$1,BU$3:CI$3,$B$8,$B$9,"Dir=V","Dts=S","Sort=A","Days=T","Fill=B") | CK4: =BDH(CK$1,CL$3:CZ$3,$B$8,$B$9,"Dir=V","Dts=S","Sort=A","Days=T","Fill=B") | DB4: =BDH(DB$1,DC$3:DQ$3,$B$8,$B$9,"Dir=V","Dts=S","Sort=A","Days=T","Fill=B") | DS4: =BDH(DS$1,DT$3:EH$3,$B$8,$B$9,"Dir=V","Dts=S","Sort=A","Days=T","Fill=B") | EJ4: =BDH(EJ$1,EK$3:EY$3,$B$8,$B$9,"Dir=V","Dts=S","Sort=A","Days=T","Fill=B") | FA4: =BDH(FA$1,FB$3:FP$3,$B$8,$B$9,"Dir=V","Dts=S","Sort=A","Days=T","Fill=B") | FR4: =BDH(FR$1,FS$3:GG$3,$B$8,$B$9,"Dir=V","Dts=S","Sort=A","Days=T","Fill=B") | GI4: =BDH(GI$1,GJ$3:GX$3,$B$8,$B$9,"Dir=V","Dts=S","Sort=A","Days=T","Fill=B") | GZ4: =BDH(GZ$1,HA$3:HO$3,$B$8,$B$9,"Dir=V","Dts=S","Sort=A","Days=T","Fill=B") | HQ4: =BDH(HQ$1,HR$3:IF$3,$B$8,$B$9,"Dir=V","Dts=S","Sort=A","Days=T","Fill=B") | IH4: =BDH(IH$1,II$3:IW$3,$B$8,$B$9,"Dir=V","Dts=S","Sort=A","Days=T","Fill=B") | IY4: =BDH(IY$1,IZ$3:JN$3,$B$8,$B$9,"Dir=V","Dts=S","Sort=A","Days=T","Fill=B") | JP4: =BDH(JP$1,JQ$3:KE$3,$B$8,$B$9,"Dir=V","Dts=S","Sort=A","Days=T","Fill=B") | KG4: =BDH(KG$1,KH$3:KV$3,$B$8,$B$9,"Dir=V","Dts=S","Sort=A","Days=T","Fill=B") | KX4: =BDH(KX$1,KY$3:LM$3,$B$8,$B$9,"Dir=V","Dts=S","Sort=A","Days=T","Fill=B") | LO4: =BDH(LO$1,LP$3:MD$3,$B$8,$B$9,"Dir=V","Dts=S","Sort=A","Days=T","Fill=B") | MF4: =BDH(MF$1,MG$3:MU$3,$B$8,$B$9,"Dir=V","Dts=S","Sort=A","Days=T","Fill=B") | MW4: =BDH(MW$1,MX$3:NL$3,$B$8,$B$9,"Dir=V","Dts=S","Sort=A","Days=T","Fill=B")
A5: Unadjusted close then | B5: =BDH(B2,"PX_LAST",B4,B4,"Days=A","Fill=P","Dts=H","CshAdjNormal=N","CshAdjAbnormal=N","CapChg=N")
A6: Strike step | B6: =IF(B5<25,0.5,IF(B5<250,1,5))
A7: ATM strike | B7: =ROUND(B5/B6,0)*B6
A8: History start | B8: =B3-100
A9: History end | B9: =B3

Sheet Apr
A1: Month | B1: 4 | D1: =Settings!$B$4&" US "&TEXT(B$3,"mm/dd/yy")&" C"&(B$7-5*B$6)&" Equity" | U1: =Settings!$B$4&" US "&TEXT(B$3,"mm/dd/yy")&" P"&(B$7-5*B$6)&" Equity" | AL1: =Settings!$B$4&" US "&TEXT(B$3,"mm/dd/yy")&" C"&(B$7-4*B$6)&" Equity" | BC1: =Settings!$B$4&" US "&TEXT(B$3,"mm/dd/yy")&" P"&(B$7-4*B$6)&" Equity" | BT1: =Settings!$B$4&" US "&TEXT(B$3,"mm/dd/yy")&" C"&(B$7-3*B$6)&" Equity" | CK1: =Settings!$B$4&" US "&TEXT(B$3,"mm/dd/yy")&" P"&(B$7-3*B$6)&" Equity" | DB1: =Settings!$B$4&" US "&TEXT(B$3,"mm/dd/yy")&" C"&(B$7-2*B$6)&" Equity" | DS1: =Settings!$B$4&" US "&TEXT(B$3,"mm/dd/yy")&" P"&(B$7-2*B$6)&" Equity" | EJ1: =Settings!$B$4&" US "&TEXT(B$3,"mm/dd/yy")&" C"&(B$7-1*B$6)&" Equity" | FA1: =Settings!$B$4&" US "&TEXT(B$3,"mm/dd/yy")&" P"&(B$7-1*B$6)&" Equity" | FR1: =Settings!$B$4&" US "&TEXT(B$3,"mm/dd/yy")&" C"&B$7&" Equity" | GI1: =Settings!$B$4&" US "&TEXT(B$3,"mm/dd/yy")&" P"&B$7&" Equity" | GZ1: =Settings!$B$4&" US "&TEXT(B$3,"mm/dd/yy")&" C"&(B$7+1*B$6)&" Equity" | HQ1: =Settings!$B$4&" US "&TEXT(B$3,"mm/dd/yy")&" P"&(B$7+1*B$6)&" Equity" | IH1: =Settings!$B$4&" US "&TEXT(B$3,"mm/dd/yy")&" C"&(B$7+2*B$6)&" Equity" | IY1: =Settings!$B$4&" US "&TEXT(B$3,"mm/dd/yy")&" P"&(B$7+2*B$6)&" Equity" | JP1: =Settings!$B$4&" US "&TEXT(B$3,"mm/dd/yy")&" C"&(B$7+3*B$6)&" Equity" | KG1: =Settings!$B$4&" US "&TEXT(B$3,"mm/dd/yy")&" P"&(B$7+3*B$6)&" Equity" | KX1: =Settings!$B$4&" US "&TEXT(B$3,"mm/dd/yy")&" C"&(B$7+4*B$6)&" Equity" | LO1: =Settings!$B$4&" US "&TEXT(B$3,"mm/dd/yy")&" P"&(B$7+4*B$6)&" Equity" | MF1: =Settings!$B$4&" US "&TEXT(B$3,"mm/dd/yy")&" C"&(B$7+5*B$6)&" Equity" | MW1: =Settings!$B$4&" US "&TEXT(B$3,"mm/dd/yy")&" P"&(B$7+5*B$6)&" Equity"
A2: Underlying | B2: =Settings!$B$4&" US Equity" | D2: call -5 from ATM | U2: put -5 from ATM | AL2: call -4 from ATM | BC2: put -4 from ATM | BT2: call -3 from ATM | CK2: put -3 from ATM | DB2: call -2 from ATM | DS2: put -2 from ATM | EJ2: call -1 from ATM | FA2: put -1 from ATM | FR2: call +0 from ATM | GI2: put +0 from ATM | GZ2: call +1 from ATM | HQ2: put +1 from ATM | IH2: call +2 from ATM | IY2: put +2 from ATM | JP2: call +3 from ATM | KG2: put +3 from ATM | KX2: call +4 from ATM | LO2: put +4 from ATM | MF2: call +5 from ATM | MW2: put +5 from ATM
A3: Expiry (3rd Friday) | B3: =DATE(Settings!$B$3,B1,15)+MOD(6-WEEKDAY(DATE(Settings!$B$3,B1,15)),7) | D3: Date | E3: PX_BID | F3: PX_ASK | G3: PX_MID | H3: PX_LAST | I3: PX_SETTLE | J3: PX_VOLUME | K3: OPEN_INT | L3: IVOL_MID | M3: IVOL_BID | N3: IVOL_ASK | O3: DELTA_MID | P3: GAMMA_MID | Q3: VEGA_MID | R3: THETA_MID | S3: OPT_UNDL_PX | U3: Date | V3: PX_BID | W3: PX_ASK | X3: PX_MID | Y3: PX_LAST | Z3: PX_SETTLE | AA3: PX_VOLUME | AB3: OPEN_INT | AC3: IVOL_MID | AD3: IVOL_BID | AE3: IVOL_ASK | AF3: DELTA_MID | AG3: GAMMA_MID | AH3: VEGA_MID | AI3: THETA_MID | AJ3: OPT_UNDL_PX | AL3: Date | AM3: PX_BID | AN3: PX_ASK | AO3: PX_MID | AP3: PX_LAST | AQ3: PX_SETTLE | AR3: PX_VOLUME | AS3: OPEN_INT | AT3: IVOL_MID | AU3: IVOL_BID | AV3: IVOL_ASK | AW3: DELTA_MID | AX3: GAMMA_MID | AY3: VEGA_MID | AZ3: THETA_MID | BA3: OPT_UNDL_PX | BC3: Date | BD3: PX_BID | BE3: PX_ASK | BF3: PX_MID | BG3: PX_LAST | BH3: PX_SETTLE | BI3: PX_VOLUME | BJ3: OPEN_INT | BK3: IVOL_MID | BL3: IVOL_BID | BM3: IVOL_ASK | BN3: DELTA_MID | BO3: GAMMA_MID | BP3: VEGA_MID | BQ3: THETA_MID | BR3: OPT_UNDL_PX | BT3: Date | BU3: PX_BID | BV3: PX_ASK | BW3: PX_MID | BX3: PX_LAST | BY3: PX_SETTLE | BZ3: PX_VOLUME | CA3: OPEN_INT | CB3: IVOL_MID | CC3: IVOL_BID | CD3: IVOL_ASK | CE3: DELTA_MID | CF3: GAMMA_MID | CG3: VEGA_MID | CH3: THETA_MID | CI3: OPT_UNDL_PX | CK3: Date | CL3: PX_BID | CM3: PX_ASK | CN3: PX_MID | CO3: PX_LAST | CP3: PX_SETTLE | CQ3: PX_VOLUME | CR3: OPEN_INT | CS3: IVOL_MID | CT3: IVOL_BID | CU3: IVOL_ASK | CV3: DELTA_MID | CW3: GAMMA_MID | CX3: VEGA_MID | CY3: THETA_MID | CZ3: OPT_UNDL_PX | DB3: Date | DC3: PX_BID | DD3: PX_ASK | DE3: PX_MID | DF3: PX_LAST | DG3: PX_SETTLE | DH3: PX_VOLUME | DI3: OPEN_INT | DJ3: IVOL_MID | DK3: IVOL_BID | DL3: IVOL_ASK | DM3: DELTA_MID | DN3: GAMMA_MID | DO3: VEGA_MID | DP3: THETA_MID | DQ3: OPT_UNDL_PX | DS3: Date | DT3: PX_BID | DU3: PX_ASK | DV3: PX_MID | DW3: PX_LAST | DX3: PX_SETTLE | DY3: PX_VOLUME | DZ3: OPEN_INT | EA3: IVOL_MID | EB3: IVOL_BID | EC3: IVOL_ASK | ED3: DELTA_MID | EE3: GAMMA_MID | EF3: VEGA_MID | EG3: THETA_MID | EH3: OPT_UNDL_PX | EJ3: Date | EK3: PX_BID | EL3: PX_ASK | EM3: PX_MID | EN3: PX_LAST | EO3: PX_SETTLE | EP3: PX_VOLUME | EQ3: OPEN_INT | ER3: IVOL_MID | ES3: IVOL_BID | ET3: IVOL_ASK | EU3: DELTA_MID | EV3: GAMMA_MID | EW3: VEGA_MID | EX3: THETA_MID | EY3: OPT_UNDL_PX | FA3: Date | FB3: PX_BID | FC3: PX_ASK | FD3: PX_MID | FE3: PX_LAST | FF3: PX_SETTLE | FG3: PX_VOLUME | FH3: OPEN_INT | FI3: IVOL_MID | FJ3: IVOL_BID | FK3: IVOL_ASK | FL3: DELTA_MID | FM3: GAMMA_MID | FN3: VEGA_MID | FO3: THETA_MID | FP3: OPT_UNDL_PX | FR3: Date | FS3: PX_BID | FT3: PX_ASK | FU3: PX_MID | FV3: PX_LAST | FW3: PX_SETTLE | FX3: PX_VOLUME | FY3: OPEN_INT | FZ3: IVOL_MID | GA3: IVOL_BID | GB3: IVOL_ASK | GC3: DELTA_MID | GD3: GAMMA_MID | GE3: VEGA_MID | GF3: THETA_MID | GG3: OPT_UNDL_PX | GI3: Date | GJ3: PX_BID | GK3: PX_ASK | GL3: PX_MID | GM3: PX_LAST | GN3: PX_SETTLE | GO3: PX_VOLUME | GP3: OPEN_INT | GQ3: IVOL_MID | GR3: IVOL_BID | GS3: IVOL_ASK | GT3: DELTA_MID | GU3: GAMMA_MID | GV3: VEGA_MID | GW3: THETA_MID | GX3: OPT_UNDL_PX | GZ3: Date | HA3: PX_BID | HB3: PX_ASK | HC3: PX_MID | HD3: PX_LAST | HE3: PX_SETTLE | HF3: PX_VOLUME | HG3: OPEN_INT | HH3: IVOL_MID | HI3: IVOL_BID | HJ3: IVOL_ASK | HK3: DELTA_MID | HL3: GAMMA_MID | HM3: VEGA_MID | HN3: THETA_MID | HO3: OPT_UNDL_PX | HQ3: Date | HR3: PX_BID | HS3: PX_ASK | HT3: PX_MID | HU3: PX_LAST | HV3: PX_SETTLE | HW3: PX_VOLUME | HX3: OPEN_INT | HY3: IVOL_MID | HZ3: IVOL_BID | IA3: IVOL_ASK | IB3: DELTA_MID | IC3: GAMMA_MID | ID3: VEGA_MID | IE3: THETA_MID | IF3: OPT_UNDL_PX | IH3: Date | II3: PX_BID | IJ3: PX_ASK | IK3: PX_MID | IL3: PX_LAST | IM3: PX_SETTLE | IN3: PX_VOLUME | IO3: OPEN_INT | IP3: IVOL_MID | IQ3: IVOL_BID | IR3: IVOL_ASK | IS3: DELTA_MID | IT3: GAMMA_MID | IU3: VEGA_MID | IV3: THETA_MID | IW3: OPT_UNDL_PX | IY3: Date | IZ3: PX_BID | JA3: PX_ASK | JB3: PX_MID | JC3: PX_LAST | JD3: PX_SETTLE | JE3: PX_VOLUME | JF3: OPEN_INT | JG3: IVOL_MID | JH3: IVOL_BID | JI3: IVOL_ASK | JJ3: DELTA_MID | JK3: GAMMA_MID | JL3: VEGA_MID | JM3: THETA_MID | JN3: OPT_UNDL_PX | JP3: Date | JQ3: PX_BID | JR3: PX_ASK | JS3: PX_MID | JT3: PX_LAST | JU3: PX_SETTLE | JV3: PX_VOLUME | JW3: OPEN_INT | JX3: IVOL_MID | JY3: IVOL_BID | JZ3: IVOL_ASK | KA3: DELTA_MID | KB3: GAMMA_MID | KC3: VEGA_MID | KD3: THETA_MID | KE3: OPT_UNDL_PX | KG3: Date | KH3: PX_BID | KI3: PX_ASK | KJ3: PX_MID | KK3: PX_LAST | KL3: PX_SETTLE | KM3: PX_VOLUME | KN3: OPEN_INT | KO3: IVOL_MID | KP3: IVOL_BID | KQ3: IVOL_ASK | KR3: DELTA_MID | KS3: GAMMA_MID | KT3: VEGA_MID | KU3: THETA_MID | KV3: OPT_UNDL_PX | KX3: Date | KY3: PX_BID | KZ3: PX_ASK | LA3: PX_MID | LB3: PX_LAST | LC3: PX_SETTLE | LD3: PX_VOLUME | LE3: OPEN_INT | LF3: IVOL_MID | LG3: IVOL_BID | LH3: IVOL_ASK | LI3: DELTA_MID | LJ3: GAMMA_MID | LK3: VEGA_MID | LL3: THETA_MID | LM3: OPT_UNDL_PX | LO3: Date | LP3: PX_BID | LQ3: PX_ASK | LR3: PX_MID | LS3: PX_LAST | LT3: PX_SETTLE | LU3: PX_VOLUME | LV3: OPEN_INT | LW3: IVOL_MID | LX3: IVOL_BID | LY3: IVOL_ASK | LZ3: DELTA_MID | MA3: GAMMA_MID | MB3: VEGA_MID | MC3: THETA_MID | MD3: OPT_UNDL_PX | MF3: Date | MG3: PX_BID | MH3: PX_ASK | MI3: PX_MID | MJ3: PX_LAST | MK3: PX_SETTLE | ML3: PX_VOLUME | MM3: OPEN_INT | MN3: IVOL_MID | MO3: IVOL_BID | MP3: IVOL_ASK | MQ3: DELTA_MID | MR3: GAMMA_MID | MS3: VEGA_MID | MT3: THETA_MID | MU3: OPT_UNDL_PX | MW3: Date | MX3: PX_BID | MY3: PX_ASK | MZ3: PX_MID | NA3: PX_LAST | NB3: PX_SETTLE | NC3: PX_VOLUME | ND3: OPEN_INT | NE3: IVOL_MID | NF3: IVOL_BID | NG3: IVOL_ASK | NH3: DELTA_MID | NI3: GAMMA_MID | NJ3: VEGA_MID | NK3: THETA_MID | NL3: OPT_UNDL_PX
A4: Strike reference date | B4: =B3-45 | D4: =BDH(D$1,E$3:S$3,$B$8,$B$9,"Dir=V","Dts=S","Sort=A","Days=T","Fill=B") | U4: =BDH(U$1,V$3:AJ$3,$B$8,$B$9,"Dir=V","Dts=S","Sort=A","Days=T","Fill=B") | AL4: =BDH(AL$1,AM$3:BA$3,$B$8,$B$9,"Dir=V","Dts=S","Sort=A","Days=T","Fill=B") | BC4: =BDH(BC$1,BD$3:BR$3,$B$8,$B$9,"Dir=V","Dts=S","Sort=A","Days=T","Fill=B") | BT4: =BDH(BT$1,BU$3:CI$3,$B$8,$B$9,"Dir=V","Dts=S","Sort=A","Days=T","Fill=B") | CK4: =BDH(CK$1,CL$3:CZ$3,$B$8,$B$9,"Dir=V","Dts=S","Sort=A","Days=T","Fill=B") | DB4: =BDH(DB$1,DC$3:DQ$3,$B$8,$B$9,"Dir=V","Dts=S","Sort=A","Days=T","Fill=B") | DS4: =BDH(DS$1,DT$3:EH$3,$B$8,$B$9,"Dir=V","Dts=S","Sort=A","Days=T","Fill=B") | EJ4: =BDH(EJ$1,EK$3:EY$3,$B$8,$B$9,"Dir=V","Dts=S","Sort=A","Days=T","Fill=B") | FA4: =BDH(FA$1,FB$3:FP$3,$B$8,$B$9,"Dir=V","Dts=S","Sort=A","Days=T","Fill=B") | FR4: =BDH(FR$1,FS$3:GG$3,$B$8,$B$9,"Dir=V","Dts=S","Sort=A","Days=T","Fill=B") | GI4: =BDH(GI$1,GJ$3:GX$3,$B$8,$B$9,"Dir=V","Dts=S","Sort=A","Days=T","Fill=B") | GZ4: =BDH(GZ$1,HA$3:HO$3,$B$8,$B$9,"Dir=V","Dts=S","Sort=A","Days=T","Fill=B") | HQ4: =BDH(HQ$1,HR$3:IF$3,$B$8,$B$9,"Dir=V","Dts=S","Sort=A","Days=T","Fill=B") | IH4: =BDH(IH$1,II$3:IW$3,$B$8,$B$9,"Dir=V","Dts=S","Sort=A","Days=T","Fill=B") | IY4: =BDH(IY$1,IZ$3:JN$3,$B$8,$B$9,"Dir=V","Dts=S","Sort=A","Days=T","Fill=B") | JP4: =BDH(JP$1,JQ$3:KE$3,$B$8,$B$9,"Dir=V","Dts=S","Sort=A","Days=T","Fill=B") | KG4: =BDH(KG$1,KH$3:KV$3,$B$8,$B$9,"Dir=V","Dts=S","Sort=A","Days=T","Fill=B") | KX4: =BDH(KX$1,KY$3:LM$3,$B$8,$B$9,"Dir=V","Dts=S","Sort=A","Days=T","Fill=B") | LO4: =BDH(LO$1,LP$3:MD$3,$B$8,$B$9,"Dir=V","Dts=S","Sort=A","Days=T","Fill=B") | MF4: =BDH(MF$1,MG$3:MU$3,$B$8,$B$9,"Dir=V","Dts=S","Sort=A","Days=T","Fill=B") | MW4: =BDH(MW$1,MX$3:NL$3,$B$8,$B$9,"Dir=V","Dts=S","Sort=A","Days=T","Fill=B")
A5: Unadjusted close then | B5: =BDH(B2,"PX_LAST",B4,B4,"Days=A","Fill=P","Dts=H","CshAdjNormal=N","CshAdjAbnormal=N","CapChg=N")
A6: Strike step | B6: =IF(B5<25,0.5,IF(B5<250,1,5))
A7: ATM strike | B7: =ROUND(B5/B6,0)*B6
A8: History start | B8: =B3-100
A9: History end | B9: =B3

Sheet May
A1: Month | B1: 5 | D1: =Settings!$B$4&" US "&TEXT(B$3,"mm/dd/yy")&" C"&(B$7-5*B$6)&" Equity" | U1: =Settings!$B$4&" US "&TEXT(B$3,"mm/dd/yy")&" P"&(B$7-5*B$6)&" Equity" | AL1: =Settings!$B$4&" US "&TEXT(B$3,"mm/dd/yy")&" C"&(B$7-4*B$6)&" Equity" | BC1: =Settings!$B$4&" US "&TEXT(B$3,"mm/dd/yy")&" P"&(B$7-4*B$6)&" Equity" | BT1: =Settings!$B$4&" US "&TEXT(B$3,"mm/dd/yy")&" C"&(B$7-3*B$6)&" Equity" | CK1: =Settings!$B$4&" US "&TEXT(B$3,"mm/dd/yy")&" P"&(B$7-3*B$6)&" Equity" | DB1: =Settings!$B$4&" US "&TEXT(B$3,"mm/dd/yy")&" C"&(B$7-2*B$6)&" Equity" | DS1: =Settings!$B$4&" US "&TEXT(B$3,"mm/dd/yy")&" P"&(B$7-2*B$6)&" Equity" | EJ1: =Settings!$B$4&" US "&TEXT(B$3,"mm/dd/yy")&" C"&(B$7-1*B$6)&" Equity" | FA1: =Settings!$B$4&" US "&TEXT(B$3,"mm/dd/yy")&" P"&(B$7-1*B$6)&" Equity" | FR1: =Settings!$B$4&" US "&TEXT(B$3,"mm/dd/yy")&" C"&B$7&" Equity" | GI1: =Settings!$B$4&" US "&TEXT(B$3,"mm/dd/yy")&" P"&B$7&" Equity" | GZ1: =Settings!$B$4&" US "&TEXT(B$3,"mm/dd/yy")&" C"&(B$7+1*B$6)&" Equity" | HQ1: =Settings!$B$4&" US "&TEXT(B$3,"mm/dd/yy")&" P"&(B$7+1*B$6)&" Equity" | IH1: =Settings!$B$4&" US "&TEXT(B$3,"mm/dd/yy")&" C"&(B$7+2*B$6)&" Equity" | IY1: =Settings!$B$4&" US "&TEXT(B$3,"mm/dd/yy")&" P"&(B$7+2*B$6)&" Equity" | JP1: =Settings!$B$4&" US "&TEXT(B$3,"mm/dd/yy")&" C"&(B$7+3*B$6)&" Equity" | KG1: =Settings!$B$4&" US "&TEXT(B$3,"mm/dd/yy")&" P"&(B$7+3*B$6)&" Equity" | KX1: =Settings!$B$4&" US "&TEXT(B$3,"mm/dd/yy")&" C"&(B$7+4*B$6)&" Equity" | LO1: =Settings!$B$4&" US "&TEXT(B$3,"mm/dd/yy")&" P"&(B$7+4*B$6)&" Equity" | MF1: =Settings!$B$4&" US "&TEXT(B$3,"mm/dd/yy")&" C"&(B$7+5*B$6)&" Equity" | MW1: =Settings!$B$4&" US "&TEXT(B$3,"mm/dd/yy")&" P"&(B$7+5*B$6)&" Equity"
A2: Underlying | B2: =Settings!$B$4&" US Equity" | D2: call -5 from ATM | U2: put -5 from ATM | AL2: call -4 from ATM | BC2: put -4 from ATM | BT2: call -3 from ATM | CK2: put -3 from ATM | DB2: call -2 from ATM | DS2: put -2 from ATM | EJ2: call -1 from ATM | FA2: put -1 from ATM | FR2: call +0 from ATM | GI2: put +0 from ATM | GZ2: call +1 from ATM | HQ2: put +1 from ATM | IH2: call +2 from ATM | IY2: put +2 from ATM | JP2: call +3 from ATM | KG2: put +3 from ATM | KX2: call +4 from ATM | LO2: put +4 from ATM | MF2: call +5 from ATM | MW2: put +5 from ATM
A3: Expiry (3rd Friday) | B3: =DATE(Settings!$B$3,B1,15)+MOD(6-WEEKDAY(DATE(Settings!$B$3,B1,15)),7) | D3: Date | E3: PX_BID | F3: PX_ASK | G3: PX_MID | H3: PX_LAST | I3: PX_SETTLE | J3: PX_VOLUME | K3: OPEN_INT | L3: IVOL_MID | M3: IVOL_BID | N3: IVOL_ASK | O3: DELTA_MID | P3: GAMMA_MID | Q3: VEGA_MID | R3: THETA_MID | S3: OPT_UNDL_PX | U3: Date | V3: PX_BID | W3: PX_ASK | X3: PX_MID | Y3: PX_LAST | Z3: PX_SETTLE | AA3: PX_VOLUME | AB3: OPEN_INT | AC3: IVOL_MID | AD3: IVOL_BID | AE3: IVOL_ASK | AF3: DELTA_MID | AG3: GAMMA_MID | AH3: VEGA_MID | AI3: THETA_MID | AJ3: OPT_UNDL_PX | AL3: Date | AM3: PX_BID | AN3: PX_ASK | AO3: PX_MID | AP3: PX_LAST | AQ3: PX_SETTLE | AR3: PX_VOLUME | AS3: OPEN_INT | AT3: IVOL_MID | AU3: IVOL_BID | AV3: IVOL_ASK | AW3: DELTA_MID | AX3: GAMMA_MID | AY3: VEGA_MID | AZ3: THETA_MID | BA3: OPT_UNDL_PX | BC3: Date | BD3: PX_BID | BE3: PX_ASK | BF3: PX_MID | BG3: PX_LAST | BH3: PX_SETTLE | BI3: PX_VOLUME | BJ3: OPEN_INT | BK3: IVOL_MID | BL3: IVOL_BID | BM3: IVOL_ASK | BN3: DELTA_MID | BO3: GAMMA_MID | BP3: VEGA_MID | BQ3: THETA_MID | BR3: OPT_UNDL_PX | BT3: Date | BU3: PX_BID | BV3: PX_ASK | BW3: PX_MID | BX3: PX_LAST | BY3: PX_SETTLE | BZ3: PX_VOLUME | CA3: OPEN_INT | CB3: IVOL_MID | CC3: IVOL_BID | CD3: IVOL_ASK | CE3: DELTA_MID | CF3: GAMMA_MID | CG3: VEGA_MID | CH3: THETA_MID | CI3: OPT_UNDL_PX | CK3: Date | CL3: PX_BID | CM3: PX_ASK | CN3: PX_MID | CO3: PX_LAST | CP3: PX_SETTLE | CQ3: PX_VOLUME | CR3: OPEN_INT | CS3: IVOL_MID | CT3: IVOL_BID | CU3: IVOL_ASK | CV3: DELTA_MID | CW3: GAMMA_MID | CX3: VEGA_MID | CY3: THETA_MID | CZ3: OPT_UNDL_PX | DB3: Date | DC3: PX_BID | DD3: PX_ASK | DE3: PX_MID | DF3: PX_LAST | DG3: PX_SETTLE | DH3: PX_VOLUME | DI3: OPEN_INT | DJ3: IVOL_MID | DK3: IVOL_BID | DL3: IVOL_ASK | DM3: DELTA_MID | DN3: GAMMA_MID | DO3: VEGA_MID | DP3: THETA_MID | DQ3: OPT_UNDL_PX | DS3: Date | DT3: PX_BID | DU3: PX_ASK | DV3: PX_MID | DW3: PX_LAST | DX3: PX_SETTLE | DY3: PX_VOLUME | DZ3: OPEN_INT | EA3: IVOL_MID | EB3: IVOL_BID | EC3: IVOL_ASK | ED3: DELTA_MID | EE3: GAMMA_MID | EF3: VEGA_MID | EG3: THETA_MID | EH3: OPT_UNDL_PX | EJ3: Date | EK3: PX_BID | EL3: PX_ASK | EM3: PX_MID | EN3: PX_LAST | EO3: PX_SETTLE | EP3: PX_VOLUME | EQ3: OPEN_INT | ER3: IVOL_MID | ES3: IVOL_BID | ET3: IVOL_ASK | EU3: DELTA_MID | EV3: GAMMA_MID | EW3: VEGA_MID | EX3: THETA_MID | EY3: OPT_UNDL_PX | FA3: Date | FB3: PX_BID | FC3: PX_ASK | FD3: PX_MID | FE3: PX_LAST | FF3: PX_SETTLE | FG3: PX_VOLUME | FH3: OPEN_INT | FI3: IVOL_MID | FJ3: IVOL_BID | FK3: IVOL_ASK | FL3: DELTA_MID | FM3: GAMMA_MID | FN3: VEGA_MID | FO3: THETA_MID | FP3: OPT_UNDL_PX | FR3: Date | FS3: PX_BID | FT3: PX_ASK | FU3: PX_MID | FV3: PX_LAST | FW3: PX_SETTLE | FX3: PX_VOLUME | FY3: OPEN_INT | FZ3: IVOL_MID | GA3: IVOL_BID | GB3: IVOL_ASK | GC3: DELTA_MID | GD3: GAMMA_MID | GE3: VEGA_MID | GF3: THETA_MID | GG3: OPT_UNDL_PX | GI3: Date | GJ3: PX_BID | GK3: PX_ASK | GL3: PX_MID | GM3: PX_LAST | GN3: PX_SETTLE | GO3: PX_VOLUME | GP3: OPEN_INT | GQ3: IVOL_MID | GR3: IVOL_BID | GS3: IVOL_ASK | GT3: DELTA_MID | GU3: GAMMA_MID | GV3: VEGA_MID | GW3: THETA_MID | GX3: OPT_UNDL_PX | GZ3: Date | HA3: PX_BID | HB3: PX_ASK | HC3: PX_MID | HD3: PX_LAST | HE3: PX_SETTLE | HF3: PX_VOLUME | HG3: OPEN_INT | HH3: IVOL_MID | HI3: IVOL_BID | HJ3: IVOL_ASK | HK3: DELTA_MID | HL3: GAMMA_MID | HM3: VEGA_MID | HN3: THETA_MID | HO3: OPT_UNDL_PX | HQ3: Date | HR3: PX_BID | HS3: PX_ASK | HT3: PX_MID | HU3: PX_LAST | HV3: PX_SETTLE | HW3: PX_VOLUME | HX3: OPEN_INT | HY3: IVOL_MID | HZ3: IVOL_BID | IA3: IVOL_ASK | IB3: DELTA_MID | IC3: GAMMA_MID | ID3: VEGA_MID | IE3: THETA_MID | IF3: OPT_UNDL_PX | IH3: Date | II3: PX_BID | IJ3: PX_ASK | IK3: PX_MID | IL3: PX_LAST | IM3: PX_SETTLE | IN3: PX_VOLUME | IO3: OPEN_INT | IP3: IVOL_MID | IQ3: IVOL_BID | IR3: IVOL_ASK | IS3: DELTA_MID | IT3: GAMMA_MID | IU3: VEGA_MID | IV3: THETA_MID | IW3: OPT_UNDL_PX | IY3: Date | IZ3: PX_BID | JA3: PX_ASK | JB3: PX_MID | JC3: PX_LAST | JD3: PX_SETTLE | JE3: PX_VOLUME | JF3: OPEN_INT | JG3: IVOL_MID | JH3: IVOL_BID | JI3: IVOL_ASK | JJ3: DELTA_MID | JK3: GAMMA_MID | JL3: VEGA_MID | JM3: THETA_MID | JN3: OPT_UNDL_PX | JP3: Date | JQ3: PX_BID | JR3: PX_ASK | JS3: PX_MID | JT3: PX_LAST | JU3: PX_SETTLE | JV3: PX_VOLUME | JW3: OPEN_INT | JX3: IVOL_MID | JY3: IVOL_BID | JZ3: IVOL_ASK | KA3: DELTA_MID | KB3: GAMMA_MID | KC3: VEGA_MID | KD3: THETA_MID | KE3: OPT_UNDL_PX | KG3: Date | KH3: PX_BID | KI3: PX_ASK | KJ3: PX_MID | KK3: PX_LAST | KL3: PX_SETTLE | KM3: PX_VOLUME | KN3: OPEN_INT | KO3: IVOL_MID | KP3: IVOL_BID | KQ3: IVOL_ASK | KR3: DELTA_MID | KS3: GAMMA_MID | KT3: VEGA_MID | KU3: THETA_MID | KV3: OPT_UNDL_PX | KX3: Date | KY3: PX_BID | KZ3: PX_ASK | LA3: PX_MID | LB3: PX_LAST | LC3: PX_SETTLE | LD3: PX_VOLUME | LE3: OPEN_INT | LF3: IVOL_MID | LG3: IVOL_BID | LH3: IVOL_ASK | LI3: DELTA_MID | LJ3: GAMMA_MID | LK3: VEGA_MID | LL3: THETA_MID | LM3: OPT_UNDL_PX | LO3: Date | LP3: PX_BID | LQ3: PX_ASK | LR3: PX_MID | LS3: PX_LAST | LT3: PX_SETTLE | LU3: PX_VOLUME | LV3: OPEN_INT | LW3: IVOL_MID | LX3: IVOL_BID | LY3: IVOL_ASK | LZ3: DELTA_MID | MA3: GAMMA_MID | MB3: VEGA_MID | MC3: THETA_MID | MD3: OPT_UNDL_PX | MF3: Date | MG3: PX_BID | MH3: PX_ASK | MI3: PX_MID | MJ3: PX_LAST | MK3: PX_SETTLE | ML3: PX_VOLUME | MM3: OPEN_INT | MN3: IVOL_MID | MO3: IVOL_BID | MP3: IVOL_ASK | MQ3: DELTA_MID | MR3: GAMMA_MID | MS3: VEGA_MID | MT3: THETA_MID | MU3: OPT_UNDL_PX | MW3: Date | MX3: PX_BID | MY3: PX_ASK | MZ3: PX_MID | NA3: PX_LAST | NB3: PX_SETTLE | NC3: PX_VOLUME | ND3: OPEN_INT | NE3: IVOL_MID | NF3: IVOL_BID | NG3: IVOL_ASK | NH3: DELTA_MID | NI3: GAMMA_MID | NJ3: VEGA_MID | NK3: THETA_MID | NL3: OPT_UNDL_PX
A4: Strike reference date | B4: =B3-45 | D4: =BDH(D$1,E$3:S$3,$B$8,$B$9,"Dir=V","Dts=S","Sort=A","Days=T","Fill=B") | U4: =BDH(U$1,V$3:AJ$3,$B$8,$B$9,"Dir=V","Dts=S","Sort=A","Days=T","Fill=B") | AL4: =BDH(AL$1,AM$3:BA$3,$B$8,$B$9,"Dir=V","Dts=S","Sort=A","Days=T","Fill=B") | BC4: =BDH(BC$1,BD$3:BR$3,$B$8,$B$9,"Dir=V","Dts=S","Sort=A","Days=T","Fill=B") | BT4: =BDH(BT$1,BU$3:CI$3,$B$8,$B$9,"Dir=V","Dts=S","Sort=A","Days=T","Fill=B") | CK4: =BDH(CK$1,CL$3:CZ$3,$B$8,$B$9,"Dir=V","Dts=S","Sort=A","Days=T","Fill=B") | DB4: =BDH(DB$1,DC$3:DQ$3,$B$8,$B$9,"Dir=V","Dts=S","Sort=A","Days=T","Fill=B") | DS4: =BDH(DS$1,DT$3:EH$3,$B$8,$B$9,"Dir=V","Dts=S","Sort=A","Days=T","Fill=B") | EJ4: =BDH(EJ$1,EK$3:EY$3,$B$8,$B$9,"Dir=V","Dts=S","Sort=A","Days=T","Fill=B") | FA4: =BDH(FA$1,FB$3:FP$3,$B$8,$B$9,"Dir=V","Dts=S","Sort=A","Days=T","Fill=B") | FR4: =BDH(FR$1,FS$3:GG$3,$B$8,$B$9,"Dir=V","Dts=S","Sort=A","Days=T","Fill=B") | GI4: =BDH(GI$1,GJ$3:GX$3,$B$8,$B$9,"Dir=V","Dts=S","Sort=A","Days=T","Fill=B") | GZ4: =BDH(GZ$1,HA$3:HO$3,$B$8,$B$9,"Dir=V","Dts=S","Sort=A","Days=T","Fill=B") | HQ4: =BDH(HQ$1,HR$3:IF$3,$B$8,$B$9,"Dir=V","Dts=S","Sort=A","Days=T","Fill=B") | IH4: =BDH(IH$1,II$3:IW$3,$B$8,$B$9,"Dir=V","Dts=S","Sort=A","Days=T","Fill=B") | IY4: =BDH(IY$1,IZ$3:JN$3,$B$8,$B$9,"Dir=V","Dts=S","Sort=A","Days=T","Fill=B") | JP4: =BDH(JP$1,JQ$3:KE$3,$B$8,$B$9,"Dir=V","Dts=S","Sort=A","Days=T","Fill=B") | KG4: =BDH(KG$1,KH$3:KV$3,$B$8,$B$9,"Dir=V","Dts=S","Sort=A","Days=T","Fill=B") | KX4: =BDH(KX$1,KY$3:LM$3,$B$8,$B$9,"Dir=V","Dts=S","Sort=A","Days=T","Fill=B") | LO4: =BDH(LO$1,LP$3:MD$3,$B$8,$B$9,"Dir=V","Dts=S","Sort=A","Days=T","Fill=B") | MF4: =BDH(MF$1,MG$3:MU$3,$B$8,$B$9,"Dir=V","Dts=S","Sort=A","Days=T","Fill=B") | MW4: =BDH(MW$1,MX$3:NL$3,$B$8,$B$9,"Dir=V","Dts=S","Sort=A","Days=T","Fill=B")
A5: Unadjusted close then | B5: =BDH(B2,"PX_LAST",B4,B4,"Days=A","Fill=P","Dts=H","CshAdjNormal=N","CshAdjAbnormal=N","CapChg=N")
A6: Strike step | B6: =IF(B5<25,0.5,IF(B5<250,1,5))
A7: ATM strike | B7: =ROUND(B5/B6,0)*B6
A8: History start | B8: =B3-100
A9: History end | B9: =B3

Sheet Jun
A1: Month | B1: 6 | D1: =Settings!$B$4&" US "&TEXT(B$3,"mm/dd/yy")&" C"&(B$7-5*B$6)&" Equity" | U1: =Settings!$B$4&" US "&TEXT(B$3,"mm/dd/yy")&" P"&(B$7-5*B$6)&" Equity" | AL1: =Settings!$B$4&" US "&TEXT(B$3,"mm/dd/yy")&" C"&(B$7-4*B$6)&" Equity" | BC1: =Settings!$B$4&" US "&TEXT(B$3,"mm/dd/yy")&" P"&(B$7-4*B$6)&" Equity" | BT1: =Settings!$B$4&" US "&TEXT(B$3,"mm/dd/yy")&" C"&(B$7-3*B$6)&" Equity" | CK1: =Settings!$B$4&" US "&TEXT(B$3,"mm/dd/yy")&" P"&(B$7-3*B$6)&" Equity" | DB1: =Settings!$B$4&" US "&TEXT(B$3,"mm/dd/yy")&" C"&(B$7-2*B$6)&" Equity" | DS1: =Settings!$B$4&" US "&TEXT(B$3,"mm/dd/yy")&" P"&(B$7-2*B$6)&" Equity" | EJ1: =Settings!$B$4&" US "&TEXT(B$3,"mm/dd/yy")&" C"&(B$7-1*B$6)&" Equity" | FA1: =Settings!$B$4&" US "&TEXT(B$3,"mm/dd/yy")&" P"&(B$7-1*B$6)&" Equity" | FR1: =Settings!$B$4&" US "&TEXT(B$3,"mm/dd/yy")&" C"&B$7&" Equity" | GI1: =Settings!$B$4&" US "&TEXT(B$3,"mm/dd/yy")&" P"&B$7&" Equity" | GZ1: =Settings!$B$4&" US "&TEXT(B$3,"mm/dd/yy")&" C"&(B$7+1*B$6)&" Equity" | HQ1: =Settings!$B$4&" US "&TEXT(B$3,"mm/dd/yy")&" P"&(B$7+1*B$6)&" Equity" | IH1: =Settings!$B$4&" US "&TEXT(B$3,"mm/dd/yy")&" C"&(B$7+2*B$6)&" Equity" | IY1: =Settings!$B$4&" US "&TEXT(B$3,"mm/dd/yy")&" P"&(B$7+2*B$6)&" Equity" | JP1: =Settings!$B$4&" US "&TEXT(B$3,"mm/dd/yy")&" C"&(B$7+3*B$6)&" Equity" | KG1: =Settings!$B$4&" US "&TEXT(B$3,"mm/dd/yy")&" P"&(B$7+3*B$6)&" Equity" | KX1: =Settings!$B$4&" US "&TEXT(B$3,"mm/dd/yy")&" C"&(B$7+4*B$6)&" Equity" | LO1: =Settings!$B$4&" US "&TEXT(B$3,"mm/dd/yy")&" P"&(B$7+4*B$6)&" Equity" | MF1: =Settings!$B$4&" US "&TEXT(B$3,"mm/dd/yy")&" C"&(B$7+5*B$6)&" Equity" | MW1: =Settings!$B$4&" US "&TEXT(B$3,"mm/dd/yy")&" P"&(B$7+5*B$6)&" Equity"
A2: Underlying | B2: =Settings!$B$4&" US Equity" | D2: call -5 from ATM | U2: put -5 from ATM | AL2: call -4 from ATM | BC2: put -4 from ATM | BT2: call -3 from ATM | CK2: put -3 from ATM | DB2: call -2 from ATM | DS2: put -2 from ATM | EJ2: call -1 from ATM | FA2: put -1 from ATM | FR2: call +0 from ATM | GI2: put +0 from ATM | GZ2: call +1 from ATM | HQ2: put +1 from ATM | IH2: call +2 from ATM | IY2: put +2 from ATM | JP2: call +3 from ATM | KG2: put +3 from ATM | KX2: call +4 from ATM | LO2: put +4 from ATM | MF2: call +5 from ATM | MW2: put +5 from ATM
A3: Expiry (3rd Friday) | B3: =DATE(Settings!$B$3,B1,15)+MOD(6-WEEKDAY(DATE(Settings!$B$3,B1,15)),7) | D3: Date | E3: PX_BID | F3: PX_ASK | G3: PX_MID | H3: PX_LAST | I3: PX_SETTLE | J3: PX_VOLUME | K3: OPEN_INT | L3: IVOL_MID | M3: IVOL_BID | N3: IVOL_ASK | O3: DELTA_MID | P3: GAMMA_MID | Q3: VEGA_MID | R3: THETA_MID | S3: OPT_UNDL_PX | U3: Date | V3: PX_BID | W3: PX_ASK | X3: PX_MID | Y3: PX_LAST | Z3: PX_SETTLE | AA3: PX_VOLUME | AB3: OPEN_INT | AC3: IVOL_MID | AD3: IVOL_BID | AE3: IVOL_ASK | AF3: DELTA_MID | AG3: GAMMA_MID | AH3: VEGA_MID | AI3: THETA_MID | AJ3: OPT_UNDL_PX | AL3: Date | AM3: PX_BID | AN3: PX_ASK | AO3: PX_MID | AP3: PX_LAST | AQ3: PX_SETTLE | AR3: PX_VOLUME | AS3: OPEN_INT | AT3: IVOL_MID | AU3: IVOL_BID | AV3: IVOL_ASK | AW3: DELTA_MID | AX3: GAMMA_MID | AY3: VEGA_MID | AZ3: THETA_MID | BA3: OPT_UNDL_PX | BC3: Date | BD3: PX_BID | BE3: PX_ASK | BF3: PX_MID | BG3: PX_LAST | BH3: PX_SETTLE | BI3: PX_VOLUME | BJ3: OPEN_INT | BK3: IVOL_MID | BL3: IVOL_BID | BM3: IVOL_ASK | BN3: DELTA_MID | BO3: GAMMA_MID | BP3: VEGA_MID | BQ3: THETA_MID | BR3: OPT_UNDL_PX | BT3: Date | BU3: PX_BID | BV3: PX_ASK | BW3: PX_MID | BX3: PX_LAST | BY3: PX_SETTLE | BZ3: PX_VOLUME | CA3: OPEN_INT | CB3: IVOL_MID | CC3: IVOL_BID | CD3: IVOL_ASK | CE3: DELTA_MID | CF3: GAMMA_MID | CG3: VEGA_MID | CH3: THETA_MID | CI3: OPT_UNDL_PX | CK3: Date | CL3: PX_BID | CM3: PX_ASK | CN3: PX_MID | CO3: PX_LAST | CP3: PX_SETTLE | CQ3: PX_VOLUME | CR3: OPEN_INT | CS3: IVOL_MID | CT3: IVOL_BID | CU3: IVOL_ASK | CV3: DELTA_MID | CW3: GAMMA_MID | CX3: VEGA_MID | CY3: THETA_MID | CZ3: OPT_UNDL_PX | DB3: Date | DC3: PX_BID | DD3: PX_ASK | DE3: PX_MID | DF3: PX_LAST | DG3: PX_SETTLE | DH3: PX_VOLUME | DI3: OPEN_INT | DJ3: IVOL_MID | DK3: IVOL_BID | DL3: IVOL_ASK | DM3: DELTA_MID | DN3: GAMMA_MID | DO3: VEGA_MID | DP3: THETA_MID | DQ3: OPT_UNDL_PX | DS3: Date | DT3: PX_BID | DU3: PX_ASK | DV3: PX_MID | DW3: PX_LAST | DX3: PX_SETTLE | DY3: PX_VOLUME | DZ3: OPEN_INT | EA3: IVOL_MID | EB3: IVOL_BID | EC3: IVOL_ASK | ED3: DELTA_MID | EE3: GAMMA_MID | EF3: VEGA_MID | EG3: THETA_MID | EH3: OPT_UNDL_PX | EJ3: Date | EK3: PX_BID | EL3: PX_ASK | EM3: PX_MID | EN3: PX_LAST | EO3: PX_SETTLE | EP3: PX_VOLUME | EQ3: OPEN_INT | ER3: IVOL_MID | ES3: IVOL_BID | ET3: IVOL_ASK | EU3: DELTA_MID | EV3: GAMMA_MID | EW3: VEGA_MID | EX3: THETA_MID | EY3: OPT_UNDL_PX | FA3: Date | FB3: PX_BID | FC3: PX_ASK | FD3: PX_MID | FE3: PX_LAST | FF3: PX_SETTLE | FG3: PX_VOLUME | FH3: OPEN_INT | FI3: IVOL_MID | FJ3: IVOL_BID | FK3: IVOL_ASK | FL3: DELTA_MID | FM3: GAMMA_MID | FN3: VEGA_MID | FO3: THETA_MID | FP3: OPT_UNDL_PX | FR3: Date | FS3: PX_BID | FT3: PX_ASK | FU3: PX_MID | FV3: PX_LAST | FW3: PX_SETTLE | FX3: PX_VOLUME | FY3: OPEN_INT | FZ3: IVOL_MID | GA3: IVOL_BID | GB3: IVOL_ASK | GC3: DELTA_MID | GD3: GAMMA_MID | GE3: VEGA_MID | GF3: THETA_MID | GG3: OPT_UNDL_PX | GI3: Date | GJ3: PX_BID | GK3: PX_ASK | GL3: PX_MID | GM3: PX_LAST | GN3: PX_SETTLE | GO3: PX_VOLUME | GP3: OPEN_INT | GQ3: IVOL_MID | GR3: IVOL_BID | GS3: IVOL_ASK | GT3: DELTA_MID | GU3: GAMMA_MID | GV3: VEGA_MID | GW3: THETA_MID | GX3: OPT_UNDL_PX | GZ3: Date | HA3: PX_BID | HB3: PX_ASK | HC3: PX_MID | HD3: PX_LAST | HE3: PX_SETTLE | HF3: PX_VOLUME | HG3: OPEN_INT | HH3: IVOL_MID | HI3: IVOL_BID | HJ3: IVOL_ASK | HK3: DELTA_MID | HL3: GAMMA_MID | HM3: VEGA_MID | HN3: THETA_MID | HO3: OPT_UNDL_PX | HQ3: Date | HR3: PX_BID | HS3: PX_ASK | HT3: PX_MID | HU3: PX_LAST | HV3: PX_SETTLE | HW3: PX_VOLUME | HX3: OPEN_INT | HY3: IVOL_MID | HZ3: IVOL_BID | IA3: IVOL_ASK | IB3: DELTA_MID | IC3: GAMMA_MID | ID3: VEGA_MID | IE3: THETA_MID | IF3: OPT_UNDL_PX | IH3: Date | II3: PX_BID | IJ3: PX_ASK | IK3: PX_MID | IL3: PX_LAST | IM3: PX_SETTLE | IN3: PX_VOLUME | IO3: OPEN_INT | IP3: IVOL_MID | IQ3: IVOL_BID | IR3: IVOL_ASK | IS3: DELTA_MID | IT3: GAMMA_MID | IU3: VEGA_MID | IV3: THETA_MID | IW3: OPT_UNDL_PX | IY3: Date | IZ3: PX_BID | JA3: PX_ASK | JB3: PX_MID | JC3: PX_LAST | JD3: PX_SETTLE | JE3: PX_VOLUME | JF3: OPEN_INT | JG3: IVOL_MID | JH3: IVOL_BID | JI3: IVOL_ASK | JJ3: DELTA_MID | JK3: GAMMA_MID | JL3: VEGA_MID | JM3: THETA_MID | JN3: OPT_UNDL_PX | JP3: Date | JQ3: PX_BID | JR3: PX_ASK | JS3: PX_MID | JT3: PX_LAST | JU3: PX_SETTLE | JV3: PX_VOLUME | JW3: OPEN_INT | JX3: IVOL_MID | JY3: IVOL_BID | JZ3: IVOL_ASK | KA3: DELTA_MID | KB3: GAMMA_MID | KC3: VEGA_MID | KD3: THETA_MID | KE3: OPT_UNDL_PX | KG3: Date | KH3: PX_BID | KI3: PX_ASK | KJ3: PX_MID | KK3: PX_LAST | KL3: PX_SETTLE | KM3: PX_VOLUME | KN3: OPEN_INT | KO3: IVOL_MID | KP3: IVOL_BID | KQ3: IVOL_ASK | KR3: DELTA_MID | KS3: GAMMA_MID | KT3: VEGA_MID | KU3: THETA_MID | KV3: OPT_UNDL_PX | KX3: Date | KY3: PX_BID | KZ3: PX_ASK | LA3: PX_MID | LB3: PX_LAST | LC3: PX_SETTLE | LD3: PX_VOLUME | LE3: OPEN_INT | LF3: IVOL_MID | LG3: IVOL_BID | LH3: IVOL_ASK | LI3: DELTA_MID | LJ3: GAMMA_MID | LK3: VEGA_MID | LL3: THETA_MID | LM3: OPT_UNDL_PX | LO3: Date | LP3: PX_BID | LQ3: PX_ASK | LR3: PX_MID | LS3: PX_LAST | LT3: PX_SETTLE | LU3: PX_VOLUME | LV3: OPEN_INT | LW3: IVOL_MID | LX3: IVOL_BID | LY3: IVOL_ASK | LZ3: DELTA_MID | MA3: GAMMA_MID | MB3: VEGA_MID | MC3: THETA_MID | MD3: OPT_UNDL_PX | MF3: Date | MG3: PX_BID | MH3: PX_ASK | MI3: PX_MID | MJ3: PX_LAST | MK3: PX_SETTLE | ML3: PX_VOLUME | MM3: OPEN_INT | MN3: IVOL_MID | MO3: IVOL_BID | MP3: IVOL_ASK | MQ3: DELTA_MID | MR3: GAMMA_MID | MS3: VEGA_MID | MT3: THETA_MID | MU3: OPT_UNDL_PX | MW3: Date | MX3: PX_BID | MY3: PX_ASK | MZ3: PX_MID | NA3: PX_LAST | NB3: PX_SETTLE | NC3: PX_VOLUME | ND3: OPEN_INT | NE3: IVOL_MID | NF3: IVOL_BID | NG3: IVOL_ASK | NH3: DELTA_MID | NI3: GAMMA_MID | NJ3: VEGA_MID | NK3: THETA_MID | NL3: OPT_UNDL_PX
