Workbook

Sheet Checklist
A1: Bloomberg price data: paste checklist
A3: 1. On the Terminal chart (G) screen, click the orange security box, type the ticker below, press Enter.
A4: 2. Click Max (or 5Y), change '1 Min' to Daily, then click Table.
A5: 3. Click in the table, Ctrl+A, Ctrl+C. Click 'Go' below, then click the yellow cell A4 on that sheet and Ctrl+V.
A6: 4. Paste the table as it comes, headers included. Rows pasted updates by itself. Save often; upload to Claude.
A7: Start with Priority 1. Extra 1-3 sheets are for anything not on the list (type its ticker in B1 there).
A9: # | B9: Priority | C9: Group | D9: Ticker | E9: Description | F9: Sheet | G9: Rows pasted | H9: Status
A10: 1 | B10: 1 | C10: Oil futures | D10: CL1 Comdty | E10: WTI crude, generic month 1 | F10: =HYPERLINK("#'CL1 Comdty'!A4","Go") | G10: =COUNTA('CL1 Comdty'!A5:A20000) | H10: =IF(G10>0,"Done","To do")
A11: 2 | B11: 1 | C11: Oil futures | D11: CO1 Comdty | E11: Brent crude, generic month 1 | F11: =HYPERLINK("#'CO1 Comdty'!A4","Go") | G11: =COUNTA('CO1 Comdty'!A5:A20000) | H11: =IF(G11>0,"Done","To do")
A12: 3 | B12: 1 | C12: Oil stocks/ETFs | D12: USO US Equity | E12: US Oil Fund (front WTI) | F12: =HYPERLINK("#'USO US Equity'!A4","Go") | G12: =COUNTA('USO US Equity'!A5:A20000) | H12: =IF(G12>0,"Done","To do")
A13: 4 | B13: 1 | C13: Oil stocks/ETFs | D13: XLE US Equity | E13: Energy Select SPDR | F13: =HYPERLINK("#'XLE US Equity'!A4","Go") | G13: =COUNTA('XLE US Equity'!A5:A20000) | H13: =IF(G13>0,"Done","To do")
A14: 5 | B14: 1 | C14: Macro | D14: OVX Index | E14: Cboe crude oil volatility index | F14: =HYPERLINK("#'OVX Index'!A4","Go") | G14: =COUNTA('OVX Index'!A5:A20000) | H14: =IF(G14>0,"Done","To do")
A15: 6 | B15: 1 | C15: Macro | D15: VIX Index | E15: Cboe VIX | F15: =HYPERLINK("#'VIX Index'!A4","Go") | G15: =COUNTA('VIX Index'!A5:A20000) | H15: =IF(G15>0,"Done","To do")
A16: 7 | B16: 1 | C16: Macro | D16: USGG3M Index | E16: US 3-month T-bill yield (risk-free rate) | F16: =HYPERLINK("#'USGG3M Index'!A4","Go") | G16: =COUNTA('USGG3M Index'!A5:A20000) | H16: =IF(G16>0,"Done","To do")
A17: 8 | B17: 1 | C17: Yen | D17: USDJPY Curncy | E17: USD/JPY spot | F17: =HYPERLINK("#'USDJPY Curncy'!A4","Go") | G17: =COUNTA('USDJPY Curncy'!A5:A20000) | H17: =IF(G17>0,"Done","To do")
A18: 9 | B18: 1 | C18: Yen | D18: USDJPYV1M Curncy | E18: 1-month ATM implied vol | F18: =HYPERLINK("#'USDJPYV1M Curncy'!A4","Go") | G18: =COUNTA('USDJPYV1M Curncy'!A5:A20000) | H18: =IF(G18>0,"Done","To do")
A19: 10 | B19: 2 | C19: Oil futures | D19: CL2 Comdty | E19: WTI crude, generic month 2 | F19: =HYPERLINK("#'CL2 Comdty'!A4","Go") | G19: =COUNTA('CL2 Comdty'!A5:A20000) | H19: =IF(G19>0,"Done","To do")
A20: 11 | B20: 2 | C20: Oil futures | D20: CL3 Comdty | E20: WTI crude, generic month 3 | F20: =HYPERLINK("#'CL3 Comdty'!A4","Go") | G20: =COUNTA('CL3 Comdty'!A5:A20000) | H20: =IF(G20>0,"Done","To do")
A21: 12 | B21: 2 | C21: Oil futures | D21: CL4 Comdty | E21: WTI crude, generic month 4 | F21: =HYPERLINK("#'CL4 Comdty'!A4","Go") | G21: =COUNTA('CL4 Comdty'!A5:A20000) | H21: =IF(G21>0,"Done","To do")
A22: 13 | B22: 2 | C22: Oil futures | D22: CL5 Comdty | E22: WTI crude, generic month 5 | F22: =HYPERLINK("#'CL5 Comdty'!A4","Go") | G22: =COUNTA('CL5 Comdty'!A5:A20000) | H22: =IF(G22>0,"Done","To do")
A23: 14 | B23: 2 | C23: Oil futures | D23: CL6 Comdty | E23: WTI crude, generic month 6 | F23: =HYPERLINK("#'CL6 Comdty'!A4","Go") | G23: =COUNTA('CL6 Comdty'!A5:A20000) | H23: =IF(G23>0,"Done","To do")
A24: 15 | B24: 2 | C24: Oil futures | D24: CL7 Comdty | E24: WTI crude, generic month 7 | F24: =HYPERLINK("#'CL7 Comdty'!A4","Go") | G24: =COUNTA('CL7 Comdty'!A5:A20000) | H24: =IF(G24>0,"Done","To do")
A25: 16 | B25: 2 | C25: Oil futures | D25: CL8 Comdty | E25: WTI crude, generic month 8 | F25: =HYPERLINK("#'CL8 Comdty'!A4","Go") | G25: =COUNTA('CL8 Comdty'!A5:A20000) | H25: =IF(G25>0,"Done","To do")
A26: 17 | B26: 2 | C26: Oil futures | D26: CL9 Comdty | E26: WTI crude, generic month 9 | F26: =HYPERLINK("#'CL9 Comdty'!A4","Go") | G26: =COUNTA('CL9 Comdty'!A5:A20000) | H26: =IF(G26>0,"Done","To do")
A27: 18 | B27: 2 | C27: Oil futures | D27: CL10 Comdty | E27: WTI crude, generic month 10 | F27: =HYPERLINK("#'CL10 Comdty'!A4","Go") | G27: =COUNTA('CL10 Comdty'!A5:A20000) | H27: =IF(G27>0,"Done","To do")
A28: 19 | B28: 2 | C28: Oil futures | D28: CL11 Comdty | E28: WTI crude, generic month 11 | F28: =HYPERLINK("#'CL11 Comdty'!A4","Go") | G28: =COUNTA('CL11 Comdty'!A5:A20000) | H28: =IF(G28>0,"Done","To do")
A29: 20 | B29: 2 | C29: Oil futures | D29: CL12 Comdty | E29: WTI crude, generic month 12 | F29: =HYPERLINK("#'CL12 Comdty'!A4","Go") | G29: =COUNTA('CL12 Comdty'!A5:A20000) | H29: =IF(G29>0,"Done","To do")
A30: 21 | B30: 2 | C30: Oil futures | D30: CO2 Comdty | E30: Brent crude, generic month 2 | F30: =HYPERLINK("#'CO2 Comdty'!A4","Go") | G30: =COUNTA('CO2 Comdty'!A5:A20000) | H30: =IF(G30>0,"Done","To do")
A31: 22 | B31: 2 | C31: Oil futures | D31: CO3 Comdty | E31: Brent crude, generic month 3 | F31: =HYPERLINK("#'CO3 Comdty'!A4","Go") | G31: =COUNTA('CO3 Comdty'!A5:A20000) | H31: =IF(G31>0,"Done","To do")
A32: 23 | B32: 2 | C32: Oil futures | D32: CO4 Comdty | E32: Brent crude, generic month 4 | F32: =HYPERLINK("#'CO4 Comdty'!A4","Go") | G32: =COUNTA('CO4 Comdty'!A5:A20000) | H32: =IF(G32>0,"Done","To do")
A33: 24 | B33: 2 | C33: Oil futures | D33: CO5 Comdty | E33: Brent crude, generic month 5 | F33: =HYPERLINK("#'CO5 Comdty'!A4","Go") | G33: =COUNTA('CO5 Comdty'!A5:A20000) | H33: =IF(G33>0,"Done","To do")
A34: 25 | B34: 2 | C34: Oil futures | D34: CO6 Comdty | E34: Brent crude, generic month 6 | F34: =HYPERLINK("#'CO6 Comdty'!A4","Go") | G34: =COUNTA('CO6 Comdty'!A5:A20000) | H34: =IF(G34>0,"Done","To do")
A35: 26 | B35: 2 | C35: Oil futures | D35: HO1 Comdty | E35: NY Harbor ULSD (heating oil), front | F35: =HYPERLINK("#'HO1 Comdty'!A4","Go") | G35: =COUNTA('HO1 Comdty'!A5:A20000) | H35: =IF(G35>0,"Done","To do")
A36: 27 | B36: 2 | C36: Oil futures | D36: XB1 Comdty | E36: RBOB gasoline, front | F36: =HYPERLINK("#'XB1 Comdty'!A4","Go") | G36: =COUNTA('XB1 Comdty'!A5:A20000) | H36: =IF(G36>0,"Done","To do")
A37: 28 | B37: 2 | C37: Oil futures | D37: QM1 Comdty | E37: E-mini WTI, front | F37: =HYPERLINK("#'QM1 Comdty'!A4","Go") | G37: =COUNTA('QM1 Comdty'!A5:A20000) | H37: =IF(G37>0,"Done","To do")
A38: 29 | B38: 2 | C38: Oil futures | D38: NG1 Comdty | E38: Henry Hub natural gas, front | F38: =HYPERLINK("#'NG1 Comdty'!A4","Go") | G38: =COUNTA('NG1 Comdty'!A5:A20000) | H38: =IF(G38>0,"Done","To do")
A39: 30 | B39: 2 | C39: Oil stocks/ETFs | D39: BNO US Equity | E39: US Brent Oil Fund | F39: =HYPERLINK("#'BNO US Equity'!A4","Go") | G39: =COUNTA('BNO US Equity'!A5:A20000) | H39: =IF(G39>0,"Done","To do")
A40: 31 | B40: 2 | C40: Oil stocks/ETFs | D40: USL US Equity | E40: US 12-Month Oil Fund | F40: =HYPERLINK("#'USL US Equity'!A4","Go") | G40: =COUNTA('USL US Equity'!A5:A20000) | H40: =IF(G40>0,"Done","To do")
A41: 32 | B41: 2 | C41: Oil stocks/ETFs | D41: DBO US Equity | E41: Invesco DB Oil | F41: =HYPERLINK("#'DBO US Equity'!A4","Go") | G41: =COUNTA('DBO US Equity'!A5:A20000) | H41: =IF(G41>0,"Done","To do")
A42: 33 | B42: 2 | C42: Oil stocks/ETFs | D42: UCO US Equity | E42: ProShares 2x crude | F42: =HYPERLINK("#'UCO US Equity'!A4","Go") | G42: =COUNTA('UCO US Equity'!A5:A20000) | H42: =IF(G42>0,"Done","To do")
...

Sheet CL1 Comdty
A1: Ticker: | B1: CL1 Comdty | C1: WTI crude, generic month 1
A2: Click the yellow cell A4 and press Ctrl+V to paste the Bloomberg table (headers included).
A3: Paste below

Sheet CO1 Comdty
A1: Ticker: | B1: CO1 Comdty | C1: Brent crude, generic month 1
A2: Click the yellow cell A4 and press Ctrl+V to paste the Bloomberg table (headers included).
A3: Paste below

Sheet USO US Equity
A1: Ticker: | B1: USO US Equity | C1: US Oil Fund (front WTI)
A2: Click the yellow cell A4 and press Ctrl+V to paste the Bloomberg table (headers included).
A3: Paste below

Sheet XLE US Equity
A1: Ticker: | B1: XLE US Equity | C1: Energy Select SPDR
A2: Click the yellow cell A4 and press Ctrl+V to paste the Bloomberg table (headers included).
A3: Paste below

Sheet OVX Index
A1: Ticker: | B1: OVX Index | C1: Cboe crude oil volatility index
A2: Click the yellow cell A4 and press Ctrl+V to paste the Bloomberg table (headers included).
A3: Paste below

Sheet VIX Index
A1: Ticker: | B1: VIX Index | C1: Cboe VIX
A2: Click the yellow cell A4 and press Ctrl+V to paste the Bloomberg table (headers included).
A3: Paste below

Sheet USGG3M Index
A1: Ticker: | B1: USGG3M Index | C1: US 3-month T-bill yield (risk-free rate)
A2: Click the yellow cell A4 and press Ctrl+V to paste the Bloomberg table (headers included).
A3: Paste below

Sheet USDJPY Curncy
A1: Ticker: | B1: USDJPY Curncy | C1: USD/JPY spot
A2: Click the yellow cell A4 and press Ctrl+V to paste the Bloomberg table (headers included).
A3: Paste below

Sheet USDJPYV1M Curncy
A1: Ticker: | B1: USDJPYV1M Curncy | C1: 1-month ATM implied vol
A2: Click the yellow cell A4 and press Ctrl+V to paste the Bloomberg table (headers included).
A3: Paste below

Sheet CL2 Comdty
A1: Ticker: | B1: CL2 Comdty | C1: WTI crude, generic month 2
A2: Click the yellow cell A4 and press Ctrl+V to paste the Bloomberg table (headers included).
A3: Paste below

Sheet CL3 Comdty
A1: Ticker: | B1: CL3 Comdty | C1: WTI crude, generic month 3
A2: Click the yellow cell A4 and press Ctrl+V to paste the Bloomberg table (headers included).
A3: Paste below

Sheet CL4 Comdty
A1: Ticker: | B1: CL4 Comdty | C1: WTI crude, generic month 4
A2: Click the yellow cell A4 and press Ctrl+V to paste the Bloomberg table (headers included).
A3: Paste below

Sheet CL5 Comdty
A1: Ticker: | B1: CL5 Comdty | C1: WTI crude, generic month 5
A2: Click the yellow cell A4 and press Ctrl+V to paste the Bloomberg table (headers included).
A3: Paste below

Sheet CL6 Comdty
A1: Ticker: | B1: CL6 Comdty | C1: WTI crude, generic month 6
A2: Click the yellow cell A4 and press Ctrl+V to paste the Bloomberg table (headers included).
A3: Paste below

Sheet CL7 Comdty
A1: Ticker: | B1: CL7 Comdty | C1: WTI crude, generic month 7
A2: Click the yellow cell A4 and press Ctrl+V to paste the Bloomberg table (headers included).
A3: Paste below

Sheet CL8 Comdty
A1: Ticker: | B1: CL8 Comdty | C1: WTI crude, generic month 8
A2: Click the yellow cell A4 and press Ctrl+V to paste the Bloomberg table (headers included).
A3: Paste below

Sheet CL9 Comdty
A1: Ticker: | B1: CL9 Comdty | C1: WTI crude, generic month 9
A2: Click the yellow cell A4 and press Ctrl+V to paste the Bloomberg table (headers included).
A3: Paste below

Sheet CL10 Comdty
A1: Ticker: | B1: CL10 Comdty | C1: WTI crude, generic month 10
A2: Click the yellow cell A4 and press Ctrl+V to paste the Bloomberg table (headers included).
A3: Paste below

Sheet CL11 Comdty
A1: Ticker: | B1: CL11 Comdty | C1: WTI crude, generic month 11
A2: Click the yellow cell A4 and press Ctrl+V to paste the Bloomberg table (headers included).
A3: Paste below

Sheet CL12 Comdty
A1: Ticker: | B1: CL12 Comdty | C1: WTI crude, generic month 12
A2: Click the yellow cell A4 and press Ctrl+V to paste the Bloomberg table (headers included).
A3: Paste below

Sheet CO2 Comdty
A1: Ticker: | B1: CO2 Comdty | C1: Brent crude, generic month 2
A2: Click the yellow cell A4 and press Ctrl+V to paste the Bloomberg table (headers included).
A3: Paste below

Sheet CO3 Comdty
A1: Ticker: | B1: CO3 Comdty | C1: Brent crude, generic month 3
A2: Click the yellow cell A4 and press Ctrl+V to paste the Bloomberg table (headers included).
A3: Paste below

Sheet CO4 Comdty
A1: Ticker: | B1: CO4 Comdty | C1: Brent crude, generic month 4
A2: Click the yellow cell A4 and press Ctrl+V to paste the Bloomberg table (headers included).
A3: Paste below

Sheet CO5 Comdty
A1: Ticker: | B1: CO5 Comdty | C1: Brent crude, generic month 5
A2: Click the yellow cell A4 and press Ctrl+V to paste the Bloomberg table (headers included).
A3: Paste below

Sheet CO6 Comdty
A1: Ticker: | B1: CO6 Comdty | C1: Brent crude, generic month 6
A2: Click the yellow cell A4 and press Ctrl+V to paste the Bloomberg table (headers included).
A3: Paste below

Sheet HO1 Comdty
A1: Ticker: | B1: HO1 Comdty | C1: NY Harbor ULSD (heating oil), front
A2: Click the yellow cell A4 and press Ctrl+V to paste the Bloomberg table (headers included).
A3: Paste below

Sheet XB1 Comdty
A1: Ticker: | B1: XB1 Comdty | C1: RBOB gasoline, front
A2: Click the yellow cell A4 and press Ctrl+V to paste the Bloomberg table (headers included).
A3: Paste below

Sheet QM1 Comdty
A1: Ticker: | B1: QM1 Comdty | C1: E-mini WTI, front
A2: Click the yellow cell A4 and press Ctrl+V to paste the Bloomberg table (headers included).
A3: Paste below

Sheet NG1 Comdty
A1: Ticker: | B1: NG1 Comdty | C1: Henry Hub natural gas, front
A2: Click the yellow cell A4 and press Ctrl+V to paste the Bloomberg table (headers included).
A3: Paste below

Sheet BNO US Equity
A1: Ticker: | B1: BNO US Equity | C1: US Brent Oil Fund
A2: Click the yellow cell A4 and press Ctrl+V to paste the Bloomberg table (headers included).
A3: Paste below

Sheet USL US Equity
A1: Ticker: | B1: USL US Equity | C1: US 12-Month Oil Fund
A2: Click the yellow cell A4 and press Ctrl+V to paste the Bloomberg table (headers included).
A3: Paste below

Sheet DBO US Equity
A1: Ticker: | B1: DBO US Equity | C1: Invesco DB Oil
A2: Click the yellow cell A4 and press Ctrl+V to paste the Bloomberg table (headers included).
A3: Paste below

Sheet UCO US Equity
A1: Ticker: | B1: UCO US Equity | C1: ProShares 2x crude
A2: Click the yellow cell A4 and press Ctrl+V to paste the Bloomberg table (headers included).
A3: Paste below

Sheet SCO US Equity
A1: Ticker: | B1: SCO US Equity | C1: ProShares -2x crude
A2: Click the yellow cell A4 and press Ctrl+V to paste the Bloomberg table (headers included).
A3: Paste below

Sheet XOP US Equity
A1: Ticker: | B1: XOP US Equity | C1: S&P Oil & Gas E&P ETF
A2: Click the yellow cell A4 and press Ctrl+V to paste the Bloomberg table (headers included).
A3: Paste below

Sheet OIH US Equity
A1: Ticker: | B1: OIH US Equity | C1: Oil services ETF
A2: Click the yellow cell A4 and press Ctrl+V to paste the Bloomberg table (headers included).
A3: Paste below

Sheet VDE US Equity
A1: Ticker: | B1: VDE US Equity | C1: Vanguard energy ETF
A2: Click the yellow cell A4 and press Ctrl+V to paste the Bloomberg table (headers included).
A3: Paste below

Sheet CRAK US Equity
A1: Ticker: | B1: CRAK US Equity | C1: Oil refiners ETF
A2: Click the yellow cell A4 and press Ctrl+V to paste the Bloomberg table (headers included).
A3: Paste below

Sheet XOM US Equity
A1: Ticker: | B1: XOM US Equity | C1: ExxonMobil
A2: Click the yellow cell A4 and press Ctrl+V to paste the Bloomberg table (headers included).
A3: Paste below

Sheet CVX US Equity
A1: Ticker: | B1: CVX US Equity | C1: Chevron
A2: Click the yellow cell A4 and press Ctrl+V to paste the Bloomberg table (headers included).
A3: Paste below

Sheet COP US Equity
A1: Ticker: | B1: COP US Equity | C1: ConocoPhillips
A2: Click the yellow cell A4 and press Ctrl+V to paste the Bloomberg table (headers included).
A3: Paste below

Sheet OXY US Equity
A1: Ticker: | B1: OXY US Equity | C1: Occidental
A2: Click the yellow cell A4 and press Ctrl+V to paste the Bloomberg table (headers included).
A3: Paste below

Sheet EOG US Equity
A1: Ticker: | B1: EOG US Equity | C1: EOG Resources
A2: Click the yellow cell A4 and press Ctrl+V to paste the Bloomberg table (headers included).
A3: Paste below

Sheet DVN US Equity
A1: Ticker: | B1: DVN US Equity | C1: Devon
A2: Click the yellow cell A4 and press Ctrl+V to paste the Bloomberg table (headers included).
A3: Paste below

Sheet FANG US Equity
A1: Ticker: | B1: FANG US Equity | C1: Diamondback
A2: Click the yellow cell A4 and press Ctrl+V to paste the Bloomberg table (headers included).
A3: Paste below

Sheet APA US Equity
A1: Ticker: | B1: APA US Equity | C1: APA Corp
A2: Click the yellow cell A4 and press Ctrl+V to paste the Bloomberg table (headers included).
A3: Paste below

Sheet DAL US Equity
A1: Ticker: | B1: DAL US Equity | C1: Delta Air Lines
A2: Click the yellow cell A4 and press Ctrl+V to paste the Bloomberg table (headers included).
A3: Paste below

Sheet UAL US Equity
A1: Ticker: | B1: UAL US Equity | C1: United Airlines
A2: Click the yellow cell A4 and press Ctrl+V to paste the Bloomberg table (headers included).
A3: Paste below

Sheet AAL US Equity
A1: Ticker: | B1: AAL US Equity | C1: American Airlines
A2: Click the yellow cell A4 and press Ctrl+V to paste the Bloomberg table (headers included).
A3: Paste below

Sheet LUV US Equity
A1: Ticker: | B1: LUV US Equity | C1: Southwest
A2: Click the yellow cell A4 and press Ctrl+V to paste the Bloomberg table (headers included).
A3: Paste below

Sheet JETS US Equity
A1: Ticker: | B1: JETS US Equity | C1: Airlines ETF
A2: Click the yellow cell A4 and press Ctrl+V to paste the Bloomberg table (headers included).
A3: Paste below

Sheet SPY US Equity
A1: Ticker: | B1: SPY US Equity | C1: S&P 500 ETF
A2: Click the yellow cell A4 and press Ctrl+V to paste the Bloomberg table (headers included).
A3: Paste below

Sheet SPX Index
A1: Ticker: | B1: SPX Index | C1: S&P 500
A2: Click the yellow cell A4 and press Ctrl+V to paste the Bloomberg table (headers included).
A3: Paste below

Sheet USGG1YR Index
A1: Ticker: | B1: USGG1YR Index | C1: US 1-year Treasury yield
A2: Click the yellow cell A4 and press Ctrl+V to paste the Bloomberg table (headers included).
A3: Paste below

Sheet USGG2YR Index
A1: Ticker: | B1: USGG2YR Index | C1: US 2-year Treasury yield
A2: Click the yellow cell A4 and press Ctrl+V to paste the Bloomberg table (headers included).
A3: Paste below

Sheet DXY Curncy
A1: Ticker: | B1: DXY Curncy | C1: US dollar index
A2: Click the yellow cell A4 and press Ctrl+V to paste the Bloomberg table (headers included).
A3: Paste below

Sheet USDJPYV1W Curncy
A1: Ticker: | B1: USDJPYV1W Curncy | C1: 1-week ATM implied vol
A2: Click the yellow cell A4 and press Ctrl+V to paste the Bloomberg table (headers included).
A3: Paste below

Sheet USDJPYV3M Curncy
A1: Ticker: | B1: USDJPYV3M Curncy | C1: 3-month ATM implied vol
A2: Click the yellow cell A4 and press Ctrl+V to paste the Bloomberg table (headers included).
A3: Paste below

Sheet USDJPY25R1M Curncy
A1: Ticker: | B1: USDJPY25R1M Curncy | C1: 1-month 25-delta risk reversal
A2: Click the yellow cell A4 and press Ctrl+V to paste the Bloomberg table (headers included).
A3: Paste below

Sheet USDJPY25B1M Curncy
A1: Ticker: | B1: USDJPY25B1M Curncy | C1: 1-month 25-delta butterfly
A2: Click the yellow cell A4 and press Ctrl+V to paste the Bloomberg table (headers included).
A3: Paste below

Sheet USDJPY10R1M Curncy
A1: Ticker: | B1: USDJPY10R1M Curncy | C1: 1-month 10-delta risk reversal
A2: Click the yellow cell A4 and press Ctrl+V to paste the Bloomberg table (headers included).
A3: Paste below

Sheet USDJPY10B1M Curncy
A1: Ticker: | B1: USDJPY10B1M Curncy | C1: 1-month 10-delta butterfly
A2: Click the yellow cell A4 and press Ctrl+V to paste the Bloomberg table (headers included).
A3: Paste below

Sheet JPY1M Curncy
A1: Ticker: | B1: JPY1M Curncy | C1: 1-month forward points
A2: Click the yellow cell A4 and press Ctrl+V to paste the Bloomberg table (headers included).
A3: Paste below

Sheet USDJPYV2W Curncy
A1: Ticker: | B1: USDJPYV2W Curncy | C1: 2-week ATM implied vol
A2: Click the yellow cell A4 and press Ctrl+V to paste the Bloomberg table (headers included).
A3: Paste below

Sheet USDJPYV2M Curncy
A1: Ticker: | B1: USDJPYV2M Curncy | C1: 2-month ATM implied vol
A2: Click the yellow cell A4 and press Ctrl+V to paste the Bloomberg table (headers included).
A3: Paste below

Sheet USDJPYV6M Curncy
A1: Ticker: | B1: USDJPYV6M Curncy | C1: 6-month ATM implied vol
A2: Click the yellow cell A4 and press Ctrl+V to paste the Bloomberg table (headers included).
A3: Paste below

Sheet USDJPYV1Y Curncy
A1: Ticker: | B1: USDJPYV1Y Curncy | C1: 1-year ATM implied vol
A2: Click the yellow cell A4 and press Ctrl+V to paste the Bloomberg table (headers included).
A3: Paste below

Sheet USDJPY25R1W Curncy
A1: Ticker: | B1: USDJPY25R1W Curncy | C1: 1-week 25-delta risk reversal
A2: Click the yellow cell A4 and press Ctrl+V to paste the Bloomberg table (headers included).
A3: Paste below

Sheet USDJPY25R3M Curncy
A1: Ticker: | B1: USDJPY25R3M Curncy | C1: 3-month 25-delta risk reversal
A2: Click the yellow cell A4 and press Ctrl+V to paste the Bloomberg table (headers included).
A3: Paste below

Sheet USDJPY25B3M Curncy
A1: Ticker: | B1: USDJPY25B3M Curncy | C1: 3-month 25-delta butterfly
A2: Click the yellow cell A4 and press Ctrl+V to paste the Bloomberg table (headers included).
A3: Paste below

Sheet JPY1W Curncy
A1: Ticker: | B1: JPY1W Curncy | C1: 1-week forward points
A2: Click the yellow cell A4 and press Ctrl+V to paste the Bloomberg table (headers included).
A3: Paste below

Sheet JPY3M Curncy
A1: Ticker: | B1: JPY3M Curncy | C1: 3-month forward points
A2: Click the yellow cell A4 and press Ctrl+V to paste the Bloomberg table (headers included).
A3: Paste below

Sheet JY1 Curncy
A1: Ticker: | B1: JY1 Curncy | C1: CME yen futures, front
A2: Click the yellow cell A4 and press Ctrl+V to paste the Bloomberg table (headers included).
A3: Paste below

Sheet JY2 Curncy
A1: Ticker: | B1: JY2 Curncy | C1: CME yen futures, second
A2: Click the yellow cell A4 and press Ctrl+V to paste the Bloomberg table (headers included).
A3: Paste below

Sheet USGG10YR Index
A1: Ticker: | B1: USGG10YR Index | C1: US 10-year Treasury yield
A2: Click the yellow cell A4 and press Ctrl+V to paste the Bloomberg table (headers included).
A3: Paste below

Sheet GTJPY2Y Govt
A1: Ticker: | B1: GTJPY2Y Govt | C1: Japan 2-year JGB yield
A2: Click the yellow cell A4 and press Ctrl+V to paste the Bloomberg table (headers included).
A3: Paste below

Sheet GTJPY10Y Govt
A1: Ticker: | B1: GTJPY10Y Govt | C1: Japan 10-year JGB yield
A2: Click the yellow cell A4 and press Ctrl+V to paste the Bloomberg table (headers included).
A3: Paste below

Sheet Extra 1
A1: Ticker: | C1: Extra 1
A2: Click the yellow cell A4 and press Ctrl+V to paste the Bloomberg table (headers included).
A3: Paste below

Sheet Extra 2
A1: Ticker: | C1: Extra 2
A2: Click the yellow cell A4 and press Ctrl+V to paste the Bloomberg table (headers included).
A3: Paste below

Sheet Extra 3
A1: Ticker: | C1: Extra 3
A2: Click the yellow cell A4 and press Ctrl+V to paste the Bloomberg table (headers included).
A3: Paste below
