Workbook

Sheet Settings
A1: Bloomberg data pull: yen and oil (same data as bbg_pull.py)
A3: As-of date | B3: 46308 | C3: Set to today's date; decides expired vs live futures tickers
A5: Section | B5: Load (Y/N) | C5: Start date | D5: End date | E5: Year | F5: Other | G5: Notes
A6: Test | B6: Y | C6: 46294 | G6: Switch on first. Test sheet: B1 shows a price and column D fills with ~2 weeks of prices
A7: Yen | B7: N | C7: 40179 | G7: Sheets: Yen Core, Yen Extra
A8: Oil core | B8: N | C8: 40179 | G8: Sheets: Oil Futures, Oil Equities, Oil Equities Unadj, Macro
A9: Oil vol A | B9: N | C9: 42370 | G9: Vol sheets for CL1, CL2, CO1, USO (large)
A10: Oil vol B | B10: N | C10: 42370 | G10: Vol sheets for BNO, XLE, XOP, OXY (large)
A11: Oil vol C | B11: N | C11: 42370 | G11: Vol sheets for XOM, DAL, JETS, SPY (large)
A12: CL futures | B12: N | C12: 42370 | G12: Every WTI contract 2016-2029, sheets CL Fut <year> (large)
A13: CO futures | B13: N | C13: 42370 | G13: Every Brent contract 2016-2029, sheets CO Fut <year> (large)
A14: CL options | B14: N | E14: 2026 | F14: 1 | G14: Year = contract year. Other = strike format: 1 gives 'CLZ6C 70', 2 gives 'CLZ6C 70.00'
A15: USO options | B15: N | E15: 2026 | G15: Year = expiry year
A16: XLE options | B16: N | E16: 2026 | G16: Year = expiry year
A17: XOP options | B17: N | E17: 2026 | G17: Year = expiry year
A18: OXY options | B18: N | E18: 2026 | G18: Year = expiry year
A19: DAL options | B19: N | E19: 2026 | G19: Year = expiry year
A20: Intraday | B20: N | C20: 46168 | D20: 46308 | F20: 5 | G20: Other = bar size in minutes. Bloomberg keeps ~140 days, so keep Start within that
A21: Blank End date = today.
A23: Legend
A24: Yellow cells, blue text | B24: inputs you may change; everything else is a formula
A26: How to use
A27: 1. Open this file in Excel on the Bloomberg PC with the Terminal logged in. Click Enable Editing / Enable Content.
A28: 2. Only sections with Load = Y request data. Test starts as Y; check the Test sheet shows numbers.
A29: 3. Change Test to N and one other section to Y. Wait until no cell says 'Requesting Data...'.
A30: 4. File > Save As .xlsx (save often). Then switch that section to N and the next to Y. Turning a section off clears its data, so Save As a new name per section, or keep each finished section on.
A31: 5. Options sections cover one Year at a time: set the Year, let it load, Save As, then change the Year (2018-2026).
A32: 6. '#N/A Invalid Security' or '#N/A Field Not Applicable' means that item isn't available; '#N/A Review' means Bloomberg is blocking downloads for this login (contact HELP HELP).
A33: 7. If nothing loads: Bloomberg tab > Refresh > Refresh Workbook. Upload saved files to Claude.

Sheet Test
A1: Latest WTI price: | B1: =IF(Settings!$B$6="Y",BDP("CL1 Comdty","PX_LAST"),"") | D1: =IF(Settings!$B$6="Y","CL1 Comdty","")
D2: WTI crude, front month
D3: Date | E3: PX_LAST
D4: =BDH(D$1,E$3:E$3,Settings!$C$6,IF(Settings!$D$6="","",Settings!$D$6),"Dir=V","Dts=S","Sort=A","Days=T","Fill=B")

Sheet Yen Core
A1: =IF(Settings!$B$7="Y","USDJPY Curncy","") | F1: =IF(Settings!$B$7="Y","USDJPYV1W Curncy","") | I1: =IF(Settings!$B$7="Y","USDJPYV1M Curncy","") | N1: =IF(Settings!$B$7="Y","USDJPYV3M Curncy","") | Q1: =IF(Settings!$B$7="Y","USDJPY25R1M Curncy","") | T1: =IF(Settings!$B$7="Y","USDJPY25B1M Curncy","") | W1: =IF(Settings!$B$7="Y","USDJPY10R1M Curncy","") | Z1: =IF(Settings!$B$7="Y","USDJPY10B1M Curncy","") | AC1: =IF(Settings!$B$7="Y","JPY1M Curncy","")
A2: USD/JPY spot | F2: 1-week ATM implied vol | I2: 1-month ATM implied vol | N2: 3-month ATM implied vol | Q2: 1-month 25-delta risk reversal | T2: 1-month 25-delta butterfly | W2: 1-month 10-delta risk reversal | Z2: 1-month 10-delta butterfly | AC2: 1-month forward points
A3: Date | B3: PX_LAST | C3: PX_HIGH | D3: PX_LOW | F3: Date | G3: PX_LAST | I3: Date | J3: PX_LAST | K3: PX_BID | L3: PX_ASK | N3: Date | O3: PX_LAST | Q3: Date | R3: PX_LAST | T3: Date | U3: PX_LAST | W3: Date | X3: PX_LAST | Z3: Date | AA3: PX_LAST | AC3: Date | AD3: PX_LAST
A4: =BDH(A$1,B$3:D$3,Settings!$C$7,IF(Settings!$D$7="","",Settings!$D$7),"Dir=V","Dts=S","Sort=A","Days=T","Fill=B") | F4: =BDH(F$1,G$3:G$3,Settings!$C$7,IF(Settings!$D$7="","",Settings!$D$7),"Dir=V","Dts=S","Sort=A","Days=T","Fill=B") | I4: =BDH(I$1,J$3:L$3,Settings!$C$7,IF(Settings!$D$7="","",Settings!$D$7),"Dir=V","Dts=S","Sort=A","Days=T","Fill=B") | N4: =BDH(N$1,O$3:O$3,Settings!$C$7,IF(Settings!$D$7="","",Settings!$D$7),"Dir=V","Dts=S","Sort=A","Days=T","Fill=B") | Q4: =BDH(Q$1,R$3:R$3,Settings!$C$7,IF(Settings!$D$7="","",Settings!$D$7),"Dir=V","Dts=S","Sort=A","Days=T","Fill=B") | T4: =BDH(T$1,U$3:U$3,Settings!$C$7,IF(Settings!$D$7="","",Settings!$D$7),"Dir=V","Dts=S","Sort=A","Days=T","Fill=B") | W4: =BDH(W$1,X$3:X$3,Settings!$C$7,IF(Settings!$D$7="","",Settings!$D$7),"Dir=V","Dts=S","Sort=A","Days=T","Fill=B") | Z4: =BDH(Z$1,AA$3:AA$3,Settings!$C$7,IF(Settings!$D$7="","",Settings!$D$7),"Dir=V","Dts=S","Sort=A","Days=T","Fill=B") | AC4: =BDH(AC$1,AD$3:AD$3,Settings!$C$7,IF(Settings!$D$7="","",Settings!$D$7),"Dir=V","Dts=S","Sort=A","Days=T","Fill=B")

Sheet Yen Extra
A1: =IF(Settings!$B$7="Y","USDJPYV2W Curncy","") | D1: =IF(Settings!$B$7="Y","USDJPYV2M Curncy","") | G1: =IF(Settings!$B$7="Y","USDJPYV6M Curncy","") | J1: =IF(Settings!$B$7="Y","USDJPYV1Y Curncy","") | M1: =IF(Settings!$B$7="Y","USDJPY25R1W Curncy","") | P1: =IF(Settings!$B$7="Y","USDJPY25R3M Curncy","") | S1: =IF(Settings!$B$7="Y","USDJPY25B3M Curncy","") | V1: =IF(Settings!$B$7="Y","JPY1W Curncy","") | Y1: =IF(Settings!$B$7="Y","JPY3M Curncy","") | AB1: =IF(Settings!$B$7="Y","JY1 Curncy","") | AH1: =IF(Settings!$B$7="Y","JY2 Curncy","") | AL1: =IF(Settings!$B$7="Y","USGG2YR Index","") | AO1: =IF(Settings!$B$7="Y","USGG10YR Index","") | AR1: =IF(Settings!$B$7="Y","GTJPY2Y Govt","") | AU1: =IF(Settings!$B$7="Y","GTJPY10Y Govt","") | AX1: =IF(Settings!$B$7="Y","CL1 Comdty","") | BA1: =IF(Settings!$B$7="Y","CO1 Comdty","") | BD1: =IF(Settings!$B$7="Y","OVX Index","") | BG1: =IF(Settings!$B$7="Y","VIX Index","")
A2: 2-week ATM implied vol | D2: 2-month ATM implied vol | G2: 6-month ATM implied vol | J2: 1-year ATM implied vol | M2: 1-week 25-delta risk reversal | P2: 3-month 25-delta risk reversal | S2: 3-month 25-delta butterfly | V2: 1-week forward points | Y2: 3-month forward points | AB2: CME yen futures, front | AH2: CME yen futures, second | AL2: US 2-year Treasury yield | AO2: US 10-year Treasury yield | AR2: Japan 2-year JGB yield | AU2: Japan 10-year JGB yield | AX2: WTI crude, front month | BA2: Brent crude, front month | BD2: Cboe crude oil volatility index | BG2: Cboe VIX
A3: Date | B3: PX_LAST | D3: Date | E3: PX_LAST | G3: Date | H3: PX_LAST | J3: Date | K3: PX_LAST | M3: Date | N3: PX_LAST | P3: Date | Q3: PX_LAST | S3: Date | T3: PX_LAST | V3: Date | W3: PX_LAST | Y3: Date | Z3: PX_LAST | AB3: Date | AC3: PX_LAST | AD3: PX_VOLUME | AE3: OPEN_INT | AF3: 30DAY_IMPVOL_100.0%MNY_DF | AH3: Date | AI3: PX_LAST | AJ3: OPEN_INT | AL3: Date | AM3: PX_LAST | AO3: Date | AP3: PX_LAST | AR3: Date | AS3: PX_LAST | AU3: Date | AV3: PX_LAST | AX3: Date | AY3: PX_LAST | BA3: Date | BB3: PX_LAST | BD3: Date | BE3: PX_LAST | BG3: Date | BH3: PX_LAST
A4: =BDH(A$1,B$3:B$3,Settings!$C$7,IF(Settings!$D$7="","",Settings!$D$7),"Dir=V","Dts=S","Sort=A","Days=T","Fill=B") | D4: =BDH(D$1,E$3:E$3,Settings!$C$7,IF(Settings!$D$7="","",Settings!$D$7),"Dir=V","Dts=S","Sort=A","Days=T","Fill=B") | G4: =BDH(G$1,H$3:H$3,Settings!$C$7,IF(Settings!$D$7="","",Settings!$D$7),"Dir=V","Dts=S","Sort=A","Days=T","Fill=B") | J4: =BDH(J$1,K$3:K$3,Settings!$C$7,IF(Settings!$D$7="","",Settings!$D$7),"Dir=V","Dts=S","Sort=A","Days=T","Fill=B") | M4: =BDH(M$1,N$3:N$3,Settings!$C$7,IF(Settings!$D$7="","",Settings!$D$7),"Dir=V","Dts=S","Sort=A","Days=T","Fill=B") | P4: =BDH(P$1,Q$3:Q$3,Settings!$C$7,IF(Settings!$D$7="","",Settings!$D$7),"Dir=V","Dts=S","Sort=A","Days=T","Fill=B") | S4: =BDH(S$1,T$3:T$3,Settings!$C$7,IF(Settings!$D$7="","",Settings!$D$7),"Dir=V","Dts=S","Sort=A","Days=T","Fill=B") | V4: =BDH(V$1,W$3:W$3,Settings!$C$7,IF(Settings!$D$7="","",Settings!$D$7),"Dir=V","Dts=S","Sort=A","Days=T","Fill=B") | Y4: =BDH(Y$1,Z$3:Z$3,Settings!$C$7,IF(Settings!$D$7="","",Settings!$D$7),"Dir=V","Dts=S","Sort=A","Days=T","Fill=B") | AB4: =BDH(AB$1,AC$3:AF$3,Settings!$C$7,IF(Settings!$D$7="","",Settings!$D$7),"Dir=V","Dts=S","Sort=A","Days=T","Fill=B") | AH4: =BDH(AH$1,AI$3:AJ$3,Settings!$C$7,IF(Settings!$D$7="","",Settings!$D$7),"Dir=V","Dts=S","Sort=A","Days=T","Fill=B") | AL4: =BDH(AL$1,AM$3:AM$3,Settings!$C$7,IF(Settings!$D$7="","",Settings!$D$7),"Dir=V","Dts=S","Sort=A","Days=T","Fill=B") | AO4: =BDH(AO$1,AP$3:AP$3,Settings!$C$7,IF(Settings!$D$7="","",Settings!$D$7),"Dir=V","Dts=S","Sort=A","Days=T","Fill=B") | AR4: =BDH(AR$1,AS$3:AS$3,Settings!$C$7,IF(Settings!$D$7="","",Settings!$D$7),"Dir=V","Dts=S","Sort=A","Days=T","Fill=B") | AU4: =BDH(AU$1,AV$3:AV$3,Settings!$C$7,IF(Settings!$D$7="","",Settings!$D$7),"Dir=V","Dts=S","Sort=A","Days=T","Fill=B") | AX4: =BDH(AX$1,AY$3:AY$3,Settings!$C$7,IF(Settings!$D$7="","",Settings!$D$7),"Dir=V","Dts=S","Sort=A","Days=T","Fill=B") | BA4: =BDH(BA$1,BB$3:BB$3,Settings!$C$7,IF(Settings!$D$7="","",Settings!$D$7),"Dir=V","Dts=S","Sort=A","Days=T","Fill=B") | BD4: =BDH(BD$1,BE$3:BE$3,Settings!$C$7,IF(Settings!$D$7="","",Settings!$D$7),"Dir=V","Dts=S","Sort=A","Days=T","Fill=B") | BG4: =BDH(BG$1,BH$3:BH$3,Settings!$C$7,IF(Settings!$D$7="","",Settings!$D$7),"Dir=V","Dts=S","Sort=A","Days=T","Fill=B")

Sheet Oil Futures
A1: =IF(Settings!$B$8="Y","CL1 Comdty","") | J1: =IF(Settings!$B$8="Y","CL2 Comdty","") | S1: =IF(Settings!$B$8="Y","CL3 Comdty","") | AB1: =IF(Settings!$B$8="Y","CL4 Comdty","") | AK1: =IF(Settings!$B$8="Y","CL5 Comdty","") | AT1: =IF(Settings!$B$8="Y","CL6 Comdty","") | BC1: =IF(Settings!$B$8="Y","CL7 Comdty","") | BL1: =IF(Settings!$B$8="Y","CL8 Comdty","") | BU1: =IF(Settings!$B$8="Y","CL9 Comdty","") | CD1: =IF(Settings!$B$8="Y","CL10 Comdty","") | CM1: =IF(Settings!$B$8="Y","CL11 Comdty","") | CV1: =IF(Settings!$B$8="Y","CL12 Comdty","") | DE1: =IF(Settings!$B$8="Y","CO1 Comdty","") | DN1: =IF(Settings!$B$8="Y","CO2 Comdty","") | DW1: =IF(Settings!$B$8="Y","CO3 Comdty","") | EF1: =IF(Settings!$B$8="Y","CO4 Comdty","") | EO1: =IF(Settings!$B$8="Y","CO5 Comdty","") | EX1: =IF(Settings!$B$8="Y","CO6 Comdty","") | FG1: =IF(Settings!$B$8="Y","HO1 Comdty","") | FP1: =IF(Settings!$B$8="Y","XB1 Comdty","") | FY1: =IF(Settings!$B$8="Y","QM1 Comdty","") | GH1: =IF(Settings!$B$8="Y","NG1 Comdty","")
A2: WTI crude, generic month 1 | J2: WTI crude, generic month 2 | S2: WTI crude, generic month 3 | AB2: WTI crude, generic month 4 | AK2: WTI crude, generic month 5 | AT2: WTI crude, generic month 6 | BC2: WTI crude, generic month 7 | BL2: WTI crude, generic month 8 | BU2: WTI crude, generic month 9 | CD2: WTI crude, generic month 10 | CM2: WTI crude, generic month 11 | CV2: WTI crude, generic month 12 | DE2: Brent crude, generic month 1 | DN2: Brent crude, generic month 2 | DW2: Brent crude, generic month 3 | EF2: Brent crude, generic month 4 | EO2: Brent crude, generic month 5 | EX2: Brent crude, generic month 6 | FG2: NY Harbor ULSD (heating oil), front | FP2: RBOB gasoline, front | FY2: E-mini WTI, front | GH2: Henry Hub natural gas, front
A3: Date | B3: PX_OPEN | C3: PX_HIGH | D3: PX_LOW | E3: PX_LAST | F3: PX_SETTLE | G3: PX_VOLUME | H3: OPEN_INT | J3: Date | K3: PX_OPEN | L3: PX_HIGH | M3: PX_LOW | N3: PX_LAST | O3: PX_SETTLE | P3: PX_VOLUME | Q3: OPEN_INT | S3: Date | T3: PX_OPEN | U3: PX_HIGH | V3: PX_LOW | W3: PX_LAST | X3: PX_SETTLE | Y3: PX_VOLUME | Z3: OPEN_INT | AB3: Date | AC3: PX_OPEN | AD3: PX_HIGH | AE3: PX_LOW | AF3: PX_LAST | AG3: PX_SETTLE | AH3: PX_VOLUME | AI3: OPEN_INT | AK3: Date | AL3: PX_OPEN | AM3: PX_HIGH | AN3: PX_LOW | AO3: PX_LAST | AP3: PX_SETTLE | AQ3: PX_VOLUME | AR3: OPEN_INT | AT3: Date | AU3: PX_OPEN | AV3: PX_HIGH | AW3: PX_LOW | AX3: PX_LAST | AY3: PX_SETTLE | AZ3: PX_VOLUME | BA3: OPEN_INT | BC3: Date | BD3: PX_OPEN | BE3: PX_HIGH | BF3: PX_LOW | BG3: PX_LAST | BH3: PX_SETTLE | BI3: PX_VOLUME | BJ3: OPEN_INT | BL3: Date | BM3: PX_OPEN | BN3: PX_HIGH | BO3: PX_LOW | BP3: PX_LAST | BQ3: PX_SETTLE | BR3: PX_VOLUME | BS3: OPEN_INT | BU3: Date | BV3: PX_OPEN | BW3: PX_HIGH | BX3: PX_LOW | BY3: PX_LAST | BZ3: PX_SETTLE | CA3: PX_VOLUME | CB3: OPEN_INT | CD3: Date | CE3: PX_OPEN | CF3: PX_HIGH | CG3: PX_LOW | CH3: PX_LAST | CI3: PX_SETTLE | CJ3: PX_VOLUME | CK3: OPEN_INT | CM3: Date | CN3: PX_OPEN | CO3: PX_HIGH | CP3: PX_LOW | CQ3: PX_LAST | CR3: PX_SETTLE | CS3: PX_VOLUME | CT3: OPEN_INT | CV3: Date | CW3: PX_OPEN | CX3: PX_HIGH | CY3: PX_LOW | CZ3: PX_LAST | DA3: PX_SETTLE | DB3: PX_VOLUME | DC3: OPEN_INT | DE3: Date | DF3: PX_OPEN | DG3: PX_HIGH | DH3: PX_LOW | DI3: PX_LAST | DJ3: PX_SETTLE | DK3: PX_VOLUME | DL3: OPEN_INT | DN3: Date | DO3: PX_OPEN | DP3: PX_HIGH | DQ3: PX_LOW | DR3: PX_LAST | DS3: PX_SETTLE | DT3: PX_VOLUME | DU3: OPEN_INT | DW3: Date | DX3: PX_OPEN | DY3: PX_HIGH | DZ3: PX_LOW | EA3: PX_LAST | EB3: PX_SETTLE | EC3: PX_VOLUME | ED3: OPEN_INT | EF3: Date | EG3: PX_OPEN | EH3: PX_HIGH | EI3: PX_LOW | EJ3: PX_LAST | EK3: PX_SETTLE | EL3: PX_VOLUME | EM3: OPEN_INT | EO3: Date | EP3: PX_OPEN | EQ3: PX_HIGH | ER3: PX_LOW | ES3: PX_LAST | ET3: PX_SETTLE | EU3: PX_VOLUME | EV3: OPEN_INT | EX3: Date | EY3: PX_OPEN | EZ3: PX_HIGH | FA3: PX_LOW | FB3: PX_LAST | FC3: PX_SETTLE | FD3: PX_VOLUME | FE3: OPEN_INT | FG3: Date | FH3: PX_OPEN | FI3: PX_HIGH | FJ3: PX_LOW | FK3: PX_LAST | FL3: PX_SETTLE | FM3: PX_VOLUME | FN3: OPEN_INT | FP3: Date | FQ3: PX_OPEN | FR3: PX_HIGH | FS3: PX_LOW | FT3: PX_LAST | FU3: PX_SETTLE | FV3: PX_VOLUME | FW3: OPEN_INT | FY3: Date | FZ3: PX_OPEN | GA3: PX_HIGH | GB3: PX_LOW | GC3: PX_LAST | GD3: PX_SETTLE | GE3: PX_VOLUME | GF3: OPEN_INT | GH3: Date | GI3: PX_OPEN | GJ3: PX_HIGH | GK3: PX_LOW | GL3: PX_LAST | GM3: PX_SETTLE | GN3: PX_VOLUME | GO3: OPEN_INT
A4: =BDH(A$1,B$3:H$3,Settings!$C$8,IF(Settings!$D$8="","",Settings!$D$8),"Dir=V","Dts=S","Sort=A","Days=T","Fill=B") | J4: =BDH(J$1,K$3:Q$3,Settings!$C$8,IF(Settings!$D$8="","",Settings!$D$8),"Dir=V","Dts=S","Sort=A","Days=T","Fill=B") | S4: =BDH(S$1,T$3:Z$3,Settings!$C$8,IF(Settings!$D$8="","",Settings!$D$8),"Dir=V","Dts=S","Sort=A","Days=T","Fill=B") | AB4: =BDH(AB$1,AC$3:AI$3,Settings!$C$8,IF(Settings!$D$8="","",Settings!$D$8),"Dir=V","Dts=S","Sort=A","Days=T","Fill=B") | AK4: =BDH(AK$1,AL$3:AR$3,Settings!$C$8,IF(Settings!$D$8="","",Settings!$D$8),"Dir=V","Dts=S","Sort=A","Days=T","Fill=B") | AT4: =BDH(AT$1,AU$3:BA$3,Settings!$C$8,IF(Settings!$D$8="","",Settings!$D$8),"Dir=V","Dts=S","Sort=A","Days=T","Fill=B") | BC4: =BDH(BC$1,BD$3:BJ$3,Settings!$C$8,IF(Settings!$D$8="","",Settings!$D$8),"Dir=V","Dts=S","Sort=A","Days=T","Fill=B") | BL4: =BDH(BL$1,BM$3:BS$3,Settings!$C$8,IF(Settings!$D$8="","",Settings!$D$8),"Dir=V","Dts=S","Sort=A","Days=T","Fill=B") | BU4: =BDH(BU$1,BV$3:CB$3,Settings!$C$8,IF(Settings!$D$8="","",Settings!$D$8),"Dir=V","Dts=S","Sort=A","Days=T","Fill=B") | CD4: =BDH(CD$1,CE$3:CK$3,Settings!$C$8,IF(Settings!$D$8="","",Settings!$D$8),"Dir=V","Dts=S","Sort=A","Days=T","Fill=B") | CM4: =BDH(CM$1,CN$3:CT$3,Settings!$C$8,IF(Settings!$D$8="","",Settings!$D$8),"Dir=V","Dts=S","Sort=A","Days=T","Fill=B") | CV4: =BDH(CV$1,CW$3:DC$3,Settings!$C$8,IF(Settings!$D$8="","",Settings!$D$8),"Dir=V","Dts=S","Sort=A","Days=T","Fill=B") | DE4: =BDH(DE$1,DF$3:DL$3,Settings!$C$8,IF(Settings!$D$8="","",Settings!$D$8),"Dir=V","Dts=S","Sort=A","Days=T","Fill=B") | DN4: =BDH(DN$1,DO$3:DU$3,Settings!$C$8,IF(Settings!$D$8="","",Settings!$D$8),"Dir=V","Dts=S","Sort=A","Days=T","Fill=B") | DW4: =BDH(DW$1,DX$3:ED$3,Settings!$C$8,IF(Settings!$D$8="","",Settings!$D$8),"Dir=V","Dts=S","Sort=A","Days=T","Fill=B") | EF4: =BDH(EF$1,EG$3:EM$3,Settings!$C$8,IF(Settings!$D$8="","",Settings!$D$8),"Dir=V","Dts=S","Sort=A","Days=T","Fill=B") | EO4: =BDH(EO$1,EP$3:EV$3,Settings!$C$8,IF(Settings!$D$8="","",Settings!$D$8),"Dir=V","Dts=S","Sort=A","Days=T","Fill=B") | EX4: =BDH(EX$1,EY$3:FE$3,Settings!$C$8,IF(Settings!$D$8="","",Settings!$D$8),"Dir=V","Dts=S","Sort=A","Days=T","Fill=B") | FG4: =BDH(FG$1,FH$3:FN$3,Settings!$C$8,IF(Settings!$D$8="","",Settings!$D$8),"Dir=V","Dts=S","Sort=A","Days=T","Fill=B") | FP4: =BDH(FP$1,FQ$3:FW$3,Settings!$C$8,IF(Settings!$D$8="","",Settings!$D$8),"Dir=V","Dts=S","Sort=A","Days=T","Fill=B") | FY4: =BDH(FY$1,FZ$3:GF$3,Settings!$C$8,IF(Settings!$D$8="","",Settings!$D$8),"Dir=V","Dts=S","Sort=A","Days=T","Fill=B") | GH4: =BDH(GH$1,GI$3:GO$3,Settings!$C$8,IF(Settings!$D$8="","",Settings!$D$8),"Dir=V","Dts=S","Sort=A","Days=T","Fill=B")

Sheet Oil Equities
A1: =IF(Settings!$B$8="Y","USO US Equity","") | H1: =IF(Settings!$B$8="Y","BNO US Equity","") | O1: =IF(Settings!$B$8="Y","USL US Equity","") | V1: =IF(Settings!$B$8="Y","DBO US Equity","") | AC1: =IF(Settings!$B$8="Y","UCO US Equity","") | AJ1: =IF(Settings!$B$8="Y","SCO US Equity","") | AQ1: =IF(Settings!$B$8="Y","XLE US Equity","") | AX1: =IF(Settings!$B$8="Y","XOP US Equity","") | BE1: =IF(Settings!$B$8="Y","OIH US Equity","") | BL1: =IF(Settings!$B$8="Y","VDE US Equity","") | BS1: =IF(Settings!$B$8="Y","CRAK US Equity","") | BZ1: =IF(Settings!$B$8="Y","XOM US Equity","") | CG1: =IF(Settings!$B$8="Y","CVX US Equity","") | CN1: =IF(Settings!$B$8="Y","COP US Equity","") | CU1: =IF(Settings!$B$8="Y","OXY US Equity","") | DB1: =IF(Settings!$B$8="Y","EOG US Equity","") | DI1: =IF(Settings!$B$8="Y","DVN US Equity","") | DP1: =IF(Settings!$B$8="Y","FANG US Equity","") | DW1: =IF(Settings!$B$8="Y","APA US Equity","") | ED1: =IF(Settings!$B$8="Y","DAL US Equity","") | EK1: =IF(Settings!$B$8="Y","UAL US Equity","") | ER1: =IF(Settings!$B$8="Y","AAL US Equity","") | EY1: =IF(Settings!$B$8="Y","LUV US Equity","") | FF1: =IF(Settings!$B$8="Y","JETS US Equity","") | FM1: =IF(Settings!$B$8="Y","SPY US Equity","")
A2: US Oil Fund (front WTI) | H2: US Brent Oil Fund | O2: US 12-Month Oil Fund | V2: Invesco DB Oil | AC2: ProShares 2x crude | AJ2: ProShares -2x crude | AQ2: Energy Select SPDR | AX2: S&P Oil & Gas E&P ETF | BE2: Oil services ETF | BL2: Vanguard energy ETF | BS2: Oil refiners ETF | BZ2: ExxonMobil | CG2: Chevron | CN2: ConocoPhillips | CU2: Occidental | DB2: EOG Resources | DI2: Devon | DP2: Diamondback | DW2: APA Corp | ED2: Delta Air Lines | EK2: United Airlines | ER2: American Airlines | EY2: Southwest | FF2: Airlines ETF | FM2: S&P 500 ETF
A3: Date | B3: PX_OPEN | C3: PX_HIGH | D3: PX_LOW | E3: PX_LAST | F3: PX_VOLUME | H3: Date | I3: PX_OPEN | J3: PX_HIGH | K3: PX_LOW | L3: PX_LAST | M3: PX_VOLUME | O3: Date | P3: PX_OPEN | Q3: PX_HIGH | R3: PX_LOW | S3: PX_LAST | T3: PX_VOLUME | V3: Date | W3: PX_OPEN | X3: PX_HIGH | Y3: PX_LOW | Z3: PX_LAST | AA3: PX_VOLUME | AC3: Date | AD3: PX_OPEN | AE3: PX_HIGH | AF3: PX_LOW | AG3: PX_LAST | AH3: PX_VOLUME | AJ3: Date | AK3: PX_OPEN | AL3: PX_HIGH | AM3: PX_LOW | AN3: PX_LAST | AO3: PX_VOLUME | AQ3: Date | AR3: PX_OPEN | AS3: PX_HIGH | AT3: PX_LOW | AU3: PX_LAST | AV3: PX_VOLUME | AX3: Date | AY3: PX_OPEN | AZ3: PX_HIGH | BA3: PX_LOW | BB3: PX_LAST | BC3: PX_VOLUME | BE3: Date | BF3: PX_OPEN | BG3: PX_HIGH | BH3: PX_LOW | BI3: PX_LAST | BJ3: PX_VOLUME | BL3: Date | BM3: PX_OPEN | BN3: PX_HIGH | BO3: PX_LOW | BP3: PX_LAST | BQ3: PX_VOLUME | BS3: Date | BT3: PX_OPEN | BU3: PX_HIGH | BV3: PX_LOW | BW3: PX_LAST | BX3: PX_VOLUME | BZ3: Date | CA3: PX_OPEN | CB3: PX_HIGH | CC3: PX_LOW | CD3: PX_LAST | CE3: PX_VOLUME | CG3: Date | CH3: PX_OPEN | CI3: PX_HIGH | CJ3: PX_LOW | CK3: PX_LAST | CL3: PX_VOLUME | CN3: Date | CO3: PX_OPEN | CP3: PX_HIGH | CQ3: PX_LOW | CR3: PX_LAST | CS3: PX_VOLUME | CU3: Date | CV3: PX_OPEN | CW3: PX_HIGH | CX3: PX_LOW | CY3: PX_LAST | CZ3: PX_VOLUME | DB3: Date | DC3: PX_OPEN | DD3: PX_HIGH | DE3: PX_LOW | DF3: PX_LAST | DG3: PX_VOLUME | DI3: Date | DJ3: PX_OPEN | DK3: PX_HIGH | DL3: PX_LOW | DM3: PX_LAST | DN3: PX_VOLUME | DP3: Date | DQ3: PX_OPEN | DR3: PX_HIGH | DS3: PX_LOW | DT3: PX_LAST | DU3: PX_VOLUME | DW3: Date | DX3: PX_OPEN | DY3: PX_HIGH | DZ3: PX_LOW | EA3: PX_LAST | EB3: PX_VOLUME | ED3: Date | EE3: PX_OPEN | EF3: PX_HIGH | EG3: PX_LOW | EH3: PX_LAST | EI3: PX_VOLUME | EK3: Date | EL3: PX_OPEN | EM3: PX_HIGH | EN3: PX_LOW | EO3: PX_LAST | EP3: PX_VOLUME | ER3: Date | ES3: PX_OPEN | ET3: PX_HIGH | EU3: PX_LOW | EV3: PX_LAST | EW3: PX_VOLUME | EY3: Date | EZ3: PX_OPEN | FA3: PX_HIGH | FB3: PX_LOW | FC3: PX_LAST | FD3: PX_VOLUME | FF3: Date | FG3: PX_OPEN | FH3: PX_HIGH | FI3: PX_LOW | FJ3: PX_LAST | FK3: PX_VOLUME | FM3: Date | FN3: PX_OPEN | FO3: PX_HIGH | FP3: PX_LOW | FQ3: PX_LAST | FR3: PX_VOLUME
A4: =BDH(A$1,B$3:F$3,Settings!$C$8,IF(Settings!$D$8="","",Settings!$D$8),"Dir=V","Dts=S","Sort=A","Days=T","Fill=B") | H4: =BDH(H$1,I$3:M$3,Settings!$C$8,IF(Settings!$D$8="","",Settings!$D$8),"Dir=V","Dts=S","Sort=A","Days=T","Fill=B") | O4: =BDH(O$1,P$3:T$3,Settings!$C$8,IF(Settings!$D$8="","",Settings!$D$8),"Dir=V","Dts=S","Sort=A","Days=T","Fill=B") | V4: =BDH(V$1,W$3:AA$3,Settings!$C$8,IF(Settings!$D$8="","",Settings!$D$8),"Dir=V","Dts=S","Sort=A","Days=T","Fill=B") | AC4: =BDH(AC$1,AD$3:AH$3,Settings!$C$8,IF(Settings!$D$8="","",Settings!$D$8),"Dir=V","Dts=S","Sort=A","Days=T","Fill=B") | AJ4: =BDH(AJ$1,AK$3:AO$3,Settings!$C$8,IF(Settings!$D$8="","",Settings!$D$8),"Dir=V","Dts=S","Sort=A","Days=T","Fill=B") | AQ4: =BDH(AQ$1,AR$3:AV$3,Settings!$C$8,IF(Settings!$D$8="","",Settings!$D$8),"Dir=V","Dts=S","Sort=A","Days=T","Fill=B") | AX4: =BDH(AX$1,AY$3:BC$3,Settings!$C$8,IF(Settings!$D$8="","",Settings!$D$8),"Dir=V","Dts=S","Sort=A","Days=T","Fill=B") | BE4: =BDH(BE$1,BF$3:BJ$3,Settings!$C$8,IF(Settings!$D$8="","",Settings!$D$8),"Dir=V","Dts=S","Sort=A","Days=T","Fill=B") | BL4: =BDH(BL$1,BM$3:BQ$3,Settings!$C$8,IF(Settings!$D$8="","",Settings!$D$8),"Dir=V","Dts=S","Sort=A","Days=T","Fill=B") | BS4: =BDH(BS$1,BT$3:BX$3,Settings!$C$8,IF(Settings!$D$8="","",Settings!$D$8),"Dir=V","Dts=S","Sort=A","Days=T","Fill=B") | BZ4: =BDH(BZ$1,CA$3:CE$3,Settings!$C$8,IF(Settings!$D$8="","",Settings!$D$8),"Dir=V","Dts=S","Sort=A","Days=T","Fill=B") | CG4: =BDH(CG$1,CH$3:CL$3,Settings!$C$8,IF(Settings!$D$8="","",Settings!$D$8),"Dir=V","Dts=S","Sort=A","Days=T","Fill=B") | CN4: =BDH(CN$1,CO$3:CS$3,Settings!$C$8,IF(Settings!$D$8="","",Settings!$D$8),"Dir=V","Dts=S","Sort=A","Days=T","Fill=B") | CU4: =BDH(CU$1,CV$3:CZ$3,Settings!$C$8,IF(Settings!$D$8="","",Settings!$D$8),"Dir=V","Dts=S","Sort=A","Days=T","Fill=B") | DB4: =BDH(DB$1,DC$3:DG$3,Settings!$C$8,IF(Settings!$D$8="","",Settings!$D$8),"Dir=V","Dts=S","Sort=A","Days=T","Fill=B") | DI4: =BDH(DI$1,DJ$3:DN$3,Settings!$C$8,IF(Settings!$D$8="","",Settings!$D$8),"Dir=V","Dts=S","Sort=A","Days=T","Fill=B") | DP4: =BDH(DP$1,DQ$3:DU$3,Settings!$C$8,IF(Settings!$D$8="","",Settings!$D$8),"Dir=V","Dts=S","Sort=A","Days=T","Fill=B") | DW4: =BDH(DW$1,DX$3:EB$3,Settings!$C$8,IF(Settings!$D$8="","",Settings!$D$8),"Dir=V","Dts=S","Sort=A","Days=T","Fill=B") | ED4: =BDH(ED$1,EE$3:EI$3,Settings!$C$8,IF(Settings!$D$8="","",Settings!$D$8),"Dir=V","Dts=S","Sort=A","Days=T","Fill=B") | EK4: =BDH(EK$1,EL$3:EP$3,Settings!$C$8,IF(Settings!$D$8="","",Settings!$D$8),"Dir=V","Dts=S","Sort=A","Days=T","Fill=B") | ER4: =BDH(ER$1,ES$3:EW$3,Settings!$C$8,IF(Settings!$D$8="","",Settings!$D$8),"Dir=V","Dts=S","Sort=A","Days=T","Fill=B") | EY4: =BDH(EY$1,EZ$3:FD$3,Settings!$C$8,IF(Settings!$D$8="","",Settings!$D$8),"Dir=V","Dts=S","Sort=A","Days=T","Fill=B") | FF4: =BDH(FF$1,FG$3:FK$3,Settings!$C$8,IF(Settings!$D$8="","",Settings!$D$8),"Dir=V","Dts=S","Sort=A","Days=T","Fill=B") | FM4: =BDH(FM$1,FN$3:FR$3,Settings!$C$8,IF(Settings!$D$8="","",Settings!$D$8),"Dir=V","Dts=S","Sort=A","Days=T","Fill=B")

Sheet Oil Equities Unadj
A1: =IF(Settings!$B$8="Y","USO US Equity","") | D1: =IF(Settings!$B$8="Y","BNO US Equity","") | G1: =IF(Settings!$B$8="Y","USL US Equity","") | J1: =IF(Settings!$B$8="Y","DBO US Equity","") | M1: =IF(Settings!$B$8="Y","UCO US Equity","") | P1: =IF(Settings!$B$8="Y","SCO US Equity","") | S1: =IF(Settings!$B$8="Y","XLE US Equity","") | V1: =IF(Settings!$B$8="Y","XOP US Equity","") | Y1: =IF(Settings!$B$8="Y","OIH US Equity","") | AB1: =IF(Settings!$B$8="Y","VDE US Equity","") | AE1: =IF(Settings!$B$8="Y","CRAK US Equity","") | AH1: =IF(Settings!$B$8="Y","XOM US Equity","") | AK1: =IF(Settings!$B$8="Y","CVX US Equity","") | AN1: =IF(Settings!$B$8="Y","COP US Equity","") | AQ1: =IF(Settings!$B$8="Y","OXY US Equity","") | AT1: =IF(Settings!$B$8="Y","EOG US Equity","") | AW1: =IF(Settings!$B$8="Y","DVN US Equity","") | AZ1: =IF(Settings!$B$8="Y","FANG US Equity","") | BC1: =IF(Settings!$B$8="Y","APA US Equity","") | BF1: =IF(Settings!$B$8="Y","DAL US Equity","") | BI1: =IF(Settings!$B$8="Y","UAL US Equity","") | BL1: =IF(Settings!$B$8="Y","AAL US Equity","") | BO1: =IF(Settings!$B$8="Y","LUV US Equity","") | BR1: =IF(Settings!$B$8="Y","JETS US Equity","") | BU1: =IF(Settings!$B$8="Y","SPY US Equity","")
A2: US Oil Fund (front WTI) (unadjusted close) | D2: US Brent Oil Fund (unadjusted close) | G2: US 12-Month Oil Fund (unadjusted close) | J2: Invesco DB Oil (unadjusted close) | M2: ProShares 2x crude (unadjusted close) | P2: ProShares -2x crude (unadjusted close) | S2: Energy Select SPDR (unadjusted close) | V2: S&P Oil & Gas E&P ETF (unadjusted close) | Y2: Oil services ETF (unadjusted close) | AB2: Vanguard energy ETF (unadjusted close) | AE2: Oil refiners ETF (unadjusted close) | AH2: ExxonMobil (unadjusted close) | AK2: Chevron (unadjusted close) | AN2: ConocoPhillips (unadjusted close) | AQ2: Occidental (unadjusted close) | AT2: EOG Resources (unadjusted close) | AW2: Devon (unadjusted close) | AZ2: Diamondback (unadjusted close) | BC2: APA Corp (unadjusted close) | BF2: Delta Air Lines (unadjusted close) | BI2: United Airlines (unadjusted close) | BL2: American Airlines (unadjusted close) | BO2: Southwest (unadjusted close) | BR2: Airlines ETF (unadjusted close) | BU2: S&P 500 ETF (unadjusted close)
A3: Date | B3: PX_LAST | D3: Date | E3: PX_LAST | G3: Date | H3: PX_LAST | J3: Date | K3: PX_LAST | M3: Date | N3: PX_LAST | P3: Date | Q3: PX_LAST | S3: Date | T3: PX_LAST | V3: Date | W3: PX_LAST | Y3: Date | Z3: PX_LAST | AB3: Date | AC3: PX_LAST | AE3: Date | AF3: PX_LAST | AH3: Date | AI3: PX_LAST | AK3: Date | AL3: PX_LAST | AN3: Date | AO3: PX_LAST | AQ3: Date | AR3: PX_LAST | AT3: Date | AU3: PX_LAST | AW3: Date | AX3: PX_LAST | AZ3: Date | BA3: PX_LAST | BC3: Date | BD3: PX_LAST | BF3: Date | BG3: PX_LAST | BI3: Date | BJ3: PX_LAST | BL3: Date | BM3: PX_LAST | BO3: Date | BP3: PX_LAST | BR3: Date | BS3: PX_LAST | BU3: Date | BV3: PX_LAST
A4: =BDH(A$1,B$3:B$3,Settings!$C$8,IF(Settings!$D$8="","",Settings!$D$8),"Dir=V","Dts=S","Sort=A","Days=T","Fill=B","CshAdjNormal=N","CshAdjAbnormal=N","CapChg=N") | D4: =BDH(D$1,E$3:E$3,Settings!$C$8,IF(Settings!$D$8="","",Settings!$D$8),"Dir=V","Dts=S","Sort=A","Days=T","Fill=B","CshAdjNormal=N","CshAdjAbnormal=N","CapChg=N") | G4: =BDH(G$1,H$3:H$3,Settings!$C$8,IF(Settings!$D$8="","",Settings!$D$8),"Dir=V","Dts=S","Sort=A","Days=T","Fill=B","CshAdjNormal=N","CshAdjAbnormal=N","CapChg=N") | J4: =BDH(J$1,K$3:K$3,Settings!$C$8,IF(Settings!$D$8="","",Settings!$D$8),"Dir=V","Dts=S","Sort=A","Days=T","Fill=B","CshAdjNormal=N","CshAdjAbnormal=N","CapChg=N") | M4: =BDH(M$1,N$3:N$3,Settings!$C$8,IF(Settings!$D$8="","",Settings!$D$8),"Dir=V","Dts=S","Sort=A","Days=T","Fill=B","CshAdjNormal=N","CshAdjAbnormal=N","CapChg=N") | P4: =BDH(P$1,Q$3:Q$3,Settings!$C$8,IF(Settings!$D$8="","",Settings!$D$8),"Dir=V","Dts=S","Sort=A","Days=T","Fill=B","CshAdjNormal=N","CshAdjAbnormal=N","CapChg=N") | S4: =BDH(S$1,T$3:T$3,Settings!$C$8,IF(Settings!$D$8="","",Settings!$D$8),"Dir=V","Dts=S","Sort=A","Days=T","Fill=B","CshAdjNormal=N","CshAdjAbnormal=N","CapChg=N") | V4: =BDH(V$1,W$3:W$3,Settings!$C$8,IF(Settings!$D$8="","",Settings!$D$8),"Dir=V","Dts=S","Sort=A","Days=T","Fill=B","CshAdjNormal=N","CshAdjAbnormal=N","CapChg=N") | Y4: =BDH(Y$1,Z$3:Z$3,Settings!$C$8,IF(Settings!$D$8="","",Settings!$D$8),"Dir=V","Dts=S","Sort=A","Days=T","Fill=B","CshAdjNormal=N","CshAdjAbnormal=N","CapChg=N") | AB4: =BDH(AB$1,AC$3:AC$3,Settings!$C$8,IF(Settings!$D$8="","",Settings!$D$8),"Dir=V","Dts=S","Sort=A","Days=T","Fill=B","CshAdjNormal=N","CshAdjAbnormal=N","CapChg=N") | AE4: =BDH(AE$1,AF$3:AF$3,Settings!$C$8,IF(Settings!$D$8="","",Settings!$D$8),"Dir=V","Dts=S","Sort=A","Days=T","Fill=B","CshAdjNormal=N","CshAdjAbnormal=N","CapChg=N") | AH4: =BDH(AH$1,AI$3:AI$3,Settings!$C$8,IF(Settings!$D$8="","",Settings!$D$8),"Dir=V","Dts=S","Sort=A","Days=T","Fill=B","CshAdjNormal=N","CshAdjAbnormal=N","CapChg=N") | AK4: =BDH(AK$1,AL$3:AL$3,Settings!$C$8,IF(Settings!$D$8="","",Settings!$D$8),"Dir=V","Dts=S","Sort=A","Days=T","Fill=B","CshAdjNormal=N","CshAdjAbnormal=N","CapChg=N") | AN4: =BDH(AN$1,AO$3:AO$3,Settings!$C$8,IF(Settings!$D$8="","",Settings!$D$8),"Dir=V","Dts=S","Sort=A","Days=T","Fill=B","CshAdjNormal=N","CshAdjAbnormal=N","CapChg=N") | AQ4: =BDH(AQ$1,AR$3:AR$3,Settings!$C$8,IF(Settings!$D$8="","",Settings!$D$8),"Dir=V","Dts=S","Sort=A","Days=T","Fill=B","CshAdjNormal=N","CshAdjAbnormal=N","CapChg=N") | AT4: =BDH(AT$1,AU$3:AU$3,Settings!$C$8,IF(Settings!$D$8="","",Settings!$D$8),"Dir=V","Dts=S","Sort=A","Days=T","Fill=B","CshAdjNormal=N","CshAdjAbnormal=N","CapChg=N") | AW4: =BDH(AW$1,AX$3:AX$3,Settings!$C$8,IF(Settings!$D$8="","",Settings!$D$8),"Dir=V","Dts=S","Sort=A","Days=T","Fill=B","CshAdjNormal=N","CshAdjAbnormal=N","CapChg=N") | AZ4: =BDH(AZ$1,BA$3:BA$3,Settings!$C$8,IF(Settings!$D$8="","",Settings!$D$8),"Dir=V","Dts=S","Sort=A","Days=T","Fill=B","CshAdjNormal=N","CshAdjAbnormal=N","CapChg=N") | BC4: =BDH(BC$1,BD$3:BD$3,Settings!$C$8,IF(Settings!$D$8="","",Settings!$D$8),"Dir=V","Dts=S","Sort=A","Days=T","Fill=B","CshAdjNormal=N","CshAdjAbnormal=N","CapChg=N") | BF4: =BDH(BF$1,BG$3:BG$3,Settings!$C$8,IF(Settings!$D$8="","",Settings!$D$8),"Dir=V","Dts=S","Sort=A","Days=T","Fill=B","CshAdjNormal=N","CshAdjAbnormal=N","CapChg=N") | BI4: =BDH(BI$1,BJ$3:BJ$3,Settings!$C$8,IF(Settings!$D$8="","",Settings!$D$8),"Dir=V","Dts=S","Sort=A","Days=T","Fill=B","CshAdjNormal=N","CshAdjAbnormal=N","CapChg=N") | BL4: =BDH(BL$1,BM$3:BM$3,Settings!$C$8,IF(Settings!$D$8="","",Settings!$D$8),"Dir=V","Dts=S","Sort=A","Days=T","Fill=B","CshAdjNormal=N","CshAdjAbnormal=N","CapChg=N") | BO4: =BDH(BO$1,BP$3:BP$3,Settings!$C$8,IF(Settings!$D$8="","",Settings!$D$8),"Dir=V","Dts=S","Sort=A","Days=T","Fill=B","CshAdjNormal=N","CshAdjAbnormal=N","CapChg=N") | BR4: =BDH(BR$1,BS$3:BS$3,Settings!$C$8,IF(Settings!$D$8="","",Settings!$D$8),"Dir=V","Dts=S","Sort=A","Days=T","Fill=B","CshAdjNormal=N","CshAdjAbnormal=N","CapChg=N") | BU4: =BDH(BU$1,BV$3:BV$3,Settings!$C$8,IF(Settings!$D$8="","",Settings!$D$8),"Dir=V","Dts=S","Sort=A","Days=T","Fill=B","CshAdjNormal=N","CshAdjAbnormal=N","CapChg=N")

Sheet Macro
A1: =IF(Settings!$B$8="Y","OVX Index","") | G1: =IF(Settings!$B$8="Y","VIX Index","") | J1: =IF(Settings!$B$8="Y","SPX Index","") | M1: =IF(Settings!$B$8="Y","USGG3M Index","") | P1: =IF(Settings!$B$8="Y","USGG1YR Index","") | S1: =IF(Settings!$B$8="Y","USGG2YR Index","") | V1: =IF(Settings!$B$8="Y","DXY Curncy","")
A2: Cboe crude oil volatility index | G2: Cboe VIX | J2: S&P 500 | M2: US 3-month T-bill yield (risk-free rate) | P2: US 1-year Treasury yield | S2: US 2-year Treasury yield | V2: US dollar index
A3: Date | B3: PX_OPEN | C3: PX_HIGH | D3: PX_LOW | E3: PX_LAST | G3: Date | H3: PX_LAST | J3: Date | K3: PX_LAST | M3: Date | N3: PX_LAST | P3: Date | Q3: PX_LAST | S3: Date | T3: PX_LAST | V3: Date | W3: PX_LAST
A4: =BDH(A$1,B$3:E$3,Settings!$C$8,IF(Settings!$D$8="","",Settings!$D$8),"Dir=V","Dts=S","Sort=A","Days=T","Fill=B") | G4: =BDH(G$1,H$3:H$3,Settings!$C$8,IF(Settings!$D$8="","",Settings!$D$8),"Dir=V","Dts=S","Sort=A","Days=T","Fill=B") | J4: =BDH(J$1,K$3:K$3,Settings!$C$8,IF(Settings!$D$8="","",Settings!$D$8),"Dir=V","Dts=S","Sort=A","Days=T","Fill=B") | M4: =BDH(M$1,N$3:N$3,Settings!$C$8,IF(Settings!$D$8="","",Settings!$D$8),"Dir=V","Dts=S","Sort=A","Days=T","Fill=B") | P4: =BDH(P$1,Q$3:Q$3,Settings!$C$8,IF(Settings!$D$8="","",Settings!$D$8),"Dir=V","Dts=S","Sort=A","Days=T","Fill=B") | S4: =BDH(S$1,T$3:T$3,Settings!$C$8,IF(Settings!$D$8="","",Settings!$D$8),"Dir=V","Dts=S","Sort=A","Days=T","Fill=B") | V4: =BDH(V$1,W$3:W$3,Settings!$C$8,IF(Settings!$D$8="","",Settings!$D$8),"Dir=V","Dts=S","Sort=A","Days=T","Fill=B")

Sheet Vol CL1
A1: =IF(Settings!$B$9="Y","CL1 Comdty","") | AA1: =IF(Settings!$B$9="Y","CL1 Comdty","")
A2: implied-vol surface (moneyness) | AA2: implied-vol surface (delta, realized, volume)
A3: Date | B3: 30DAY_IMPVOL_90.0%MNY_DF | C3: 30DAY_IMPVOL_95.0%MNY_DF | D3: 30DAY_IMPVOL_100.0%MNY_DF | E3: 30DAY_IMPVOL_105.0%MNY_DF | F3: 30DAY_IMPVOL_110.0%MNY_DF | G3: 60DAY_IMPVOL_90.0%MNY_DF | H3: 60DAY_IMPVOL_95.0%MNY_DF | I3: 60DAY_IMPVOL_100.0%MNY_DF | J3: 60DAY_IMPVOL_105.0%MNY_DF | K3: 60DAY_IMPVOL_110.0%MNY_DF | L3: 3MTH_IMPVOL_90.0%MNY_DF | M3: 3MTH_IMPVOL_95.0%MNY_DF | N3: 3MTH_IMPVOL_100.0%MNY_DF | O3: 3MTH_IMPVOL_105.0%MNY_DF | P3: 3MTH_IMPVOL_110.0%MNY_DF | Q3: 6MTH_IMPVOL_90.0%MNY_DF | R3: 6MTH_IMPVOL_95.0%MNY_DF | S3: 6MTH_IMPVOL_100.0%MNY_DF | T3: 6MTH_IMPVOL_105.0%MNY_DF | U3: 6MTH_IMPVOL_110.0%MNY_DF | V3: 1M_CALL_IMP_VOL_10DELTA_DFLT | W3: 1M_CALL_IMP_VOL_25DELTA_DFLT | X3: 1M_CALL_IMP_VOL_50DELTA_DFLT | Y3: 1M_PUT_IMP_VOL_10DELTA_DFLT | AA3: Date | AB3: 1M_PUT_IMP_VOL_25DELTA_DFLT | AC3: 1M_PUT_IMP_VOL_50DELTA_DFLT | AD3: 2M_CALL_IMP_VOL_10DELTA_DFLT | AE3: 2M_CALL_IMP_VOL_25DELTA_DFLT | AF3: 2M_CALL_IMP_VOL_50DELTA_DFLT | AG3: 2M_PUT_IMP_VOL_10DELTA_DFLT | AH3: 2M_PUT_IMP_VOL_25DELTA_DFLT | AI3: 2M_PUT_IMP_VOL_50DELTA_DFLT | AJ3: 3M_CALL_IMP_VOL_10DELTA_DFLT | AK3: 3M_CALL_IMP_VOL_25DELTA_DFLT | AL3: 3M_CALL_IMP_VOL_50DELTA_DFLT | AM3: 3M_PUT_IMP_VOL_10DELTA_DFLT | AN3: 3M_PUT_IMP_VOL_25DELTA_DFLT | AO3: 3M_PUT_IMP_VOL_50DELTA_DFLT | AP3: HIST_CALL_IMP_VOL | AQ3: HIST_PUT_IMP_VOL | AR3: VOLATILITY_10D | AS3: VOLATILITY_30D | AT3: VOLATILITY_90D | AU3: PUT_CALL_VOLUME_RATIO_CUR_DAY | AV3: OPEN_INT_TOTAL_CALL | AW3: OPEN_INT_TOTAL_PUT | AX3: VOLUME_TOTAL_CALL | AY3: VOLUME_TOTAL_PUT
A4: =BDH(A$1,B$3:Y$3,Settings!$C$9,IF(Settings!$D$9="","",Settings!$D$9),"Dir=V","Dts=S","Sort=A","Days=T","Fill=B") | AA4: =BDH(AA$1,AB$3:AY$3,Settings!$C$9,IF(Settings!$D$9="","",Settings!$D$9),"Dir=V","Dts=S","Sort=A","Days=T","Fill=B")

Sheet Vol CL2
A1: =IF(Settings!$B$9="Y","CL2 Comdty","") | AA1: =IF(Settings!$B$9="Y","CL2 Comdty","")
A2: implied-vol surface (moneyness) | AA2: implied-vol surface (delta, realized, volume)
A3: Date | B3: 30DAY_IMPVOL_90.0%MNY_DF | C3: 30DAY_IMPVOL_95.0%MNY_DF | D3: 30DAY_IMPVOL_100.0%MNY_DF | E3: 30DAY_IMPVOL_105.0%MNY_DF | F3: 30DAY_IMPVOL_110.0%MNY_DF | G3: 60DAY_IMPVOL_90.0%MNY_DF | H3: 60DAY_IMPVOL_95.0%MNY_DF | I3: 60DAY_IMPVOL_100.0%MNY_DF | J3: 60DAY_IMPVOL_105.0%MNY_DF | K3: 60DAY_IMPVOL_110.0%MNY_DF | L3: 3MTH_IMPVOL_90.0%MNY_DF | M3: 3MTH_IMPVOL_95.0%MNY_DF | N3: 3MTH_IMPVOL_100.0%MNY_DF | O3: 3MTH_IMPVOL_105.0%MNY_DF | P3: 3MTH_IMPVOL_110.0%MNY_DF | Q3: 6MTH_IMPVOL_90.0%MNY_DF | R3: 6MTH_IMPVOL_95.0%MNY_DF | S3: 6MTH_IMPVOL_100.0%MNY_DF | T3: 6MTH_IMPVOL_105.0%MNY_DF | U3: 6MTH_IMPVOL_110.0%MNY_DF | V3: 1M_CALL_IMP_VOL_10DELTA_DFLT | W3: 1M_CALL_IMP_VOL_25DELTA_DFLT | X3: 1M_CALL_IMP_VOL_50DELTA_DFLT | Y3: 1M_PUT_IMP_VOL_10DELTA_DFLT | AA3: Date | AB3: 1M_PUT_IMP_VOL_25DELTA_DFLT | AC3: 1M_PUT_IMP_VOL_50DELTA_DFLT | AD3: 2M_CALL_IMP_VOL_10DELTA_DFLT | AE3: 2M_CALL_IMP_VOL_25DELTA_DFLT | AF3: 2M_CALL_IMP_VOL_50DELTA_DFLT | AG3: 2M_PUT_IMP_VOL_10DELTA_DFLT | AH3: 2M_PUT_IMP_VOL_25DELTA_DFLT | AI3: 2M_PUT_IMP_VOL_50DELTA_DFLT | AJ3: 3M_CALL_IMP_VOL_10DELTA_DFLT | AK3: 3M_CALL_IMP_VOL_25DELTA_DFLT | AL3: 3M_CALL_IMP_VOL_50DELTA_DFLT | AM3: 3M_PUT_IMP_VOL_10DELTA_DFLT | AN3: 3M_PUT_IMP_VOL_25DELTA_DFLT | AO3: 3M_PUT_IMP_VOL_50DELTA_DFLT | AP3: HIST_CALL_IMP_VOL | AQ3: HIST_PUT_IMP_VOL | AR3: VOLATILITY_10D | AS3: VOLATILITY_30D | AT3: VOLATILITY_90D | AU3: PUT_CALL_VOLUME_RATIO_CUR_DAY | AV3: OPEN_INT_TOTAL_CALL | AW3: OPEN_INT_TOTAL_PUT | AX3: VOLUME_TOTAL_CALL | AY3: VOLUME_TOTAL_PUT
A4: =BDH(A$1,B$3:Y$3,Settings!$C$9,IF(Settings!$D$9="","",Settings!$D$9),"Dir=V","Dts=S","Sort=A","Days=T","Fill=B") | AA4: =BDH(AA$1,AB$3:AY$3,Settings!$C$9,IF(Settings!$D$9="","",Settings!$D$9),"Dir=V","Dts=S","Sort=A","Days=T","Fill=B")

Sheet Vol CO1
A1: =IF(Settings!$B$9="Y","CO1 Comdty","") | AA1: =IF(Settings!$B$9="Y","CO1 Comdty","")
A2: implied-vol surface (moneyness) | AA2: implied-vol surface (delta, realized, volume)
A3: Date | B3: 30DAY_IMPVOL_90.0%MNY_DF | C3: 30DAY_IMPVOL_95.0%MNY_DF | D3: 30DAY_IMPVOL_100.0%MNY_DF | E3: 30DAY_IMPVOL_105.0%MNY_DF | F3: 30DAY_IMPVOL_110.0%MNY_DF | G3: 60DAY_IMPVOL_90.0%MNY_DF | H3: 60DAY_IMPVOL_95.0%MNY_DF | I3: 60DAY_IMPVOL_100.0%MNY_DF | J3: 60DAY_IMPVOL_105.0%MNY_DF | K3: 60DAY_IMPVOL_110.0%MNY_DF | L3: 3MTH_IMPVOL_90.0%MNY_DF | M3: 3MTH_IMPVOL_95.0%MNY_DF | N3: 3MTH_IMPVOL_100.0%MNY_DF | O3: 3MTH_IMPVOL_105.0%MNY_DF | P3: 3MTH_IMPVOL_110.0%MNY_DF | Q3: 6MTH_IMPVOL_90.0%MNY_DF | R3: 6MTH_IMPVOL_95.0%MNY_DF | S3: 6MTH_IMPVOL_100.0%MNY_DF | T3: 6MTH_IMPVOL_105.0%MNY_DF | U3: 6MTH_IMPVOL_110.0%MNY_DF | V3: 1M_CALL_IMP_VOL_10DELTA_DFLT | W3: 1M_CALL_IMP_VOL_25DELTA_DFLT | X3: 1M_CALL_IMP_VOL_50DELTA_DFLT | Y3: 1M_PUT_IMP_VOL_10DELTA_DFLT | AA3: Date | AB3: 1M_PUT_IMP_VOL_25DELTA_DFLT | AC3: 1M_PUT_IMP_VOL_50DELTA_DFLT | AD3: 2M_CALL_IMP_VOL_10DELTA_DFLT | AE3: 2M_CALL_IMP_VOL_25DELTA_DFLT | AF3: 2M_CALL_IMP_VOL_50DELTA_DFLT | AG3: 2M_PUT_IMP_VOL_10DELTA_DFLT | AH3: 2M_PUT_IMP_VOL_25DELTA_DFLT | AI3: 2M_PUT_IMP_VOL_50DELTA_DFLT | AJ3: 3M_CALL_IMP_VOL_10DELTA_DFLT | AK3: 3M_CALL_IMP_VOL_25DELTA_DFLT | AL3: 3M_CALL_IMP_VOL_50DELTA_DFLT | AM3: 3M_PUT_IMP_VOL_10DELTA_DFLT | AN3: 3M_PUT_IMP_VOL_25DELTA_DFLT | AO3: 3M_PUT_IMP_VOL_50DELTA_DFLT | AP3: HIST_CALL_IMP_VOL | AQ3: HIST_PUT_IMP_VOL | AR3: VOLATILITY_10D | AS3: VOLATILITY_30D | AT3: VOLATILITY_90D | AU3: PUT_CALL_VOLUME_RATIO_CUR_DAY | AV3: OPEN_INT_TOTAL_CALL | AW3: OPEN_INT_TOTAL_PUT | AX3: VOLUME_TOTAL_CALL | AY3: VOLUME_TOTAL_PUT
A4: =BDH(A$1,B$3:Y$3,Settings!$C$9,IF(Settings!$D$9="","",Settings!$D$9),"Dir=V","Dts=S","Sort=A","Days=T","Fill=B") | AA4: =BDH(AA$1,AB$3:AY$3,Settings!$C$9,IF(Settings!$D$9="","",Settings!$D$9),"Dir=V","Dts=S","Sort=A","Days=T","Fill=B")

Sheet Vol USO
A1: =IF(Settings!$B$9="Y","USO US Equity","") | AA1: =IF(Settings!$B$9="Y","USO US Equity","")
A2: implied-vol surface (moneyness) | AA2: implied-vol surface (delta, realized, volume)
A3: Date | B3: 30DAY_IMPVOL_90.0%MNY_DF | C3: 30DAY_IMPVOL_95.0%MNY_DF | D3: 30DAY_IMPVOL_100.0%MNY_DF | E3: 30DAY_IMPVOL_105.0%MNY_DF | F3: 30DAY_IMPVOL_110.0%MNY_DF | G3: 60DAY_IMPVOL_90.0%MNY_DF | H3: 60DAY_IMPVOL_95.0%MNY_DF | I3: 60DAY_IMPVOL_100.0%MNY_DF | J3: 60DAY_IMPVOL_105.0%MNY_DF | K3: 60DAY_IMPVOL_110.0%MNY_DF | L3: 3MTH_IMPVOL_90.0%MNY_DF | M3: 3MTH_IMPVOL_95.0%MNY_DF | N3: 3MTH_IMPVOL_100.0%MNY_DF | O3: 3MTH_IMPVOL_105.0%MNY_DF | P3: 3MTH_IMPVOL_110.0%MNY_DF | Q3: 6MTH_IMPVOL_90.0%MNY_DF | R3: 6MTH_IMPVOL_95.0%MNY_DF | S3: 6MTH_IMPVOL_100.0%MNY_DF | T3: 6MTH_IMPVOL_105.0%MNY_DF | U3: 6MTH_IMPVOL_110.0%MNY_DF | V3: 1M_CALL_IMP_VOL_10DELTA_DFLT | W3: 1M_CALL_IMP_VOL_25DELTA_DFLT | X3: 1M_CALL_IMP_VOL_50DELTA_DFLT | Y3: 1M_PUT_IMP_VOL_10DELTA_DFLT | AA3: Date | AB3: 1M_PUT_IMP_VOL_25DELTA_DFLT | AC3: 1M_PUT_IMP_VOL_50DELTA_DFLT | AD3: 2M_CALL_IMP_VOL_10DELTA_DFLT | AE3: 2M_CALL_IMP_VOL_25DELTA_DFLT | AF3: 2M_CALL_IMP_VOL_50DELTA_DFLT | AG3: 2M_PUT_IMP_VOL_10DELTA_DFLT | AH3: 2M_PUT_IMP_VOL_25DELTA_DFLT | AI3: 2M_PUT_IMP_VOL_50DELTA_DFLT | AJ3: 3M_CALL_IMP_VOL_10DELTA_DFLT | AK3: 3M_CALL_IMP_VOL_25DELTA_DFLT | AL3: 3M_CALL_IMP_VOL_50DELTA_DFLT | AM3: 3M_PUT_IMP_VOL_10DELTA_DFLT | AN3: 3M_PUT_IMP_VOL_25DELTA_DFLT | AO3: 3M_PUT_IMP_VOL_50DELTA_DFLT | AP3: HIST_CALL_IMP_VOL | AQ3: HIST_PUT_IMP_VOL | AR3: VOLATILITY_10D | AS3: VOLATILITY_30D | AT3: VOLATILITY_90D | AU3: PUT_CALL_VOLUME_RATIO_CUR_DAY | AV3: OPEN_INT_TOTAL_CALL | AW3: OPEN_INT_TOTAL_PUT | AX3: VOLUME_TOTAL_CALL | AY3: VOLUME_TOTAL_PUT
A4: =BDH(A$1,B$3:Y$3,Settings!$C$9,IF(Settings!$D$9="","",Settings!$D$9),"Dir=V","Dts=S","Sort=A","Days=T","Fill=B") | AA4: =BDH(AA$1,AB$3:AY$3,Settings!$C$9,IF(Settings!$D$9="","",Settings!$D$9),"Dir=V","Dts=S","Sort=A","Days=T","Fill=B")

Sheet Vol BNO
A1: =IF(Settings!$B$10="Y","BNO US Equity","") | AA1: =IF(Settings!$B$10="Y","BNO US Equity","")
A2: implied-vol surface (moneyness) | AA2: implied-vol surface (delta, realized, volume)
A3: Date | B3: 30DAY_IMPVOL_90.0%MNY_DF | C3: 30DAY_IMPVOL_95.0%MNY_DF | D3: 30DAY_IMPVOL_100.0%MNY_DF | E3: 30DAY_IMPVOL_105.0%MNY_DF | F3: 30DAY_IMPVOL_110.0%MNY_DF | G3: 60DAY_IMPVOL_90.0%MNY_DF | H3: 60DAY_IMPVOL_95.0%MNY_DF | I3: 60DAY_IMPVOL_100.0%MNY_DF | J3: 60DAY_IMPVOL_105.0%MNY_DF | K3: 60DAY_IMPVOL_110.0%MNY_DF | L3: 3MTH_IMPVOL_90.0%MNY_DF | M3: 3MTH_IMPVOL_95.0%MNY_DF | N3: 3MTH_IMPVOL_100.0%MNY_DF | O3: 3MTH_IMPVOL_105.0%MNY_DF | P3: 3MTH_IMPVOL_110.0%MNY_DF | Q3: 6MTH_IMPVOL_90.0%MNY_DF | R3: 6MTH_IMPVOL_95.0%MNY_DF | S3: 6MTH_IMPVOL_100.0%MNY_DF | T3: 6MTH_IMPVOL_105.0%MNY_DF | U3: 6MTH_IMPVOL_110.0%MNY_DF | V3: 1M_CALL_IMP_VOL_10DELTA_DFLT | W3: 1M_CALL_IMP_VOL_25DELTA_DFLT | X3: 1M_CALL_IMP_VOL_50DELTA_DFLT | Y3: 1M_PUT_IMP_VOL_10DELTA_DFLT | AA3: Date | AB3: 1M_PUT_IMP_VOL_25DELTA_DFLT | AC3: 1M_PUT_IMP_VOL_50DELTA_DFLT | AD3: 2M_CALL_IMP_VOL_10DELTA_DFLT | AE3: 2M_CALL_IMP_VOL_25DELTA_DFLT | AF3: 2M_CALL_IMP_VOL_50DELTA_DFLT | AG3: 2M_PUT_IMP_VOL_10DELTA_DFLT | AH3: 2M_PUT_IMP_VOL_25DELTA_DFLT | AI3: 2M_PUT_IMP_VOL_50DELTA_DFLT | AJ3: 3M_CALL_IMP_VOL_10DELTA_DFLT | AK3: 3M_CALL_IMP_VOL_25DELTA_DFLT | AL3: 3M_CALL_IMP_VOL_50DELTA_DFLT | AM3: 3M_PUT_IMP_VOL_10DELTA_DFLT | AN3: 3M_PUT_IMP_VOL_25DELTA_DFLT | AO3: 3M_PUT_IMP_VOL_50DELTA_DFLT | AP3: HIST_CALL_IMP_VOL | AQ3: HIST_PUT_IMP_VOL | AR3: VOLATILITY_10D | AS3: VOLATILITY_30D | AT3: VOLATILITY_90D | AU3: PUT_CALL_VOLUME_RATIO_CUR_DAY | AV3: OPEN_INT_TOTAL_CALL | AW3: OPEN_INT_TOTAL_PUT | AX3: VOLUME_TOTAL_CALL | AY3: VOLUME_TOTAL_PUT
A4: =BDH(A$1,B$3:Y$3,Settings!$C$10,IF(Settings!$D$10="","",Settings!$D$10),"Dir=V","Dts=S","Sort=A","Days=T","Fill=B") | AA4: =BDH(AA$1,AB$3:AY$3,Settings!$C$10,IF(Settings!$D$10="","",Settings!$D$10),"Dir=V","Dts=S","Sort=A","Days=T","Fill=B")

Sheet Vol XLE
A1: =IF(Settings!$B$10="Y","XLE US Equity","") | AA1: =IF(Settings!$B$10="Y","XLE US Equity","")
A2: implied-vol surface (moneyness) | AA2: implied-vol surface (delta, realized, volume)
A3: Date | B3: 30DAY_IMPVOL_90.0%MNY_DF | C3: 30DAY_IMPVOL_95.0%MNY_DF | D3: 30DAY_IMPVOL_100.0%MNY_DF | E3: 30DAY_IMPVOL_105.0%MNY_DF | F3: 30DAY_IMPVOL_110.0%MNY_DF | G3: 60DAY_IMPVOL_90.0%MNY_DF | H3: 60DAY_IMPVOL_95.0%MNY_DF | I3: 60DAY_IMPVOL_100.0%MNY_DF | J3: 60DAY_IMPVOL_105.0%MNY_DF | K3: 60DAY_IMPVOL_110.0%MNY_DF | L3: 3MTH_IMPVOL_90.0%MNY_DF | M3: 3MTH_IMPVOL_95.0%MNY_DF | N3: 3MTH_IMPVOL_100.0%MNY_DF | O3: 3MTH_IMPVOL_105.0%MNY_DF | P3: 3MTH_IMPVOL_110.0%MNY_DF | Q3: 6MTH_IMPVOL_90.0%MNY_DF | R3: 6MTH_IMPVOL_95.0%MNY_DF | S3: 6MTH_IMPVOL_100.0%MNY_DF | T3: 6MTH_IMPVOL_105.0%MNY_DF | U3: 6MTH_IMPVOL_110.0%MNY_DF | V3: 1M_CALL_IMP_VOL_10DELTA_DFLT | W3: 1M_CALL_IMP_VOL_25DELTA_DFLT | X3: 1M_CALL_IMP_VOL_50DELTA_DFLT | Y3: 1M_PUT_IMP_VOL_10DELTA_DFLT | AA3: Date | AB3: 1M_PUT_IMP_VOL_25DELTA_DFLT | AC3: 1M_PUT_IMP_VOL_50DELTA_DFLT | AD3: 2M_CALL_IMP_VOL_10DELTA_DFLT | AE3: 2M_CALL_IMP_VOL_25DELTA_DFLT | AF3: 2M_CALL_IMP_VOL_50DELTA_DFLT | AG3: 2M_PUT_IMP_VOL_10DELTA_DFLT | AH3: 2M_PUT_IMP_VOL_25DELTA_DFLT | AI3: 2M_PUT_IMP_VOL_50DELTA_DFLT | AJ3: 3M_CALL_IMP_VOL_10DELTA_DFLT | AK3: 3M_CALL_IMP_VOL_25DELTA_DFLT | AL3: 3M_CALL_IMP_VOL_50DELTA_DFLT | AM3: 3M_PUT_IMP_VOL_10DELTA_DFLT | AN3: 3M_PUT_IMP_VOL_25DELTA_DFLT | AO3: 3M_PUT_IMP_VOL_50DELTA_DFLT | AP3: HIST_CALL_IMP_VOL | AQ3: HIST_PUT_IMP_VOL | AR3: VOLATILITY_10D | AS3: VOLATILITY_30D | AT3: VOLATILITY_90D | AU3: PUT_CALL_VOLUME_RATIO_CUR_DAY | AV3: OPEN_INT_TOTAL_CALL | AW3: OPEN_INT_TOTAL_PUT | AX3: VOLUME_TOTAL_CALL | AY3: VOLUME_TOTAL_PUT
A4: =BDH(A$1,B$3:Y$3,Settings!$C$10,IF(Settings!$D$10="","",Settings!$D$10),"Dir=V","Dts=S","Sort=A","Days=T","Fill=B") | AA4: =BDH(AA$1,AB$3:AY$3,Settings!$C$10,IF(Settings!$D$10="","",Settings!$D$10),"Dir=V","Dts=S","Sort=A","Days=T","Fill=B")

Sheet Vol XOP
A1: =IF(Settings!$B$10="Y","XOP US Equity","") | AA1: =IF(Settings!$B$10="Y","XOP US Equity","")
A2: implied-vol surface (moneyness) | AA2: implied-vol surface (delta, realized, volume)
A3: Date | B3: 30DAY_IMPVOL_90.0%MNY_DF | C3: 30DAY_IMPVOL_95.0%MNY_DF | D3: 30DAY_IMPVOL_100.0%MNY_DF | E3: 30DAY_IMPVOL_105.0%MNY_DF | F3: 30DAY_IMPVOL_110.0%MNY_DF | G3: 60DAY_IMPVOL_90.0%MNY_DF | H3: 60DAY_IMPVOL_95.0%MNY_DF | I3: 60DAY_IMPVOL_100.0%MNY_DF | J3: 60DAY_IMPVOL_105.0%MNY_DF | K3: 60DAY_IMPVOL_110.0%MNY_DF | L3: 3MTH_IMPVOL_90.0%MNY_DF | M3: 3MTH_IMPVOL_95.0%MNY_DF | N3: 3MTH_IMPVOL_100.0%MNY_DF | O3: 3MTH_IMPVOL_105.0%MNY_DF | P3: 3MTH_IMPVOL_110.0%MNY_DF | Q3: 6MTH_IMPVOL_90.0%MNY_DF | R3: 6MTH_IMPVOL_95.0%MNY_DF | S3: 6MTH_IMPVOL_100.0%MNY_DF | T3: 6MTH_IMPVOL_105.0%MNY_DF | U3: 6MTH_IMPVOL_110.0%MNY_DF | V3: 1M_CALL_IMP_VOL_10DELTA_DFLT | W3: 1M_CALL_IMP_VOL_25DELTA_DFLT | X3: 1M_CALL_IMP_VOL_50DELTA_DFLT | Y3: 1M_PUT_IMP_VOL_10DELTA_DFLT | AA3: Date | AB3: 1M_PUT_IMP_VOL_25DELTA_DFLT | AC3: 1M_PUT_IMP_VOL_50DELTA_DFLT | AD3: 2M_CALL_IMP_VOL_10DELTA_DFLT | AE3: 2M_CALL_IMP_VOL_25DELTA_DFLT | AF3: 2M_CALL_IMP_VOL_50DELTA_DFLT | AG3: 2M_PUT_IMP_VOL_10DELTA_DFLT | AH3: 2M_PUT_IMP_VOL_25DELTA_DFLT | AI3: 2M_PUT_IMP_VOL_50DELTA_DFLT | AJ3: 3M_CALL_IMP_VOL_10DELTA_DFLT | AK3: 3M_CALL_IMP_VOL_25DELTA_DFLT | AL3: 3M_CALL_IMP_VOL_50DELTA_DFLT | AM3: 3M_PUT_IMP_VOL_10DELTA_DFLT | AN3: 3M_PUT_IMP_VOL_25DELTA_DFLT | AO3: 3M_PUT_IMP_VOL_50DELTA_DFLT | AP3: HIST_CALL_IMP_VOL | AQ3: HIST_PUT_IMP_VOL | AR3: VOLATILITY_10D | AS3: VOLATILITY_30D | AT3: VOLATILITY_90D | AU3: PUT_CALL_VOLUME_RATIO_CUR_DAY | AV3: OPEN_INT_TOTAL_CALL | AW3: OPEN_INT_TOTAL_PUT | AX3: VOLUME_TOTAL_CALL | AY3: VOLUME_TOTAL_PUT
A4: =BDH(A$1,B$3:Y$3,Settings!$C$10,IF(Settings!$D$10="","",Settings!$D$10),"Dir=V","Dts=S","Sort=A","Days=T","Fill=B") | AA4: =BDH(AA$1,AB$3:AY$3,Settings!$C$10,IF(Settings!$D$10="","",Settings!$D$10),"Dir=V","Dts=S","Sort=A","Days=T","Fill=B")

Sheet Vol OXY
A1: =IF(Settings!$B$10="Y","OXY US Equity","") | AA1: =IF(Settings!$B$10="Y","OXY US Equity","")
A2: implied-vol surface (moneyness) | AA2: implied-vol surface (delta, realized, volume)
A3: Date | B3: 30DAY_IMPVOL_90.0%MNY_DF | C3: 30DAY_IMPVOL_95.0%MNY_DF | D3: 30DAY_IMPVOL_100.0%MNY_DF | E3: 30DAY_IMPVOL_105.0%MNY_DF | F3: 30DAY_IMPVOL_110.0%MNY_DF | G3: 60DAY_IMPVOL_90.0%MNY_DF | H3: 60DAY_IMPVOL_95.0%MNY_DF | I3: 60DAY_IMPVOL_100.0%MNY_DF | J3: 60DAY_IMPVOL_105.0%MNY_DF | K3: 60DAY_IMPVOL_110.0%MNY_DF | L3: 3MTH_IMPVOL_90.0%MNY_DF | M3: 3MTH_IMPVOL_95.0%MNY_DF | N3: 3MTH_IMPVOL_100.0%MNY_DF | O3: 3MTH_IMPVOL_105.0%MNY_DF | P3: 3MTH_IMPVOL_110.0%MNY_DF | Q3: 6MTH_IMPVOL_90.0%MNY_DF | R3: 6MTH_IMPVOL_95.0%MNY_DF | S3: 6MTH_IMPVOL_100.0%MNY_DF | T3: 6MTH_IMPVOL_105.0%MNY_DF | U3: 6MTH_IMPVOL_110.0%MNY_DF | V3: 1M_CALL_IMP_VOL_10DELTA_DFLT | W3: 1M_CALL_IMP_VOL_25DELTA_DFLT | X3: 1M_CALL_IMP_VOL_50DELTA_DFLT | Y3: 1M_PUT_IMP_VOL_10DELTA_DFLT | AA3: Date | AB3: 1M_PUT_IMP_VOL_25DELTA_DFLT | AC3: 1M_PUT_IMP_VOL_50DELTA_DFLT | AD3: 2M_CALL_IMP_VOL_10DELTA_DFLT | AE3: 2M_CALL_IMP_VOL_25DELTA_DFLT | AF3: 2M_CALL_IMP_VOL_50DELTA_DFLT | AG3: 2M_PUT_IMP_VOL_10DELTA_DFLT | AH3: 2M_PUT_IMP_VOL_25DELTA_DFLT | AI3: 2M_PUT_IMP_VOL_50DELTA_DFLT | AJ3: 3M_CALL_IMP_VOL_10DELTA_DFLT | AK3: 3M_CALL_IMP_VOL_25DELTA_DFLT | AL3: 3M_CALL_IMP_VOL_50DELTA_DFLT | AM3: 3M_PUT_IMP_VOL_10DELTA_DFLT | AN3: 3M_PUT_IMP_VOL_25DELTA_DFLT | AO3: 3M_PUT_IMP_VOL_50DELTA_DFLT | AP3: HIST_CALL_IMP_VOL | AQ3: HIST_PUT_IMP_VOL | AR3: VOLATILITY_10D | AS3: VOLATILITY_30D | AT3: VOLATILITY_90D | AU3: PUT_CALL_VOLUME_RATIO_CUR_DAY | AV3: OPEN_INT_TOTAL_CALL | AW3: OPEN_INT_TOTAL_PUT | AX3: VOLUME_TOTAL_CALL | AY3: VOLUME_TOTAL_PUT
A4: =BDH(A$1,B$3:Y$3,Settings!$C$10,IF(Settings!$D$10="","",Settings!$D$10),"Dir=V","Dts=S","Sort=A","Days=T","Fill=B") | AA4: =BDH(AA$1,AB$3:AY$3,Settings!$C$10,IF(Settings!$D$10="","",Settings!$D$10),"Dir=V","Dts=S","Sort=A","Days=T","Fill=B")

Sheet Vol XOM
A1: =IF(Settings!$B$11="Y","XOM US Equity","") | AA1: =IF(Settings!$B$11="Y","XOM US Equity","")
A2: implied-vol surface (moneyness) | AA2: implied-vol surface (delta, realized, volume)
A3: Date | B3: 30DAY_IMPVOL_90.0%MNY_DF | C3: 30DAY_IMPVOL_95.0%MNY_DF | D3: 30DAY_IMPVOL_100.0%MNY_DF | E3: 30DAY_IMPVOL_105.0%MNY_DF | F3: 30DAY_IMPVOL_110.0%MNY_DF | G3: 60DAY_IMPVOL_90.0%MNY_DF | H3: 60DAY_IMPVOL_95.0%MNY_DF | I3: 60DAY_IMPVOL_100.0%MNY_DF | J3: 60DAY_IMPVOL_105.0%MNY_DF | K3: 60DAY_IMPVOL_110.0%MNY_DF | L3: 3MTH_IMPVOL_90.0%MNY_DF | M3: 3MTH_IMPVOL_95.0%MNY_DF | N3: 3MTH_IMPVOL_100.0%MNY_DF | O3: 3MTH_IMPVOL_105.0%MNY_DF | P3: 3MTH_IMPVOL_110.0%MNY_DF | Q3: 6MTH_IMPVOL_90.0%MNY_DF | R3: 6MTH_IMPVOL_95.0%MNY_DF | S3: 6MTH_IMPVOL_100.0%MNY_DF | T3: 6MTH_IMPVOL_105.0%MNY_DF | U3: 6MTH_IMPVOL_110.0%MNY_DF | V3: 1M_CALL_IMP_VOL_10DELTA_DFLT | W3: 1M_CALL_IMP_VOL_25DELTA_DFLT | X3: 1M_CALL_IMP_VOL_50DELTA_DFLT | Y3: 1M_PUT_IMP_VOL_10DELTA_DFLT | AA3: Date | AB3: 1M_PUT_IMP_VOL_25DELTA_DFLT | AC3: 1M_PUT_IMP_VOL_50DELTA_DFLT | AD3: 2M_CALL_IMP_VOL_10DELTA_DFLT | AE3: 2M_CALL_IMP_VOL_25DELTA_DFLT | AF3: 2M_CALL_IMP_VOL_50DELTA_DFLT | AG3: 2M_PUT_IMP_VOL_10DELTA_DFLT | AH3: 2M_PUT_IMP_VOL_25DELTA_DFLT | AI3: 2M_PUT_IMP_VOL_50DELTA_DFLT | AJ3: 3M_CALL_IMP_VOL_10DELTA_DFLT | AK3: 3M_CALL_IMP_VOL_25DELTA_DFLT | AL3: 3M_CALL_IMP_VOL_50DELTA_DFLT | AM3: 3M_PUT_IMP_VOL_10DELTA_DFLT | AN3: 3M_PUT_IMP_VOL_25DELTA_DFLT | AO3: 3M_PUT_IMP_VOL_50DELTA_DFLT | AP3: HIST_CALL_IMP_VOL | AQ3: HIST_PUT_IMP_VOL | AR3: VOLATILITY_10D | AS3: VOLATILITY_30D | AT3: VOLATILITY_90D | AU3: PUT_CALL_VOLUME_RATIO_CUR_DAY | AV3: OPEN_INT_TOTAL_CALL | AW3: OPEN_INT_TOTAL_PUT | AX3: VOLUME_TOTAL_CALL | AY3: VOLUME_TOTAL_PUT
A4: =BDH(A$1,B$3:Y$3,Settings!$C$11,IF(Settings!$D$11="","",Settings!$D$11),"Dir=V","Dts=S","Sort=A","Days=T","Fill=B") | AA4: =BDH(AA$1,AB$3:AY$3,Settings!$C$11,IF(Settings!$D$11="","",Settings!$D$11),"Dir=V","Dts=S","Sort=A","Days=T","Fill=B")

Sheet Vol DAL
A1: =IF(Settings!$B$11="Y","DAL US Equity","") | AA1: =IF(Settings!$B$11="Y","DAL US Equity","")
A2: implied-vol surface (moneyness) | AA2: implied-vol surface (delta, realized, volume)
A3: Date | B3: 30DAY_IMPVOL_90.0%MNY_DF | C3: 30DAY_IMPVOL_95.0%MNY_DF | D3: 30DAY_IMPVOL_100.0%MNY_DF | E3: 30DAY_IMPVOL_105.0%MNY_DF | F3: 30DAY_IMPVOL_110.0%MNY_DF | G3: 60DAY_IMPVOL_90.0%MNY_DF | H3: 60DAY_IMPVOL_95.0%MNY_DF | I3: 60DAY_IMPVOL_100.0%MNY_DF | J3: 60DAY_IMPVOL_105.0%MNY_DF | K3: 60DAY_IMPVOL_110.0%MNY_DF | L3: 3MTH_IMPVOL_90.0%MNY_DF | M3: 3MTH_IMPVOL_95.0%MNY_DF | N3: 3MTH_IMPVOL_100.0%MNY_DF | O3: 3MTH_IMPVOL_105.0%MNY_DF | P3: 3MTH_IMPVOL_110.0%MNY_DF | Q3: 6MTH_IMPVOL_90.0%MNY_DF | R3: 6MTH_IMPVOL_95.0%MNY_DF | S3: 6MTH_IMPVOL_100.0%MNY_DF | T3: 6MTH_IMPVOL_105.0%MNY_DF | U3: 6MTH_IMPVOL_110.0%MNY_DF | V3: 1M_CALL_IMP_VOL_10DELTA_DFLT | W3: 1M_CALL_IMP_VOL_25DELTA_DFLT | X3: 1M_CALL_IMP_VOL_50DELTA_DFLT | Y3: 1M_PUT_IMP_VOL_10DELTA_DFLT | AA3: Date | AB3: 1M_PUT_IMP_VOL_25DELTA_DFLT | AC3: 1M_PUT_IMP_VOL_50DELTA_DFLT | AD3: 2M_CALL_IMP_VOL_10DELTA_DFLT | AE3: 2M_CALL_IMP_VOL_25DELTA_DFLT | AF3: 2M_CALL_IMP_VOL_50DELTA_DFLT | AG3: 2M_PUT_IMP_VOL_10DELTA_DFLT | AH3: 2M_PUT_IMP_VOL_25DELTA_DFLT | AI3: 2M_PUT_IMP_VOL_50DELTA_DFLT | AJ3: 3M_CALL_IMP_VOL_10DELTA_DFLT | AK3: 3M_CALL_IMP_VOL_25DELTA_DFLT | AL3: 3M_CALL_IMP_VOL_50DELTA_DFLT | AM3: 3M_PUT_IMP_VOL_10DELTA_DFLT | AN3: 3M_PUT_IMP_VOL_25DELTA_DFLT | AO3: 3M_PUT_IMP_VOL_50DELTA_DFLT | AP3: HIST_CALL_IMP_VOL | AQ3: HIST_PUT_IMP_VOL | AR3: VOLATILITY_10D | AS3: VOLATILITY_30D | AT3: VOLATILITY_90D | AU3: PUT_CALL_VOLUME_RATIO_CUR_DAY | AV3: OPEN_INT_TOTAL_CALL | AW3: OPEN_INT_TOTAL_PUT | AX3: VOLUME_TOTAL_CALL | AY3: VOLUME_TOTAL_PUT
A4: =BDH(A$1,B$3:Y$3,Settings!$C$11,IF(Settings!$D$11="","",Settings!$D$11),"Dir=V","Dts=S","Sort=A","Days=T","Fill=B") | AA4: =BDH(AA$1,AB$3:AY$3,Settings!$C$11,IF(Settings!$D$11="","",Settings!$D$11),"Dir=V","Dts=S","Sort=A","Days=T","Fill=B")

Sheet Vol JETS
A1: =IF(Settings!$B$11="Y","JETS US Equity","") | AA1: =IF(Settings!$B$11="Y","JETS US Equity","")
A2: implied-vol surface (moneyness) | AA2: implied-vol surface (delta, realized, volume)
A3: Date | B3: 30DAY_IMPVOL_90.0%MNY_DF | C3: 30DAY_IMPVOL_95.0%MNY_DF | D3: 30DAY_IMPVOL_100.0%MNY_DF | E3: 30DAY_IMPVOL_105.0%MNY_DF | F3: 30DAY_IMPVOL_110.0%MNY_DF | G3: 60DAY_IMPVOL_90.0%MNY_DF | H3: 60DAY_IMPVOL_95.0%MNY_DF | I3: 60DAY_IMPVOL_100.0%MNY_DF | J3: 60DAY_IMPVOL_105.0%MNY_DF | K3: 60DAY_IMPVOL_110.0%MNY_DF | L3: 3MTH_IMPVOL_90.0%MNY_DF | M3: 3MTH_IMPVOL_95.0%MNY_DF | N3: 3MTH_IMPVOL_100.0%MNY_DF | O3: 3MTH_IMPVOL_105.0%MNY_DF | P3: 3MTH_IMPVOL_110.0%MNY_DF | Q3: 6MTH_IMPVOL_90.0%MNY_DF | R3: 6MTH_IMPVOL_95.0%MNY_DF | S3: 6MTH_IMPVOL_100.0%MNY_DF | T3: 6MTH_IMPVOL_105.0%MNY_DF | U3: 6MTH_IMPVOL_110.0%MNY_DF | V3: 1M_CALL_IMP_VOL_10DELTA_DFLT | W3: 1M_CALL_IMP_VOL_25DELTA_DFLT | X3: 1M_CALL_IMP_VOL_50DELTA_DFLT | Y3: 1M_PUT_IMP_VOL_10DELTA_DFLT | AA3: Date | AB3: 1M_PUT_IMP_VOL_25DELTA_DFLT | AC3: 1M_PUT_IMP_VOL_50DELTA_DFLT | AD3: 2M_CALL_IMP_VOL_10DELTA_DFLT | AE3: 2M_CALL_IMP_VOL_25DELTA_DFLT | AF3: 2M_CALL_IMP_VOL_50DELTA_DFLT | AG3: 2M_PUT_IMP_VOL_10DELTA_DFLT | AH3: 2M_PUT_IMP_VOL_25DELTA_DFLT | AI3: 2M_PUT_IMP_VOL_50DELTA_DFLT | AJ3: 3M_CALL_IMP_VOL_10DELTA_DFLT | AK3: 3M_CALL_IMP_VOL_25DELTA_DFLT | AL3: 3M_CALL_IMP_VOL_50DELTA_DFLT | AM3: 3M_PUT_IMP_VOL_10DELTA_DFLT | AN3: 3M_PUT_IMP_VOL_25DELTA_DFLT | AO3: 3M_PUT_IMP_VOL_50DELTA_DFLT | AP3: HIST_CALL_IMP_VOL | AQ3: HIST_PUT_IMP_VOL | AR3: VOLATILITY_10D | AS3: VOLATILITY_30D | AT3: VOLATILITY_90D | AU3: PUT_CALL_VOLUME_RATIO_CUR_DAY | AV3: OPEN_INT_TOTAL_CALL | AW3: OPEN_INT_TOTAL_PUT | AX3: VOLUME_TOTAL_CALL | AY3: VOLUME_TOTAL_PUT
A4: =BDH(A$1,B$3:Y$3,Settings!$C$11,IF(Settings!$D$11="","",Settings!$D$11),"Dir=V","Dts=S","Sort=A","Days=T","Fill=B") | AA4: =BDH(AA$1,AB$3:AY$3,Settings!$C$11,IF(Settings!$D$11="","",Settings!$D$11),"Dir=V","Dts=S","Sort=A","Days=T","Fill=B")

Sheet Vol SPY
A1: =IF(Settings!$B$11="Y","SPY US Equity","") | AA1: =IF(Settings!$B$11="Y","SPY US Equity","")
A2: implied-vol surface (moneyness) | AA2: implied-vol surface (delta, realized, volume)
A3: Date | B3: 30DAY_IMPVOL_90.0%MNY_DF | C3: 30DAY_IMPVOL_95.0%MNY_DF | D3: 30DAY_IMPVOL_100.0%MNY_DF | E3: 30DAY_IMPVOL_105.0%MNY_DF | F3: 30DAY_IMPVOL_110.0%MNY_DF | G3: 60DAY_IMPVOL_90.0%MNY_DF | H3: 60DAY_IMPVOL_95.0%MNY_DF | I3: 60DAY_IMPVOL_100.0%MNY_DF | J3: 60DAY_IMPVOL_105.0%MNY_DF | K3: 60DAY_IMPVOL_110.0%MNY_DF | L3: 3MTH_IMPVOL_90.0%MNY_DF | M3: 3MTH_IMPVOL_95.0%MNY_DF | N3: 3MTH_IMPVOL_100.0%MNY_DF | O3: 3MTH_IMPVOL_105.0%MNY_DF | P3: 3MTH_IMPVOL_110.0%MNY_DF | Q3: 6MTH_IMPVOL_90.0%MNY_DF | R3: 6MTH_IMPVOL_95.0%MNY_DF | S3: 6MTH_IMPVOL_100.0%MNY_DF | T3: 6MTH_IMPVOL_105.0%MNY_DF | U3: 6MTH_IMPVOL_110.0%MNY_DF | V3: 1M_CALL_IMP_VOL_10DELTA_DFLT | W3: 1M_CALL_IMP_VOL_25DELTA_DFLT | X3: 1M_CALL_IMP_VOL_50DELTA_DFLT | Y3: 1M_PUT_IMP_VOL_10DELTA_DFLT | AA3: Date | AB3: 1M_PUT_IMP_VOL_25DELTA_DFLT | AC3: 1M_PUT_IMP_VOL_50DELTA_DFLT | AD3: 2M_CALL_IMP_VOL_10DELTA_DFLT | AE3: 2M_CALL_IMP_VOL_25DELTA_DFLT | AF3: 2M_CALL_IMP_VOL_50DELTA_DFLT | AG3: 2M_PUT_IMP_VOL_10DELTA_DFLT | AH3: 2M_PUT_IMP_VOL_25DELTA_DFLT | AI3: 2M_PUT_IMP_VOL_50DELTA_DFLT | AJ3: 3M_CALL_IMP_VOL_10DELTA_DFLT | AK3: 3M_CALL_IMP_VOL_25DELTA_DFLT | AL3: 3M_CALL_IMP_VOL_50DELTA_DFLT | AM3: 3M_PUT_IMP_VOL_10DELTA_DFLT | AN3: 3M_PUT_IMP_VOL_25DELTA_DFLT | AO3: 3M_PUT_IMP_VOL_50DELTA_DFLT | AP3: HIST_CALL_IMP_VOL | AQ3: HIST_PUT_IMP_VOL | AR3: VOLATILITY_10D | AS3: VOLATILITY_30D | AT3: VOLATILITY_90D | AU3: PUT_CALL_VOLUME_RATIO_CUR_DAY | AV3: OPEN_INT_TOTAL_CALL | AW3: OPEN_INT_TOTAL_PUT | AX3: VOLUME_TOTAL_CALL | AY3: VOLUME_TOTAL_PUT
A4: =BDH(A$1,B$3:Y$3,Settings!$C$11,IF(Settings!$D$11="","",Settings!$D$11),"Dir=V","Dts=S","Sort=A","Days=T","Fill=B") | AA4: =BDH(AA$1,AB$3:AY$3,Settings!$C$11,IF(Settings!$D$11="","",Settings!$D$11),"Dir=V","Dts=S","Sort=A","Days=T","Fill=B")

Sheet CL Fut 2016
A1: =IF(Settings!$B$12="Y","CLF"&IF(A$2<Settings!$B$3,"16","6")&" Comdty","") | J1: =IF(Settings!$B$12="Y","CLG"&IF(J$2<Settings!$B$3,"16","6")&" Comdty","") | S1: =IF(Settings!$B$12="Y","CLH"&IF(S$2<Settings!$B$3,"16","6")&" Comdty","") | AB1: =IF(Settings!$B$12="Y","CLJ"&IF(AB$2<Settings!$B$3,"16","6")&" Comdty","") | AK1: =IF(Settings!$B$12="Y","CLK"&IF(AK$2<Settings!$B$3,"16","6")&" Comdty","") | AT1: =IF(Settings!$B$12="Y","CLM"&IF(AT$2<Settings!$B$3,"16","6")&" Comdty","") | BC1: =IF(Settings!$B$12="Y","CLN"&IF(BC$2<Settings!$B$3,"16","6")&" Comdty","") | BL1: =IF(Settings!$B$12="Y","CLQ"&IF(BL$2<Settings!$B$3,"16","6")&" Comdty","") | BU1: =IF(Settings!$B$12="Y","CLU"&IF(BU$2<Settings!$B$3,"16","6")&" Comdty","") | CD1: =IF(Settings!$B$12="Y","CLV"&IF(CD$2<Settings!$B$3,"16","6")&" Comdty","") | CM1: =IF(Settings!$B$12="Y","CLX"&IF(CM$2<Settings!$B$3,"16","6")&" Comdty","") | CV1: =IF(Settings!$B$12="Y","CLZ"&IF(CV$2<Settings!$B$3,"16","6")&" Comdty","")
A2: =WORKDAY(DATE(2016,1-1,25),-3) | B2: =IF(A$1="","",BDP(A$1,"LAST_TRADEABLE_DT")) | J2: =WORKDAY(DATE(2016,2-1,25),-3) | K2: =IF(J$1="","",BDP(J$1,"LAST_TRADEABLE_DT")) | S2: =WORKDAY(DATE(2016,3-1,25),-3) | T2: =IF(S$1="","",BDP(S$1,"LAST_TRADEABLE_DT")) | AB2: =WORKDAY(DATE(2016,4-1,25),-3) | AC2: =IF(AB$1="","",BDP(AB$1,"LAST_TRADEABLE_DT")) | AK2: =WORKDAY(DATE(2016,5-1,25),-3) | AL2: =IF(AK$1="","",BDP(AK$1,"LAST_TRADEABLE_DT")) | AT2: =WORKDAY(DATE(2016,6-1,25),-3) | AU2: =IF(AT$1="","",BDP(AT$1,"LAST_TRADEABLE_DT")) | BC2: =WORKDAY(DATE(2016,7-1,25),-3) | BD2: =IF(BC$1="","",BDP(BC$1,"LAST_TRADEABLE_DT")) | BL2: =WORKDAY(DATE(2016,8-1,25),-3) | BM2: =IF(BL$1="","",BDP(BL$1,"LAST_TRADEABLE_DT")) | BU2: =WORKDAY(DATE(2016,9-1,25),-3) | BV2: =IF(BU$1="","",BDP(BU$1,"LAST_TRADEABLE_DT")) | CD2: =WORKDAY(DATE(2016,10-1,25),-3) | CE2: =IF(CD$1="","",BDP(CD$1,"LAST_TRADEABLE_DT")) | CM2: =WORKDAY(DATE(2016,11-1,25),-3) | CN2: =IF(CM$1="","",BDP(CM$1,"LAST_TRADEABLE_DT")) | CV2: =WORKDAY(DATE(2016,12-1,25),-3) | CW2: =IF(CV$1="","",BDP(CV$1,"LAST_TRADEABLE_DT"))
A3: Date | B3: PX_OPEN | C3: PX_HIGH | D3: PX_LOW | E3: PX_LAST | F3: PX_SETTLE | G3: PX_VOLUME | H3: OPEN_INT | J3: Date | K3: PX_OPEN | L3: PX_HIGH | M3: PX_LOW | N3: PX_LAST | O3: PX_SETTLE | P3: PX_VOLUME | Q3: OPEN_INT | S3: Date | T3: PX_OPEN | U3: PX_HIGH | V3: PX_LOW | W3: PX_LAST | X3: PX_SETTLE | Y3: PX_VOLUME | Z3: OPEN_INT | AB3: Date | AC3: PX_OPEN | AD3: PX_HIGH | AE3: PX_LOW | AF3: PX_LAST | AG3: PX_SETTLE | AH3: PX_VOLUME | AI3: OPEN_INT | AK3: Date | AL3: PX_OPEN | AM3: PX_HIGH | AN3: PX_LOW | AO3: PX_LAST | AP3: PX_SETTLE | AQ3: PX_VOLUME | AR3: OPEN_INT | AT3: Date | AU3: PX_OPEN | AV3: PX_HIGH | AW3: PX_LOW | AX3: PX_LAST | AY3: PX_SETTLE | AZ3: PX_VOLUME | BA3: OPEN_INT | BC3: Date | BD3: PX_OPEN | BE3: PX_HIGH | BF3: PX_LOW | BG3: PX_LAST | BH3: PX_SETTLE | BI3: PX_VOLUME | BJ3: OPEN_INT | BL3: Date | BM3: PX_OPEN | BN3: PX_HIGH | BO3: PX_LOW | BP3: PX_LAST | BQ3: PX_SETTLE | BR3: PX_VOLUME | BS3: OPEN_INT | BU3: Date | BV3: PX_OPEN | BW3: PX_HIGH | BX3: PX_LOW | BY3: PX_LAST | BZ3: PX_SETTLE | CA3: PX_VOLUME | CB3: OPEN_INT | CD3: Date | CE3: PX_OPEN | CF3: PX_HIGH | CG3: PX_LOW | CH3: PX_LAST | CI3: PX_SETTLE | CJ3: PX_VOLUME | CK3: OPEN_INT | CM3: Date | CN3: PX_OPEN | CO3: PX_HIGH | CP3: PX_LOW | CQ3: PX_LAST | CR3: PX_SETTLE | CS3: PX_VOLUME | CT3: OPEN_INT | CV3: Date | CW3: PX_OPEN | CX3: PX_HIGH | CY3: PX_LOW | CZ3: PX_LAST | DA3: PX_SETTLE | DB3: PX_VOLUME | DC3: OPEN_INT
